File: DP800 Tensile Tests/Fehlemann_Test_WP_KL_2024_1012.TRA
$Fehlemann_Test_WP_KL_2024_101.ZSE
Material:                               St
Auftrags-Nr.:                           WP_KL_2024_101
Probe:                                  1_0°_B
Vorkraft:                               100 N
Probengeometrie:                        H12,5x50
Messlänge:                              50.372 mm
Probendicke a0:                         1.49 mm
Probenbreite b0:                        12.6 mm
Prüfgeschwindigkeit:                    1 mm/min
Datum:                                  26.09.2024
Maschinendaten:                         4204 WN:800315
Traversenwegaufnehmer WN:800315
Videoextensometer
Videoextensometer - Querdehnung
Kraftsensor ID:0 WN:800316 50 kN

Bemerkung:
$
      Prüfzeit	   Standardweg	 Spannug        Breitenänderung	       Dehnung	 wahre Dehnung	wahre Spannung
 1.998047e-002	-4.159720e-005	 1.965188e+002	-3.813959e-004	-8.257999e-005	 0.000000e+000	 1.046976e+001
 1.799805e-001	-1.814471e-003	 1.970195e+002	-9.132345e-004	-3.602142e-003	 0.000000e+000	 1.049607e+001
 3.599805e-001	-3.766726e-003	 1.977706e+002	 6.196364e-004	-7.477817e-003	 0.000000e+000	 1.053567e+001
 7.199805e-001	-2.960565e-003	 2.873935e+002	-7.649120e-004	-5.877402e-003	 0.000000e+000	 1.531033e+001
 1.039980e+000	-1.206315e-003	 3.737619e+002	-6.145331e-005	-2.394812e-003	 0.000000e+000	 1.991213e+001
 1.779980e+000	-6.929198e-004	 5.683621e+002	 1.595734e-003	-1.375605e-003	 0.000000e+000	 3.027975e+001
 1.899980e+000	 1.971177e-003	 6.009067e+002	 5.437654e-004	 3.913239e-003	 0.000000e+000	 3.201527e+001
 1.959980e+000	 3.976726e-003	 6.170956e+002	 2.432493e-004	 7.894713e-003	 0.000000e+000	 3.287909e+001
 2.179981e+000	 4.452185e-003	 6.751752e+002	-3.362345e-004	 8.838610e-003	 0.000000e+000	 3.597394e+001
 2.319980e+000	 2.514919e-003	 7.128102e+002	 2.148282e-003	 4.992692e-003	 0.000000e+000	 3.797770e+001
 2.379981e+000	 4.779189e-004	 7.286652e+002	 2.544411e-003	 9.487788e-004	 0.000000e+000	 3.882087e+001
 2.459980e+000	 9.015318e-004	 7.497775e+002	 2.825798e-003	 1.789748e-003	 0.000000e+000	 3.994600e+001
 2.579980e+000	 3.250467e-003	 7.817380e+002	 2.899152e-003	 6.452924e-003	 0.000000e+000	 4.165071e+001
 2.999980e+000	 3.822564e-003	 8.948932e+002	 3.083766e-003	 7.588668e-003	 0.000000e+000	 4.768011e+001
 3.379981e+000	 5.170532e-003	 1.000705e+003	 2.715396e-004	 1.026469e-002	 0.000000e+000	 5.331921e+001
 3.519980e+000	 6.874306e-003	 1.037923e+003	 2.160604e-003	 1.364708e-002	 0.000000e+000	 5.530411e+001
 3.839980e+000	 7.397016e-003	 1.127045e+003	 1.328765e-003	 1.468477e-002	 0.000000e+000	 6.005347e+001
 4.279981e+000	 9.025790e-003	 1.249797e+003	 2.594484e-003	 1.791827e-002	 0.000000e+000	 6.659632e+001
 4.559980e+000	 1.089018e-002	 1.327320e+003	 3.334540e-003	 2.161952e-002	 0.000000e+000	 7.072981e+001
 4.679980e+000	 1.341503e-002	 1.360365e+003	 3.436765e-003	 2.663191e-002	 0.000000e+000	 7.249435e+001
 4.899981e+000	 1.144482e-002	 1.420030e+003	 1.543453e-003	 2.272060e-002	 0.000000e+000	 7.567097e+001
 5.179980e+000	 1.339822e-002	 1.497469e+003	 1.547765e-003	 2.659854e-002	 0.000000e+000	 7.980068e+001
 5.939981e+000	 1.509221e-002	 1.702668e+003	 2.320475e-003	 2.996150e-002	 0.000000e+000	 9.073881e+001
 6.219980e+000	 1.612443e-002	 1.776352e+003	 2.848862e-003	 3.201071e-002	 0.000000e+000	 9.466754e+001
 6.419981e+000	 1.787078e-002	 1.830510e+003	 3.212641e-003	 3.547760e-002	 1.412430e-005	 9.755715e+001
 6.799981e+000	 1.945537e-002	 1.930563e+003	 2.477922e-003	 3.862338e-002	 1.564387e-005	 1.028928e+002
 7.359981e+000	 2.134379e-002	 2.077598e+003	 4.829410e-003	 4.237233e-002	 9.137402e-006	 1.107334e+002
 7.559980e+000	 2.081556e-002	 2.130922e+003	 4.227733e-003	 4.132367e-002	 0.000000e+000	 1.135743e+002
 7.959980e+000	 2.283408e-002	 2.231476e+003	 4.850120e-003	 4.533089e-002	 0.000000e+000	 1.189384e+002
 8.259980e+000	 2.457747e-002	 2.310000e+003	 3.416733e-003	 4.879192e-002	 3.793721e-006	 1.231280e+002
 8.739981e+000	 2.628227e-002	 2.427745e+003	 6.262894e-003	 5.217635e-002	 2.406291e-006	 1.294085e+002
 9.219980e+000	 2.638244e-002	 2.543738e+003	 3.642185e-003	 5.237519e-002	 0.000000e+000	 1.355916e+002
 9.379980e+000	 2.845634e-002	 2.582374e+003	 3.382056e-003	 5.649237e-002	 0.000000e+000	 1.376567e+002
 9.879980e+000	 3.034363e-002	 2.700703e+003	 4.915088e-003	 6.023907e-002	 1.358874e-006	 1.439698e+002
 1.015998e+001	 3.092325e-002	 2.763956e+003	 7.871141e-003	 6.138975e-002	 0.000000e+000	 1.473434e+002
 1.035998e+001	 3.273611e-002	 2.811104e+003	 4.656540e-003	 6.498870e-002	 1.582059e-005	 1.498622e+002
 1.049998e+001	 3.452666e-002	 2.841229e+003	 5.042830e-003	 6.854335e-002	 4.235237e-005	 1.514736e+002
 1.095998e+001	 3.386831e-002	 2.940615e+003	 8.316991e-003	 6.723636e-002	 0.000000e+000	 1.567701e+002
 1.165998e+001	 3.563650e-002	 3.086148e+003	 7.664765e-003	 7.074663e-002	 0.000000e+000	 1.645345e+002
 1.213998e+001	 3.589908e-002	 3.181195e+003	 8.579056e-003	 7.126792e-002	 0.000000e+000	 1.696027e+002
 1.241998e+001	 3.735115e-002	 3.238190e+003	 1.025814e-002	 7.415062e-002	 0.000000e+000	 1.726463e+002
 1.273998e+001	 3.904776e-002	 3.295769e+003	 9.747410e-003	 7.751877e-002	 0.000000e+000	 1.757221e+002
 1.303998e+001	 4.088993e-002	 3.355017e+003	 9.179671e-003	 8.117591e-002	 1.494254e-005	 1.788876e+002
 1.325998e+001	 4.285076e-002	 3.392819e+003	 9.941024e-003	 8.506860e-002	 4.255754e-005	 1.809102e+002
 1.353998e+001	 4.097493e-002	 3.444222e+003	 9.005203e-003	 8.134465e-002	 0.000000e+000	 1.836443e+002
 1.389998e+001	 4.187756e-002	 3.506057e+003	 8.994141e-003	 8.313658e-002	 0.000000e+000	 1.869446e+002
 1.415998e+001	 4.358987e-002	 3.551787e+003	 8.542266e-003	 8.653591e-002	 9.664887e-006	 1.893894e+002
 1.487998e+001	 4.416205e-002	 3.673871e+003	 8.064636e-003	 8.767180e-002	 0.000000e+000	 1.959014e+002
 1.507998e+001	 4.603166e-002	 3.705915e+003	 8.919798e-003	 9.138342e-002	 1.202159e-005	 1.976174e+002
 1.557998e+001	 4.714105e-002	 3.790114e+003	 8.334282e-003	 9.358581e-002	 8.851474e-006	 2.021117e+002
 1.909998e+001	 5.764434e-002	 4.336112e+003	 5.652798e-003	 1.144372e-001	 5.399006e-005	 2.312758e+002
 2.413998e+001	 6.857527e-002	 4.999355e+003	 6.064991e-003	 1.361377e-001	 7.253677e-005	 2.667091e+002
 3.013998e+001	 8.488441e-002	 5.699815e+003	 1.322928e-002	 1.685150e-001	 1.867032e-004	 3.041760e+002
 3.507998e+001	 9.780111e-002	 6.216441e+003	 1.562428e-002	 1.941577e-001	 2.885200e-004	 3.318311e+002
 3.913998e+001	 1.068576e-001	 6.606225e+003	 1.196899e-002	 2.121368e-001	 3.516594e-004	 3.527009e+002
 4.513998e+001	 1.249405e-001	 7.122517e+003	 1.042041e-002	 2.480355e-001	 5.560685e-004	 3.804015e+002
 4.921998e+001	 1.381144e-001	 7.435028e+003	 1.250060e-002	 2.741889e-001	 7.239844e-004	 3.971958e+002
 5.413998e+001	 1.557608e-001	 7.784842e+003	 1.383964e-002	 3.092210e-001	 9.694262e-004	 4.160289e+002
 5.805998e+001	 1.684392e-001	 8.043947e+003	 1.823802e-002	 3.343905e-001	 1.143407e-003	 4.299835e+002
 6.313998e+001	 1.850788e-001	 8.347613e+003	 2.015931e-002	 3.674239e-001	 1.382576e-003	 4.463627e+002
 6.657998e+001	 1.990499e-001	 8.544467e+003	 2.484693e-002	 3.951599e-001	 1.600707e-003	 4.570150e+002
 7.175998e+001	 2.193268e-001	 8.812668e+003	 2.607028e-002	 4.354140e-001	 1.922430e-003	 4.715492e+002
 7.513998e+001	 2.343609e-001	 8.976226e+003	 2.641383e-002	 4.652601e-001	 2.171441e-003	 4.804435e+002
 7.867998e+001	 2.496562e-001	 9.140200e+003	 2.717176e-002	 4.956248e-001	 2.425439e-003	 4.893680e+002
 8.363998e+001	 2.699481e-001	 9.358333e+003	 2.829948e-002	 5.359090e-001	 2.762136e-003	 5.012476e+002
 8.713998e+001	 2.860343e-001	 9.507621e+003	 2.747599e-002	 5.678438e-001	 3.036018e-003	 5.094055e+002
 9.021998e+001	 3.000374e-001	 9.627785e+003	 3.017851e-002	 5.956432e-001	 3.277295e-003	 5.159863e+002
 9.485998e+001	 3.202127e-001	 9.806197e+003	 2.991189e-002	 6.356957e-001	 3.623239e-003	 5.257572e+002
 9.913998e+001	 3.401144e-001	 9.964080e+003	 3.303580e-002	 6.752053e-001	 3.969775e-003	 5.344317e+002
 1.021400e+002	 3.552434e-001	 1.006572e+004	 3.626728e-002	 7.052398e-001	 4.238601e-003	 5.400443e+002
 1.054600e+002	 3.709348e-001	 1.018038e+004	 3.753880e-002	 7.363908e-001	 4.514593e-003	 5.463648e+002
 1.094000e+002	 3.909858e-001	 1.030872e+004	 3.740658e-002	 7.761965e-001	 4.872564e-003	 5.534713e+002
 1.133000e+002	 4.113867e-001	 1.043289e+004	 4.038386e-002	 8.166971e-001	 5.238560e-003	 5.603630e+002
 1.169200e+002	 4.318517e-001	 1.054596e+004	 4.199370e-002	 8.573248e-001	 5.608989e-003	 5.666644e+002
 1.201400e+002	 4.488882e-001	 1.063800e+004	 4.464351e-002	 8.911462e-001	 5.917876e-003	 5.718018e+002
 1.231400e+002	 4.656316e-001	 1.072654e+004	 4.657709e-002	 9.243857e-001	 6.221928e-003	 5.767507e+002
 1.265600e+002	 4.832307e-001	 1.082217e+004	 4.887686e-002	 9.593239e-001	 6.540654e-003	 5.820941e+002
 1.303800e+002	 5.032758e-001	 1.092431e+004	 4.943415e-002	 9.991180e-001	 6.905571e-003	 5.878195e+002
 1.337000e+002	 5.234509e-001	 1.101026e+004	 5.174596e-002	 1.039170e+000	 7.277727e-003	 5.926792e+002
 1.371400e+002	 5.438524e-001	 1.110064e+004	 5.391357e-002	 1.079672e+000	 7.652892e-003	 5.977835e+002
 1.405200e+002	 5.641156e-001	 1.118317e+004	 5.658818e-002	 1.119899e+000	 8.027518e-003	 6.024675e+002
 1.439400e+002	 5.850281e-001	 1.125977e+004	 5.618025e-002	 1.161415e+000	 8.416545e-003	 6.068434e+002
 1.471400e+002	 6.014053e-001	 1.133588e+004	 6.121048e-002	 1.193928e+000	 8.716320e-003	 6.111413e+002
 1.501400e+002	 6.199816e-001	 1.140572e+004	 6.080202e-002	 1.230806e+000	 9.061125e-003	 6.151309e+002
 1.531400e+002	 6.374799e-001	 1.147257e+004	 6.358618e-002	 1.265544e+000	 9.385499e-003	 6.189481e+002
 1.561400e+002	 6.552847e-001	 1.153690e+004	 6.628080e-002	 1.300891e+000	 9.716537e-003	 6.226363e+002
 1.592800e+002	 6.767470e-001	 1.160274e+004	 6.649792e-002	 1.343498e+000	 1.011890e-002	 6.264530e+002
 1.630400e+002	 6.971394e-001	 1.167710e+004	 7.242145e-002	 1.383982e+000	 1.049757e-002	 6.307192e+002
 1.659800e+002	 7.176450e-001	 1.173843e+004	 7.070496e-002	 1.424690e+000	 1.088216e-002	 6.342866e+002
 1.690400e+002	 7.381107e-001	 1.180035e+004	 7.431105e-002	 1.465319e+000	 1.126566e-002	 6.378877e+002
 1.725000e+002	 7.584988e-001	 1.186677e+004	 7.556763e-002	 1.505794e+000	 1.164615e-002	 6.417343e+002
 1.754200e+002	 7.786489e-001	 1.192585e+004	 8.012383e-002	 1.545797e+000	 1.202400e-002	 6.451834e+002
 1.786600e+002	 7.988784e-001	 1.199003e+004	 8.138651e-002	 1.585957e+000	 1.240176e-002	 6.489115e+002
 1.815000e+002	 8.194747e-001	 1.204427e+004	 8.206012e-002	 1.626845e+000	 1.278950e-002	 6.521094e+002
 1.849600e+002	 8.403252e-001	 1.210635e+004	 8.728057e-002	 1.668239e+000	 1.317975e-002	 6.557378e+002
 1.879400e+002	 8.607156e-001	 1.216510e+004	 8.618738e-002	 1.708718e+000	 1.356182e-002	 6.591821e+002
 1.907200e+002	 8.812295e-001	 1.221308e+004	 8.821815e-002	 1.749443e+000	 1.394935e-002	 6.620470e+002
 1.936000e+002	 9.013031e-001	 1.226907e+004	 9.245477e-002	 1.789294e+000	 1.432574e-002	 6.653427e+002
 1.965400e+002	 9.216082e-001	 1.231981e+004	 9.267592e-002	 1.829604e+000	 1.470807e-002	 6.683587e+002
 1.994400e+002	 9.416599e-001	 1.236980e+004	 9.733915e-002	 1.869411e+000	 1.508552e-002	 6.713327e+002
 2.021200e+002	 9.619217e-001	 1.241619e+004	 1.000662e-001	 1.909635e+000	 1.546799e-002	 6.741167e+002
 2.047600e+002	 9.823375e-001	 1.246150e+004	 1.035543e-001	 1.950166e+000	 1.585365e-002	 6.768459e+002
 2.074400e+002	 1.002462e+000	 1.250473e+004	 1.034134e-001	 1.990117e+000	 1.623408e-002	 6.794598e+002
 2.095800e+002	 1.016812e+000	 1.254228e+004	 1.050860e-001	 2.018605e+000	 1.650328e-002	 6.816906e+002
 2.120000e+002	 1.036098e+000	 1.258209e+004	 1.077615e-001	 2.056892e+000	 1.686810e-002	 6.841106e+002
 2.144400e+002	 1.054409e+000	 1.262014e+004	 1.111741e-001	 2.093244e+000	 1.721429e-002	 6.864239e+002
 2.168600e+002	 1.072626e+000	 1.265686e+004	 1.109177e-001	 2.129409e+000	 1.755891e-002	 6.886648e+002
 2.192800e+002	 1.085871e+000	 1.269407e+004	 1.176920e-001	 2.155704e+000	 1.780630e-002	 6.908676e+002
 2.221400e+002	 1.108816e+000	 1.274156e+004	 1.180882e-001	 2.201254e+000	 1.823971e-002	 6.937610e+002
 2.251400e+002	 1.136329e+000	 1.278779e+004	 1.189015e-001	 2.255874e+000	 1.876232e-002	 6.966501e+002
 2.277600e+002	 1.158964e+000	 1.282175e+004	 1.204531e-001	 2.300810e+000	 1.919326e-002	 6.988073e+002
 2.301600e+002	 1.177047e+000	 1.285905e+004	 1.251416e-001	 2.336708e+000	 1.953441e-002	 7.010861e+002
 2.325800e+002	 1.197135e+000	 1.289043e+004	 1.246919e-001	 2.376588e+000	 1.991621e-002	 7.030706e+002
 2.350000e+002	 1.218699e+000	 1.292639e+004	 1.292766e-001	 2.419396e+000	 2.032523e-002	 7.053270e+002
 2.374200e+002	 1.237635e+000	 1.296136e+004	 1.282945e-001	 2.456990e+000	 2.068328e-002	 7.074944e+002
 2.401400e+002	 1.261039e+000	 1.299974e+004	 1.318365e-001	 2.503451e+000	 2.112703e-002	 7.099114e+002
 2.431400e+002	 1.286803e+000	 1.303863e+004	 1.346655e-001	 2.554600e+000	 2.161632e-002	 7.123903e+002
 2.458800e+002	 1.310510e+000	 1.307919e+004	 1.371826e-001	 2.601664e+000	 2.206491e-002	 7.149340e+002
 2.483000e+002	 1.329836e+000	 1.310856e+004	 1.383210e-001	 2.640030e+000	 2.243154e-002	 7.168074e+002
 2.507200e+002	 1.352562e+000	 1.314160e+004	 1.393963e-001	 2.685147e+000	 2.286294e-002	 7.189303e+002
 2.531400e+002	 1.372516e+000	 1.317014e+004	 1.414849e-001	 2.724760e+000	 2.324170e-002	 7.207694e+002
 2.555600e+002	 1.393830e+000	 1.319927e+004	 1.450000e-001	 2.767073e+000	 2.364651e-002	 7.226608e+002
 2.581400e+002	 1.416369e+000	 1.322839e+004	 1.451624e-001	 2.811818e+000	 2.407490e-002	 7.245705e+002
 2.611400e+002	 1.443566e+000	 1.326319e+004	 1.520449e-001	 2.865810e+000	 2.459168e-002	 7.268580e+002
 2.640400e+002	 1.465552e+000	 1.330166e+004	 1.523634e-001	 2.909457e+000	 2.500623e-002	 7.292755e+002
 2.664600e+002	 1.489595e+000	 1.333003e+004	 1.540603e-001	 2.957187e+000	 2.546336e-002	 7.311699e+002
 2.688800e+002	 1.510118e+000	 1.335665e+004	 1.558281e-001	 2.997932e+000	 2.585272e-002	 7.329199e+002
 2.713000e+002	 1.530821e+000	 1.338469e+004	 1.568003e-001	 3.039031e+000	 2.624498e-002	 7.347515e+002
 2.737200e+002	 1.552475e+000	 1.341122e+004	 1.592452e-001	 3.082020e+000	 2.665591e-002	 7.365153e+002
 2.761400e+002	 1.573713e+000	 1.343935e+004	 1.608531e-001	 3.124182e+000	 2.705816e-002	 7.383615e+002
 2.791400e+002	 1.601624e+000	 1.347189e+004	 1.642317e-001	 3.179591e+000	 2.758784e-002	 7.405471e+002
 2.821400e+002	 1.629134e+000	 1.350452e+004	 1.658830e-001	 3.234204e+000	 2.810948e-002	 7.427335e+002
 2.846000e+002	 1.650023e+000	 1.353139e+004	 1.696609e-001	 3.275675e+000	 2.850480e-002	 7.445102e+002
 2.870200e+002	 1.672930e+000	 1.355651e+004	 1.713870e-001	 3.321149e+000	 2.893936e-002	 7.462206e+002
 2.894400e+002	 1.694641e+000	 1.358196e+004	 1.729738e-001	 3.364253e+000	 2.935062e-002	 7.479334e+002
 2.918600e+002	 1.716547e+000	 1.360349e+004	 1.738071e-001	 3.407739e+000	 2.976656e-002	 7.494341e+002
 2.942800e+002	 1.736420e+000	 1.362710e+004	 1.783546e-001	 3.447192e+000	 3.014259e-002	 7.510215e+002
 2.971400e+002	 1.762903e+000	 1.365623e+004	 1.806254e-001	 3.499768e+000	 3.064416e-002	 7.530090e+002
 3.001400e+002	 1.788224e+000	 1.368452e+004	 1.837085e-001	 3.550034e+000	 3.112333e-002	 7.549352e+002
 3.027400e+002	 1.812842e+000	 1.370821e+004	 1.860930e-001	 3.598909e+000	 3.159011e-002	 7.565995e+002
 3.051600e+002	 1.833801e+000	 1.373342e+004	 1.880534e-001	 3.640515e+000	 3.198585e-002	 7.582948e+002
 3.075800e+002	 1.855334e+000	 1.375461e+004	 1.893282e-001	 3.683264e+000	 3.239366e-002	 7.597783e+002
 3.099800e+002	 1.876210e+000	 1.377731e+004	 1.924321e-001	 3.724707e+000	 3.278823e-002	 7.613363e+002
 3.124000e+002	 1.900125e+000	 1.379984e+004	 1.946348e-001	 3.772185e+000	 3.324106e-002	 7.629303e+002
 3.151400e+002	 1.925038e+000	 1.381937e+004	 1.982467e-001	 3.821642e+000	 3.371370e-002	 7.643739e+002
 3.181400e+002	 1.952793e+000	 1.384849e+004	 2.002082e-001	 3.876743e+000	 3.423788e-002	 7.663912e+002
 3.208800e+002	 1.976982e+000	 1.387453e+004	 2.015240e-001	 3.924763e+000	 3.469428e-002	 7.681869e+002
 3.233000e+002	 2.000584e+000	 1.389447e+004	 2.034632e-001	 3.971619e+000	 3.514101e-002	 7.696379e+002
 3.257000e+002	 2.019140e+000	 1.391475e+004	 2.092215e-001	 4.008456e+000	 3.549073e-002	 7.710342e+002
 3.281200e+002	 2.040964e+000	 1.393436e+004	 2.104558e-001	 4.051783e+000	 3.590315e-002	 7.724424e+002
 3.305400e+002	 2.062502e+000	 1.395380e+004	 2.113221e-001	 4.094541e+000	 3.630995e-002	 7.738380e+002
 3.331400e+002	 2.087989e+000	 1.397475e+004	 2.146374e-001	 4.145137e+000	 3.679171e-002	 7.753762e+002
 3.361400e+002	 2.117302e+000	 1.399886e+004	 2.159764e-001	 4.203331e+000	 3.734552e-002	 7.771482e+002
 3.390200e+002	 2.143716e+000	 1.401947e+004	 2.186396e-001	 4.255768e+000	 3.784460e-002	 7.786840e+002
 3.414400e+002	 2.167246e+000	 1.403783e+004	 2.214119e-001	 4.302480e+000	 3.828899e-002	 7.800530e+002
 3.438600e+002	 2.188255e+000	 1.405602e+004	 2.238142e-001	 4.344189e+000	 3.868510e-002	 7.813761e+002
 3.462600e+002	 2.210312e+000	 1.407405e+004	 2.257834e-001	 4.387977e+000	 3.910109e-002	 7.827064e+002
 3.487000e+002	 2.234877e+000	 1.409249e+004	 2.282660e-001	 4.436744e+000	 3.956464e-002	 7.840981e+002
 3.511400e+002	 2.257300e+000	 1.411035e+004	 2.303933e-001	 4.481260e+000	 3.998730e-002	 7.854263e+002
 3.541400e+002	 2.284697e+000	 1.412888e+004	 2.321481e-001	 4.535649e+000	 4.050441e-002	 7.868668e+002
 3.571600e+002	 2.313433e+000	 1.415091e+004	 2.344219e-001	 4.592696e+000	 4.104576e-002	 7.885237e+002
 3.596000e+002	 2.339917e+000	 1.416576e+004	 2.344497e-001	 4.645273e+000	 4.154600e-002	 7.897481e+002
 3.620200e+002	 2.364795e+000	 1.418220e+004	 2.388959e-001	 4.694661e+000	 4.201495e-002	 7.910377e+002
 3.644400e+002	 2.382403e+000	 1.419672e+004	 2.407699e-001	 4.729616e+000	 4.234590e-002	 7.921118e+002
 3.668600e+002	 2.408531e+000	 1.421341e+004	 2.429563e-001	 4.781488e+000	 4.283820e-002	 7.934358e+002
 3.692800e+002	 2.430943e+000	 1.422910e+004	 2.446060e-001	 4.825979e+000	 4.325987e-002	 7.946487e+002
 3.721600e+002	 2.459793e+000	 1.424645e+004	 2.457758e-001	 4.883255e+000	 4.380326e-002	 7.960527e+002
 3.751600e+002	 2.488827e+000	 1.426523e+004	 2.499738e-001	 4.940892e+000	 4.434940e-002	 7.975398e+002
 3.777600e+002	 2.513494e+000	 1.428083e+004	 2.495129e-001	 4.989863e+000	 4.481330e-002	 7.987847e+002
 3.801800e+002	 2.537889e+000	 1.429577e+004	 2.538858e-001	 5.038292e+000	 4.527198e-002	 7.999890e+002
 3.826000e+002	 2.560156e+000	 1.431079e+004	 2.573472e-001	 5.082498e+000	 4.569009e-002	 8.011665e+002
 3.850200e+002	 2.584553e+000	 1.432581e+004	 2.586936e-001	 5.130931e+000	 4.614839e-002	 8.023770e+002
 3.874400e+002	 2.608937e+000	 1.433983e+004	 2.584808e-001	 5.179338e+000	 4.660652e-002	 8.035320e+002
 3.901600e+002	 2.634368e+000	 1.435685e+004	 2.620658e-001	 5.229826e+000	 4.708344e-002	 8.048719e+002
 3.931600e+002	 2.664455e+000	 1.437338e+004	 2.654668e-001	 5.289556e+000	 4.764839e-002	 8.062555e+002
 3.959200e+002	 2.692237e+000	 1.438573e+004	 2.654057e-001	 5.344709e+000	 4.817059e-002	 8.073709e+002
 3.983400e+002	 2.717333e+000	 1.439950e+004	 2.698698e-001	 5.394530e+000	 4.864134e-002	 8.085258e+002
 4.007600e+002	 2.738840e+000	 1.441084e+004	 2.713377e-001	 5.437226e+000	 4.904471e-002	 8.094907e+002
 4.031800e+002	 2.761706e+000	 1.442436e+004	 2.747798e-001	 5.482620e+000	 4.947298e-002	 8.105989e+002
 4.056000e+002	 2.786542e+000	 1.443922e+004	 2.763814e-001	 5.531926e+000	 4.993790e-002	 8.118128e+002
 4.081600e+002	 2.810674e+000	 1.445624e+004	 2.779064e-001	 5.579834e+000	 5.038870e-002	 8.131388e+002
 4.111600e+002	 2.839272e+000	 1.446692e+004	 2.802598e-001	 5.636606e+000	 5.092534e-002	 8.141771e+002
 4.140600e+002	 2.869272e+000	 1.448278e+004	 2.830318e-001	 5.696163e+000	 5.148667e-002	 8.155288e+002
 4.164600e+002	 2.892378e+000	 1.449521e+004	 2.850977e-001	 5.742034e+000	 5.191873e-002	 8.165831e+002
 4.188600e+002	 2.915872e+000	 1.450739e+004	 2.866677e-001	 5.788675e+000	 5.235799e-002	 8.176299e+002
 4.213000e+002	 2.939151e+000	 1.451933e+004	 2.903125e-001	 5.834889e+000	 5.279307e-002	 8.186599e+002
 4.237200e+002	 2.963481e+000	 1.453159e+004	 2.912788e-001	 5.883191e+000	 5.324767e-002	 8.197254e+002
 4.261600e+002	 2.985924e+000	 1.454227e+004	 2.937148e-001	 5.927744e+000	 5.366698e-002	 8.206730e+002
 4.291600e+002	 3.015481e+000	 1.455312e+004	 2.961248e-001	 5.986421e+000	 5.421986e-002	 8.217401e+002
 4.321600e+002	 3.045243e+000	 1.457048e+004	 2.993558e-001	 6.045506e+000	 5.477445e-002	 8.231787e+002
 4.346000e+002	 3.068711e+000	 1.458091e+004	 3.014685e-001	 6.092096e+000	 5.521246e-002	 8.241298e+002
 4.370200e+002	 3.092627e+000	 1.459034e+004	 3.036410e-001	 6.139575e+000	 5.565898e-002	 8.250318e+002
 4.394400e+002	 3.116653e+000	 1.459977e+004	 3.050748e-001	 6.187273e+000	 5.610737e-002	 8.259359e+002
 4.418400e+002	 3.140638e+000	 1.461095e+004	 3.092098e-001	 6.234887e+000	 5.655427e-002	 8.269391e+002
 4.442600e+002	 3.163417e+000	 1.462247e+004	 3.108927e-001	 6.280110e+000	 5.697829e-002	 8.279430e+002
 4.471600e+002	 3.191921e+000	 1.463524e+004	 3.142808e-001	 6.336697e+000	 5.750907e-002	 8.291071e+002
 4.501600e+002	 3.221885e+000	 1.464458e+004	 3.167298e-001	 6.396183e+000	 5.806788e-002	 8.301006e+002
 4.527000e+002	 3.247256e+000	 1.465835e+004	 3.186404e-001	 6.446549e+000	 5.853913e-002	 8.312743e+002
 4.551200e+002	 3.271043e+000	 1.467120e+004	 3.222218e-001	 6.493771e+000	 5.898078e-002	 8.323721e+002
 4.575400e+002	 3.296636e+000	 1.467796e+004	 3.224915e-001	 6.544579e+000	 5.945774e-002	 8.331528e+002
 4.599600e+002	 3.322033e+000	 1.468572e+004	 3.257389e-001	 6.594998e+000	 5.993053e-002	 8.339877e+002
 4.623800e+002	 3.345683e+000	 1.469465e+004	 3.261727e-001	 6.641949e+000	 6.037011e-002	 8.348623e+002
 4.651600e+002	 3.374485e+000	 1.470783e+004	 3.300828e-001	 6.699129e+000	 6.090455e-002	 8.360593e+002
 4.681600e+002	 3.405849e+000	 1.471651e+004	 3.331238e-001	 6.761393e+000	 6.148779e-002	 8.370407e+002
 4.708400e+002	 3.430638e+000	 1.472636e+004	 3.361348e-001	 6.810604e+000	 6.194768e-002	 8.379868e+002
 4.732600e+002	 3.455711e+000	 1.473529e+004	 3.381255e-001	 6.860379e+000	 6.241291e-002	 8.388856e+002
 4.756800e+002	 3.482135e+000	 1.474380e+004	 3.398218e-001	 6.912837e+000	 6.290324e-002	 8.397821e+002
 4.781200e+002	 3.503687e+000	 1.475298e+004	 3.431468e-001	 6.955624e+000	 6.330236e-002	 8.406412e+002
 4.805400e+002	 3.530690e+000	 1.475999e+004	 3.456432e-001	 7.009231e+000	 6.380346e-002	 8.414621e+002
 4.831600e+002	 3.557514e+000	 1.476850e+004	 3.469108e-001	 7.062483e+000	 6.430055e-002	 8.423662e+002
 4.861600e+002	 3.587211e+000	 1.477793e+004	 3.514698e-001	 7.121438e+000	 6.485059e-002	 8.433681e+002
 4.890000e+002	 3.615373e+000	 1.478861e+004	 3.526588e-001	 7.177346e+000	 6.537143e-002	 8.444181e+002
 4.914200e+002	 3.640534e+000	 1.479679e+004	 3.559275e-001	 7.227296e+000	 6.583692e-002	 8.452787e+002
 4.938400e+002	 3.664994e+000	 1.480605e+004	 3.574768e-001	 7.275856e+000	 6.628888e-002	 8.461908e+002
 4.962600e+002	 3.690150e+000	 1.481240e+004	 3.624180e-001	 7.325794e+000	 6.675435e-002	 8.469473e+002
 4.986800e+002	 3.714980e+000	 1.481882e+004	 3.635528e-001	 7.375088e+000	 6.721355e-002	 8.477037e+002
 5.011600e+002	 3.740010e+000	 1.482608e+004	 3.645398e-001	 7.424778e+000	 6.767601e-002	 8.485115e+002
 5.041600e+002	 3.770890e+000	 1.483651e+004	 3.697988e-001	 7.486082e+000	 6.824585e-002	 8.495929e+002
 5.071600e+002	 3.801865e+000	 1.484302e+004	 3.721588e-001	 7.547574e+000	 6.881823e-002	 8.504518e+002
 5.101600e+002	 3.832672e+000	 1.485028e+004	 3.739068e-001	 7.608735e+000	 6.938697e-002	 8.513515e+002
 5.131600e+002	 3.864048e+000	 1.485904e+004	 3.805438e-001	 7.671024e+000	 6.996549e-002	 8.523469e+002
 5.156200e+002	 3.889087e+000	 1.486697e+004	 3.825728e-001	 7.720730e+000	 7.042665e-002	 8.531952e+002
 5.180400e+002	 3.916636e+000	 1.487565e+004	 3.828249e-001	 7.775422e+000	 7.093383e-002	 8.541266e+002
 5.204600e+002	 3.939526e+000	 1.488216e+004	 3.839497e-001	 7.820864e+000	 7.135523e-002	 8.548606e+002
 5.228800e+002	 3.965935e+000	 1.488892e+004	 3.855478e-001	 7.873291e+000	 7.184139e-002	 8.556646e+002
 5.253000e+002	 3.989096e+000	 1.489709e+004	 3.900811e-001	 7.919272e+000	 7.226695e-002	 8.564995e+002
 5.281600e+002	 4.019475e+000	 1.490369e+004	 3.935428e-001	 7.979580e+000	 7.282600e-002	 8.573573e+002
 5.311600e+002	 4.050582e+000	 1.491345e+004	 3.979438e-001	 8.041336e+000	 7.339731e-002	 8.584095e+002
 5.337800e+002	 4.078418e+000	 1.491512e+004	 3.989098e-001	 8.096597e+000	 7.391021e-002	 8.589445e+002
 5.362000e+002	 4.102985e+000	 1.492188e+004	 4.007351e-001	 8.145368e+000	 7.436120e-002	 8.597215e+002
 5.386200e+002	 4.129415e+000	 1.492789e+004	 4.061668e-001	 8.197837e+000	 7.484650e-002	 8.604848e+002
 5.410400e+002	 4.153486e+000	 1.493298e+004	 4.055616e-001	 8.245623e+000	 7.528839e-002	 8.611583e+002
 5.434600e+002	 4.178796e+000	 1.493982e+004	 4.124431e-001	 8.295869e+000	 7.575240e-002	 8.619528e+002
 5.461600e+002	 4.205327e+000	 1.495042e+004	 4.115408e-001	 8.348539e+000	 7.623762e-002	 8.629837e+002
 5.491600e+002	 4.236900e+000	 1.495634e+004	 4.146978e-001	 8.411220e+000	 7.681661e-002	 8.638250e+002
 5.519200e+002	 4.266760e+000	 1.496494e+004	 4.188473e-001	 8.470498e+000	 7.736303e-002	 8.647939e+002
 5.543600e+002	 4.291869e+000	 1.496569e+004	 4.219567e-001	 8.520345e+000	 7.782407e-002	 8.652347e+002
 5.567600e+002	 4.318784e+000	 1.497395e+004	 4.224540e-001	 8.573778e+000	 7.831598e-002	 8.661385e+002
 5.592000e+002	 4.345560e+000	 1.497570e+004	 4.246970e-001	 8.626935e+000	 7.880691e-002	 8.666639e+002
 5.616200e+002	 4.369825e+000	 1.498138e+004	 4.266158e-001	 8.675106e+000	 7.925045e-002	 8.673767e+002
 5.641600e+002	 4.396894e+000	 1.498647e+004	 4.291445e-001	 8.728844e+000	 7.974536e-002	 8.681004e+002
 5.671600e+002	 4.429593e+000	 1.499064e+004	 4.340734e-001	 8.793760e+000	 8.034342e-002	 8.688604e+002
 5.700800e+002	 4.460394e+000	 1.500007e+004	 4.359764e-001	 8.854906e+000	 8.090492e-002	 8.698955e+002
 5.725000e+002	 4.486147e+000	 1.500382e+004	 4.383208e-001	 8.906032e+000	 8.137530e-002	 8.705218e+002
 5.749400e+002	 4.510310e+000	 1.500700e+004	 4.425055e-001	 8.954001e+000	 8.181652e-002	 8.710892e+002
 5.773600e+002	 4.537556e+000	 1.501392e+004	 4.438403e-001	 9.008090e+000	 8.231289e-002	 8.719239e+002
 5.797800e+002	 4.563462e+000	 1.501743e+004	 4.481514e-001	 9.059520e+000	 8.278547e-002	 8.725388e+002
 5.822000e+002	 4.588385e+000	 1.502202e+004	 4.487977e-001	 9.108997e+000	 8.323957e-002	 8.732013e+002
 5.851600e+002	 4.620937e+000	 1.502827e+004	 4.508448e-001	 9.173622e+000	 8.383230e-002	 8.740824e+002
 5.881600e+002	 4.652999e+000	 1.503654e+004	 4.555415e-001	 9.237272e+000	 8.441517e-002	 8.750727e+002
 5.906800e+002	 4.681337e+000	 1.503821e+004	 4.577268e-001	 9.293530e+000	 8.493162e-002	 8.756205e+002
 5.931000e+002	 4.705948e+000	 1.504388e+004	 4.601761e-001	 9.342387e+000	 8.537875e-002	 8.763424e+002
 5.955200e+002	 4.731927e+000	 1.504738e+004	 4.626088e-001	 9.393962e+000	 8.585122e-002	 8.769599e+002
 5.979600e+002	 4.758647e+000	 1.504889e+004	 4.634472e-001	 9.447008e+000	 8.633751e-002	 8.774727e+002
 6.003800e+002	 4.785617e+000	 1.505131e+004	 4.663798e-001	 9.500550e+000	 8.682785e-002	 8.780431e+002
 6.031600e+002	 4.814763e+000	 1.506107e+004	 4.680928e-001	 9.558410e+000	 8.735552e-002	 8.790767e+002
 6.061600e+002	 4.848742e+000	 1.506457e+004	 4.731675e-001	 9.625866e+000	 8.797250e-002	 8.798226e+002
 6.088400e+002	 4.877172e+000	 1.506891e+004	 4.750473e-001	 9.682307e+000	 8.848806e-002	 8.805291e+002
 6.112600e+002	 4.904026e+000	 1.507225e+004	 4.778296e-001	 9.735617e+000	 8.897498e-002	 8.811521e+002
 6.136800e+002	 4.930184e+000	 1.507526e+004	 4.801288e-001	 9.787547e+000	 8.944914e-002	 8.817447e+002
 6.161000e+002	 4.956954e+000	 1.508135e+004	 4.825060e-001	 9.840693e+000	 8.993334e-002	 8.825280e+002
 6.185400e+002	 4.983363e+000	 1.508168e+004	 4.824282e-001	 9.893120e+000	 9.041231e-002	 8.829687e+002
 6.211600e+002	 5.011573e+000	 1.508402e+004	 4.874886e-001	 9.949123e+000	 9.092316e-002	 8.835554e+002
 6.241600e+002	 5.044794e+000	 1.508811e+004	 4.900290e-001	 1.001507e+001	 9.152405e-002	 8.843249e+002
 6.270000e+002	 5.076325e+000	 1.509537e+004	 4.921973e-001	 1.007767e+001	 9.209313e-002	 8.852537e+002
 6.294200e+002	 5.101721e+000	 1.509962e+004	 4.941520e-001	 1.012809e+001	 9.255167e-002	 8.859088e+002
 6.318400e+002	 5.128321e+000	 1.510062e+004	 4.957502e-001	 1.018090e+001	 9.303268e-002	 8.863923e+002
 6.342600e+002	 5.154920e+000	 1.510304e+004	 5.011597e-001	 1.023370e+001	 9.351304e-002	 8.869592e+002
 6.366800e+002	 5.180881e+000	 1.510571e+004	 5.003658e-001	 1.028524e+001	 9.398158e-002	 8.875307e+002
 6.391600e+002	 5.207600e+000	 1.510805e+004	 5.051960e-001	 1.033828e+001	 9.446368e-002	 8.880948e+002
 6.421600e+002	 5.242246e+000	 1.511414e+004	 5.073439e-001	 1.040706e+001	 9.508763e-002	 8.890066e+002
 6.451400e+002	 5.274604e+000	 1.511923e+004	 5.103768e-001	 1.047130e+001	 9.567019e-002	 8.898233e+002
 6.475600e+002	 5.300507e+000	 1.512382e+004	 5.114236e-001	 1.052272e+001	 9.613615e-002	 8.905077e+002
 6.499800e+002	 5.326078e+000	 1.512441e+004	 5.140807e-001	 1.057349e+001	 9.659701e-002	 8.909511e+002
 6.524000e+002	 5.353370e+000	 1.512850e+004	 5.188410e-001	 1.062767e+001	 9.708768e-002	 8.916285e+002
 6.548200e+002	 5.381042e+000	 1.513167e+004	 5.195866e-001	 1.068260e+001	 9.758522e-002	 8.922582e+002
 6.572600e+002	 5.408692e+000	 1.513108e+004	 5.218037e-001	 1.073750e+001	 9.808315e-002	 8.926662e+002
 6.601600e+002	 5.440750e+000	 1.513642e+004	 5.232955e-001	 1.080114e+001	 9.865850e-002	 8.934944e+002
 6.631600e+002	 5.472389e+000	 1.513868e+004	 5.275438e-001	 1.086395e+001	 9.922683e-002	 8.941338e+002
 6.657000e+002	 5.501167e+000	 1.514268e+004	 5.295248e-001	 1.092108e+001	 9.974295e-002	 8.948312e+002
 6.681200e+002	 5.529908e+000	 1.514443e+004	 5.317467e-001	 1.097814e+001	 1.002587e-001	 8.953950e+002
 6.705400e+002	 5.556929e+000	 1.514569e+004	 5.352571e-001	 1.103178e+001	 1.007435e-001	 8.959018e+002
 6.729600e+002	 5.585815e+000	 1.514869e+004	 5.379136e-001	 1.108913e+001	 1.012611e-001	 8.965422e+002
 6.753800e+002	 5.611816e+000	 1.514969e+004	 5.377387e-001	 1.114074e+001	 1.017272e-001	 8.970181e+002
 6.781600e+002	 5.642707e+000	 1.515119e+004	 5.416408e-001	 1.120207e+001	 1.022806e-001	 8.976019e+002
 6.811600e+002	 5.674809e+000	 1.515336e+004	 5.442877e-001	 1.126580e+001	 1.028551e-001	 8.982448e+002
 6.838600e+002	 5.705896e+000	 1.515703e+004	 5.467008e-001	 1.132751e+001	 1.034108e-001	 8.989607e+002
 6.862800e+002	 5.733434e+000	 1.516004e+004	 5.496488e-001	 1.138218e+001	 1.039029e-001	 8.995804e+002
 6.887000e+002	 5.759667e+000	 1.516137e+004	 5.511258e-001	 1.143426e+001	 1.043718e-001	 9.000802e+002
 6.911200e+002	 5.787639e+000	 1.516371e+004	 5.534105e-001	 1.148979e+001	 1.048713e-001	 9.006673e+002
 6.935200e+002	 5.814669e+000	 1.516688e+004	 5.546489e-001	 1.154345e+001	 1.053535e-001	 9.012893e+002
 6.961600e+002	 5.845437e+000	 1.516530e+004	 5.561574e-001	 1.160453e+001	 1.059035e-001	 9.016884e+002
 6.991600e+002	 5.879544e+000	 1.516797e+004	 5.606245e-001	 1.167224e+001	 1.065117e-001	 9.023942e+002
 7.020000e+002	 5.912310e+000	 1.516963e+004	 5.643763e-001	 1.173729e+001	 1.070958e-001	 9.030191e+002
 7.044200e+002	 5.940260e+000	 1.517080e+004	 5.673186e-001	 1.179278e+001	 1.075939e-001	 9.035371e+002
 7.068400e+002	 5.968925e+000	 1.517256e+004	 5.684842e-001	 1.184969e+001	 1.081043e-001	 9.041013e+002
 7.092600e+002	 5.997356e+000	 1.517506e+004	 5.719064e-001	 1.190613e+001	 1.086101e-001	 9.047067e+002
 7.116800e+002	 6.025500e+000	 1.517631e+004	 5.729927e-001	 1.196200e+001	 1.091109e-001	 9.052330e+002
 7.141600e+002	 6.053851e+000	 1.517906e+004	 5.755926e-001	 1.201828e+001	 1.096147e-001	 9.058523e+002
 7.171600e+002	 6.088333e+000	 1.517948e+004	 5.780917e-001	 1.208674e+001	 1.102279e-001	 9.064307e+002
 7.201600e+002	 6.118541e+000	 1.517998e+004	 5.802853e-001	 1.214671e+001	 1.107647e-001	 9.069455e+002
 7.231600e+002	 6.158115e+000	 1.518048e+004	 5.841247e-001	 1.222527e+001	 1.114676e-001	 9.076107e+002
 7.261600e+002	 6.191867e+000	 1.518315e+004	 5.890998e-001	 1.229228e+001	 1.120661e-001	 9.083122e+002
 7.286000e+002	 6.220516e+000	 1.518524e+004	 5.899998e-001	 1.234915e+001	 1.125738e-001	 9.088971e+002
 7.310200e+002	 6.246420e+000	 1.518708e+004	 5.916657e-001	 1.240058e+001	 1.130327e-001	 9.094229e+002
 7.334600e+002	 6.275042e+000	 1.518649e+004	 5.925926e-001	 1.245740e+001	 1.135402e-001	 9.098475e+002
 7.358800e+002	 6.305801e+000	 1.518624e+004	 5.976177e-001	 1.251846e+001	 1.140852e-001	 9.103265e+002
 7.383200e+002	 6.334669e+000	 1.518683e+004	 5.998099e-001	 1.257577e+001	 1.145963e-001	 9.108251e+002
 7.411600e+002	 6.365540e+000	 1.519217e+004	 6.034498e-001	 1.263706e+001	 1.151412e-001	 9.116414e+002
 7.441600e+002	 6.402175e+000	 1.519242e+004	 6.050637e-001	 1.270979e+001	 1.157891e-001	 9.122449e+002
 7.467800e+002	 6.432724e+000	 1.519575e+004	 6.082908e-001	 1.277043e+001	 1.163282e-001	 9.129362e+002
 7.492000e+002	 6.459959e+000	 1.519525e+004	 6.118295e-001	 1.282450e+001	 1.168095e-001	 9.133438e+002
 7.516400e+002	 6.489964e+000	 1.519726e+004	 6.135917e-001	 1.288407e+001	 1.173389e-001	 9.139464e+002
 7.540600e+002	 6.517964e+000	 1.519634e+004	 6.161698e-001	 1.293966e+001	 1.178333e-001	 9.143411e+002
 7.564800e+002	 6.545849e+000	 1.519734e+004	 6.187561e-001	 1.299501e+001	 1.183250e-001	 9.148494e+002
 7.591600e+002	 6.580441e+000	 1.519817e+004	 6.218747e-001	 1.306369e+001	 1.189347e-001	 9.154556e+002
 7.621600e+002	 6.613575e+000	 1.519784e+004	 6.256238e-001	 1.312947e+001	 1.195186e-001	 9.159680e+002
 7.649400e+002	 6.648502e+000	 1.520243e+004	 6.275297e-001	 1.319880e+001	 1.201325e-001	 9.168060e+002
 7.673600e+002	 6.676884e+000	 1.520293e+004	 6.314330e-001	 1.325515e+001	 1.206319e-001	 9.172925e+002
 7.697800e+002	 6.709540e+000	 1.520210e+004	 6.344448e-001	 1.331998e+001	 1.212066e-001	 9.177672e+002
 7.722000e+002	 6.736562e+000	 1.520009e+004	 6.352190e-001	 1.337362e+001	 1.216822e-001	 9.180806e+002
 7.746200e+002	 6.765900e+000	 1.519993e+004	 6.377168e-001	 1.343186e+001	 1.221978e-001	 9.185420e+002
 7.771600e+002	 6.796005e+000	 1.520151e+004	 6.422728e-001	 1.349163e+001	 1.227262e-001	 9.191218e+002
 7.801600e+002	 6.832425e+000	 1.520343e+004	 6.452287e-001	 1.356393e+001	 1.233649e-001	 9.198233e+002
 7.830800e+002	 6.868227e+000	 1.520326e+004	 6.487783e-001	 1.363501e+001	 1.239931e-001	 9.203888e+002
 7.855000e+002	 6.898600e+000	 1.520477e+004	 6.504397e-001	 1.369531e+001	 1.245252e-001	 9.209681e+002
 7.879200e+002	 6.927459e+000	 1.520518e+004	 6.528102e-001	 1.375260e+001	 1.250308e-001	 9.214573e+002
 7.903400e+002	 6.957013e+000	 1.520435e+004	 6.548368e-001	 1.381127e+001	 1.255486e-001	 9.218819e+002
 7.927600e+002	 6.987170e+000	 1.520602e+004	 6.582380e-001	 1.387114e+001	 1.260761e-001	 9.224680e+002
 7.951800e+002	 7.017523e+000	 1.520560e+004	 6.617748e-001	 1.393140e+001	 1.266073e-001	 9.229308e+002
 7.981600e+002	 7.053933e+000	 1.520585e+004	 6.626357e-001	 1.400368e+001	 1.272439e-001	 9.235314e+002
 8.011600e+002	 7.092601e+000	 1.520644e+004	 6.673778e-001	 1.408044e+001	 1.279194e-001	 9.241887e+002
 8.036400e+002	 7.124890e+000	 1.520460e+004	 6.714306e-001	 1.414454e+001	 1.284838e-001	 9.245962e+002
 8.060600e+002	 7.151001e+000	 1.520543e+004	 6.733428e-001	 1.419638e+001	 1.289393e-001	 9.250668e+002
 8.084800e+002	 7.183533e+000	 1.520326e+004	 6.750366e-001	 1.426096e+001	 1.295074e-001	 9.254578e+002
 8.109000e+002	 7.212971e+000	 1.520385e+004	 6.783388e-001	 1.431940e+001	 1.300206e-001	 9.259666e+002
 8.133200e+002	 7.243373e+000	 1.520485e+004	 6.826628e-001	 1.437976e+001	 1.305501e-001	 9.265165e+002
 8.161600e+002	 7.278695e+000	 1.520268e+004	 6.853868e-001	 1.444988e+001	 1.311659e-001	 9.269521e+002
 8.191600e+002	 7.317065e+000	 1.520101e+004	 6.898739e-001	 1.452606e+001	 1.318342e-001	 9.274671e+002
 8.218000e+002	 7.349822e+000	 1.520452e+004	 6.925553e-001	 1.459108e+001	 1.324031e-001	 9.282076e+002
 8.242200e+002	 7.380845e+000	 1.520660e+004	 6.948696e-001	 1.465267e+001	 1.329419e-001	 9.288338e+002
 8.266200e+002	 7.413188e+000	 1.520669e+004	 6.959133e-001	 1.471688e+001	 1.335039e-001	 9.293589e+002
 8.290400e+002	 7.441730e+000	 1.520593e+004	 6.991796e-001	 1.477354e+001	           0.0	           0.0
 8.314600e+002	 7.477165e+000	 1.520468e+004	 7.015725e-001	 1.484389e+001	           0.0	           0.0
 8.341600e+002	 7.511049e+000	 1.520193e+004	 7.081924e-001	 1.491116e+001	           0.0	           0.0
 8.371600e+002	 7.546189e+000	 1.520410e+004	 7.107504e-001	 1.498092e+001	           0.0	           0.0
 8.399400e+002	 7.585247e+000	 1.520109e+004	 7.149897e-001	 1.505846e+001	           0.0	           0.0
 8.423600e+002	 7.615029e+000	 1.520151e+004	 7.167754e-001	 1.511758e+001	           0.0	           0.0
 8.447800e+002	 7.645214e+000	 1.520151e+004	 7.197741e-001	 1.517751e+001	           0.0	           0.0
 8.472000e+002	 7.675937e+000	 1.520243e+004	 7.228727e-001	 1.523850e+001	           0.0	           0.0
 8.496200e+002	 7.707149e+000	 1.519943e+004	 7.251378e-001	 1.530046e+001	           0.0	           0.0
 8.521600e+002	 7.740772e+000	 1.520093e+004	 7.307000e-001	 1.536721e+001	           0.0	           0.0
 8.551600e+002	 7.776951e+000	 1.520068e+004	 7.333993e-001	 1.543903e+001	           0.0	           0.0
 8.581200e+002	 7.820099e+000	 1.519651e+004	 7.354633e-001	 1.552469e+001	           0.0	           0.0
 8.605400e+002	 7.850966e+000	 1.519609e+004	 7.401472e-001	 1.558597e+001	           0.0	           0.0
 8.629600e+002	 7.882263e+000	 1.519692e+004	 7.417574e-001	 1.564810e+001	           0.0	           0.0
 8.665800e+002	 7.929842e+000	 1.519609e+004	 7.451687e-001	 1.574256e+001	           0.0	           0.0
 8.689800e+002	 7.959962e+000	 1.519509e+004	 7.508934e-001	 1.580235e+001	           0.0	           0.0
 8.714200e+002	 7.994838e+000	 1.519117e+004	 7.532461e-001	 1.587159e+001	           0.0	           0.0
 8.738400e+002	 8.025119e+000	 1.519083e+004	 7.570655e-001	 1.593170e+001	           0.0	           0.0
 8.762800e+002	 8.058506e+000	 1.519033e+004	 7.594691e-001	 1.599799e+001	           0.0	           0.0
 8.791600e+002	 8.099190e+000	 1.519066e+004	 7.626888e-001	 1.607875e+001	           0.0	           0.0
 8.821600e+002	 8.139392e+000	 1.518975e+004	 7.666771e-001	 1.615856e+001	           0.0	           0.0
 8.847200e+002	 8.173954e+000	 1.519058e+004	 7.679188e-001	 1.622718e+001	           0.0	           0.0
 8.871600e+002	 8.207714e+000	 1.518733e+004	 7.704408e-001	 1.629420e+001	           0.0	           0.0
 8.895800e+002	 8.241541e+000	 1.518599e+004	 7.736573e-001	 1.636135e+001	           0.0	           0.0
 8.919800e+002	 8.273079e+000	 1.518457e+004	 7.778435e-001	 1.642396e+001	           0.0	           0.0
 8.944000e+002	 8.307246e+000	 1.518240e+004	 7.822278e-001	 1.649179e+001	           0.0	           0.0
 8.971600e+002	 8.347194e+000	 1.518015e+004	 7.822728e-001	 1.657110e+001	           0.0	           0.0
 9.001600e+002	 8.387283e+000	 1.517940e+004	 7.870247e-001	 1.665068e+001	           0.0	           0.0
 9.028600e+002	 8.420458e+000	 1.517715e+004	 7.912858e-001	 1.671654e+001	           0.0	           0.0
 9.052800e+002	 8.461102e+000	 1.517531e+004	 7.950647e-001	 1.679723e+001	           0.0	           0.0
 9.077000e+002	 8.493786e+000	 1.517397e+004	 7.955254e-001	 1.686212e+001	           0.0	           0.0
 9.101200e+002	 8.527598e+000	 1.517147e+004	 7.999347e-001	 1.692924e+001	           0.0	           0.0
 9.125400e+002	 8.562737e+000	 1.516955e+004	 8.040038e-001	 1.699900e+001	           0.0	           0.0
 9.151600e+002	 8.598572e+000	 1.516822e+004	 8.069068e-001	 1.707014e+001	           0.0	           0.0
 9.181600e+002	 8.641037e+000	 1.516630e+004	 8.096167e-001	 1.715444e+001	           0.0	           0.0
 9.210000e+002	 8.679574e+000	 1.516538e+004	 8.132117e-001	 1.723095e+001	           0.0	           0.0
 9.234200e+002	 8.717643e+000	 1.516471e+004	 8.149279e-001	 1.730652e+001	           0.0	           0.0
 9.258400e+002	 8.752861e+000	 1.516238e+004	 8.190247e-001	 1.737644e+001	           0.0	           0.0
 9.282600e+002	 8.787142e+000	 1.515979e+004	 8.232789e-001	 1.744449e+001	           0.0	           0.0
 9.306800e+002	 8.822674e+000	 1.515787e+004	 8.254170e-001	 1.751503e+001	           0.0	           0.0
 9.331600e+002	 8.859295e+000	 1.515161e+004	 8.293198e-001	 1.758774e+001	           0.0	           0.0
 9.361600e+002	 8.903702e+000	 1.515161e+004	 8.324848e-001	 1.767589e+001	           0.0	           0.0
 9.391400e+002	 8.945362e+000	 1.514861e+004	 8.366666e-001	 1.775860e+001	           0.0	           0.0
 9.415600e+002	 8.981690e+000	 1.514569e+004	 8.409958e-001	 1.783072e+001	           0.0	           0.0
 9.439800e+002	 9.016661e+000	 1.514352e+004	 8.438424e-001	 1.790014e+001	           0.0	           0.0
 9.464000e+002	 9.054454e+000	 1.513976e+004	 8.465868e-001	 1.797517e+001	           0.0	           0.0
 9.488200e+002	 9.088851e+000	 1.513792e+004	 8.494438e-001	 1.804346e+001	           0.0	           0.0
 9.512400e+002	 9.123263e+000	 1.513525e+004	 8.550245e-001	 1.811177e+001	           0.0	           0.0
 9.541600e+002	 9.167442e+000	 1.513016e+004	 8.575228e-001	 1.819948e+001	           0.0	           0.0
 9.571600e+002	 9.213856e+000	 1.512599e+004	 8.632178e-001	 1.829162e+001	           0.0	           0.0
 9.597200e+002	 9.249237e+000	 1.512733e+004	 8.662628e-001	 1.836186e+001	           0.0	           0.0
 9.621400e+002	 9.286766e+000	 1.512491e+004	 8.705820e-001	 1.843636e+001	           0.0	           0.0
 9.645600e+002	 9.323641e+000	 1.512149e+004	 8.730378e-001	 1.850957e+001	           0.0	           0.0
 9.669800e+002	 9.359243e+000	 1.511915e+004	 8.755899e-001	 1.858025e+001	           0.0	           0.0
 9.694000e+002	 9.396267e+000	 1.511506e+004	 8.808708e-001	 1.865375e+001	           0.0	           0.0
 9.721600e+002	 9.437187e+000	 1.510780e+004	 8.842728e-001	 1.873498e+001	           0.0	           0.0
 9.751600e+002	 9.484539e+000	 1.510538e+004	 8.918081e-001	 1.882899e+001	           0.0	           0.0
 9.778600e+002	 9.525106e+000	 1.510004e+004	 8.952401e-001	 1.890952e+001	           0.0	           0.0
 9.802800e+002	 9.563037e+000	 1.509762e+004	 8.985519e-001	 1.898482e+001	           0.0	           0.0
 9.827000e+002	 9.597916e+000	 1.509228e+004	 9.013186e-001	 1.905407e+001	           0.0	           0.0
 9.851200e+002	 9.639698e+000	 1.508953e+004	 9.049591e-001	 1.913701e+001	           0.0	           0.0
 9.875200e+002	 9.674543e+000	 1.508635e+004	 9.079704e-001	 1.920619e+001	           0.0	           0.0
 9.901600e+002	 9.714880e+000	 1.508101e+004	 9.167290e-001	 1.928627e+001	           0.0	           0.0
 9.931600e+002	 9.765423e+000	 1.507601e+004	 9.191770e-001	 1.938661e+001	           0.0	           0.0
 9.960200e+002	 9.811266e+000	 1.507017e+004	 9.216647e-001	 1.947762e+001	           0.0	           0.0
 9.984200e+002	 9.849724e+000	 1.506407e+004	 9.271255e-001	 1.955396e+001	           0.0	           0.0
 1.000840e+003	 9.887354e+000	 1.505982e+004	 9.295528e-001	 1.962867e+001	           0.0	           0.0
 1.003260e+003	 9.926622e+000	 1.505489e+004	 9.323703e-001	 1.970663e+001	           0.0	           0.0
 1.005680e+003	 9.964411e+000	 1.504813e+004	 9.359612e-001	 1.978164e+001	           0.0	           0.0
 1.008160e+003	 1.000673e+001	 1.504179e+004	 9.398698e-001	 1.986565e+001	           0.0	           0.0
 1.011160e+003	 1.005265e+001	 1.503170e+004	 9.459128e-001	 1.995683e+001	           0.0	           0.0
 1.014160e+003	 1.010387e+001	 1.502385e+004	 9.489688e-001	 2.005850e+001	           0.0	           0.0
 1.017160e+003	 1.014869e+001	 1.501576e+004	 9.549237e-001	 2.014749e+001	           0.0	           0.0
 1.020160e+003	 1.019926e+001	 1.500716e+004	 9.581007e-001	 2.024787e+001	           0.0	           0.0
 1.022620e+003	 1.023850e+001	 1.499907e+004	 9.612018e-001	 2.032577e+001	           0.0	           0.0
 1.025040e+003	 1.027769e+001	 1.499106e+004	 9.645578e-001	 2.040357e+001	           0.0	           0.0
 1.027460e+003	 1.031945e+001	 1.498446e+004	 9.648383e-001	 2.048647e+001	           0.0	           0.0
 1.029900e+003	 1.035853e+001	 1.497128e+004	 9.682348e-001	 2.056406e+001	           0.0	           0.0
 1.032300e+003	 1.039890e+001	 1.496319e+004	 9.709621e-001	 2.064420e+001	           0.0	           0.0
 1.035160e+003	 1.044670e+001	 1.495175e+004	 9.726812e-001	 2.073911e+001	           0.0	           0.0
 1.038160e+003	 1.049598e+001	 1.493632e+004	 9.746611e-001	 2.083693e+001	           0.0	           0.0
 1.040760e+003	 1.053951e+001	 1.492071e+004	 9.762014e-001	 2.092334e+001	           0.0	           0.0
 1.043180e+003	 1.057991e+001	 1.490527e+004	 9.800576e-001	 2.100355e+001	           0.0	           0.0
 1.045600e+003	 1.061750e+001	 1.489034e+004	 9.849465e-001	 2.107818e+001	           0.0	           0.0
 1.048020e+003	 1.065980e+001	 1.487047e+004	 9.812225e-001	 2.116214e+001	           0.0	           0.0
 1.050440e+003	 1.069979e+001	 1.484995e+004	 9.835198e-001	 2.124153e+001	           0.0	           0.0
 1.053160e+003	 1.074668e+001	 1.483142e+004	 9.826142e-001	 2.133462e+001	           0.0	           0.0
 1.056160e+003	 1.079953e+001	 1.480121e+004	 9.851693e-001	 2.143955e+001	           0.0	           0.0
 1.058900e+003	 1.084625e+001	 1.477593e+004	 9.862168e-001	 2.153230e+001	           0.0	           0.0
 1.061320e+003	 1.088804e+001	 1.474530e+004	 9.858541e-001	 2.161526e+001	           0.0	           0.0
 1.063740e+003	 1.092947e+001	 1.471000e+004	 9.864569e-001	 2.169752e+001	           0.0	           0.0
 1.066160e+003	 1.097245e+001	 1.463340e+004	 9.880498e-001	 2.178284e+001	           0.0	           0.0
 1.068160e+003	 1.101382e+001	 1.435585e+004	 9.841032e-001	 2.186495e+001	           0.0	           0.0