File: DP800 Tensile Tests/Fehlemann_Test_WP_KL_2024_1019.TRA
$Fehlemann_Test_WP_KL_2024_101.ZSE
Material:                               St
Auftrags-Nr.:                           WP_KL_2024_101
Probe:                                  3_45°_C
Vorkraft:                               100 N
Probengeometrie:                        H12,5x50
Messlänge:                              50.1126 mm
Probendicke a0:                         1.48 mm
Probenbreite b0:                        12.59 mm
Prüfgeschwindigkeit:                    1 mm/min
Datum:                                  26.09.2024
Maschinendaten:                         4204 WN:800315
Traversenwegaufnehmer WN:800315
Videoextensometer
Videoextensometer - Querdehnung
Kraftsensor ID:0 WN:800316 50 kN

Bemerkung:
$
      Prüfzeit	   Standardweg	 Spannung	Breitenänderung	       Dehnung	 wahre Dehnung	wahre Spannung
 1.718750e-002	 3.290974e-005	 2.067874e+002	-4.370638e-004	 6.567163e-005	 0.000000e+000	 1.102419e+001
 4.371875e-001	 1.292306e-003	 2.127122e+002	-2.889838e-003	 2.578806e-003	 0.000000e+000	 1.134033e+001
 6.171875e-001	 1.770684e-003	 2.671202e+002	 6.131620e-004	 3.533413e-003	 0.000000e+000	 1.424112e+001
 6.971875e-001	-2.482515e-004	 2.883994e+002	 5.439362e-004	-4.953878e-004	 0.000000e+000	 1.537497e+001
 8.171875e-001	 2.056587e-003	 3.213612e+002	-1.810483e-003	 4.103935e-003	 0.000000e+000	 1.713300e+001
 1.037187e+000	 3.748837e-003	 3.819443e+002	 2.921620e-004	 7.480832e-003	 0.000000e+000	 2.036360e+001
 1.417187e+000	 1.595743e-003	 4.836671e+002	 9.790682e-004	 3.184318e-003	 0.000000e+000	 2.578591e+001
 1.477188e+000	-1.783806e-004	 4.994388e+002	 1.990194e-003	-3.559598e-004	 0.000000e+000	 2.662581e+001
 1.577188e+000	 2.113910e-003	 5.277275e+002	 2.412452e-003	 4.218322e-003	 0.000000e+000	 2.813521e+001
 1.637187e+000	 4.559651e-003	 5.437495e+002	 2.526194e-003	 9.098818e-003	 0.000000e+000	 2.899082e+001
 1.697188e+000	 6.589523e-003	 5.597715e+002	 2.501872e-003	 1.314944e-002	 0.000000e+000	 2.984627e+001
 1.897187e+000	 7.124620e-003	 6.151808e+002	 1.431620e-004	 1.421723e-002	 0.000000e+000	 3.280097e+001
 1.957188e+000	 5.462555e-003	 6.316201e+002	-1.960316e-004	 1.090057e-002	 0.000000e+000	 3.367638e+001
 2.257188e+000	 6.024910e-003	 7.110623e+002	 9.109039e-004	 1.202275e-002	 0.000000e+000	 3.791246e+001
 2.577188e+000	 8.083716e-003	 7.994335e+002	 3.144807e-003	 1.613112e-002	 0.000000e+000	 4.262599e+001
 3.017188e+000	 8.615200e-003	 9.171783e+002	-4.995154e-004	 1.719170e-002	 0.000000e+000	 4.890469e+001
 3.397187e+000	 9.277007e-003	 1.024325e+003	 6.911620e-004	 1.851234e-002	 0.000000e+000	 5.461857e+001
 3.577188e+000	 1.123472e-002	 1.072808e+003	-1.475870e-003	 2.241896e-002	 0.000000e+000	 5.720600e+001
 4.037188e+000	 1.167846e-002	 1.202570e+003	 1.489662e-003	 2.330446e-002	 0.000000e+000	 6.412591e+001
 4.297187e+000	 1.383796e-002	 1.277506e+003	 1.066912e-003	 2.761376e-002	 0.000000e+000	 6.812474e+001
 4.737187e+000	 1.550785e-002	 1.399256e+003	-7.215477e-004	 3.094602e-002	 0.000000e+000	 7.461973e+001
 5.357187e+000	 1.674710e-002	 1.570240e+003	 6.716781e-004	 3.341897e-002	 0.000000e+000	 8.374008e+001
 5.537188e+000	 1.856146e-002	 1.620893e+003	-6.523380e-004	 3.703953e-002	 0.000000e+000	 8.644450e+001
 6.077188e+000	 1.922014e-002	 1.768846e+003	 2.625549e-003	 3.835392e-002	 0.000000e+000	 9.433627e+001
 6.557188e+000	 2.100259e-002	 1.893183e+003	-6.078380e-004	 4.191082e-002	 2.712914e-006	 1.009710e+002
 7.177187e+000	 2.282234e-002	 2.051901e+003	-5.811927e-005	 4.554214e-002	 0.000000e+000	 1.094400e+002
 7.437188e+000	 2.477871e-002	 2.120912e+003	 1.270162e-003	 4.944610e-002	 1.852724e-005	 1.131252e+002
 8.177188e+000	 2.486593e-002	 2.299240e+003	 1.109225e-003	 4.962015e-002	 0.000000e+000	 1.226371e+002
 8.377188e+000	 2.688743e-002	 2.345470e+003	-5.088380e-004	 5.365406e-002	 1.897657e-006	 1.251080e+002
 8.897187e+000	 2.731207e-002	 2.461880e+003	 2.021620e-004	 5.450144e-002	 0.000000e+000	 1.313184e+002
 9.257188e+000	 2.928955e-002	 2.543241e+003	 3.936388e-003	 5.844752e-002	 0.000000e+000	 1.356636e+002
 9.957188e+000	 3.117920e-002	 2.688357e+003	 2.928323e-003	 6.221833e-002	 0.000000e+000	 1.434099e+002
 1.039719e+001	 3.164962e-002	 2.774475e+003	 2.178162e-003	 6.315705e-002	 0.000000e+000	 1.480053e+002
 1.053719e+001	 3.362602e-002	 2.804016e+003	 9.096620e-004	 6.710098e-002	 1.648275e-005	 1.495870e+002
 1.081719e+001	 3.302759e-002	 2.855253e+003	 4.227426e-004	 6.590679e-002	 0.000000e+000	 1.523185e+002
 1.133719e+001	 3.421330e-002	 2.949131e+003	 1.292162e-003	 6.827289e-002	 0.000000e+000	 1.573304e+002
 1.199719e+001	 3.599020e-002	 3.062036e+003	 2.371162e-003	 7.181871e-002	 0.000000e+000	 1.633594e+002
 1.257719e+001	 3.757242e-002	 3.155832e+003	 3.146259e-003	 7.497605e-002	 3.253533e-006	 1.683687e+002
 1.307719e+001	 3.816872e-002	 3.235691e+003	 1.873001e-003	 7.616596e-002	 0.000000e+000	 1.726314e+002
 1.337719e+001	 3.889427e-002	 3.282422e+003	 4.572162e-003	 7.761380e-002	 0.000000e+000	 1.751271e+002
 1.381719e+001	 4.063059e-002	 3.351767e+003	 1.031162e-003	 8.107864e-002	 1.305320e-005	 1.788331e+002
 1.423719e+001	 4.071568e-002	 3.412767e+003	 3.553710e-003	 8.124845e-002	 0.000000e+000	 1.820881e+002
 1.439719e+001	 4.253559e-002	 3.438636e+003	 3.810162e-003	 8.488008e-002	 2.835592e-005	 1.834749e+002
 1.459719e+001	 4.286933e-002	 3.467926e+003	 4.575162e-003	 8.554606e-002	 2.735801e-005	 1.850390e+002
 1.491719e+001	 4.245399e-002	 3.514406e+003	 3.760475e-003	 8.471726e-002	 6.918321e-006	 1.875175e+002
 1.511719e+001	 4.296504e-002	 3.545616e+003	 3.330162e-003	 8.573705e-002	 8.956748e-006	 1.891847e+002
 1.535719e+001	 4.103646e-002	 3.580581e+003	 4.715581e-003	 8.188855e-002	 0.000000e+000	 1.910430e+002
 1.573719e+001	 4.181794e-002	 3.636908e+003	 3.814291e-003	 8.344801e-002	 0.000000e+000	 1.940513e+002
 1.601719e+001	 4.363636e-002	 3.677130e+003	 4.880098e-003	 8.707669e-002	 0.000000e+000	 1.962045e+002
 1.623719e+001	 4.542475e-002	 3.709090e+003	 5.115775e-003	 9.064542e-002	 1.530096e-005	 1.979170e+002
 1.665719e+001	 4.601059e-002	 3.768004e+003	 4.948162e-003	 9.181447e-002	 1.158874e-005	 2.010630e+002
 1.689719e+001	 4.623436e-002	 3.804137e+003	 5.290162e-003	 9.226101e-002	 6.607521e-006	 2.029919e+002
 2.313719e+001	 5.673088e-002	 4.601647e+003	 5.086452e-003	 1.132069e-001	 7.562038e-006	 2.455991e+002
 3.189719e+001	 5.762146e-002	 5.513064e+003	 7.703162e-003	 1.149840e-001	 0.000000e+000	 2.942485e+002
 3.789719e+001	 6.784768e-002	 6.044376e+003	 6.488162e-003	 1.353906e-001	 0.000000e+000	 3.226719e+002
 4.389719e+001	 7.625372e-002	 6.512602e+003	 9.065162e-003	 1.521649e-001	 0.000000e+000	 3.477258e+002
 4.989719e+001	 8.645710e-002	 6.922497e+003	 1.154316e-002	 1.725258e-001	 0.000000e+000	 3.696864e+002
 5.589719e+001	 9.931958e-002	 7.298763e+003	 9.109162e-003	 1.981930e-001	 1.522668e-004	 3.898802e+002
 6.189719e+001	 1.123344e-001	 7.647825e+003	 1.044916e-002	 2.241641e-001	 3.206777e-004	 4.086320e+002
 6.789719e+001	 1.256511e-001	 7.971018e+003	 1.140516e-002	 2.507377e-001	 5.018428e-004	 4.260135e+002
 7.215719e+001	 1.373525e-001	 8.187148e+003	 1.151016e-002	 2.740878e-001	 6.787338e-004	 4.376666e+002
 7.689719e+001	 1.463491e-001	 8.412290e+003	 1.416516e-002	 2.920407e-001	 7.993114e-004	 4.497827e+002
 8.289719e+001	 1.661837e-001	 8.684496e+003	 1.728516e-002	 3.316207e-001	 1.123633e-003	 4.645200e+002
 8.623719e+001	 1.778052e-001	 8.827609e+003	 1.743487e-002	 3.548117e-001	 1.317889e-003	 4.722841e+002
 9.189719e+001	 1.937490e-001	 9.063016e+003	 2.057016e-002	 3.866275e-001	 1.574131e-003	 4.850322e+002
 9.593719e+001	 2.083008e-001	 9.222651e+003	 2.224616e-002	 4.156657e-001	 1.822355e-003	 4.937183e+002
 1.008972e+002	 2.243194e-001	 9.410909e+003	 2.672316e-002	 4.476310e-001	 2.092261e-003	 5.039567e+002
 1.046172e+002	 2.386028e-001	 9.538584e+003	 2.711916e-002	 4.761336e-001	 2.343350e-003	 5.109387e+002
 1.097572e+002	 2.587709e-001	 9.714576e+003	 2.899823e-002	 5.163792e-001	 2.698896e-003	 5.205742e+002
 1.128972e+002	 2.701032e-001	 9.815381e+003	 3.095816e-002	 5.389930e-001	 2.898121e-003	 5.260943e+002
 1.178372e+002	 2.890423e-001	 9.970510e+003	 3.137216e-002	 5.767860e-001	 3.234460e-003	 5.346100e+002
 1.218972e+002	 3.059616e-001	 1.008934e+004	 3.272816e-002	 6.105487e-001	 3.539983e-003	 5.411631e+002
 1.254372e+002	 3.195410e-001	 1.019090e+004	 3.573916e-002	 6.376464e-001	 3.783516e-003	 5.467575e+002
 1.303772e+002	 3.397458e-001	 1.032283e+004	 4.060803e-002	 6.779654e-001	 4.150753e-003	 5.540576e+002
 1.338972e+002	 3.538978e-001	 1.041345e+004	 4.040216e-002	 7.062056e-001	 4.408358e-003	 5.590785e+002
 1.378772e+002	 3.702090e-001	 1.051108e+004	 4.115052e-002	 7.387548e-001	 4.706960e-003	 5.645027e+002
 1.425972e+002	 3.904463e-001	 1.062307e+004	 4.244836e-002	 7.791384e-001	 5.079689e-003	 5.707456e+002
 1.458972e+002	 4.032671e-001	 1.070126e+004	 4.447716e-002	 8.047225e-001	 5.313867e-003	 5.750925e+002
 1.499372e+002	 4.206209e-001	 1.078529e+004	 4.555093e-002	 8.393521e-001	 5.636423e-003	 5.798076e+002
 1.548372e+002	 4.406505e-001	 1.089286e+004	 4.813616e-002	 8.793214e-001	 6.005837e-003	 5.858222e+002
 1.578972e+002	 4.517751e-001	 1.095169e+004	 5.095916e-002	 9.015205e-001	 6.211189e-003	 5.891157e+002
 1.624372e+002	 4.707664e-001	 1.103405e+004	 5.246258e-002	 9.394179e-001	 6.566353e-003	 5.937691e+002
 1.668972e+002	 4.885759e-001	 1.111525e+004	 5.414716e-002	 9.749569e-001	 6.898273e-003	 5.983490e+002
 1.698972e+002	 5.015689e-001	 1.117099e+004	 5.452416e-002	 1.000884e+000	 7.141264e-003	 6.015041e+002
 1.746172e+002	 5.209625e-001	 1.125677e+004	 5.730516e-002	 1.039584e+000	 7.503176e-003	 6.063554e+002
 1.788972e+002	 5.388899e-001	 1.132879e+004	 5.859916e-002	 1.075359e+000	 7.839501e-003	 6.104506e+002
 1.842172e+002	 5.614219e-001	 1.142083e+004	 6.298394e-002	 1.120322e+000	 8.261653e-003	 6.156841e+002
 1.878972e+002	 5.774876e-001	 1.148567e+004	 6.249257e-002	 1.152381e+000	 8.562749e-003	 6.193758e+002
 1.908972e+002	 5.916729e-001	 1.153582e+004	 6.364116e-002	 1.180688e+000	 8.830369e-003	 6.222544e+002
 1.952772e+002	 6.119590e-001	 1.161093e+004	 6.595153e-002	 1.221169e+000	 9.212085e-003	 6.265560e+002
 1.995772e+002	 6.323100e-001	 1.168386e+004	 6.880306e-002	 1.261779e+000	 9.595500e-003	 6.307446e+002
 2.028972e+002	 6.481287e-001	 1.174102e+004	 7.042316e-002	 1.293346e+000	 9.893304e-003	 6.340281e+002
 2.058972e+002	 6.635120e-001	 1.178850e+004	 7.239316e-002	 1.324043e+000	 1.018492e-002	 6.367850e+002
 2.097972e+002	 6.825657e-001	 1.185184e+004	 7.628445e-002	 1.362065e+000	 1.054483e-002	 6.404465e+002
 2.135372e+002	 7.027145e-001	 1.191276e+004	 7.698869e-002	 1.402272e+000	 1.092685e-002	 6.439937e+002
 2.177772e+002	 7.228053e-001	 1.197776e+004	 7.793394e-002	 1.442363e+000	 1.130653e-002	 6.477638e+002
 2.208972e+002	 7.390530e-001	 1.202716e+004	 8.224216e-002	 1.474786e+000	 1.161429e-002	 6.506434e+002
 2.238972e+002	 7.554198e-001	 1.207273e+004	 8.485416e-002	 1.507446e+000	 1.192529e-002	 6.533184e+002
 2.271372e+002	 7.732657e-001	 1.212046e+004	 8.416800e-002	 1.543057e+000	 1.226480e-002	 6.561315e+002
 2.309972e+002	 7.936449e-001	 1.218446e+004	 8.830455e-002	 1.583724e+000	 1.264991e-002	 6.598605e+002
 2.345772e+002	 8.139017e-001	 1.224062e+004	 9.260391e-002	 1.624147e+000	 1.303448e-002	 6.631656e+002
 2.380172e+002	 8.344528e-001	 1.229219e+004	 9.355171e-002	 1.665157e+000	 1.342588e-002	 6.662283e+002
 2.414972e+002	 8.546895e-001	 1.234410e+004	 9.547413e-002	 1.705539e+000	 1.381086e-002	 6.693073e+002
 2.448972e+002	 8.745285e-001	 1.239325e+004	 9.828416e-002	 1.745128e+000	 1.418857e-002	 6.722338e+002
 2.478972e+002	 8.945493e-001	 1.243647e+004	 1.014282e-001	 1.785080e+000	 1.457124e-002	 6.748433e+002
 2.508972e+002	 9.127923e-001	 1.248212e+004	 1.023052e-001	 1.821484e+000	 1.491820e-002	 6.775624e+002
 2.538972e+002	 9.316183e-001	 1.252777e+004	 1.049662e-001	 1.859051e+000	 1.527649e-002	 6.802911e+002
 2.568972e+002	 9.509178e-001	 1.257250e+004	 1.092712e-001	 1.897563e+000	 1.564419e-002	 6.829781e+002
 2.598972e+002	 9.702116e-001	 1.261288e+004	 1.092712e-001	 1.936064e+000	 1.601276e-002	 6.854310e+002
 2.628972e+002	 9.899728e-001	 1.265336e+004	 1.110762e-001	 1.975498e+000	 1.639034e-002	 6.878963e+002
 2.649572e+002	 1.003443e+000	 1.268390e+004	 1.152804e-001	 2.002378e+000	 1.664689e-002	 6.897385e+002
 2.673772e+002	 1.019242e+000	 1.271711e+004	 1.150862e-001	 2.033906e+000	 1.694837e-002	 6.917583e+002
 2.697972e+002	 1.035002e+000	 1.274548e+004	 1.169505e-001	 2.065354e+000	 1.725023e-002	 6.935153e+002
 2.722172e+002	 1.053356e+000	 1.277744e+004	 1.193091e-001	 2.101980e+000	 1.760195e-002	 6.955038e+002
 2.748972e+002	 1.066844e+000	 1.280999e+004	 1.228962e-001	 2.128895e+000	 1.785801e-002	 6.974591e+002
 2.778972e+002	 1.087832e+000	 1.284921e+004	 1.258912e-001	 2.170777e+000	 1.825926e-002	 6.998814e+002
 2.806772e+002	 1.105528e+000	 1.288342e+004	 1.284437e-001	 2.206089e+000	 1.859716e-002	 7.019875e+002
 2.830972e+002	 1.119233e+000	 1.291204e+004	 1.285749e-001	 2.233438e+000	 1.885823e-002	 7.037353e+002
 2.855172e+002	 1.138820e+000	 1.294075e+004	 1.292387e-001	 2.272524e+000	 1.923435e-002	 7.055695e+002
 2.879372e+002	 1.151090e+000	 1.296695e+004	 1.323641e-001	 2.297009e+000	 1.946780e-002	 7.071673e+002
 2.903572e+002	 1.169938e+000	 1.299299e+004	 1.338667e-001	 2.334620e+000	 1.982991e-002	 7.088478e+002
 2.928972e+002	 1.183882e+000	 1.301836e+004	 1.334612e-001	 2.362446e+000	 2.009616e-002	 7.104249e+002
 2.958972e+002	 1.203704e+000	 1.305441e+004	 1.402692e-001	 2.402000e+000	 2.047453e-002	 7.126673e+002
 2.988572e+002	 1.224369e+000	 1.308453e+004	 1.397062e-001	 2.443237e+000	 2.087075e-002	 7.145995e+002
 3.012772e+002	 1.240435e+000	 1.310698e+004	 1.397549e-001	 2.475297e+000	 2.117893e-002	 7.160495e+002
 3.036972e+002	 1.254715e+000	 1.313093e+004	 1.415422e-001	 2.503792e+000	 2.145174e-002	 7.175574e+002
 3.061172e+002	 1.269629e+000	 1.315563e+004	 1.457152e-001	 2.533553e+000	 2.173668e-002	 7.191159e+002
 3.085372e+002	 1.287046e+000	 1.317949e+004	 1.463862e-001	 2.568309e+000	 2.207060e-002	 7.206646e+002
 3.109572e+002	 1.300787e+000	 1.320152e+004	 1.495885e-001	 2.595729e+000	 2.233315e-002	 7.220622e+002
 3.138972e+002	 1.319602e+000	 1.323098e+004	 1.498120e-001	 2.633275e+000	 2.269271e-002	 7.239382e+002
 3.168972e+002	 1.340264e+000	 1.326177e+004	 1.519526e-001	 2.674507e+000	 2.308784e-002	 7.259145e+002
 3.194372e+002	 1.355802e+000	 1.328773e+004	 1.536037e-001	 2.705512e+000	 2.338414e-002	 7.275547e+002
 3.218572e+002	 1.371114e+000	 1.330784e+004	 1.561371e-001	 2.736067e+000	 2.367745e-002	 7.288726e+002
 3.242572e+002	 1.386927e+000	 1.333037e+004	 1.585344e-001	 2.767624e+000	 2.397983e-002	 7.303308e+002
 3.266772e+002	 1.403821e+000	 1.335398e+004	 1.602558e-001	 2.801335e+000	 2.430288e-002	 7.318647e+002
 3.290972e+002	 1.418747e+000	 1.337735e+004	 1.597804e-001	 2.831121e+000	 2.458758e-002	 7.333576e+002
 3.318972e+002	 1.437222e+000	 1.340005e+004	 1.627237e-001	 2.867988e+000	 2.494144e-002	 7.348652e+002
 3.348972e+002	 1.458685e+000	 1.342825e+004	 1.654392e-001	 2.910817e+000	 2.535190e-002	 7.367186e+002
 3.375772e+002	 1.476606e+000	 1.345287e+004	 1.670942e-001	 2.946578e+000	 2.569424e-002	 7.383257e+002
 3.400172e+002	 1.492921e+000	 1.347348e+004	 1.681226e-001	 2.979135e+000	 2.600624e-002	 7.396907e+002
 3.424172e+002	 1.507371e+000	 1.349618e+004	 1.728350e-001	 3.007970e+000	 2.628137e-002	 7.411442e+002
 3.448172e+002	 1.527981e+000	 1.351829e+004	 1.734522e-001	 3.049097e+000	 2.667626e-002	 7.426550e+002
 3.472372e+002	 1.544556e+000	 1.354224e+004	 1.736579e-001	 3.082174e+000	 2.699218e-002	 7.442095e+002
 3.498972e+002	 1.565252e+000	 1.356594e+004	 1.759295e-001	 3.123472e+000	 2.738806e-002	 7.458105e+002
 3.528972e+002	 1.584723e+000	 1.359456e+004	 1.784347e-001	 3.162326e+000	 2.775875e-002	 7.476657e+002
 3.557172e+002	 1.604510e+000	 1.361484e+004	 1.810945e-001	 3.201811e+000	 2.813756e-002	 7.490675e+002
 3.581372e+002	 1.624453e+000	 1.363963e+004	 1.833466e-001	 3.241609e+000	 2.851812e-002	 7.507204e+002
 3.605572e+002	 1.642354e+000	 1.365957e+004	 1.864430e-001	 3.277331e+000	 2.886017e-002	 7.520783e+002
 3.629772e+002	 1.664033e+000	 1.368143e+004	 1.867142e-001	 3.320590e+000	 2.927481e-002	 7.535975e+002
 3.653972e+002	 1.680230e+000	 1.370179e+004	 1.887952e-001	 3.352911e+000	 2.958349e-002	 7.549552e+002
 3.678972e+002	 1.700268e+000	 1.372190e+004	 1.913389e-001	 3.392898e+000	 2.996652e-002	 7.563557e+002
 3.708972e+002	 1.723210e+000	 1.374752e+004	 1.939693e-001	 3.438678e+000	 3.040421e-002	 7.581033e+002
 3.738772e+002	 1.745640e+000	 1.376822e+004	 1.965196e-001	 3.483438e+000	 3.083307e-002	 7.595731e+002
 3.762972e+002	 1.763910e+000	 1.379075e+004	 1.980907e-001	 3.519896e+000	 3.118081e-002	 7.610841e+002
 3.787172e+002	 1.779515e+000	 1.381136e+004	 2.002062e-001	 3.551035e+000	 3.147737e-002	 7.624508e+002
 3.811372e+002	 1.794285e+000	 1.383289e+004	 2.000975e-001	 3.580509e+000	 3.175748e-002	 7.638567e+002
 3.835572e+002	 1.811018e+000	 1.385158e+004	 2.041032e-001	 3.613899e+000	 3.207616e-002	 7.651355e+002
 3.859772e+002	 1.825668e+000	 1.387094e+004	 2.070682e-001	 3.643134e+000	 3.235434e-002	 7.664211e+002
 3.888972e+002	 1.846058e+000	 1.389114e+004	 2.067997e-001	 3.683822e+000	 3.274308e-002	 7.678382e+002
 3.918972e+002	 1.867313e+000	 1.391634e+004	 2.110219e-001	 3.726236e+000	 3.314710e-002	 7.695458e+002
 3.944572e+002	 1.884564e+000	 1.393528e+004	 2.143359e-001	 3.760662e+000	 3.347529e-002	 7.708490e+002
 3.968772e+002	 1.903488e+000	 1.395489e+004	 2.140351e-001	 3.798425e+000	 3.383546e-002	 7.722147e+002
 3.992972e+002	 1.921673e+000	 1.397383e+004	 2.182164e-001	 3.834712e+000	 3.418141e-002	 7.735332e+002
 4.017172e+002	 1.939695e+000	 1.399094e+004	 2.197515e-001	 3.870676e+000	 3.452459e-002	 7.747484e+002
 4.041372e+002	 1.958358e+000	 1.400863e+004	 2.202876e-001	 3.907918e+000	 3.487984e-002	 7.760062e+002
 4.068972e+002	 1.979552e+000	 1.403158e+004	 2.254977e-001	 3.950211e+000	 3.528240e-002	 7.775937e+002
 4.098972e+002	 2.004488e+000	 1.405394e+004	 2.259543e-001	 3.999971e+000	 3.575698e-002	 7.792059e+002
 4.125972e+002	 2.026890e+000	 1.407047e+004	 2.296328e-001	 4.044673e+000	 3.618405e-002	 7.804573e+002
 4.150172e+002	 2.047646e+000	 1.408716e+004	 2.297449e-001	 4.086093e+000	 3.657924e-002	 7.816940e+002
 4.174372e+002	 2.068091e+000	 1.410301e+004	 2.330711e-001	 4.126891e+000	 3.696850e-002	 7.828806e+002
 4.198572e+002	 2.088363e+000	 1.412028e+004	 2.341991e-001	 4.167344e+000	 3.735391e-002	 7.841439e+002
 4.222772e+002	 2.108885e+000	 1.413864e+004	 2.388667e-001	 4.208296e+000	 3.774372e-002	 7.854721e+002
 4.248972e+002	 2.130409e+000	 1.415600e+004	 2.406777e-001	 4.251247e+000	 3.815287e-002	 7.867605e+002
 4.278972e+002	 2.154670e+000	 1.417444e+004	 2.440236e-001	 4.299661e+000	 3.861414e-002	 7.881512e+002
 4.307372e+002	 2.181778e+000	 1.419555e+004	 2.466548e-001	 4.353754e+000	 3.912914e-002	 7.897345e+002
 4.331772e+002	 2.201546e+000	 1.420841e+004	 2.480258e-001	 4.393201e+000	 3.950517e-002	 7.907482e+002
 4.355972e+002	 2.220094e+000	 1.422393e+004	 2.508049e-001	 4.430214e+000	 3.985700e-002	 7.918927e+002
 4.380172e+002	 2.241216e+000	 1.423761e+004	 2.514898e-001	 4.472363e+000	 4.025850e-002	 7.929745e+002
 4.404372e+002	 2.261791e+000	 1.425422e+004	 2.541836e-001	 4.513421e+000	 4.064863e-002	 7.942114e+002
 4.428972e+002	 2.281931e+000	 1.426774e+004	 2.579267e-001	 4.553610e+000	 4.103105e-002	 7.952703e+002
 4.458972e+002	 2.308558e+000	 1.428735e+004	 2.599975e-001	 4.606745e+000	 4.153599e-002	 7.967680e+002
 4.488972e+002	 2.334232e+000	 1.430888e+004	 2.628017e-001	 4.657978e+000	 4.202196e-002	 7.983594e+002
 4.518972e+002	 2.359151e+000	 1.432749e+004	 2.650084e-001	 4.707703e+000	 4.249396e-002	 7.997775e+002
 4.548972e+002	 2.384492e+000	 1.434442e+004	 2.681776e-001	 4.758271e+000	 4.297425e-002	 8.011098e+002
 4.573972e+002	 2.405778e+000	 1.436145e+004	 2.711482e-001	 4.800749e+000	 4.337681e-002	 8.023857e+002
 4.598172e+002	 2.427536e+000	 1.437505e+004	 2.721107e-001	 4.844165e+000	 4.378906e-002	 8.034783e+002
 4.622172e+002	 2.448510e+000	 1.439015e+004	 2.760467e-001	 4.886020e+000	 4.418581e-002	 8.046436e+002
 4.646372e+002	 2.469568e+000	 1.440359e+004	 2.780008e-001	 4.928041e+000	 4.458443e-002	 8.057175e+002
 4.670572e+002	 2.490569e+000	 1.441527e+004	 2.792736e-001	 4.969948e+000	 4.498222e-002	 8.066930e+002
 4.698972e+002	 2.515762e+000	 1.442954e+004	 2.828563e-001	 5.020221e+000	 4.545916e-002	 8.078783e+002
 4.728972e+002	 2.542681e+000	 1.444364e+004	 2.861439e-001	 5.073938e+000	 4.596880e-002	 8.090815e+002
 4.755372e+002	 2.563466e+000	 1.445875e+004	 2.880046e-001	 5.115415e+000	 4.636108e-002	 8.102472e+002
 4.779572e+002	 2.585148e+000	 1.447193e+004	 2.930504e-001	 5.158682e+000	 4.677078e-002	 8.113199e+002
 4.803772e+002	 2.605869e+000	 1.448487e+004	 2.923592e-001	 5.200030e+000	 4.716207e-002	 8.123643e+002
 4.828172e+002	 2.627510e+000	 1.449446e+004	 2.958378e-001	 5.243215e+000	 4.757154e-002	 8.132362e+002
 4.852372e+002	 2.647847e+000	 1.450823e+004	 2.970693e-001	 5.283798e+000	 4.795501e-002	 8.143225e+002
 4.878972e+002	 2.670635e+000	 1.451816e+004	 3.011798e-001	 5.329272e+000	 4.838589e-002	 8.152319e+002
 4.908972e+002	 2.696331e+000	 1.453435e+004	 3.033305e-001	 5.380548e+000	 4.887029e-002	 8.165382e+002
 4.937172e+002	 2.720974e+000	 1.454570e+004	 3.066436e-001	 5.429725e+000	 4.933566e-002	 8.175571e+002
 4.961372e+002	 2.743014e+000	 1.456022e+004	 3.093478e-001	 5.473705e+000	 4.975059e-002	 8.187146e+002
 4.985572e+002	 2.762293e+000	 1.457090e+004	 3.107200e-001	 5.512176e+000	 5.011391e-002	 8.196140e+002
 5.009772e+002	 2.782784e+000	 1.458250e+004	 3.145732e-001	 5.553066e+000	 5.049986e-002	 8.205843e+002
 5.034172e+002	 2.804183e+000	 1.459210e+004	 3.175492e-001	 5.595767e+000	 5.090338e-002	 8.214565e+002
 5.058972e+002	 2.825264e+000	 1.460603e+004	 3.189698e-001	 5.637834e+000	 5.129963e-002	 8.225685e+002
 5.088972e+002	 2.849848e+000	 1.461872e+004	 3.252818e-001	 5.686893e+000	 5.176243e-002	 8.236652e+002
 5.118972e+002	 2.876256e+000	 1.463107e+004	 3.243875e-001	 5.739590e+000	 5.225962e-002	 8.247720e+002
 5.148972e+002	 2.906998e+000	 1.464317e+004	 3.288593e-001	 5.800937e+000	 5.283869e-002	 8.259330e+002
 5.178972e+002	 2.936421e+000	 1.465844e+004	 3.315721e-001	 5.859650e+000	 5.339166e-002	 8.272531e+002
 5.203372e+002	 2.955248e+000	 1.466511e+004	 3.339512e-001	 5.897219e+000	 5.374611e-002	 8.279235e+002
 5.227572e+002	 2.977578e+000	 1.467454e+004	 3.365756e-001	 5.941779e+000	 5.416596e-002	 8.288045e+002
 5.251772e+002	 3.000084e+000	 1.468614e+004	 3.373525e-001	 5.986689e+000	 5.458842e-002	 8.298112e+002
 5.275972e+002	 3.021400e+000	 1.469549e+004	 3.395708e-001	 6.029226e+000	 5.498879e-002	 8.306725e+002
 5.300172e+002	 3.045199e+000	 1.470517e+004	 3.436995e-001	 6.076716e+000	 5.543580e-002	 8.315920e+002
 5.328972e+002	 3.071743e+000	 1.471694e+004	 3.478342e-001	 6.129686e+000	 5.593390e-002	 8.326729e+002
 5.358972e+002	 3.098833e+000	 1.473020e+004	 3.488978e-001	 6.183745e+000	 5.644167e-002	 8.338481e+002
 5.384772e+002	 3.123000e+000	 1.473571e+004	 3.523246e-001	 6.231970e+000	 5.689599e-002	 8.345386e+002
 5.408972e+002	 3.145242e+000	 1.474364e+004	 3.539585e-001	 6.276354e+000	 5.731324e-002	 8.353364e+002
 5.433172e+002	 3.168488e+000	 1.475282e+004	 3.547357e-001	 6.322740e+000	 5.774890e-002	 8.362213e+002
 5.457372e+002	 3.190651e+000	 1.476158e+004	 3.588778e-001	 6.366967e+000	 5.816410e-002	 8.370660e+002
 5.481572e+002	 3.213890e+000	 1.477118e+004	 3.634012e-001	 6.413341e+000	 5.859918e-002	 8.379753e+002
 5.508972e+002	 3.236042e+000	 1.478194e+004	 3.636793e-001	 6.457546e+000	 5.901333e-002	 8.389344e+002
 5.538972e+002	 3.265928e+000	 1.478937e+004	 3.665640e-001	 6.517184e+000	 5.957354e-002	 8.398260e+002
 5.565972e+002	 3.292494e+000	 1.480222e+004	 3.691108e-001	 6.570196e+000	 6.006971e-002	 8.409741e+002
 5.590172e+002	 3.312572e+000	 1.481132e+004	 3.711100e-001	 6.610261e+000	 6.044470e-002	 8.418072e+002
 5.614372e+002	 3.336826e+000	 1.481832e+004	 3.738580e-001	 6.658662e+000	 6.089849e-002	 8.425879e+002
 5.638572e+002	 3.359067e+000	 1.482759e+004	 3.771088e-001	 6.703044e+000	 6.131372e-002	 8.434654e+002
 5.662772e+002	 3.381365e+000	 1.483343e+004	 3.791472e-001	 6.747539e+000	 6.173069e-002	 8.441495e+002
 5.688972e+002	 3.406522e+000	 1.484027e+004	 3.831936e-001	 6.797739e+000	 6.220085e-002	 8.449361e+002
 5.718972e+002	 3.433011e+000	 1.485004e+004	 3.844929e-001	 6.850598e+000	 6.269504e-002	 8.459104e+002
 5.747372e+002	 3.460403e+000	 1.486105e+004	 3.877154e-001	 6.905261e+000	 6.320561e-002	 8.469709e+002
 5.771572e+002	 3.483506e+000	 1.486906e+004	 3.925217e-001	 6.951362e+000	 6.363633e-002	 8.477929e+002
 5.795772e+002	 3.506327e+000	 1.487590e+004	 3.941952e-001	 6.996902e+000	 6.406188e-002	 8.485441e+002
 5.819972e+002	 3.529197e+000	 1.488408e+004	 3.955807e-001	 7.042538e+000	 6.448782e-002	 8.493727e+002
 5.844172e+002	 3.550351e+000	 1.489001e+004	 3.993591e-001	 7.084751e+000	 6.488206e-002	 8.500459e+002
 5.868972e+002	 3.573583e+000	 1.489710e+004	 3.996905e-001	 7.131111e+000	 6.531471e-002	 8.508190e+002
 5.898972e+002	 3.603894e+000	 1.490686e+004	 4.014674e-001	 7.191597e+000	 6.587877e-002	 8.518572e+002
 5.928772e+002	 3.632304e+000	 1.491554e+004	 4.054667e-001	 7.248289e+000	 6.640729e-002	 8.528039e+002
 5.952972e+002	 3.654877e+000	 1.492197e+004	 4.072032e-001	 7.293335e+000	 6.682714e-002	 8.535297e+002
 5.977172e+002	 3.677189e+000	 1.492806e+004	 4.103328e-001	 7.337858e+000	 6.724201e-002	 8.542324e+002
 6.001172e+002	 3.699880e+000	 1.493599e+004	 4.134521e-001	 7.383138e+000	 6.766334e-002	 8.550466e+002
 6.025372e+002	 3.723094e+000	 1.494174e+004	 4.141167e-001	 7.429462e+000	 6.809477e-002	 8.557452e+002
 6.049572e+002	 3.746617e+000	 1.494725e+004	 4.162992e-001	 7.476401e+000	 6.853183e-002	 8.564346e+002
 6.078972e+002	 3.773709e+000	 1.495384e+004	 4.189543e-001	 7.530465e+000	 6.903492e-002	 8.572433e+002
 6.108972e+002	 3.802271e+000	 1.496052e+004	 4.226393e-001	 7.587459e+000	 6.956507e-002	 8.580805e+002
 6.134372e+002	 3.825475e+000	 1.496778e+004	 4.244244e-001	 7.633763e+000	 6.999513e-002	 8.588664e+002
 6.158372e+002	 3.849307e+000	 1.497304e+004	 4.272059e-001	 7.681320e+000	 7.043717e-002	 8.595477e+002
 6.182572e+002	 3.871865e+000	 1.498030e+004	 4.284691e-001	 7.726335e+000	 7.085485e-002	 8.603239e+002
 6.206772e+002	 3.893474e+000	 1.498505e+004	 4.324040e-001	 7.769456e+000	 7.125533e-002	 8.609415e+002
 6.230972e+002	 3.917458e+000	 1.499281e+004	 4.346875e-001	 7.817317e+000	 7.169903e-002	 8.617699e+002
 6.258972e+002	 3.945024e+000	 1.499440e+004	 4.370261e-001	 7.872325e+000	 7.221053e-002	 8.623007e+002
 6.288972e+002	 3.973144e+000	 1.500208e+004	 4.405445e-001	 7.928438e+000	 7.273058e-002	 8.631909e+002
 6.315572e+002	 3.997951e+000	 1.500750e+004	 4.401191e-001	 7.977941e+000	 7.318945e-002	 8.638991e+002
 6.339772e+002	 4.020953e+000	 1.501468e+004	 4.465090e-001	 8.023841e+000	 7.361422e-002	 8.646796e+002
 6.363972e+002	 4.045027e+000	 1.501843e+004	 4.480161e-001	 8.071882e+000	 7.405953e-002	 8.652805e+002
 6.388172e+002	 4.068352e+000	 1.502411e+004	 4.494118e-001	 8.118426e+000	 7.449027e-002	 8.659801e+002
 6.412372e+002	 4.092068e+000	 1.502928e+004	 4.507797e-001	 8.165751e+000	 7.492820e-002	 8.666575e+002
 6.438972e+002	 4.117311e+000	 1.503462e+004	 4.539202e-001	 8.216125e+000	 7.539417e-002	 8.673692e+002
 6.468972e+002	 4.146241e+000	 1.504263e+004	 4.567397e-001	 8.273854e+000	 7.592745e-002	 8.682943e+002
 6.497172e+002	 4.172840e+000	 1.504380e+004	 4.592703e-001	 8.326933e+000	 7.641903e-002	 8.687874e+002
 6.521372e+002	 4.196517e+000	 1.504822e+004	 4.606590e-001	 8.374181e+000	 7.685558e-002	 8.694218e+002
 6.545572e+002	 4.219521e+000	 1.505465e+004	 4.646074e-001	 8.420084e+000	 7.727901e-002	 8.701614e+002
 6.569772e+002	 4.241188e+000	 1.506091e+004	 4.663837e-001	 8.463322e+000	 7.767764e-002	 8.708703e+002
 6.593772e+002	 4.264762e+000	 1.506525e+004	 4.688017e-001	 8.510364e+000	 7.811176e-002	 8.714990e+002
 6.618972e+002	 4.287074e+000	 1.507234e+004	 4.721163e-001	 8.554887e+000	 7.852173e-002	 8.722671e+002
 6.648972e+002	 4.316661e+000	 1.507584e+004	 4.772123e-001	 8.613929e+000	 7.906657e-002	 8.729444e+002
 6.678572e+002	 4.342923e+000	 1.508169e+004	 4.791632e-001	 8.666335e+000	 7.954927e-002	 8.737040e+002
 6.702772e+002	 4.363255e+000	 1.508302e+004	 4.796990e-001	 8.706907e+000	 7.992356e-002	 8.741075e+002
 6.726972e+002	 4.389026e+000	 1.508794e+004	 4.832332e-001	 8.758333e+000	 8.039703e-002	 8.748065e+002
 6.763172e+002	 4.420984e+000	 1.509696e+004	 4.880758e-001	 8.822107e+000	 8.098315e-002	 8.758423e+002
 6.787372e+002	 4.443880e+000	 1.509904e+004	 4.894812e-001	 8.867795e+000	 8.140390e-002	 8.763310e+002
 6.811572e+002	 4.465581e+000	 1.510113e+004	 4.914966e-001	 8.911100e+000	 8.180251e-002	 8.768007e+002
 6.835772e+002	 4.488401e+000	 1.510547e+004	 4.942321e-001	 8.956637e+000	 8.222098e-002	 8.774194e+002
 6.859972e+002	 4.511065e+000	 1.510931e+004	 4.980370e-001	 9.001864e+000	 8.263654e-002	 8.780066e+002
 6.888972e+002	 4.537971e+000	 1.511456e+004	 4.993572e-001	 9.055556e+000	 8.312949e-002	 8.787447e+002
 6.918972e+002	 4.565132e+000	 1.511473e+004	 5.032145e-001	 9.109755e+000	 8.362808e-002	 8.791911e+002
 6.944572e+002	 4.589524e+000	 1.512358e+004	 5.067822e-001	 9.158429e+000	 8.407354e-002	 8.800980e+002
 6.968772e+002	 4.610434e+000	 1.512875e+004	 5.087281e-001	 9.200154e+000	 8.445584e-002	 8.807356e+002
 6.992972e+002	 4.632466e+000	 1.512992e+004	 5.116515e-001	 9.244121e+000	 8.485953e-002	 8.811582e+002
 7.017172e+002	 4.655270e+000	 1.513259e+004	 5.131029e-001	 9.289626e+000	 8.527683e-002	 8.816808e+002
 7.041372e+002	 4.675497e+000	 1.513467e+004	 5.142099e-001	 9.329988e+000	 8.564689e-002	 8.821280e+002
 7.068972e+002	 4.701156e+000	 1.514043e+004	 5.175866e-001	 9.381192e+000	 8.611541e-002	 8.828769e+002
 7.098972e+002	 4.728208e+000	 1.514185e+004	 5.202524e-001	 9.435173e+000	 8.661022e-002	 8.833953e+002
 7.126172e+002	 4.751750e+000	 1.514477e+004	 5.244451e-001	 9.482153e+000	 8.704025e-002	 8.839450e+002
 7.150372e+002	 4.774484e+000	 1.514903e+004	 5.264373e-001	 9.527518e+000	 8.745498e-002	 8.845598e+002
 7.174572e+002	 4.794362e+000	 1.515228e+004	 5.279344e-001	 9.567184e+000	 8.781757e-002	 8.850701e+002
 7.198772e+002	 4.819840e+000	 1.515437e+004	 5.291437e-001	 9.618026e+000	 8.828265e-002	 8.856028e+002
 7.222972e+002	 4.843183e+000	 1.515662e+004	 5.336059e-001	 9.664608e+000	 8.870847e-002	 8.861108e+002
 7.248972e+002	 4.868859e+000	 1.515904e+004	 5.361689e-001	 9.715845e+000	 8.917666e-002	 8.866663e+002
 7.278972e+002	 4.896576e+000	 1.516455e+004	 5.392771e-001	 9.771154e+000	 8.968112e-002	 8.874356e+002
 7.307572e+002	 4.924098e+000	 1.516730e+004	 5.413806e-001	 9.826073e+000	 9.018242e-002	 8.880407e+002
 7.331772e+002	 4.947347e+000	 1.516972e+004	 5.444344e-001	 9.872467e+000	 9.060568e-002	 8.885576e+002
 7.355972e+002	 4.970752e+000	 1.517214e+004	 5.464827e-001	 9.919173e+000	 9.103161e-002	 8.890771e+002
 7.380172e+002	 4.993836e+000	 1.517348e+004	 5.457422e-001	 9.965237e+000	 9.145177e-002	 8.895280e+002
 7.404372e+002	 5.017344e+000	 1.517456e+004	 5.506505e-001	 1.001215e+001	 9.187953e-002	 8.899710e+002
 7.428972e+002	 5.040635e+000	 1.517698e+004	 5.494102e-001	 1.005862e+001	 9.230282e-002	 8.904890e+002
 7.458972e+002	 5.068558e+000	 1.517974e+004	 5.570102e-001	 1.011434e+001	 9.281011e-002	 8.911014e+002
 7.488972e+002	 5.098033e+000	 1.518057e+004	 5.583112e-001	 1.017316e+001	 9.334583e-002	 8.916264e+002
 7.513372e+002	 5.120525e+000	 1.518099e+004	 5.600362e-001	 1.021805e+001	 9.375447e-002	 8.920141e+002
 7.537572e+002	 5.143927e+000	 1.518383e+004	 5.648911e-001	 1.026474e+001	 9.417890e-002	 8.925588e+002
 7.561772e+002	 5.165924e+000	 1.518758e+004	 5.644202e-001	 1.030864e+001	 9.457741e-002	 8.931349e+002
 7.585972e+002	 5.188757e+000	 1.518792e+004	 5.671710e-001	 1.035420e+001	 9.499178e-002	 8.935235e+002
 7.610172e+002	 5.211384e+000	 1.519008e+004	 5.679182e-001	 1.039936e+001	 9.540178e-002	 8.940167e+002
 7.638972e+002	 5.238717e+000	 1.519000e+004	 5.726821e-001	 1.045390e+001	 9.589747e-002	 8.944534e+002
 7.668972e+002	 5.265130e+000	 1.519058e+004	 5.748392e-001	 1.050660e+001	 9.637609e-002	 8.949146e+002
 7.694772e+002	 5.288416e+000	 1.519351e+004	 5.739042e-001	 1.055307e+001	 9.679730e-002	 8.954631e+002
 7.718972e+002	 5.310368e+000	 1.519492e+004	 5.780472e-001	 1.059688e+001	 9.719452e-002	 8.959015e+002
 7.743172e+002	 5.331173e+000	 1.519593e+004	 5.807279e-001	 1.063840e+001	 9.757093e-002	 8.962969e+002
 7.767172e+002	 5.353014e+000	 1.519601e+004	 5.831861e-001	 1.068198e+001	 9.796616e-002	 8.966548e+002
 7.791372e+002	 5.374020e+000	 1.519759e+004	 5.843132e-001	 1.072390e+001	 9.834576e-002	 8.970880e+002
 7.818972e+002	 5.398587e+000	 1.519851e+004	 5.889522e-001	 1.077292e+001	 9.878976e-002	 8.975393e+002
 7.848972e+002	 5.424607e+000	 1.520001e+004	 5.887262e-001	 1.082484e+001	 9.925968e-002	 8.980488e+002
 7.876172e+002	 5.446651e+000	 1.519793e+004	 5.928361e-001	 1.086883e+001	 9.965843e-002	 8.982819e+002
 7.900372e+002	 5.468299e+000	 1.519843e+004	 5.945077e-001	 1.091203e+001	 1.000492e-001	 8.986615e+002
 7.924572e+002	 5.483303e+000	 1.520026e+004	 5.958222e-001	 1.094197e+001	           0.0	           0.0
 7.948772e+002	 5.507093e+000	 1.520035e+004	 5.989541e-001	 1.098944e+001	           0.0	           0.0
 7.972972e+002	 5.527761e+000	 1.519935e+004	 5.996062e-001	 1.103069e+001	           0.0	           0.0
 7.998972e+002	 5.549031e+000	 1.519960e+004	 6.011732e-001	 1.107313e+001	           0.0	           0.0
 8.028972e+002	 5.573228e+000	 1.519960e+004	 6.051946e-001	 1.112142e+001	           0.0	           0.0
 8.057772e+002	 5.597475e+000	 1.519634e+004	 6.047654e-001	 1.116980e+001	           0.0	           0.0
 8.081972e+002	 5.617330e+000	 1.519434e+004	 6.065660e-001	 1.120942e+001	           0.0	           0.0
 8.106172e+002	 5.634698e+000	 1.519284e+004	 6.094368e-001	 1.124408e+001	           0.0	           0.0
 8.130372e+002	 5.653767e+000	 1.518983e+004	 6.073619e-001	 1.128213e+001	           0.0	           0.0
 8.154572e+002	 5.670631e+000	 1.518766e+004	 6.121147e-001	 1.131579e+001	           0.0	           0.0
 8.178972e+002	 5.689293e+000	 1.518541e+004	 6.125253e-001	 1.135303e+001	           0.0	           0.0
 8.208972e+002	 5.710563e+000	 1.517999e+004	 6.146024e-001	 1.139547e+001	           0.0	           0.0
 8.238972e+002	 5.729603e+000	 1.517740e+004	 6.157008e-001	 1.143346e+001	           0.0	           0.0
 8.268972e+002	 5.750060e+000	 1.517431e+004	 6.127511e-001	 1.147429e+001	           0.0	           0.0
 8.298972e+002	 5.771286e+000	 1.517022e+004	 6.192371e-001	 1.151664e+001	           0.0	           0.0
 8.323572e+002	 5.785527e+000	 1.516438e+004	 6.203412e-001	 1.154506e+001	           0.0	           0.0
 8.347772e+002	 5.800704e+000	 1.515946e+004	 6.196226e-001	 1.157535e+001	           0.0	           0.0
 8.371972e+002	 5.816399e+000	 1.515212e+004	 6.196868e-001	 1.160667e+001	           0.0	           0.0
 8.396172e+002	 5.831313e+000	 1.514302e+004	 6.222174e-001	 1.163643e+001	           0.0	           0.0
 8.420172e+002	 5.841176e+000	 1.513609e+004	 6.234474e-001	 1.165611e+001	           0.0	           0.0
 8.448972e+002	 5.856282e+000	 1.512608e+004	 6.241547e-001	 1.168625e+001	           0.0	           0.0
 8.478972e+002	 5.871999e+000	 1.511148e+004	 6.260296e-001	 1.171762e+001	           0.0	           0.0
 8.504772e+002	 5.884704e+000	 1.510063e+004	 6.243435e-001	 1.174297e+001	           0.0	           0.0
 8.528972e+002	 5.898964e+000	 1.508678e+004	 6.239145e-001	 1.177143e+001	           0.0	           0.0
 8.553172e+002	 5.910399e+000	 1.507201e+004	 6.261311e-001	 1.179425e+001	           0.0	           0.0
 8.577372e+002	 5.916484e+000	 1.505807e+004	 6.236387e-001	 1.180639e+001	           0.0	           0.0
 8.601572e+002	 5.930061e+000	 1.504038e+004	 6.268533e-001	 1.183348e+001	           0.0	           0.0
 8.628972e+002	 5.939777e+000	 1.501835e+004	 6.279952e-001	 1.185287e+001	           0.0	           0.0
 8.658972e+002	 5.950187e+000	 1.499231e+004	 6.292672e-001	 1.187364e+001	           0.0	           0.0
 8.686372e+002	 5.958193e+000	 1.496836e+004	 6.278912e-001	 1.188962e+001	           0.0	           0.0
 8.710572e+002	 5.967629e+000	 1.494450e+004	 6.270864e-001	 1.190845e+001	           0.0	           0.0
 8.734772e+002	 5.972497e+000	 1.491571e+004	 6.264919e-001	 1.191816e+001	           0.0	           0.0
 8.758972e+002	 5.979398e+000	 1.488725e+004	 6.272280e-001	 1.193193e+001	           0.0	           0.0
 8.783172e+002	 5.983261e+000	 1.485037e+004	 6.286778e-001	 1.193964e+001	           0.0	           0.0
 8.808972e+002	 5.990331e+000	 1.479846e+004	 6.283065e-001	 1.195375e+001	           0.0	           0.0
 8.838972e+002	 5.992733e+000	 1.467438e+004	 6.264628e-001	 1.195854e+001	           0.0	           0.0
 8.843772e+002	 5.993607e+000	 1.462339e+004	 6.255218e-001	 1.196029e+001	           0.0	           0.0