File: DP800 Tensile Tests/Fehlemann_Test_WP_KL_2024_10110.TRA
$Fehlemann_Test_WP_KL_2024_101.ZSE
Material:                               St
Auftrags-Nr.:                           WP_KL_2024_101
Probe:                                  3_45°_D
Vorkraft:                               100 N
Probengeometrie:                        H12,5x50
Messlänge:                              50.6912 mm
Probendicke a0:                         1.48 mm
Probenbreite b0:                        12.59 mm
Prüfgeschwindigkeit:                    1 mm/min
Datum:                                  26.09.2024
Maschinendaten:                         4204 WN:800315
Traversenwegaufnehmer WN:800315
Videoextensometer
Videoextensometer - Querdehnung
Kraftsensor ID:0 WN:800316 50 kN

Bemerkung:
$
      Prüfzeit	   Standardweg	 Spannung	Breitenänderung	       Dehnung	 wahre Dehnung	wahre Spannung
 1.937500e-002	-4.793522e-005	 2.064537e+002	-9.785403e-006	-9.456313e-005	 0.000000e+000	 1.108113e+001
 4.393750e-001	 1.135107e-005	 2.146315e+002	 1.057342e-003	 2.239258e-005	 0.000000e+000	 1.152008e+001
 7.793750e-001	 1.072261e-004	 3.189413e+002	 1.325828e-003	 2.115278e-004	 0.000000e+000	 1.711881e+001
 1.119375e+000	 1.957581e-003	 4.109007e+002	 4.569565e-004	 3.861774e-003	 0.000000e+000	 2.205543e+001
 1.739375e+000	 3.641710e-003	 5.829700e+002	 1.444053e-003	 7.184102e-003	 0.000000e+000	 3.129243e+001
 2.279375e+000	 5.401226e-003	 7.319243e+002	 8.462468e-004	 1.065515e-002	 0.000000e+000	 3.928930e+001
 2.799375e+000	 7.229678e-003	 8.796268e+002	 1.572376e-003	 1.426219e-002	 0.000000e+000	 4.721960e+001
 3.199375e+000	 8.879539e-003	 9.947847e+002	 2.246779e-003	 1.751691e-002	 0.000000e+000	 5.340318e+001
 3.959375e+000	 8.900726e-003	 1.208745e+003	 2.640404e-003	 1.755871e-002	 0.000000e+000	 6.488925e+001
 4.319375e+000	 1.064469e-002	 1.306128e+003	 2.389779e-003	 2.099908e-002	 0.000000e+000	 7.011952e+001
 4.899375e+000	 1.246619e-002	 1.466181e+003	 3.766279e-003	 2.459241e-002	 0.000000e+000	 7.871479e+001
 5.139375e+000	 1.430129e-002	 1.532772e+003	 3.260118e-003	 2.821255e-002	 0.000000e+000	 8.229285e+001
 5.439375e+000	 1.480123e-002	 1.612799e+003	 2.236279e-003	 2.919879e-002	 0.000000e+000	 8.659023e+001
 5.619375e+000	 1.662277e-002	 1.663034e+003	 2.326279e-003	 3.279221e-002	 0.000000e+000	 8.929056e+001
 6.179375e+000	 1.884761e-002	 1.810820e+003	 3.444279e-003	 3.718121e-002	 0.000000e+000	 9.722966e+001
 6.799375e+000	 1.779542e-002	 1.969204e+003	 1.800311e-003	 3.510552e-002	 0.000000e+000	 1.057317e+002
 6.879375e+000	 1.594119e-002	 1.989899e+003	 3.023182e-003	 3.144763e-002	 0.000000e+000	 1.068389e+002
 7.039375e+000	 1.536955e-002	 2.029537e+003	 3.199698e-003	 3.031993e-002	 0.000000e+000	 1.089659e+002
 7.139375e+000	 1.796794e-002	 2.055156e+003	 1.980666e-003	 3.544584e-002	 0.000000e+000	 1.103470e+002
 7.239375e+000	 2.045487e-002	 2.079856e+003	 7.488598e-004	 4.035189e-002	 2.273322e-005	 1.116787e+002
 7.359375e+000	 2.289374e-002	 2.109396e+003	 1.221150e-003	 4.516312e-002	 6.382027e-005	 1.132703e+002
 7.619375e+000	 2.076410e-002	 2.172733e+003	 4.321279e-003	 4.096191e-002	 6.751432e-006	 1.166665e+002
 7.879375e+000	 2.157777e-002	 2.236821e+003	 3.305085e-003	 4.256707e-002	 7.565713e-006	 1.201097e+002
 7.999375e+000	 2.393723e-002	 2.266863e+003	 1.578279e-003	 4.722163e-002	 4.696768e-005	 1.217285e+002
 8.319375e+000	 2.341273e-002	 2.341214e+003	 2.587467e-003	 4.618693e-002	 1.894404e-005	 1.257198e+002
 8.639375e+000	 2.415632e-002	 2.421074e+003	 4.169215e-003	 4.765385e-002	 1.462607e-005	 1.300100e+002
 9.219375e+000	 2.475023e-002	 2.555091e+003	 5.328279e-003	 4.882545e-002	 0.000000e+000	 1.372083e+002
 9.639375e+000	 2.648423e-002	 2.646967e+003	 1.973311e-003	 5.224617e-002	 6.841775e-006	 1.421469e+002
 1.011938e+001	 2.612361e-002	 2.747939e+003	 5.427279e-003	 5.153477e-002	 0.000000e+000	 1.475682e+002
 1.031938e+001	 2.698294e-002	 2.790748e+003	 4.405310e-003	 5.323000e-002	 0.000000e+000	 1.498696e+002
 1.049938e+001	 2.621810e-002	 2.826296e+003	 2.795118e-003	 5.172117e-002	 0.000000e+000	 1.517764e+002
 1.063937e+001	 2.842494e-002	 2.854001e+003	 4.809376e-003	 5.607466e-002	 0.000000e+000	 1.532708e+002
 1.071937e+001	 3.057277e-002	 2.870023e+003	 6.376408e-003	 6.031176e-002	 3.446407e-005	 1.541378e+002
 1.079937e+001	 3.274403e-002	 2.886796e+003	 4.832247e-003	 6.459506e-002	 7.330709e-005	 1.550452e+002
 1.089937e+001	 3.108568e-002	 2.905238e+003	 6.533279e-003	 6.132358e-002	 3.620963e-005	 1.560306e+002
 1.095938e+001	 2.732948e-002	 2.916921e+003	 5.899841e-003	 5.391361e-002	 0.000000e+000	 1.566465e+002
 1.115938e+001	 2.718594e-002	 2.953053e+003	 3.106505e-003	 5.363045e-002	 0.000000e+000	 1.585864e+002
 1.129937e+001	 2.964923e-002	 2.978171e+003	 2.499053e-003	 5.848985e-002	 0.000000e+000	 1.599431e+002
 1.139937e+001	 3.171632e-002	 2.995862e+003	 4.001279e-003	 6.256767e-002	 2.710434e-005	 1.608997e+002
 1.163937e+001	 3.087052e-002	 3.039672e+003	 3.755602e-003	 6.089912e-002	 3.012016e-009	 1.632500e+002
 1.191938e+001	 3.058558e-002	 3.086487e+003	 6.085279e-003	 6.033702e-002	 0.000000e+000	 1.657633e+002
 1.213937e+001	 3.238403e-002	 3.123203e+003	 3.674924e-003	 6.388488e-002	 1.000050e-005	 1.677411e+002
 1.235938e+001	 3.061884e-002	 3.157250e+003	 4.235053e-003	 6.040263e-002	 0.000000e+000	 1.695638e+002
 1.267937e+001	 3.242877e-002	 3.210490e+003	 3.821279e-003	 6.397314e-002	 0.000000e+000	 1.724292e+002
 1.273938e+001	 3.489203e-002	 3.219669e+003	 3.257118e-003	 6.883248e-002	 3.654049e-005	 1.729307e+002
 1.281938e+001	 3.149816e-002	 3.230684e+003	 3.858498e-003	 6.213730e-002	 0.000000e+000	 1.735107e+002
 1.315938e+001	 3.188784e-002	 3.280085e+003	 5.847053e-003	 6.290602e-002	 0.000000e+000	 1.761652e+002
 1.323938e+001	 3.482929e-002	 3.294104e+003	 4.933924e-003	 6.870871e-002	 1.760579e-005	 1.769284e+002
 1.373938e+001	 3.577306e-002	 3.366203e+003	 3.109731e-003	 7.057051e-002	 1.908184e-005	 1.808042e+002
 1.397937e+001	 3.551568e-002	 3.401835e+003	 3.271892e-003	 7.006276e-002	 5.532677e-006	 1.827172e+002
 1.417937e+001	 3.581555e-002	 3.429791e+003	 5.771279e-003	 7.065432e-002	 4.801811e-006	 1.842198e+002
 1.429937e+001	 3.800687e-002	 3.447148e+003	 6.049763e-003	 7.497721e-002	 4.390292e-005	 1.851601e+002
 1.445938e+001	 3.671623e-002	 3.467926e+003	 4.985841e-003	 7.243112e-002	 1.350263e-005	 1.862714e+002
 1.451937e+001	 3.429845e-002	 3.476938e+003	 4.504956e-003	 6.766151e-002	 0.000000e+000	 1.867466e+002
 1.485938e+001	 3.352552e-002	 3.523169e+003	 5.398924e-003	 6.613671e-002	 0.000000e+000	 1.892267e+002
 1.503938e+001	 3.547826e-002	 3.548453e+003	 5.507569e-003	 6.998894e-002	 0.000000e+000	 1.905921e+002
 1.519938e+001	 3.783160e-002	 3.569899e+003	 4.557904e-003	 7.463144e-002	 1.126116e-005	 1.917529e+002
 1.533937e+001	 3.699498e-002	 3.587090e+003	 6.181279e-003	 7.298101e-002	 0.000000e+000	 1.926730e+002
 1.555937e+001	 3.808707e-002	 3.617798e+003	 5.968279e-003	 7.513541e-002	 4.912559e-006	 1.943267e+002
 1.571937e+001	 3.857706e-002	 3.639745e+003	 4.844505e-003	 7.610204e-002	 9.360871e-006	 1.955074e+002
 1.599938e+001	 3.798722e-002	 3.675210e+003	 4.677279e-003	 7.493845e-002	 0.000000e+000	 1.974101e+002
 1.645938e+001	 3.867323e-002	 3.734125e+003	 9.133029e-003	 7.629174e-002	 0.000000e+000	 2.005774e+002
 1.917937e+001	 4.914635e-002	 4.051810e+003	 6.674279e-003	 9.695237e-002	 1.198858e-004	 2.176867e+002
 2.749937e+001	 5.393652e-002	 4.944117e+003	 6.256537e-003	 1.064021e-001	 2.237828e-006	 2.656516e+002
 3.349937e+001	 6.064223e-002	 5.533091e+003	 6.860279e-003	 1.196306e-001	 0.000000e+000	 2.973370e+002
 4.043938e+001	 6.931223e-002	 6.135334e+003	 7.575654e-003	 1.367342e-001	 2.233878e-005	 3.297566e+002
 4.687938e+001	 7.933087e-002	 6.620667e+003	 8.262731e-003	 1.564982e-001	 1.045830e-004	 3.559121e+002
 5.407938e+001	 8.942782e-002	 7.107083e+003	 1.173250e-002	 1.764167e-001	 1.881072e-004	 3.821367e+002
 5.973938e+001	 9.943500e-002	 7.449970e+003	 1.297012e-002	 1.961582e-001	 3.039695e-004	 4.006521e+002
 6.435938e+001	 1.095438e-001	 7.706155e+003	 1.261112e-002	 2.161002e-001	 4.424280e-004	 4.145120e+002
 6.949937e+001	 1.200712e-001	 7.971602e+003	 1.490428e-002	 2.368678e-001	 5.869184e-004	 4.288791e+002
 7.549937e+001	 1.353452e-001	 8.264003e+003	 1.819928e-002	 2.669993e-001	 8.185497e-004	 4.447442e+002
 8.145937e+001	 1.501345e-001	 8.528950e+003	 1.809278e-002	 2.961744e-001	 1.047095e-003	 4.591364e+002
 8.509937e+001	 1.602006e-001	 8.684330e+003	 1.947792e-002	 3.160321e-001	 1.208547e-003	 4.675935e+002
 9.049937e+001	 1.762922e-001	 8.900793e+003	 1.856128e-002	 3.477765e-001	 1.474169e-003	 4.794002e+002
 9.507938e+001	 1.905268e-001	 9.077202e+003	 2.136012e-002	 3.758574e-001	 1.712655e-003	 4.890385e+002
 9.949937e+001	 2.048872e-001	 9.237672e+003	 2.280528e-002	 4.041867e-001	 1.957346e-003	 4.978243e+002
 1.044194e+002	 2.208513e-001	 9.413997e+003	 2.355109e-002	 4.356794e-001	 2.229779e-003	 5.074857e+002
 1.084994e+002	 2.376712e-001	 9.553771e+003	 2.581928e-002	 4.688606e-001	 2.527650e-003	 5.151907e+002
 1.129994e+002	 2.509152e-001	 9.695216e+003	 2.904628e-002	 4.949874e-001	 2.754688e-003	 5.229541e+002
 1.174994e+002	 2.682302e-001	 9.840665e+003	 2.976428e-002	 5.291452e-001	 3.060793e-003	 5.309799e+002
 1.205394e+002	 2.812957e-001	 9.931373e+003	 3.137089e-002	 5.549198e-001	 3.296224e-003	 5.360117e+002
 1.260794e+002	 3.014942e-001	 1.009476e+004	 3.474606e-002	 5.947660e-001	 3.654591e-003	 5.450460e+002
 1.294994e+002	 3.167232e-001	 1.018931e+004	 3.681728e-002	 6.248087e-001	 3.931486e-003	 5.503152e+002
 1.331794e+002	 3.319119e-001	 1.029187e+004	 3.725928e-002	 6.547718e-001	 4.205616e-003	 5.560197e+002
 1.376594e+002	 3.519862e-001	 1.041353e+004	 3.959828e-002	 6.943730e-001	 4.571093e-003	 5.628141e+002
 1.414994e+002	 3.678622e-001	 1.051467e+004	 4.135628e-002	 7.256920e-001	 4.858877e-003	 5.684570e+002
 1.452394e+002	 3.829633e-001	 1.061381e+004	 4.495176e-002	 7.554822e-001	 5.131842e-003	 5.739863e+002
 1.495394e+002	 4.031083e-001	 1.072329e+004	 4.705134e-002	 7.952229e-001	 5.501250e-003	 5.801358e+002
 1.534994e+002	 4.219592e-001	 1.082426e+004	 4.897528e-002	 8.324106e-001	 5.847151e-003	 5.858144e+002
 1.564994e+002	 4.355282e-001	 1.089386e+004	 4.946328e-002	 8.591786e-001	 6.096789e-003	 5.897375e+002
 1.600194e+002	 4.534368e-001	 1.098340e+004	 5.189783e-002	 8.945072e-001	 6.426714e-003	 5.947929e+002
 1.640194e+002	 4.735148e-001	 1.107778e+004	 5.587873e-002	 9.341157e-001	 6.797897e-003	 6.001394e+002
 1.676794e+002	 4.937524e-001	 1.116123e+004	 5.849628e-002	 9.740391e-001	 7.174649e-003	 6.048993e+002
 1.710794e+002	 5.137655e-001	 1.124342e+004	 5.936056e-002	 1.013519e+000	 7.547157e-003	 6.095923e+002
 1.744994e+002	 5.331802e-001	 1.132145e+004	 6.160028e-002	 1.051819e+000	 7.908801e-003	 6.140553e+002
 1.774994e+002	 5.511972e-001	 1.138904e+004	 6.438828e-002	 1.087362e+000	 8.245427e-003	 6.179386e+002
 1.804994e+002	 5.681462e-001	 1.145563e+004	 6.526928e-002	 1.120798e+000	 8.561287e-003	 6.217572e+002
 1.834994e+002	 5.869142e-001	 1.151980e+004	 6.778228e-002	 1.157822e+000	 8.913183e-003	 6.254691e+002
 1.866194e+002	 6.048779e-001	 1.158222e+004	 7.159328e-002	 1.193259e+000	 9.249648e-003	 6.290784e+002
 1.894994e+002	 6.233402e-001	 1.164739e+004	 7.244228e-002	 1.229681e+000	 9.595094e-003	 6.328458e+002
 1.924994e+002	 6.464462e-001	 1.171090e+004	 7.675328e-002	 1.275262e+000	 1.003151e-002	 6.365827e+002
 1.958194e+002	 6.659592e-001	 1.177999e+004	 7.852700e-002	 1.313756e+000	 1.039627e-002	 6.405819e+002
 1.990794e+002	 6.860072e-001	 1.184291e+004	 8.356072e-002	 1.353305e+000	 1.077280e-002	 6.442548e+002
 2.019394e+002	 7.062413e-001	 1.190241e+004	 8.324528e-002	 1.393222e+000	 1.115362e-002	 6.477465e+002
 2.049594e+002	 7.264140e-001	 1.195890e+004	 8.522972e-002	 1.433017e+000	 1.153380e-002	 6.510764e+002
 2.078994e+002	 7.465745e-001	 1.201415e+004	 8.840328e-002	 1.472788e+000	 1.191390e-002	 6.543403e+002
 2.106394e+002	 7.667416e-001	 1.207056e+004	 9.065250e-002	 1.512572e+000	 1.229370e-002	 6.576705e+002
 2.138194e+002	 7.871019e-001	 1.212930e+004	 9.342847e-002	 1.552738e+000	 1.267658e-002	 6.611328e+002
 2.164994e+002	 8.082502e-001	 1.217862e+004	 9.470928e-002	 1.594458e+000	 1.307687e-002	 6.640936e+002
 2.194994e+002	 8.289332e-001	 1.223545e+004	 9.690028e-002	 1.635260e+000	 1.346617e-002	 6.674603e+002
 2.224994e+002	 8.518222e-001	 1.229002e+004	 9.909828e-002	 1.680413e+000	 1.389877e-002	 6.707353e+002
 2.254994e+002	 8.721542e-001	 1.234193e+004	 1.025973e-001	 1.720523e+000	 1.428209e-002	 6.738337e+002
 2.284994e+002	 8.960232e-001	 1.239483e+004	 1.038323e-001	 1.767610e+000	 1.473378e-002	 6.770354e+002
 2.314994e+002	 9.181323e-001	 1.244757e+004	 1.076322e-001	 1.811225e+000	 1.515111e-002	 6.802075e+002
 2.344194e+002	 9.390464e-001	 1.249589e+004	 1.106460e-001	 1.852483e+000	 1.554609e-002	 6.831245e+002
 2.369794e+002	 9.592139e-001	 1.254003e+004	 1.108603e-001	 1.892268e+000	 1.592740e-002	 6.858055e+002
 2.397594e+002	 9.795058e-001	 1.258284e+004	 1.136887e-001	 1.932298e+000	 1.631129e-002	 6.884170e+002
 2.423994e+002	 9.997879e-001	 1.262724e+004	 1.162963e-001	 1.972309e+000	 1.669447e-002	 6.911170e+002
 2.443594e+002	 1.015182e+000	 1.265744e+004	 1.154180e-001	 2.002678e+000	 1.698602e-002	 6.929766e+002
 2.464994e+002	 1.032883e+000	 1.269349e+004	 1.194884e-001	 2.037597e+000	 1.732085e-002	 6.951882e+002
 2.492394e+002	 1.052459e+000	 1.273455e+004	 1.205098e-001	 2.076215e+000	 1.769073e-002	 6.977006e+002
 2.516594e+002	 1.071961e+000	 1.277302e+004	 1.224091e-001	 2.114688e+000	 1.805966e-002	 7.000720e+002
 2.540794e+002	 1.090924e+000	 1.281124e+004	 1.258758e-001	 2.152095e+000	 1.841805e-002	 7.024240e+002
 2.564994e+002	 1.108772e+000	 1.284604e+004	 1.248133e-001	 2.187306e+000	 1.875555e-002	 7.045746e+002
 2.589194e+002	 1.128847e+000	 1.288017e+004	 1.299421e-001	 2.226908e+000	 1.913618e-002	 7.067203e+002
 2.614994e+002	 1.149284e+000	 1.291697e+004	 1.315593e-001	 2.267225e+000	 1.952305e-002	 7.090190e+002
 2.644994e+002	 1.172497e+000	 1.296069e+004	 1.338383e-001	 2.313018e+000	 1.996183e-002	 7.117377e+002
 2.673794e+002	 1.196331e+000	 1.299925e+004	 1.353153e-001	 2.360036e+000	 2.041363e-002	 7.141829e+002
 2.697994e+002	 1.216663e+000	 1.303238e+004	 1.383557e-001	 2.400145e+000	 2.079883e-002	 7.162835e+002
 2.722194e+002	 1.236355e+000	 1.306575e+004	 1.412173e-001	 2.438992e+000	 2.117146e-002	 7.183905e+002
 2.746394e+002	 1.257557e+000	 1.309755e+004	 1.431487e-001	 2.480818e+000	 2.157347e-002	 7.204325e+002
 2.770594e+002	 1.277374e+000	 1.313043e+004	 1.443053e-001	 2.519911e+000	 2.194834e-002	 7.225165e+002
 2.794994e+002	 1.298275e+000	 1.316364e+004	 1.476323e-001	 2.561143e+000	 2.234391e-002	 7.246353e+002
 2.824994e+002	 1.323242e+000	 1.319844e+004	 1.497843e-001	 2.610396e+000	 2.281735e-002	 7.268998e+002
 2.854994e+002	 1.348526e+000	 1.323774e+004	 1.510183e-001	 2.660275e+000	 2.329564e-002	 7.294188e+002
 2.879194e+002	 1.369067e+000	 1.326862e+004	 1.534796e-001	 2.700797e+000	 2.368428e-002	 7.314086e+002
 2.903394e+002	 1.390258e+000	 1.329699e+004	 1.554883e-001	 2.742600e+000	 2.408586e-002	 7.332709e+002
 2.927594e+002	 1.409463e+000	 1.332561e+004	 1.559864e-001	 2.780486e+000	 2.444899e-002	 7.351203e+002
 2.951794e+002	 1.433711e+000	 1.335231e+004	 1.591073e-001	 2.828322e+000	 2.490950e-002	 7.369362e+002
 2.975994e+002	 1.454143e+000	 1.337935e+004	 1.620113e-001	 2.868628e+000	 2.529630e-002	 7.387178e+002
 3.004994e+002	 1.480270e+000	 1.341615e+004	 1.641473e-001	 2.920170e+000	 2.579019e-002	 7.411208e+002
 3.034994e+002	 1.506641e+000	 1.344953e+004	 1.656823e-001	 2.972193e+000	 2.628931e-002	 7.433402e+002
 3.060594e+002	 1.528447e+000	 1.347240e+004	 1.666103e-001	 3.015210e+000	 2.670294e-002	 7.449149e+002
 3.084794e+002	 1.549998e+000	 1.349785e+004	 1.712180e-001	 3.057725e+000	 2.711091e-002	 7.466301e+002
 3.109194e+002	 1.571729e+000	 1.352347e+004	 1.739084e-001	 3.100594e+000	 2.752212e-002	 7.483584e+002
 3.133394e+002	 1.593761e+000	 1.355000e+004	 1.737233e-001	 3.144056e+000	 2.793873e-002	 7.501429e+002
 3.157594e+002	 1.615960e+000	 1.357429e+004	 1.780985e-001	 3.187848e+000	 2.835888e-002	 7.518063e+002
 3.184994e+002	 1.638668e+000	 1.360207e+004	 1.797913e-001	 3.232646e+000	 2.878782e-002	 7.536723e+002
 3.214994e+002	 1.665714e+000	 1.363145e+004	 1.817583e-001	 3.286001e+000	 2.929930e-002	 7.556902e+002
 3.242194e+002	 1.689701e+000	 1.366115e+004	 1.848793e-001	 3.333320e+000	 2.975188e-002	 7.576840e+002
 3.266394e+002	 1.712218e+000	 1.368310e+004	 1.874474e-001	 3.377739e+000	 3.017789e-002	 7.592275e+002
 3.290594e+002	 1.733485e+000	 1.370763e+004	 1.900833e-001	 3.419693e+000	 3.057921e-002	 7.608974e+002
 3.314794e+002	 1.754968e+000	 1.372791e+004	 1.930041e-001	 3.462074e+000	 3.098551e-002	 7.623352e+002
 3.338994e+002	 1.776919e+000	 1.374928e+004	 1.944783e-001	 3.505376e+000	 3.140030e-002	 7.638410e+002
 3.364994e+002	 1.800384e+000	 1.377473e+004	 1.968803e-001	 3.551668e+000	 3.184295e-002	 7.655972e+002
 3.394994e+002	 1.827373e+000	 1.380143e+004	 2.000573e-001	 3.604910e+000	 3.235240e-002	 7.674757e+002
 3.423594e+002	 1.851044e+000	 1.382705e+004	 2.035165e-001	 3.651605e+000	 3.279849e-002	 7.692469e+002
 3.447794e+002	 1.874122e+000	 1.384733e+004	 2.047533e-001	 3.697133e+000	 3.323432e-002	 7.707133e+002
 3.471994e+002	 1.896688e+000	 1.386902e+004	 2.074575e-001	 3.741649e+000	 3.365985e-002	 7.722522e+002
 3.496394e+002	 1.918435e+000	 1.388930e+004	 2.094443e-001	 3.784549e+000	 3.406990e-002	 7.737011e+002
 3.520594e+002	 1.939405e+000	 1.390958e+004	 2.122543e-001	 3.825918e+000	 3.446500e-002	 7.751395e+002
 3.544994e+002	 1.962887e+000	 1.393094e+004	 2.165223e-001	 3.872242e+000	 3.490754e-002	 7.766763e+002
 3.574994e+002	 1.988071e+000	 1.395623e+004	 2.185163e-001	 3.921923e+000	 3.538139e-002	 7.784581e+002
 3.604994e+002	 2.017971e+000	 1.398218e+004	 2.200723e-001	 3.980908e+000	 3.594462e-002	 7.803483e+002
 3.634994e+002	 2.044327e+000	 1.400354e+004	 2.223533e-001	 4.032901e+000	 3.644117e-002	 7.819313e+002
 3.664994e+002	 2.073456e+000	 1.402590e+004	 2.252143e-001	 4.090365e+000	 3.698996e-002	 7.836126e+002
 3.689794e+002	 2.094697e+000	 1.404326e+004	 2.289078e-001	 4.132266e+000	 3.738971e-002	 7.848981e+002
 3.713994e+002	 2.117552e+000	 1.406079e+004	 2.330183e-001	 4.177353e+000	 3.781992e-002	 7.862178e+002
 3.738194e+002	 2.140507e+000	 1.407931e+004	 2.342543e-001	 4.222638e+000	 3.825163e-002	 7.875958e+002
 3.762394e+002	 2.162605e+000	 1.409658e+004	 2.373613e-001	 4.266230e+000	 3.866715e-002	 7.888919e+002
 3.786594e+002	 2.184479e+000	 1.411711e+004	 2.410993e-001	 4.309383e+000	 3.907753e-002	 7.903677e+002
 3.814994e+002	 2.212013e+000	 1.413372e+004	 2.425243e-001	 4.363700e+000	 3.959596e-002	 7.917094e+002
 3.844994e+002	 2.239662e+000	 1.415733e+004	 2.459783e-001	 4.418243e+000	 4.011469e-002	 7.934467e+002
 3.871394e+002	 2.263730e+000	 1.417252e+004	 2.478660e-001	 4.465722e+000	 4.056723e-002	 7.946590e+002
 3.895594e+002	 2.286056e+000	 1.418871e+004	 2.501603e-001	 4.509766e+000	 4.098638e-002	 7.959020e+002
 3.919794e+002	 2.309690e+000	 1.420732e+004	 2.524529e-001	 4.556389e+000	 4.142954e-002	 7.973014e+002
 3.943994e+002	 2.329246e+000	 1.422317e+004	 2.573083e-001	 4.594967e+000	 4.179598e-002	 7.984856e+002
 3.968194e+002	 2.353149e+000	 1.423836e+004	 2.577493e-001	 4.642122e+000	 4.224467e-002	 7.996986e+002
 3.994994e+002	 2.378135e+000	 1.425530e+004	 2.590063e-001	 4.691413e+000	 4.271321e-002	 8.010271e+002
 4.024994e+002	 2.405861e+000	 1.427450e+004	 2.614143e-001	 4.746109e+000	 4.323279e-002	 8.025246e+002
 4.052794e+002	 2.431911e+000	 1.428776e+004	 2.669093e-001	 4.797499e+000	 4.372181e-002	 8.036646e+002
 4.076994e+002	 2.455332e+000	 1.430220e+004	 2.673820e-001	 4.843702e+000	 4.416069e-002	 8.048313e+002
 4.101194e+002	 2.479769e+000	 1.431655e+004	 2.704263e-001	 4.891910e+000	 4.461858e-002	 8.060094e+002
 4.125394e+002	 2.501175e+000	 1.433341e+004	 2.726917e-001	 4.934138e+000	 4.501852e-002	 8.072832e+002
 4.149594e+002	 2.524698e+000	 1.434735e+004	 2.764298e-001	 4.980542e+000	 4.545887e-002	 8.084254e+002
 4.174994e+002	 2.547577e+000	 1.436303e+004	 2.799073e-001	 5.025676e+000	 4.588649e-002	 8.096573e+002
 4.204994e+002	 2.576328e+000	 1.438039e+004	 2.786373e-001	 5.082394e+000	 4.642415e-002	 8.110735e+002
 4.234394e+002	 2.603805e+000	 1.439541e+004	 2.836923e-001	 5.136599e+000	 4.693807e-002	 8.123394e+002
 4.258594e+002	 2.627390e+000	 1.440910e+004	 2.845569e-001	 5.183125e+000	 4.737879e-002	 8.134715e+002
 4.282794e+002	 2.651790e+000	 1.442153e+004	 2.888303e-001	 5.231260e+000	 4.783494e-002	 8.145460e+002
 4.306994e+002	 2.673562e+000	 1.443255e+004	 2.906699e-001	 5.274210e+000	 4.824180e-002	 8.155008e+002
 4.331194e+002	 2.696989e+000	 1.444682e+004	 2.918993e-001	 5.320425e+000	 4.867886e-002	 8.166654e+002
 4.355394e+002	 2.722946e+000	 1.446075e+004	 2.954233e-001	 5.371631e+000	 4.916332e-002	 8.178506e+002
 4.384994e+002	 2.751549e+000	 1.447227e+004	 2.980843e-001	 5.428057e+000	 4.969776e-002	 8.189401e+002
 4.414994e+002	 2.783176e+000	 1.449046e+004	 3.008293e-001	 5.490449e+000	 5.028714e-002	 8.204547e+002
 4.439994e+002	 2.806949e+000	 1.450222e+004	 3.045493e-001	 5.537346e+000	 5.073035e-002	 8.214860e+002
 4.464194e+002	 2.831876e+000	 1.451407e+004	 3.061530e-001	 5.586521e+000	 5.119499e-002	 8.225402e+002
 4.488394e+002	 2.856592e+000	 1.452467e+004	 3.086743e-001	 5.635277e+000	 5.165572e-002	 8.235209e+002
 4.512594e+002	 2.879243e+000	 1.453494e+004	 3.117057e-001	 5.679963e+000	 5.207767e-002	 8.244514e+002
 4.536794e+002	 2.902630e+000	 1.454562e+004	 3.139833e-001	 5.726099e+000	 5.251312e-002	 8.254174e+002
 4.564994e+002	 2.931255e+000	 1.456197e+004	 3.152873e-001	 5.782568e+000	 5.304509e-002	 8.267868e+002
 4.594994e+002	 2.960109e+000	 1.457716e+004	 3.202403e-001	 5.839489e+000	 5.358133e-002	 8.280944e+002
 4.621394e+002	 2.985824e+000	 1.458767e+004	 3.238352e-001	 5.890217e+000	 5.405965e-002	 8.290889e+002
 4.645594e+002	 3.009479e+000	 1.460069e+004	 3.246353e-001	 5.936882e+000	 5.449872e-002	 8.301944e+002
 4.669794e+002	 3.034642e+000	 1.461121e+004	 3.284806e-001	 5.986523e+000	 5.496632e-002	 8.311815e+002
 4.694194e+002	 3.057714e+000	 1.461863e+004	 3.300375e-001	 6.032037e+000	 5.539536e-002	 8.319611e+002
 4.718194e+002	 3.081184e+000	 1.462881e+004	 3.326093e-001	 6.078337e+000	 5.583102e-002	 8.329040e+002
 4.744994e+002	 3.108360e+000	 1.464350e+004	 3.358003e-001	 6.131948e+000	 5.633459e-002	 8.341616e+002
 4.774994e+002	 3.138504e+000	 1.465527e+004	 3.381013e-001	 6.191414e+000	 5.689388e-002	 8.352995e+002
 4.802994e+002	 3.163435e+000	 1.466753e+004	 3.390239e-001	 6.240595e+000	 5.735562e-002	 8.363858e+002
 4.827194e+002	 3.188571e+000	 1.467805e+004	 3.433341e-001	 6.290182e+000	 5.782138e-002	 8.373760e+002
 4.851394e+002	 3.217068e+000	 1.468631e+004	 3.419907e-001	 6.346399e+000	 5.834998e-002	 8.382904e+002
 4.875394e+002	 3.236471e+000	 1.469699e+004	 3.464419e-001	 6.384676e+000	 5.870859e-002	 8.392019e+002
 4.899794e+002	 3.258466e+000	 1.470400e+004	 3.500844e-001	 6.428067e+000	 5.911610e-002	 8.399446e+002
 4.924994e+002	 3.284252e+000	 1.471518e+004	 3.509873e-001	 6.478935e+000	 5.959297e-002	 8.409851e+002
 4.954994e+002	 3.313057e+000	 1.472545e+004	 3.545373e-001	 6.535760e+000	 6.012590e-002	 8.420208e+002
 4.984194e+002	 3.345160e+000	 1.473897e+004	 3.595094e-001	 6.599089e+000	 6.071903e-002	 8.432947e+002
 5.008394e+002	 3.367015e+000	 1.474739e+004	 3.597353e-001	 6.642203e+000	 6.112281e-002	 8.441182e+002
 5.032594e+002	 3.391837e+000	 1.475641e+004	 3.638256e-001	 6.691170e+000	 6.158133e-002	 8.450218e+002
 5.056794e+002	 3.416367e+000	 1.476250e+004	 3.631113e-001	 6.739561e+000	 6.203486e-002	 8.457540e+002
 5.080994e+002	 3.440399e+000	 1.477026e+004	 3.643193e-001	 6.786971e+000	 6.247861e-002	 8.465745e+002
 5.105194e+002	 3.464124e+000	 1.477885e+004	 3.686029e-001	 6.833773e+000	 6.291628e-002	 8.474383e+002
 5.134994e+002	 3.494564e+000	 1.478920e+004	 3.691493e-001	 6.893824e+000	 6.347769e-002	 8.485083e+002
 5.164994e+002	 3.525593e+000	 1.479780e+004	 3.748183e-001	 6.955035e+000	 6.405008e-002	 8.494876e+002
 5.189994e+002	 3.551315e+000	 1.480806e+004	 3.754013e-001	 7.005778e+000	 6.452363e-002	 8.504800e+002
 5.214194e+002	 3.574628e+000	 1.481507e+004	 3.774396e-001	 7.051768e+000	 6.495314e-002	 8.512483e+002
 5.238394e+002	 3.599656e+000	 1.482550e+004	 3.799563e-001	 7.101140e+000	 6.541338e-002	 8.522404e+002
 5.262594e+002	 3.625057e+000	 1.483226e+004	 3.836769e-001	 7.151251e+000	 6.588114e-002	 8.530279e+002
 5.286794e+002	 3.649485e+000	 1.484019e+004	 3.864133e-001	 7.199440e+000	 6.633044e-002	 8.538676e+002
 5.314994e+002	 3.677879e+000	 1.484745e+004	 3.883073e-001	 7.255454e+000	 6.685288e-002	 8.547317e+002
 5.344994e+002	 3.710392e+000	 1.485454e+004	 3.922303e-001	 7.319593e+000	 6.745104e-002	 8.556513e+002
 5.371394e+002	 3.737526e+000	 1.486230e+004	 3.936538e-001	 7.373121e+000	 6.794955e-002	 8.565253e+002
 5.395594e+002	 3.763741e+000	 1.487031e+004	 3.946533e-001	 7.424835e+000	 6.843083e-002	 8.573997e+002
 5.419794e+002	 3.786270e+000	 1.487916e+004	 3.979687e-001	 7.469279e+000	 6.884382e-002	 8.582646e+002
 5.443994e+002	 3.814400e+000	 1.488442e+004	 4.007663e-001	 7.524772e+000	 6.936053e-002	 8.590111e+002
 5.468194e+002	 3.837573e+000	 1.488992e+004	 4.038730e-001	 7.570486e+000	 6.978573e-002	 8.596943e+002
 5.494994e+002	 3.867107e+000	 1.489835e+004	 4.057983e-001	 7.628749e+000	 7.032707e-002	 8.606467e+002
 5.524994e+002	 3.898330e+000	 1.490828e+004	 4.080823e-001	 7.690344e+000	 7.089882e-002	 8.617132e+002
 5.552794e+002	 3.926536e+000	 1.491446e+004	 4.116313e-001	 7.745987e+000	 7.141567e-002	 8.625155e+002
 5.576794e+002	 3.953048e+000	 1.492046e+004	 4.144999e-001	 7.798288e+000	 7.190118e-002	 8.632818e+002
 5.600994e+002	 3.976093e+000	 1.492555e+004	 4.153743e-001	 7.843749e+000	 7.232304e-002	 8.639404e+002
 5.625193e+002	 4.002604e+000	 1.493415e+004	 4.194593e-001	 7.896048e+000	 7.280752e-002	 8.648571e+002
 5.649194e+002	 4.026475e+000	 1.494091e+004	 4.225719e-001	 7.943138e+000	 7.324377e-002	 8.656262e+002
 5.674994e+002	 4.054226e+000	 1.494433e+004	 4.271033e-001	 7.997885e+000	 7.375168e-002	 8.662635e+002
 5.704994e+002	 4.085087e+000	 1.495242e+004	 4.259613e-001	 8.058765e+000	 7.431525e-002	 8.672212e+002
 5.733994e+002	 4.113983e+000	 1.495885e+004	 4.311973e-001	 8.115767e+000	 7.484289e-002	 8.680515e+002
 5.758194e+002	 4.138885e+000	 1.496386e+004	 4.336073e-001	 8.164893e+000	 7.529752e-002	 8.687366e+002
 5.782394e+002	 4.163535e+000	 1.497012e+004	 4.356796e-001	 8.213520e+000	 7.574703e-002	 8.694906e+002
 5.806594e+002	 4.187862e+000	 1.497412e+004	 4.398723e-001	 8.261512e+000	 7.619096e-002	 8.701089e+002
 5.830793e+002	 4.210524e+000	 1.498255e+004	 4.436030e-001	 8.306216e+000	 7.660327e-002	 8.709581e+002
 5.867194e+002	 4.248337e+000	 1.498714e+004	 4.445513e-001	 8.380812e+000	 7.729297e-002	 8.718249e+002
 5.891394e+002	 4.272376e+000	 1.499306e+004	 4.486577e-001	 8.428234e+000	 7.773052e-002	 8.725511e+002
 5.915594e+002	 4.296311e+000	 1.499982e+004	 4.519833e-001	 8.475451e+000	 7.816580e-002	 8.733246e+002
 5.944994e+002	 4.327938e+000	 1.500792e+004	 4.524633e-001	 8.537843e+000	 7.874086e-002	 8.742984e+002
 5.974994e+002	 4.359184e+000	 1.501326e+004	 4.564953e-001	 8.599483e+000	 7.930925e-002	 8.751062e+002
 6.000193e+002	 4.383595e+000	 1.501827e+004	 4.581954e-001	 8.647638e+000	 7.975288e-002	 8.757862e+002
 6.024394e+002	 4.406780e+000	 1.502277e+004	 4.639673e-001	 8.693377e+000	 8.017413e-002	 8.764177e+002
 6.048394e+002	 4.432148e+000	 1.502995e+004	 4.649203e-001	 8.743422e+000	 8.063434e-002	 8.772400e+002
 6.072594e+002	 4.458004e+000	 1.503187e+004	 4.660763e-001	 8.794428e+000	 8.110436e-002	 8.777635e+002
 6.096794e+002	 4.483081e+000	 1.503504e+004	 4.694796e-001	 8.843899e+000	 8.155973e-002	 8.783479e+002
 6.124994e+002	 4.511253e+000	 1.504514e+004	 4.725763e-001	 8.899474e+000	 8.206961e-002	 8.793865e+002
 6.154994e+002	 4.541683e+000	 1.504672e+004	 4.735943e-001	 8.959504e+000	 8.262211e-002	 8.799639e+002
 6.181394e+002	 4.568071e+000	 1.505206e+004	 4.768050e-001	 9.011560e+000	 8.310011e-002	 8.806967e+002
 6.205594e+002	 4.592367e+000	 1.505548e+004	 4.786013e-001	 9.059489e+000	 8.354033e-002	 8.812842e+002
 6.229794e+002	 4.617513e+000	 1.506049e+004	 4.818602e-001	 9.109095e+000	 8.399544e-002	 8.819783e+002
 6.253994e+002	 4.642385e+000	 1.506450e+004	 4.842561e-001	 9.158161e+000	 8.444559e-002	 8.826095e+002
 6.278194e+002	 4.668149e+000	 1.506850e+004	 4.881709e-001	 9.208988e+000	 8.491171e-002	 8.832552e+002
 6.304994e+002	 4.695133e+000	 1.507184e+004	 4.916230e-001	 9.262218e+000	 8.539984e-002	 8.838814e+002
 6.334994e+002	 4.726201e+000	 1.507643e+004	 4.923393e-001	 9.323508e+000	 8.596140e-002	 8.846465e+002
 6.362594e+002	 4.754287e+000	 1.508427e+004	 4.933620e-001	 9.378913e+000	 8.646798e-002	 8.855553e+002
 6.386794e+002	 4.780260e+000	 1.508686e+004	 4.972731e-001	 9.430151e+000	 8.693725e-002	 8.861220e+002
 6.410994e+002	 4.806516e+000	 1.508911e+004	 5.007085e-001	 9.481946e+000	 8.741147e-002	 8.866738e+002
 6.435193e+002	 4.831874e+000	 1.509379e+004	 5.008167e-001	 9.531971e+000	 8.786872e-002	 8.873536e+002
 6.459394e+002	 4.857207e+000	 1.509562e+004	 5.038305e-001	 9.581947e+000	 8.832594e-002	 8.878664e+002
 6.484994e+002	 4.885577e+000	 1.509971e+004	 5.050998e-001	 9.637913e+000	 8.883727e-002	 8.885605e+002
 6.514994e+002	 4.916872e+000	 1.510388e+004	 5.101870e-001	 9.699649e+000	 8.940108e-002	 8.893064e+002
 6.544194e+002	 4.948935e+000	 1.510739e+004	 5.107965e-001	 9.762900e+000	 8.997857e-002	 8.900256e+002
 6.568194e+002	 4.975332e+000	 1.511106e+004	 5.126873e-001	 9.814976e+000	 9.045360e-002	 8.906642e+002
 6.592194e+002	 5.000323e+000	 1.511498e+004	 5.159458e-001	 9.864275e+000	 9.090301e-002	 8.912953e+002
 6.616394e+002	 5.026210e+000	 1.511690e+004	 5.188553e-001	 9.915344e+000	 9.136880e-002	 8.918228e+002
 6.640594e+002	 5.051558e+000	 1.512157e+004	 5.210575e-001	 9.965347e+000	 9.182405e-002	 8.925043e+002
 6.664994e+002	 5.079192e+000	 1.512283e+004	 5.234015e-001	 1.001986e+001	 9.232098e-002	 8.930206e+002
 6.694994e+002	 5.110280e+000	 1.512858e+004	 5.229588e-001	 1.008119e+001	 9.287877e-002	 8.938585e+002
 6.724994e+002	 5.137880e+000	 1.512825e+004	 5.277929e-001	 1.013564e+001	 9.337491e-002	 8.942809e+002
 6.749594e+002	 5.163077e+000	 1.513259e+004	 5.297512e-001	 1.018534e+001	 9.382661e-002	 8.949411e+002
 6.773794e+002	 5.189944e+000	 1.513684e+004	 5.318704e-001	 1.023835e+001	 9.430812e-002	 8.956233e+002
 6.797994e+002	 5.215956e+000	 1.513743e+004	 5.341643e-001	 1.028966e+001	 9.477485e-002	 8.960748e+002
 6.822194e+002	 5.240591e+000	 1.514085e+004	 5.348028e-001	 1.033826e+001	 9.521605e-002	 8.966722e+002
 6.846394e+002	 5.265954e+000	 1.514527e+004	 5.387658e-001	 1.038829e+001	 9.566988e-002	 8.973408e+002
 6.874994e+002	 5.297191e+000	 1.514619e+004	 5.407668e-001	 1.044992e+001	 9.622954e-002	 8.978961e+002
 6.904994e+002	 5.327195e+000	 1.514769e+004	 5.422966e-001	 1.050910e+001	 9.676666e-002	 8.984663e+002
 6.931394e+002	 5.354988e+000	 1.515178e+004	 5.452573e-001	 1.056393e+001	 9.726337e-002	 8.991547e+002
 6.955594e+002	 5.378856e+000	 1.515420e+004	 5.488222e-001	 1.061102e+001	 9.768997e-002	 8.996812e+002
 6.979794e+002	 5.404380e+000	 1.515904e+004	 5.495716e-001	 1.066137e+001	 9.814547e-002	 9.003782e+002
 7.004194e+002	 5.428407e+000	 1.515988e+004	 5.506813e-001	 1.070877e+001	 9.857487e-002	 9.008134e+002
 7.028394e+002	 5.454735e+000	 1.516472e+004	 5.530783e-001	 1.076071e+001	 9.904435e-002	 9.015237e+002
 7.054994e+002	 5.482027e+000	 1.516163e+004	 5.558503e-001	 1.081455e+001	 9.953252e-002	 9.017782e+002
 7.084994e+002	 5.513622e+000	 1.516513e+004	 5.567704e-001	 1.087687e+001	 1.000958e-001	 9.024940e+002
 7.113194e+002	 5.543837e+000	 1.516755e+004	 5.593393e-001	 1.093648e+001	 1.006345e-001	 9.031232e+002
 7.137394e+002	 5.570617e+000	 1.516780e+004	 5.609978e-001	 1.098931e+001	 1.011120e-001	 9.035681e+002
 7.161594e+002	 5.594577e+000	 1.517114e+004	 5.649132e-001	 1.103658e+001	 1.015384e-001	 9.041518e+002
 7.185793e+002	 5.620479e+000	 1.517056e+004	 5.656648e-001	 1.108767e+001	 1.020001e-001	 9.045330e+002
 7.209994e+002	 5.645561e+000	 1.517248e+004	 5.681693e-001	 1.113715e+001	 1.024464e-001	 9.050503e+002
 7.234994e+002	 5.670540e+000	 1.517573e+004	 5.708883e-001	 1.118643e+001	 1.028904e-001	 9.056458e+002
 7.264994e+002	 5.703064e+000	 1.517690e+004	 5.717943e-001	 1.125059e+001	 1.034688e-001	 9.062381e+002
 7.294794e+002	 5.732822e+000	 1.517531e+004	 5.738473e-001	 1.130930e+001	 1.039984e-001	 9.066216e+002
 7.318994e+002	 5.758133e+000	 1.517665e+004	 5.763003e-001	 1.135923e+001	 1.044480e-001	 9.071080e+002
 7.343194e+002	 5.784408e+000	 1.517773e+004	 5.769075e-001	 1.141106e+001	 1.049146e-001	 9.075951e+002
 7.367394e+002	 5.809684e+000	 1.517949e+004	 5.802902e-001	 1.146092e+001	 1.053631e-001	 9.081061e+002
 7.391594e+002	 5.834975e+000	 1.518116e+004	 5.806715e-001	 1.151082e+001	 1.058116e-001	 9.086124e+002
 7.415793e+002	 5.860458e+000	 1.518274e+004	 5.831681e-001	 1.156109e+001	 1.062634e-001	 9.091169e+002
 7.444994e+002	 5.890543e+000	 1.518166e+004	 5.842037e-001	 1.162044e+001	 1.067972e-001	 9.095355e+002
 7.474994e+002	 5.920942e+000	 1.518399e+004	 5.879011e-001	 1.168041e+001	 1.073355e-001	 9.101642e+002
 7.500594e+002	 5.947786e+000	 1.517974e+004	 5.887632e-001	 1.173336e+001	 1.078119e-001	 9.103405e+002
 7.524794e+002	 5.972448e+000	 1.518174e+004	 5.908044e-001	 1.178201e+001	           0.0	           0.0
 7.548994e+002	 5.997506e+000	 1.518049e+004	 5.915635e-001	 1.183145e+001	           0.0	           0.0
 7.573194e+002	 6.022935e+000	 1.518107e+004	 5.935375e-001	 1.188161e+001	           0.0	           0.0
 7.597394e+002	 6.046869e+000	 1.518066e+004	 5.963674e-001	 1.192883e+001	           0.0	           0.0
 7.624994e+002	 6.075886e+000	 1.518182e+004	 5.973493e-001	 1.198607e+001	           0.0	           0.0
 7.654994e+002	 6.107048e+000	 1.518191e+004	 5.981453e-001	 1.204754e+001	           0.0	           0.0
 7.682194e+002	 6.135223e+000	 1.517940e+004	 6.003413e-001	 1.210312e+001	           0.0	           0.0
 7.706394e+002	 6.160318e+000	 1.517790e+004	 6.014401e-001	 1.215263e+001	           0.0	           0.0
 7.730594e+002	 6.182833e+000	 1.517640e+004	 6.045685e-001	 1.219705e+001	           0.0	           0.0
 7.754794e+002	 6.205610e+000	 1.517398e+004	 6.056293e-001	 1.224198e+001	           0.0	           0.0
 7.778994e+002	 6.231712e+000	 1.517231e+004	 6.067674e-001	 1.229347e+001	           0.0	           0.0
 7.804994e+002	 6.255988e+000	 1.517239e+004	 6.072310e-001	 1.234136e+001	           0.0	           0.0
 7.834994e+002	 6.285702e+000	 1.516939e+004	 6.100346e-001	 1.239998e+001	           0.0	           0.0
 7.863594e+002	 6.314158e+000	 1.516305e+004	 6.107405e-001	 1.245611e+001	           0.0	           0.0
 7.887794e+002	 6.337169e+000	 1.516180e+004	 6.122670e-001	 1.250151e+001	           0.0	           0.0
 7.911994e+002	 6.359611e+000	 1.515954e+004	 6.138381e-001	 1.254578e+001	           0.0	           0.0
 7.936194e+002	 6.382275e+000	 1.515646e+004	 6.147945e-001	 1.259049e+001	           0.0	           0.0
 7.960394e+002	 6.404109e+000	 1.515195e+004	 6.165892e-001	 1.263356e+001	           0.0	           0.0
 7.984994e+002	 6.426127e+000	 1.514853e+004	 6.162974e-001	 1.267700e+001	           0.0	           0.0
 8.014994e+002	 6.452482e+000	 1.514252e+004	 6.186564e-001	 1.272899e+001	           0.0	           0.0
 8.044994e+002	 6.478640e+000	 1.513943e+004	 6.199040e-001	 1.278059e+001	           0.0	           0.0
 8.074994e+002	 6.504959e+000	 1.513242e+004	 6.208506e-001	 1.283251e+001	           0.0	           0.0
 8.104994e+002	 6.530823e+000	 1.512149e+004	 6.208656e-001	 1.288353e+001	           0.0	           0.0
 8.129794e+002	 6.554592e+000	 1.511248e+004	 6.218992e-001	 1.293043e+001	           0.0	           0.0
 8.153994e+002	 6.575578e+000	 1.510338e+004	 6.241708e-001	 1.297182e+001	           0.0	           0.0
 8.178194e+002	 6.596407e+000	 1.509604e+004	 6.229947e-001	 1.301292e+001	           0.0	           0.0
 8.202394e+002	 6.615060e+000	 1.508586e+004	 6.243924e-001	 1.304971e+001	           0.0	           0.0
 8.226594e+002	 6.631130e+000	 1.507434e+004	 6.243663e-001	 1.308141e+001	           0.0	           0.0
 8.254994e+002	 6.661896e+000	 1.505957e+004	 6.222783e-001	 1.314211e+001	           0.0	           0.0
 8.284994e+002	 6.689308e+000	 1.504205e+004	 6.260223e-001	 1.319618e+001	           0.0	           0.0
 8.311194e+002	 6.709882e+000	 1.502945e+004	 6.256560e-001	 1.323677e+001	           0.0	           0.0
 8.335394e+002	 6.731010e+000	 1.501242e+004	 6.235053e-001	 1.327845e+001	           0.0	           0.0
 8.359594e+002	 6.751215e+000	 1.499724e+004	 6.277951e-001	 1.331831e+001	           0.0	           0.0
 8.383794e+002	 6.770664e+000	 1.498096e+004	 6.239443e-001	 1.335668e+001	           0.0	           0.0
 8.407994e+002	 6.787879e+000	 1.496261e+004	 6.256344e-001	 1.339064e+001	           0.0	           0.0
 8.434994e+002	 6.809112e+000	 1.493507e+004	 6.262373e-001	 1.343252e+001	           0.0	           0.0
 8.464994e+002	 6.833397e+000	 1.490803e+004	 6.258483e-001	 1.348043e+001	           0.0	           0.0
 8.492794e+002	 6.855522e+000	 1.487916e+004	 6.272073e-001	 1.352408e+001	           0.0	           0.0
 8.516994e+002	 6.875412e+000	 1.485462e+004	 6.271113e-001	 1.356332e+001	           0.0	           0.0
 8.541194e+002	 6.894862e+000	 1.482717e+004	 6.263708e-001	 1.360169e+001	           0.0	           0.0
 8.565394e+002	 6.914009e+000	 1.479629e+004	 6.265283e-001	 1.363946e+001	           0.0	           0.0
 8.589594e+002	 6.931906e+000	 1.476567e+004	 6.262106e-001	 1.367476e+001	           0.0	           0.0
 8.614994e+002	 6.953720e+000	 1.472970e+004	 6.281713e-001	 1.371780e+001	           0.0	           0.0
 8.644994e+002	 6.980102e+000	 1.468172e+004	 6.249033e-001	 1.376984e+001	           0.0	           0.0
 8.674394e+002	 6.998882e+000	 1.462489e+004	 6.265383e-001	 1.380689e+001	           0.0	           0.0
 8.698594e+002	 7.017643e+000	 1.457441e+004	 6.267455e-001	 1.384390e+001	           0.0	           0.0
 8.722794e+002	 7.034111e+000	 1.451958e+004	 6.264933e-001	 1.387639e+001	           0.0	           0.0
 8.746994e+002	 7.051681e+000	 1.445491e+004	 6.274633e-001	 1.391105e+001	           0.0	           0.0
 8.771194e+002	 7.066500e+000	 1.436871e+004	 6.280137e-001	 1.394028e+001	           0.0	           0.0
 8.795394e+002	 7.080723e+000	 1.423569e+004	 6.270353e-001	 1.396834e+001	           0.0	           0.0
 8.807394e+002	 7.088984e+000	 1.413297e+004	 6.253574e-001	 1.398463e+001	           0.0	           0.0