File: DP800 Tensile Tests/Fehlemann_Test_WP_KL_2024_1011.TRA
$Fehlemann_Test_WP_KL_2024_101.ZSE
Material:                               St
Auftrags-Nr.:                           WP_KL_2024_101
Probe:                                  1_0°_A
Vorkraft:                               100 N
Probengeometrie:                        H12,5x50
Messlänge:                              50.0107 mm
Probendicke a0:                         1.49 mm
Probenbreite b0:                        12.63 mm
Prüfgeschwindigkeit:                    1 mm/min
Datum:                                  26.09.2024
Maschinendaten:                         4204 WN:800315
Traversenwegaufnehmer WN:800315
Videoextensometer
Videoextensometer - Querdehnung
Kraftsensor ID:0 WN:800316 50 kN

Bemerkung:
$
      Prüfzeit	   Standardweg	 Spannung     	Breitenänderung	       Dehnung	 wahre Dehnung	wahre Spannung
 1.999268e-002	 1.122898e-004	 2.002740e+002	-1.906680e-004	 2.245315e-004	 0.000000e+000	 1.064373e+001
 2.599927e-001	-1.144463e-003	 2.007747e+002	-1.436293e-003	-2.288437e-003	 0.000000e+000	 1.067008e+001
 6.599927e-001	-6.614290e-004	 2.762115e+002	 2.373238e-003	-1.322575e-003	 0.000000e+000	 1.467927e+001
 1.059993e+000	 1.070182e-003	 3.876142e+002	 9.429802e-004	 2.139906e-003	 0.000000e+000	 2.060049e+001
 1.739993e+000	 2.798537e-003	 5.728683e+002	 8.974964e-004	 5.595876e-003	 0.000000e+000	 3.044721e+001
 2.199993e+000	 4.584504e-003	 6.992916e+002	 1.142271e-003	 9.167047e-003	 0.000000e+000	 3.716778e+001
 2.739993e+000	 6.216988e-003	 8.491638e+002	 6.621415e-004	 1.243132e-002	 0.000000e+000	 4.513505e+001
 3.019993e+000	 7.565008e-003	 9.251848e+002	 4.917383e-004	 1.512678e-002	 0.000000e+000	 4.917707e+001
 3.379993e+000	 9.398666e-003	 1.027408e+003	 1.840426e-003	 1.879331e-002	 0.000000e+000	 5.461263e+001
 3.719993e+000	 9.953827e-003	 1.121287e+003	 1.215561e-003	 1.990339e-002	 0.000000e+000	 5.960349e+001
 4.119993e+000	 1.159650e-002	 1.233190e+003	 2.613206e-003	 2.318805e-002	 0.000000e+000	 6.555402e+001
 4.519993e+000	 1.359760e-002	 1.348348e+003	 2.523832e-003	 2.718939e-002	 0.000000e+000	 7.167846e+001
 5.039993e+000	 1.415229e-002	 1.497803e+003	 1.607303e-003	 2.829852e-002	 0.000000e+000	 7.962439e+001
 5.539993e+000	 1.595260e-002	 1.636994e+003	 2.808948e-003	 3.189838e-002	 0.000000e+000	 8.702702e+001
 5.699993e+000	 1.768202e-002	 1.681472e+003	 2.888883e-003	 3.535648e-002	 1.252027e-005	 8.939466e+001
 6.119993e+000	 1.776244e-002	 1.796379e+003	 2.062141e-003	 3.551728e-002	 0.000000e+000	 9.550382e+001
 6.239993e+000	 1.958496e-002	 1.830343e+003	 1.766367e-003	 3.916153e-002	 8.530433e-006	 9.731301e+001
 6.679993e+000	 2.113931e-002	 1.948922e+003	 3.424400e-003	 4.226958e-002	 6.124654e-006	 1.036207e+002
 7.119993e+000	 2.311067e-002	 2.064581e+003	 3.128851e-003	 4.621144e-002	 1.288182e-005	 1.097744e+002
 7.659993e+000	 2.396495e-002	 2.202937e+003	 2.970238e-003	 4.791964e-002	 0.000000e+000	 1.171328e+002
 7.979993e+000	 2.590163e-002	 2.288805e+003	 4.001819e-003	 5.179218e-002	 5.369490e-006	 1.217032e+002
 8.479993e+000	 2.747470e-002	 2.413392e+003	 5.993109e-003	 5.493764e-002	 1.641080e-006	 1.283320e+002
 8.959992e+000	 2.927125e-002	 2.531387e+003	 4.687013e-003	 5.852997e-002	 4.243106e-006	 1.346112e+002
 9.259993e+000	 3.032696e-002	 2.602151e+003	 5.780426e-003	 6.064094e-002	 5.369458e-006	 1.383771e+002
 9.719993e+000	 3.092757e-002	 2.710133e+003	 7.512819e-003	 6.184190e-002	 0.000000e+000	 1.441211e+002
 1.003999e+001	 3.259660e-002	 2.779811e+003	 6.964464e-003	 6.517926e-002	 5.822973e-007	 1.478314e+002
 1.055999e+001	 3.428934e-002	 2.897806e+003	 7.961142e-003	 6.856401e-002	 1.108559e-006	 1.541117e+002
 1.103999e+001	 3.595988e-002	 3.000030e+003	 8.734851e-003	 7.190438e-002	 5.644788e-006	 1.595535e+002
 1.153999e+001	 3.666882e-002	 3.104089e+003	 8.715529e-003	 7.332195e-002	 0.000000e+000	 1.650901e+002
 1.211999e+001	 3.803389e-002	 3.221083e+003	 8.415529e-003	 7.605151e-002	 0.000000e+000	 1.713170e+002
 1.269999e+001	 3.986244e-002	 3.331818e+003	 6.889883e-003	 7.970782e-002	 0.000000e+000	 1.772131e+002
 1.303999e+001	 4.148285e-002	 3.398660e+003	 6.537851e-003	 8.294795e-002	 3.509302e-006	 1.807741e+002
 1.359999e+001	 4.320976e-002	 3.502636e+003	 5.910916e-003	 8.640103e-002	 8.677740e-006	 1.863110e+002
 1.385999e+001	 4.502212e-002	 3.550451e+003	 7.792755e-003	 9.002497e-002	 3.141383e-005	 1.888612e+002
 1.411999e+001	 4.325315e-002	 3.596264e+003	 6.494561e-003	 8.648779e-002	 0.000000e+000	 1.912914e+002
 1.465999e+001	 4.505351e-002	 3.694983e+003	 6.351238e-003	 9.008774e-002	 0.000000e+000	 1.965495e+002
 1.519999e+001	 4.621402e-002	 3.789446e+003	 5.443625e-003	 9.240827e-002	 0.000000e+000	 2.015790e+002
 1.919999e+001	 5.631395e-002	 4.435499e+003	 6.048528e-003	 1.126038e-001	 7.269572e-006	 2.359933e+002
 2.401999e+001	 6.708651e-002	 5.098157e+003	 6.981770e-003	 1.341443e-001	 3.554232e-005	 2.713088e+002
 3.001999e+001	 7.997219e-002	 5.817477e+003	 1.087386e-002	 1.599102e-001	 9.006489e-005	 3.096685e+002
 3.601999e+001	 9.586960e-002	 6.465282e+003	 1.289286e-002	 1.916982e-001	 2.249867e-004	 3.442608e+002
 3.975999e+001	 1.069302e-001	 6.828780e+003	 1.445305e-002	 2.138146e-001	 3.434671e-004	 3.636965e+002
 4.501999e+001	 1.191994e-001	 7.302096e+003	 1.437764e-002	 2.383477e-001	 4.550913e-004	 3.890002e+002
 5.091999e+001	 1.372639e-001	 7.774661e+003	 1.351921e-002	 2.744690e-001	 6.827249e-004	 4.143241e+002
 5.443999e+001	 1.473650e-001	 8.027591e+003	 1.568295e-002	 2.946669e-001	 8.131794e-004	 4.278893e+002
 6.001999e+001	 1.653959e-001	 8.393343e+003	 1.645849e-002	 3.307211e-001	 1.070193e-003	 4.475455e+002
 6.333999e+001	 1.777756e-001	 8.598958e+003	 1.617962e-002	 3.554752e-001	 1.259449e-003	 4.586223e+002
 6.877999e+001	 1.979743e-001	 8.902541e+003	 1.902302e-002	 3.958639e-001	 1.577154e-003	 4.750049e+002
 7.201999e+001	 2.129412e-001	 9.073275e+003	 2.095149e-002	 4.257913e-001	 1.827787e-003	 4.842589e+002
 7.653999e+001	 2.280926e-001	 9.296748e+003	 2.203879e-002	 4.560876e-001	 2.067175e-003	 4.963357e+002
 8.073999e+001	 2.481860e-001	 9.488261e+003	 2.491811e-002	 4.962658e-001	 2.414098e-003	 5.067628e+002
 8.401999e+001	 2.615533e-001	 9.633627e+003	 2.641024e-002	 5.229947e-001	 2.639764e-003	 5.146636e+002
 8.805999e+001	 2.784996e-001	 9.800856e+003	 2.765650e-002	 5.568800e-001	 2.930582e-003	 5.237741e+002
 9.217999e+001	 2.988631e-001	 9.962161e+003	 3.020653e-002	 5.975983e-001	 3.291090e-003	 5.326100e+002
 9.601999e+001	 3.173815e-001	 1.010661e+004	 3.288561e-002	 6.346271e-001	 3.619450e-003	 5.405315e+002
 9.901999e+001	 3.317935e-001	 1.021367e+004	 3.550883e-002	 6.634451e-001	 3.876431e-003	 5.464140e+002
 1.023400e+002	 3.490663e-001	 1.032958e+004	 3.556320e-002	 6.979831e-001	 4.187821e-003	 5.528045e+002
 1.065600e+002	 3.692695e-001	 1.046710e+004	 4.065846e-002	 7.383811e-001	 4.551372e-003	 5.603889e+002
 1.102400e+002	 3.894385e-001	 1.059094e+004	 4.183011e-002	 7.787104e-001	 4.917955e-003	 5.672458e+002
 1.140200e+002	 4.078722e-001	 1.070568e+004	 4.566958e-002	 8.155699e-001	 5.252442e-003	 5.736010e+002
 1.170200e+002	 4.239259e-001	 1.079564e+004	 4.773583e-002	 8.476704e-001	 5.546453e-003	 5.786049e+002
 1.200200e+002	 4.407875e-001	 1.088543e+004	 4.899690e-002	 8.813863e-001	 5.856483e-003	 5.836124e+002
 1.237200e+002	 4.604586e-001	 1.099474e+004	 4.974611e-002	 9.207202e-001	 6.216769e-003	 5.897031e+002
 1.274600e+002	 4.806316e-001	 1.109813e+004	 5.232304e-002	 9.610575e-001	 6.588557e-003	 5.954864e+002
 1.312000e+002	 5.007963e-001	 1.119685e+004	 5.500840e-002	 1.001378e+000	 6.961354e-003	 6.010232e+002
 1.347800e+002	 5.208545e-001	 1.129223e+004	 5.728374e-002	 1.041486e+000	 7.332831e-003	 6.063837e+002
 1.378600e+002	 5.412198e-001	 1.136725e+004	 6.128740e-002	 1.082208e+000	 7.715972e-003	 6.106581e+002
 1.410200e+002	 5.567045e-001	 1.144678e+004	 6.448437e-002	 1.113171e+000	 8.000894e-003	 6.151187e+002
 1.440200e+002	 5.731365e-001	 1.151588e+004	 6.371368e-002	 1.146028e+000	 8.307442e-003	 6.190327e+002
 1.470200e+002	 5.933709e-001	 1.158764e+004	 6.681815e-002	 1.186488e+000	 8.688524e-003	 6.231395e+002
 1.509200e+002	 6.126702e-001	 1.167284e+004	 6.958243e-002	 1.225078e+000	 9.047174e-003	 6.279606e+002
 1.545000e+002	 6.329596e-001	 1.174786e+004	 7.005372e-002	 1.265648e+000	 9.428154e-003	 6.322497e+002
 1.580200e+002	 6.530638e-001	 1.182063e+004	 7.231518e-002	 1.305848e+000	 9.805953e-003	 6.364184e+002
 1.611800e+002	 6.732299e-001	 1.188730e+004	 7.401388e-002	 1.346172e+000	 1.018654e-002	 6.402629e+002
 1.645800e+002	 6.933246e-001	 1.195256e+004	 7.523311e-002	 1.386353e+000	 1.056596e-002	 6.440328e+002
 1.679800e+002	 7.136004e-001	 1.202307e+004	 7.789650e-002	 1.426895e+000	 1.094735e-002	 6.480913e+002
 1.710200e+002	 7.326288e-001	 1.208315e+004	 7.908786e-002	 1.464944e+000	 1.130685e-002	 6.515743e+002
 1.740200e+002	 7.497544e-001	 1.213948e+004	 8.113627e-002	 1.499188e+000	 1.162966e-002	 6.548326e+002
 1.770200e+002	 7.701128e-001	 1.219856e+004	 8.531117e-002	 1.539896e+000	 1.201546e-002	 6.582834e+002
 1.800200e+002	 7.897059e-001	 1.225305e+004	 8.666921e-002	 1.579074e+000	 1.238729e-002	 6.614791e+002
 1.830200e+002	 8.092710e-001	 1.230996e+004	 8.725230e-002	 1.618196e+000	 1.275775e-002	 6.648074e+002
 1.860200e+002	 8.289192e-001	 1.235911e+004	 8.994171e-002	 1.657484e+000	 1.313188e-002	 6.677198e+002
 1.890200e+002	 8.508290e-001	 1.241486e+004	 9.185977e-002	 1.701294e+000	 1.354864e-002	 6.710204e+002
 1.920200e+002	 8.696179e-001	 1.246768e+004	 9.382146e-002	 1.738864e+000	 1.390450e-002	 6.741243e+002
 1.950200e+002	 8.910224e-001	 1.251892e+004	 9.581739e-002	 1.781664e+000	 1.431224e-002	 6.771795e+002
 1.980200e+002	 9.118845e-001	 1.256773e+004	 9.820755e-002	 1.823379e+000	 1.470979e-002	 6.800986e+002
 2.010200e+002	 9.337515e-001	 1.261330e+004	 1.002904e-001	 1.867103e+000	 1.512789e-002	 6.828573e+002
 2.040200e+002	 9.541579e-001	 1.266103e+004	 1.017905e-001	 1.907907e+000	 1.551645e-002	 6.857160e+002
 2.070200e+002	 9.760333e-001	 1.270784e+004	 1.055884e-001	 1.951649e+000	 1.593403e-002	 6.885468e+002
 2.100200e+002	 9.973600e-001	 1.275541e+004	 1.056589e-001	 1.994293e+000	 1.634043e-002	 6.914131e+002
 2.118400e+002	 1.009018e+000	 1.278570e+004	 1.068640e-001	 2.017605e+000	 1.656133e-002	 6.932134e+002
 2.142600e+002	 1.028211e+000	 1.282150e+004	 1.085776e-001	 2.055982e+000	 1.692878e-002	 6.954158e+002
 2.166800e+002	 1.046588e+000	 1.285680e+004	 1.100802e-001	 2.092728e+000	 1.728021e-002	 6.975814e+002
 2.191000e+002	 1.062865e+000	 1.289393e+004	 1.113168e-001	 2.125276e+000	 1.758976e-002	 6.998192e+002
 2.220200e+002	 1.085017e+000	 1.293699e+004	 1.141685e-001	 2.169569e+000	 1.801293e-002	 7.024607e+002
 2.250400e+002	 1.107033e+000	 1.297805e+004	 1.165639e-001	 2.213593e+000	 1.843383e-002	 7.049937e+002
 2.275800e+002	 1.127152e+000	 1.301301e+004	 1.175306e-001	 2.253821e+000	 1.881900e-002	 7.071712e+002
 2.300000e+002	 1.146361e+000	 1.304756e+004	 1.183395e-001	 2.292232e+000	 1.918631e-002	 7.093149e+002
 2.324200e+002	 1.163674e+000	 1.308202e+004	 1.220699e-001	 2.326851e+000	 1.951632e-002	 7.114292e+002
 2.348400e+002	 1.182936e+000	 1.311482e+004	 1.225182e-001	 2.365365e+000	 1.988487e-002	 7.134810e+002
 2.372600e+002	 1.201901e+000	 1.314911e+004	 1.248991e-001	 2.403287e+000	 2.024706e-002	 7.156118e+002
 2.400400e+002	 1.222954e+000	 1.318475e+004	 1.256766e-001	 2.445385e+000	 2.064966e-002	 7.178460e+002
 2.430400e+002	 1.246283e+000	 1.322188e+004	 1.321123e-001	 2.492032e+000	 2.109622e-002	 7.201955e+002
 2.457400e+002	 1.268097e+000	 1.326210e+004	 1.325522e-001	 2.535651e+000	 2.151209e-002	 7.226938e+002
 2.481600e+002	 1.287512e+000	 1.329323e+004	 1.328902e-001	 2.574473e+000	 2.188338e-002	 7.246642e+002
 2.505800e+002	 1.307122e+000	 1.332235e+004	 1.348698e-001	 2.613684e+000	 2.225889e-002	 7.265294e+002
 2.530000e+002	 1.326133e+000	 1.335223e+004	 1.385490e-001	 2.651699e+000	 2.262235e-002	 7.284283e+002
 2.554200e+002	 1.345905e+000	 1.338077e+004	 1.392781e-001	 2.691234e+000	 2.300091e-002	 7.302664e+002
 2.580400e+002	 1.365993e+000	 1.341006e+004	 1.423174e-001	 2.731401e+000	 2.338529e-002	 7.321511e+002
 2.610400e+002	 1.389507e+000	 1.344694e+004	 1.429457e-001	 2.778420e+000	 2.383434e-002	 7.345008e+002
 2.639000e+002	 1.412234e+000	 1.348082e+004	 1.458609e-001	 2.823863e+000	 2.426862e-002	 7.366770e+002
 2.663000e+002	 1.432516e+000	 1.350719e+004	 1.471786e-001	 2.864419e+000	 2.465712e-002	 7.384090e+002
 2.687200e+002	 1.452361e+000	 1.353665e+004	 1.483805e-001	 2.904100e+000	 2.503607e-002	 7.403048e+002
 2.711400e+002	 1.471853e+000	 1.356318e+004	 1.518989e-001	 2.943077e+000	 2.540883e-002	 7.420370e+002
 2.735600e+002	 1.491807e+000	 1.359155e+004	 1.539552e-001	 2.982976e+000	 2.578992e-002	 7.438774e+002
 2.760400e+002	 1.513322e+000	 1.362059e+004	 1.541039e-001	 3.025996e+000	 2.620109e-002	 7.457782e+002
 2.790400e+002	 1.536503e+000	 1.365322e+004	 1.584546e-001	 3.072349e+000	 2.664357e-002	 7.479010e+002
 2.820400e+002	 1.562820e+000	 1.368235e+004	 1.589239e-001	 3.124971e+000	 2.714781e-002	 7.498789e+002
 2.850400e+002	 1.590149e+000	 1.371239e+004	 1.636726e-001	 3.179618e+000	 2.767126e-002	 7.519235e+002
 2.880400e+002	 1.613171e+000	 1.374301e+004	 1.648755e-001	 3.225652e+000	 2.811053e-002	 7.539390e+002
 2.905200e+002	 1.633999e+000	 1.376696e+004	 1.678928e-001	 3.267298e+000	 2.850879e-002	 7.555576e+002
 2.929400e+002	 1.655163e+000	 1.378941e+004	 1.715219e-001	 3.309618e+000	 2.891384e-002	 7.570996e+002
 2.953800e+002	 1.676148e+000	 1.381052e+004	 1.717462e-001	 3.351578e+000	 2.931562e-002	 7.585667e+002
 2.978000e+002	 1.695731e+000	 1.383539e+004	 1.724585e-001	 3.390737e+000	 2.968900e-002	 7.602205e+002
 3.002200e+002	 1.717908e+000	 1.385925e+004	 1.749189e-001	 3.435081e+000	 3.011284e-002	 7.618585e+002
 3.030400e+002	 1.743727e+000	 1.388562e+004	 1.797834e-001	 3.486709e+000	 3.060646e-002	 7.636889e+002
 3.060400e+002	 1.769203e+000	 1.391358e+004	 1.819880e-001	 3.537649e+000	 3.109273e-002	 7.656031e+002
 3.086800e+002	 1.791505e+000	 1.393878e+004	 1.819334e-001	 3.582243e+000	 3.151803e-002	 7.673201e+002
 3.110800e+002	 1.812729e+000	 1.395881e+004	 1.861477e-001	 3.624682e+000	 3.192368e-002	 7.687374e+002
 3.135000e+002	 1.834626e+000	 1.397842e+004	 1.871986e-001	 3.668468e+000	 3.234233e-002	 7.701426e+002
 3.159000e+002	 1.855738e+000	 1.399978e+004	 1.888236e-001	 3.710681e+000	 3.274511e-002	 7.716336e+002
 3.183200e+002	 1.876988e+000	 1.401989e+004	 1.885577e-001	 3.753172e+000	 3.315076e-002	 7.730586e+002
 3.210400e+002	 1.901958e+000	 1.404409e+004	 1.941865e-001	 3.803102e+000	 3.362705e-002	 7.747656e+002
 3.240400e+002	 1.927949e+000	 1.406696e+004	 1.957658e-001	 3.855074e+000	 3.412321e-002	 7.764155e+002
 3.268000e+002	 1.952912e+000	 1.408682e+004	 1.991826e-001	 3.904988e+000	 3.460008e-002	 7.778853e+002
 3.292200e+002	 1.975127e+000	 1.410910e+004	 2.017097e-001	 3.949409e+000	 3.502302e-002	 7.794487e+002
 3.316400e+002	 1.996742e+000	 1.412554e+004	 2.043016e-001	 3.992629e+000	 3.543577e-002	 7.806813e+002
 3.340600e+002	 2.018491e+000	 1.414331e+004	 2.053301e-001	 4.036118e+000	 3.585059e-002	 7.819905e+002
 3.364800e+002	 2.039815e+000	 1.416242e+004	 2.076084e-001	 4.078758e+000	 3.625668e-002	 7.833680e+002
 3.390400e+002	 2.062623e+000	 1.418462e+004	 2.099240e-001	 4.124364e+000	 3.669037e-002	 7.849395e+002
 3.420400e+002	 2.089547e+000	 1.420715e+004	 2.118302e-001	 4.178199e+000	 3.720306e-002	 7.865927e+002
 3.449200e+002	 2.115572e+000	 1.422960e+004	 2.152496e-001	 4.230240e+000	 3.769823e-002	 7.882290e+002
 3.473400e+002	 2.138552e+000	 1.424695e+004	 2.169322e-001	 4.276190e+000	 3.813591e-002	 7.895384e+002
 3.497600e+002	 2.161154e+000	 1.426456e+004	 2.194655e-001	 4.321383e+000	 3.856606e-002	 7.908567e+002
 3.521800e+002	 2.182719e+000	 1.428117e+004	 2.222847e-001	 4.364503e+000	 3.897635e-002	 7.921046e+002
 3.546000e+002	 2.205852e+000	 1.429552e+004	 2.238612e-001	 4.410759e+000	 3.941723e-002	 7.932521e+002
 3.570400e+002	 2.227389e+000	 1.430962e+004	 2.279857e-001	 4.453824e+000	 3.982732e-002	 7.943621e+002
 3.600400e+002	 2.254027e+000	 1.433357e+004	 2.281885e-001	 4.507089e+000	 4.033255e-002	 7.960973e+002
 3.630400e+002	 2.280972e+000	 1.435276e+004	 2.333109e-001	 4.560969e+000	 4.084471e-002	 7.975742e+002
 3.655000e+002	 2.302991e+000	 1.436754e+004	 2.360239e-001	 4.604996e+000	 4.126327e-002	 7.987311e+002
 3.679200e+002	 2.325181e+000	 1.438306e+004	 2.367474e-001	 4.649368e+000	 4.168476e-002	 7.999332e+002
 3.703400e+002	 2.348118e+000	 1.439883e+004	 2.403215e-001	 4.695232e+000	 4.212031e-002	 8.011612e+002
 3.727600e+002	 2.369516e+000	 1.441502e+004	 2.412029e-001	 4.738019e+000	 4.252606e-002	 8.023897e+002
 3.751800e+002	 2.392400e+000	 1.442820e+004	 2.448490e-001	 4.783776e+000	 4.296092e-002	 8.034745e+002
 3.780400e+002	 2.419053e+000	 1.444698e+004	 2.488381e-001	 4.837071e+000	 4.346625e-002	 8.049292e+002
 3.810400e+002	 2.445750e+000	 1.446350e+004	 2.502905e-001	 4.890452e+000	 4.397277e-002	 8.062600e+002
 3.836400e+002	 2.469613e+000	 1.448286e+004	 2.528399e-001	 4.938170e+000	 4.442408e-002	 8.077065e+002
 3.860600e+002	 2.492124e+000	 1.449554e+004	 2.571306e-001	 4.983181e+000	 4.485111e-002	 8.087606e+002
 3.884800e+002	 2.515259e+000	 1.451040e+004	 2.590266e-001	 5.029441e+000	 4.528932e-002	 8.099460e+002
 3.909000e+002	 2.537654e+000	 1.452241e+004	 2.628102e-001	 5.074222e+000	 4.571397e-002	 8.109623e+002
 3.933200e+002	 2.560947e+000	 1.453668e+004	 2.611185e-001	 5.120798e+000	 4.615497e-002	 8.121189e+002
 3.960400e+002	 2.586505e+000	 1.454928e+004	 2.668601e-001	 5.171903e+000	 4.663945e-002	 8.132180e+002
 3.990400e+002	 2.615502e+000	 1.456514e+004	 2.670364e-001	 5.229885e+000	 4.718842e-002	 8.145530e+002
 4.017800e+002	 2.640781e+000	 1.458166e+004	 2.709432e-001	 5.280431e+000	 4.766602e-002	 8.158687e+002
 4.042200e+002	 2.664770e+000	 1.459309e+004	 2.716965e-001	 5.328399e+000	 4.812019e-002	 8.168803e+002
 4.066200e+002	 2.687483e+000	 1.460645e+004	 2.750274e-001	 5.373817e+000	 4.854934e-002	 8.179802e+002
 4.090400e+002	 2.710895e+000	 1.461696e+004	 2.785330e-001	 5.420631e+000	 4.899237e-002	 8.189327e+002
 4.114400e+002	 2.733510e+000	 1.463123e+004	 2.797717e-001	 5.465849e+000	 4.941901e-002	 8.200837e+002
 4.140400e+002	 2.757750e+000	 1.464200e+004	 2.828236e-001	 5.514319e+000	 4.987734e-002	 8.210642e+002
 4.170400e+002	 2.787865e+000	 1.465677e+004	 2.869447e-001	 5.574537e+000	 5.044610e-002	 8.223615e+002
 4.199200e+002	 2.815048e+000	 1.466795e+004	 2.875701e-001	 5.628890e+000	 5.095975e-002	 8.234125e+002
 4.223400e+002	 2.838482e+000	 1.468046e+004	 2.925893e-001	 5.675749e+000	 5.140160e-002	 8.244807e+002
 4.247600e+002	 2.863281e+000	 1.469140e+004	 2.925115e-001	 5.725336e+000	 5.186959e-002	 8.254818e+002
 4.271800e+002	 2.886207e+000	 1.470275e+004	 2.954775e-001	 5.771179e+000	 5.230170e-002	 8.264776e+002
 4.296000e+002	 2.911114e+000	 1.471343e+004	 2.994252e-001	 5.820981e+000	 5.277138e-002	 8.274674e+002
 4.320400e+002	 2.933938e+000	 1.472369e+004	 2.988408e-001	 5.866620e+000	 5.320146e-002	 8.284017e+002
 4.350400e+002	 2.963439e+000	 1.473671e+004	 3.011152e-001	 5.925609e+000	 5.375715e-002	 8.295961e+002
 4.380400e+002	 2.992828e+000	 1.474797e+004	 3.047804e-001	 5.984375e+000	 5.431089e-002	 8.306908e+002
 4.405000e+002	 3.015564e+000	 1.475824e+004	 3.074818e-001	 6.029837e+000	 5.473864e-002	 8.316254e+002
 4.429200e+002	 3.038745e+000	 1.477084e+004	 3.085474e-001	 6.076189e+000	 5.517400e-002	 8.326993e+002
 4.453400e+002	 3.063516e+000	 1.477943e+004	 3.111507e-001	 6.125721e+000	 5.564033e-002	 8.335729e+002
 4.477600e+002	 3.086545e+000	 1.478961e+004	 3.132406e-001	 6.171770e+000	 5.607308e-002	 8.345090e+002
 4.501800e+002	 3.110657e+000	 1.480096e+004	 3.160290e-001	 6.219982e+000	 5.652578e-002	 8.355285e+002
 4.530400e+002	 3.139577e+000	 1.481039e+004	 3.186790e-001	 6.277811e+000	 5.706962e-002	 8.365159e+002
 4.560400e+002	 3.169832e+000	 1.482358e+004	 3.210407e-001	 6.338308e+000	 5.763735e-002	 8.377372e+002
 4.586600e+002	 3.196174e+000	 1.483242e+004	 3.249442e-001	 6.390981e+000	 5.813210e-002	 8.386522e+002
 4.610800e+002	 3.219078e+000	 1.484027e+004	 3.293003e-001	 6.436778e+000	 5.856203e-002	 8.394569e+002
 4.635000e+002	 3.243763e+000	 1.484794e+004	 3.303171e-001	 6.486138e+000	 5.902540e-002	 8.402806e+002
 4.659200e+002	 3.266790e+000	 1.485679e+004	 3.325732e-001	 6.532181e+000	 5.945700e-002	 8.411447e+002
 4.683400e+002	 3.290651e+000	 1.486797e+004	 3.320586e-001	 6.579894e+000	 5.990351e-002	 8.421548e+002
 4.710400e+002	 3.316962e+000	 1.487899e+004	 3.352042e-001	 6.632505e+000	 6.039597e-002	 8.431946e+002
 4.740400e+002	 3.347533e+000	 1.489067e+004	 3.391270e-001	 6.693634e+000	 6.096816e-002	 8.443404e+002
 4.768000e+002	 3.374554e+000	 1.489609e+004	 3.421880e-001	 6.747663e+000	 6.147494e-002	 8.450756e+002
 4.792200e+002	 3.398486e+000	 1.490527e+004	 3.432564e-001	 6.795517e+000	 6.192240e-002	 8.459754e+002
 4.816400e+002	 3.421744e+000	 1.491312e+004	 3.458765e-001	 6.842023e+000	 6.235736e-002	 8.467892e+002
 4.840600e+002	 3.447253e+000	 1.492221e+004	 3.475219e-001	 6.893031e+000	 6.283408e-002	 8.477101e+002
 4.864800e+002	 3.469751e+000	 1.493114e+004	 3.529439e-001	 6.938018e+000	 6.325409e-002	 8.485743e+002
 4.890400e+002	 3.496620e+000	 1.494132e+004	 3.524673e-001	 6.991744e+000	 6.375560e-002	 8.495794e+002
 4.920400e+002	 3.526814e+000	 1.494950e+004	 3.556951e-001	 7.052118e+000	 6.431973e-002	 8.505240e+002
 4.949600e+002	 3.556002e+000	 1.495751e+004	 3.583432e-001	 7.110482e+000	 6.486474e-002	 8.514437e+002
 4.973800e+002	 3.580647e+000	 1.496402e+004	 3.615042e-001	 7.159762e+000	 6.532476e-002	 8.522060e+002
 4.998000e+002	 3.604247e+000	 1.497186e+004	 3.622946e-001	 7.206951e+000	 6.576463e-002	 8.530282e+002
 5.022200e+002	 3.628817e+000	 1.497887e+004	 3.639623e-001	 7.256080e+000	 6.622270e-002	 8.538187e+002
 5.046400e+002	 3.655777e+000	 1.498588e+004	 3.654785e-001	 7.309989e+000	 6.672526e-002	 8.546475e+002
 5.070600e+002	 3.676169e+000	 1.499373e+004	 3.697405e-001	 7.350765e+000	 6.710456e-002	 8.554197e+002
 5.100400e+002	 3.708201e+000	 1.500266e+004	 3.726636e-001	 7.414816e+000	 6.770096e-002	 8.564398e+002
 5.130400e+002	 3.738373e+000	 1.501209e+004	 3.740231e-001	 7.475146e+000	 6.826212e-002	 8.574593e+002
 5.155000e+002	 3.763699e+000	 1.501935e+004	 3.767385e-001	 7.525788e+000	 6.873310e-002	 8.582782e+002
 5.179400e+002	 3.788949e+000	 1.502485e+004	 3.787071e-001	 7.576278e+000	 6.920290e-002	 8.589960e+002
 5.203600e+002	 3.814753e+000	 1.503019e+004	 3.800930e-001	 7.627873e+000	 6.968283e-002	 8.597134e+002
 5.227600e+002	 3.835206e+000	 1.503712e+004	 3.829146e-001	 7.668770e+000	 7.006238e-002	 8.604364e+002
 5.251800e+002	 3.861655e+000	 1.504029e+004	 3.867433e-001	 7.721659e+000	 7.055452e-002	 8.610405e+002
 5.280400e+002	 3.890317e+000	 1.505022e+004	 3.896952e-001	 7.778970e+000	 7.108584e-002	 8.620674e+002
 5.310400e+002	 3.921838e+000	 1.505907e+004	 3.920752e-001	 7.841998e+000	 7.167038e-002	 8.630784e+002
 5.336400e+002	 3.949295e+000	 1.506341e+004	 3.944222e-001	 7.896899e+000	 7.218014e-002	 8.637666e+002
 5.360600e+002	 3.973419e+000	 1.506666e+004	 3.953458e-001	 7.945138e+000	 7.262798e-002	 8.643394e+002
 5.384800e+002	 3.998714e+000	 1.507359e+004	 3.972417e-001	 7.995716e+000	 7.309641e-002	 8.651419e+002
 5.409000e+002	 4.022757e+000	 1.507934e+004	 3.997522e-001	 8.043792e+000	 7.354166e-002	 8.658575e+002
 5.433400e+002	 4.049708e+000	 1.508519e+004	 4.018008e-001	 8.097683e+000	 7.404071e-002	 8.666250e+002
 5.460400e+002	 4.075904e+000	 1.509303e+004	 4.042493e-001	 8.150065e+000	 7.452497e-002	 8.674957e+002
 5.490400e+002	 4.107106e+000	 1.509887e+004	 4.073975e-001	 8.212454e+000	 7.510236e-002	 8.683320e+002
 5.518000e+002	 4.135627e+000	 1.510830e+004	 4.107987e-001	 8.269484e+000	 7.562879e-002	 8.693321e+002
 5.542200e+002	 4.160032e+000	 1.511339e+004	 4.123778e-001	 8.318283e+000	 7.607980e-002	 8.700170e+002
 5.566400e+002	 4.185115e+000	 1.511923e+004	 4.138805e-001	 8.368440e+000	 7.654299e-002	 8.707562e+002
 5.590600e+002	 4.211598e+000	 1.512299e+004	 4.167090e-001	 8.421394e+000	 7.703240e-002	 8.713980e+002
 5.615000e+002	 4.237078e+000	 1.512833e+004	 4.161392e-001	 8.472343e+000	 7.750262e-002	 8.721153e+002
 5.640400e+002	 4.262766e+000	 1.512958e+004	 4.221932e-001	 8.523708e+000	 7.797752e-002	 8.726004e+002
 5.670400e+002	 4.296546e+000	 1.513717e+004	 4.267922e-001	 8.591253e+000	 7.860013e-002	 8.735817e+002
 5.699800e+002	 4.327749e+000	 1.514477e+004	 4.271729e-001	 8.653647e+000	 7.917475e-002	 8.745221e+002
 5.724000e+002	 4.352890e+000	 1.514794e+004	 4.283390e-001	 8.703917e+000	 7.963825e-002	 8.751098e+002
 5.748200e+002	 4.378017e+000	 1.515403e+004	 4.320482e-001	 8.754161e+000	 8.010054e-002	 8.758664e+002
 5.784600e+002	 4.415043e+000	 1.516129e+004	 4.337475e-001	 8.828197e+000	 8.078178e-002	 8.768824e+002
 5.808800e+002	 4.440947e+000	 1.516479e+004	 4.379152e-001	 8.879994e+000	 8.125852e-002	 8.775025e+002
 5.833000e+002	 4.465935e+000	 1.517080e+004	 4.395552e-001	 8.929958e+000	 8.171750e-002	 8.782530e+002
 5.857200e+002	 4.491377e+000	 1.517514e+004	 4.420904e-001	 8.980833e+000	 8.218509e-002	 8.789144e+002
 5.881400e+002	 4.515493e+000	 1.517923e+004	 4.440675e-001	 9.029054e+000	 8.262809e-002	 8.795402e+002
 5.910400e+002	 4.546775e+000	 1.518090e+004	 4.468890e-001	 9.091605e+000	 8.320340e-002	 8.801415e+002
 5.940400e+002	 4.579263e+000	 1.518858e+004	 4.498999e-001	 9.156566e+000	 8.379897e-002	 8.811109e+002
 5.966200e+002	 4.605912e+000	 1.519083e+004	 4.539680e-001	 9.209853e+000	 8.428830e-002	 8.816718e+002
 5.990400e+002	 4.631206e+000	 1.519459e+004	 4.570692e-001	 9.260429e+000	 8.475210e-002	 8.822981e+002
 6.014600e+002	 4.656606e+000	 1.519884e+004	 4.587538e-001	 9.311220e+000	 8.521752e-002	 8.829554e+002
 6.038800e+002	 4.684016e+000	 1.520193e+004	 4.611642e-001	 9.366027e+000	 8.571990e-002	 8.835775e+002
 6.062800e+002	 4.709812e+000	 1.520610e+004	 4.645302e-001	 9.417609e+000	 8.619215e-002	 8.842368e+002
 6.090400e+002	 4.740121e+000	 1.521027e+004	 4.667465e-001	 9.478213e+000	 8.674691e-002	 8.849693e+002
 6.120400e+002	 4.773927e+000	 1.521653e+004	 4.704085e-001	 9.545811e+000	 8.736490e-002	 8.858800e+002
 6.147600e+002	 4.803262e+000	 1.521812e+004	 4.738796e-001	 9.604468e+000	 8.790185e-002	 8.864467e+002
 6.171800e+002	 4.828833e+000	 1.522054e+004	 4.740538e-001	 9.655599e+000	 8.836940e-002	 8.870012e+002
 6.196000e+002	 4.856604e+000	 1.522421e+004	 4.785912e-001	 9.711130e+000	 8.887667e-002	 8.876644e+002
 6.220200e+002	 4.882686e+000	 1.522938e+004	 4.810717e-001	 9.763283e+000	 8.935239e-002	 8.883881e+002
 6.244400e+002	 4.910227e+000	 1.523255e+004	 4.830382e-001	 9.818353e+000	 8.985508e-002	 8.890188e+002
 6.270400e+002	 4.940416e+000	 1.523406e+004	 4.856623e-001	 9.878719e+000	 9.040632e-002	 8.895952e+002
 6.300400e+002	 4.972786e+000	 1.523639e+004	 4.889753e-001	 9.943445e+000	 9.099685e-002	 8.902557e+002
 6.329200e+002	 5.004214e+000	 1.523848e+004	 4.911051e-001	 1.000629e+001	 9.156991e-002	 8.908864e+002
 6.353400e+002	 5.029523e+000	 1.524082e+004	 4.937461e-001	 1.005689e+001	 9.203099e-002	 8.914329e+002
 6.377600e+002	 5.056498e+000	 1.524324e+004	 4.948806e-001	 1.011083e+001	 9.252221e-002	 8.920113e+002
 6.401800e+002	 5.082234e+000	 1.524724e+004	 4.978540e-001	 1.016229e+001	 9.299021e-002	 8.926627e+002
 6.426000e+002	 5.109237e+000	 1.525275e+004	 4.997471e-001	 1.021629e+001	 9.348066e-002	 8.934227e+002
 6.450400e+002	 5.134191e+000	 1.525692e+004	 5.039376e-001	 1.026619e+001	 9.393393e-002	 8.940717e+002
 6.480400e+002	 5.169520e+000	 1.525876e+004	 5.059492e-001	 1.033683e+001	 9.457634e-002	 8.947521e+002
 6.510400e+002	 5.201704e+000	 1.526218e+004	 5.073074e-001	 1.040118e+001	 9.516075e-002	 8.954746e+002
 6.534600e+002	 5.228822e+000	 1.526518e+004	 5.114446e-001	 1.045541e+001	 9.565289e-002	 8.960907e+002
 6.558800e+002	 5.254906e+000	 1.526777e+004	 5.122700e-001	 1.050756e+001	 9.612610e-002	 8.966657e+002
 6.583000e+002	 5.282482e+000	 1.527119e+004	 5.162530e-001	 1.056270e+001	 9.662596e-002	 8.973141e+002
 6.607200e+002	 5.310136e+000	 1.527269e+004	 5.187189e-001	 1.061800e+001	 9.712749e-002	 8.978511e+002
 6.631400e+002	 5.338567e+000	 1.527344e+004	 5.207875e-001	 1.067485e+001	 9.764305e-002	 8.983567e+002
 6.660400e+002	 5.370262e+000	 1.527887e+004	 5.236694e-001	 1.073823e+001	 9.821629e-002	 8.991903e+002
 6.690400e+002	 5.405065e+000	 1.528179e+004	 5.258164e-001	 1.080782e+001	 9.884616e-002	 8.999273e+002
 6.716000e+002	 5.434961e+000	 1.528029e+004	 5.311868e-001	 1.086760e+001	 9.938793e-002	 9.003242e+002
 6.740000e+002	 5.459994e+000	 1.528104e+004	 5.324076e-001	 1.091765e+001	 9.984082e-002	 9.007749e+002
 6.764400e+002	 5.487120e+000	 1.528296e+004	 5.321065e-001	 1.097189e+001	 1.003311e-001	 9.013285e+002
 6.788600e+002	 5.514926e+000	 1.528513e+004	 5.384328e-001	 1.102749e+001	 1.008333e-001	 9.019081e+002
 6.812800e+002	 5.542388e+000	 1.528780e+004	 5.389653e-001	 1.108240e+001	 1.013290e-001	 9.025117e+002
 6.840400e+002	 5.572816e+000	 1.528988e+004	 5.417349e-001	 1.114325e+001	 1.018781e-001	 9.031293e+002
 6.870400e+002	 5.606381e+000	 1.529205e+004	 5.429433e-001	 1.121036e+001	 1.024835e-001	 9.038028e+002
 6.897400e+002	 5.637589e+000	 1.529798e+004	 5.480682e-001	 1.127276e+001	 1.030451e-001	 9.046602e+002
 6.921600e+002	 5.666144e+000	 1.529756e+004	 5.492612e-001	 1.132986e+001	 1.035601e-001	 9.050997e+002
 6.945800e+002	 5.691708e+000	 1.530015e+004	 5.531152e-001	 1.138098e+001	 1.040202e-001	 9.056684e+002
 6.970200e+002	 5.720008e+000	 1.529798e+004	 5.551041e-001	 1.143757e+001	 1.045306e-001	 9.059999e+002
 6.994200e+002	 5.747307e+000	 1.530148e+004	 5.579583e-001	 1.149215e+001	 1.050213e-001	 9.066513e+002
 7.020400e+002	 5.777207e+000	 1.530365e+004	 5.609882e-001	 1.155194e+001	 1.055589e-001	 9.072661e+002
 7.050400e+002	 5.810549e+000	 1.530290e+004	 5.646203e-001	 1.161861e+001	 1.061588e-001	 9.077637e+002
 7.078800e+002	 5.842485e+000	 1.530766e+004	 5.663232e-001	 1.168247e+001	 1.067317e-001	 9.085654e+002
 7.103000e+002	 5.871040e+000	 1.530841e+004	 5.704545e-001	 1.173957e+001	 1.072445e-001	 9.090744e+002
 7.127200e+002	 5.900513e+000	 1.531108e+004	 5.724217e-001	 1.179850e+001	 1.077731e-001	 9.097124e+002
 7.151400e+002	 5.929103e+000	 1.531091e+004	 5.745943e-001	 1.185567e+001	 1.082863e-001	 9.101676e+002
 7.175600e+002	 5.956670e+000	 1.531241e+004	 5.766382e-001	 1.191079e+001	 1.087805e-001	 9.107054e+002
 7.200400e+002	 5.984877e+000	 1.531375e+004	 5.794672e-001	 1.196719e+001	 1.092859e-001	 9.112438e+002
 7.230400e+002	 6.020403e+000	 1.531508e+004	 5.823252e-001	 1.203823e+001	 1.099222e-001	 9.119014e+002
 7.260000e+002	 6.057142e+000	 1.531784e+004	 5.851705e-001	 1.211169e+001	 1.105794e-001	 9.126634e+002
 7.284200e+002	 6.084486e+000	 1.531892e+004	 5.889273e-001	 1.216637e+001	 1.110685e-001	 9.131730e+002
 7.308400e+002	 6.113137e+000	 1.531976e+004	 5.913045e-001	 1.222366e+001	 1.115809e-001	 9.136892e+002
 7.332600e+002	 6.141379e+000	 1.531867e+004	 5.947232e-001	 1.228013e+001	 1.120861e-001	 9.140841e+002
 7.356800e+002	 6.169611e+000	 1.531992e+004	 5.966291e-001	 1.233658e+001	 1.125903e-001	 9.146184e+002
 7.381000e+002	 6.197286e+000	 1.531909e+004	 6.000702e-001	 1.239192e+001	 1.130849e-001	 9.150190e+002
 7.410400e+002	 6.232284e+000	 1.532084e+004	 6.020513e-001	 1.246190e+001	 1.137092e-001	 9.156935e+002
 7.440400e+002	 6.268469e+000	 1.531884e+004	 6.077662e-001	 1.253426e+001	 1.143553e-001	 9.161628e+002
 7.465800e+002	 6.297916e+000	 1.532159e+004	 6.088394e-001	 1.259314e+001	 1.148797e-001	 9.168069e+002
 7.490000e+002	 6.327073e+000	 1.532360e+004	 6.124538e-001	 1.265144e+001	 1.153987e-001	 9.174014e+002
 7.514200e+002	 6.357071e+000	 1.532527e+004	 6.146689e-001	 1.271142e+001	 1.159326e-001	 9.179898e+002
 7.538400e+002	 6.385556e+000	 1.532585e+004	 6.167241e-001	 1.276838e+001	 1.164396e-001	 9.184887e+002
 7.562600e+002	 6.413762e+000	 1.532610e+004	 6.220202e-001	 1.282478e+001	 1.169414e-001	 9.189630e+002
 7.590400e+002	 6.447020e+000	 1.532318e+004	 6.237872e-001	 1.289128e+001	 1.175336e-001	 9.193293e+002
 7.620400e+002	 6.484254e+000	 1.532435e+004	 6.264362e-001	 1.296573e+001	 1.181951e-001	 9.200057e+002
 7.647200e+002	 6.515821e+000	 1.532702e+004	 6.302192e-001	 1.302885e+001	 1.187550e-001	 9.206801e+002
 7.671400e+002	 6.545374e+000	 1.532685e+004	 6.317251e-001	 1.308795e+001	 1.192797e-001	 9.211514e+002
 7.695600e+002	 6.573149e+000	 1.532785e+004	 6.352406e-001	 1.314349e+001	 1.197723e-001	 9.216640e+002
 7.720000e+002	 6.603914e+000	 1.532760e+004	 6.376010e-001	 1.320500e+001	 1.203179e-001	 9.221499e+002
 7.744200e+002	 6.632698e+000	 1.532718e+004	 6.406998e-001	 1.326256e+001	 1.208282e-001	 9.225936e+002
 7.770400e+002	 6.666103e+000	 1.532727e+004	 6.446872e-001	 1.332935e+001	 1.214200e-001	 9.231426e+002
 7.800400e+002	 6.703396e+000	 1.532769e+004	 6.467173e-001	 1.340392e+001	 1.220801e-001	 9.237752e+002
 7.829000e+002	 6.736876e+000	 1.532819e+004	 6.495726e-001	 1.347087e+001	 1.226723e-001	 9.243506e+002
 7.853200e+002	 6.767749e+000	 1.532844e+004	 6.531312e-001	 1.353260e+001	           0.0	           0.0
 7.877400e+002	 6.798571e+000	 1.532777e+004	 6.567847e-001	 1.359423e+001	           0.0	           0.0
 7.901600e+002	 6.827393e+000	 1.532777e+004	 6.598163e-001	 1.365186e+001	           0.0	           0.0
 7.925800e+002	 6.858512e+000	 1.532969e+004	 6.613795e-001	 1.371409e+001	           0.0	           0.0
 7.950400e+002	 6.889037e+000	 1.532877e+004	 6.657342e-001	 1.377513e+001	           0.0	           0.0
 7.980400e+002	 6.926594e+000	 1.532627e+004	 6.670132e-001	 1.385022e+001	           0.0	           0.0
 8.010400e+002	 6.964283e+000	 1.532577e+004	 6.728532e-001	 1.392558e+001	           0.0	           0.0
 8.034800e+002	 6.993531e+000	 1.532476e+004	 6.742740e-001	 1.398407e+001	           0.0	           0.0
 8.059000e+002	 7.024307e+000	 1.532518e+004	 6.767772e-001	 1.404561e+001	           0.0	           0.0
 8.083200e+002	 7.054130e+000	 1.532468e+004	 6.803232e-001	 1.410524e+001	           0.0	           0.0
 8.107400e+002	 7.080945e+000	 1.532710e+004	 6.836609e-001	 1.415886e+001	           0.0	           0.0
 8.131800e+002	 7.115254e+000	 1.532627e+004	 6.856042e-001	 1.422746e+001	           0.0	           0.0
 8.160400e+002	 7.150532e+000	 1.532426e+004	 6.895862e-001	 1.429800e+001	           0.0	           0.0
 8.190400e+002	 7.190583e+000	 1.532293e+004	 6.937842e-001	 1.437809e+001	           0.0	           0.0
 8.216400e+002	 7.224960e+000	 1.532510e+004	 6.968516e-001	 1.444683e+001	           0.0	           0.0
 8.240600e+002	 7.255345e+000	 1.532543e+004	 6.998757e-001	 1.450759e+001	           0.0	           0.0
 8.264800e+002	 7.286014e+000	 1.532326e+004	 7.013422e-001	 1.456891e+001	           0.0	           0.0
 8.289000e+002	 7.319551e+000	 1.532351e+004	 7.059127e-001	 1.463597e+001	           0.0	           0.0
 8.313200e+002	 7.350206e+000	 1.532318e+004	 7.082983e-001	 1.469727e+001	           0.0	           0.0
 8.340400e+002	 7.387517e+000	 1.532234e+004	 7.130452e-001	 1.477187e+001	           0.0	           0.0
 8.370400e+002	 7.427051e+000	 1.532126e+004	 7.163413e-001	 1.485092e+001	           0.0	           0.0
 8.398000e+002	 7.464597e+000	 1.531717e+004	 7.196321e-001	 1.492600e+001	           0.0	           0.0
 8.422200e+002	 7.496564e+000	 1.531709e+004	 7.226958e-001	 1.498992e+001	           0.0	           0.0
 8.446400e+002	 7.528906e+000	 1.531467e+004	 7.264665e-001	 1.505459e+001	           0.0	           0.0
 8.470600e+002	 7.561441e+000	 1.531533e+004	 7.308003e-001	 1.511965e+001	           0.0	           0.0
 8.494800e+002	 7.595121e+000	 1.531442e+004	 7.327800e-001	 1.518699e+001	           0.0	           0.0
 8.520400e+002	 7.629937e+000	 1.531533e+004	 7.372032e-001	 1.525661e+001	           0.0	           0.0
 8.550400e+002	 7.670601e+000	 1.531225e+004	 7.395462e-001	 1.533792e+001	           0.0	           0.0
 8.579400e+002	 7.710450e+000	 1.530958e+004	 7.465365e-001	 1.541760e+001	           0.0	           0.0
 8.603600e+002	 7.743830e+000	 1.530874e+004	 7.474390e-001	 1.548435e+001	           0.0	           0.0
 8.627800e+002	 7.776806e+000	 1.530407e+004	 7.506880e-001	 1.555028e+001	           0.0	           0.0
 8.652000e+002	 7.809651e+000	 1.530457e+004	 7.557213e-001	 1.561596e+001	           0.0	           0.0
 8.676200e+002	 7.843580e+000	 1.530415e+004	 7.601390e-001	 1.568380e+001	           0.0	           0.0
 8.712400e+002	 7.893718e+000	 1.530132e+004	 7.652833e-001	 1.578406e+001	           0.0	           0.0
 8.736600e+002	 7.927971e+000	 1.529923e+004	 7.680553e-001	 1.585255e+001	           0.0	           0.0
 8.760800e+002	 7.961613e+000	 1.529581e+004	 7.730414e-001	 1.591982e+001	           0.0	           0.0
 8.790400e+002	 8.003614e+000	 1.529714e+004	 7.765242e-001	 1.600380e+001	           0.0	           0.0
 8.820400e+002	 8.046700e+000	 1.529305e+004	 7.799895e-001	 1.608996e+001	           0.0	           0.0
 8.845600e+002	 8.080866e+000	 1.529022e+004	 7.844723e-001	 1.615827e+001	           0.0	           0.0
 8.869600e+002	 8.117195e+000	 1.528988e+004	 7.870733e-001	 1.623092e+001	           0.0	           0.0
 8.893800e+002	 8.152625e+000	 1.528780e+004	 7.926702e-001	 1.630176e+001	           0.0	           0.0
 8.918000e+002	 8.188643e+000	 1.528554e+004	 7.977274e-001	 1.637378e+001	           0.0	           0.0
 8.942200e+002	 8.223093e+000	 1.528312e+004	 8.005842e-001	 1.644267e+001	           0.0	           0.0
 8.970400e+002	 8.263469e+000	 1.527812e+004	 8.054522e-001	 1.652340e+001	           0.0	           0.0
 9.000400e+002	 8.308375e+000	 1.527595e+004	 8.104725e-001	 1.661320e+001	           0.0	           0.0
 9.027000e+002	 8.347614e+000	 1.527269e+004	 8.159118e-001	 1.669166e+001	           0.0	           0.0
 9.051200e+002	 8.382277e+000	 1.526902e+004	 8.217035e-001	 1.676097e+001	           0.0	           0.0
 9.075400e+002	 8.417349e+000	 1.526610e+004	 8.261374e-001	 1.683110e+001	           0.0	           0.0
 9.099600e+002	 8.453442e+000	 1.526243e+004	 8.265427e-001	 1.690327e+001	           0.0	           0.0
 9.123800e+002	 8.490803e+000	 1.525834e+004	 8.318085e-001	 1.697797e+001	           0.0	           0.0
 9.150400e+002	 8.528625e+000	 1.525575e+004	 8.388534e-001	 1.705360e+001	           0.0	           0.0
 9.180400e+002	 8.575556e+000	 1.525325e+004	 8.431355e-001	 1.714744e+001	           0.0	           0.0
 9.208600e+002	 8.617927e+000	 1.524799e+004	 8.497654e-001	 1.723217e+001	           0.0	           0.0
 9.232800e+002	 8.653126e+000	 1.524282e+004	 8.566730e-001	 1.730255e+001	           0.0	           0.0
 9.257000e+002	 8.691163e+000	 1.523915e+004	 8.593209e-001	 1.737861e+001	           0.0	           0.0
 9.281200e+002	 8.727212e+000	 1.523439e+004	 8.639458e-001	 1.745069e+001	           0.0	           0.0
 9.305400e+002	 8.765838e+000	 1.522813e+004	 8.687096e-001	 1.752792e+001	           0.0	           0.0
 9.330400e+002	 8.805146e+000	 1.522146e+004	 8.721793e-001	 1.760652e+001	           0.0	           0.0
 9.360400e+002	 8.852628e+000	 1.521228e+004	 8.798526e-001	 1.770147e+001	           0.0	           0.0
 9.390200e+002	 8.901041e+000	 1.520210e+004	 8.863075e-001	 1.779827e+001	           0.0	           0.0
 9.414400e+002	 8.938179e+000	 1.519509e+004	 8.922674e-001	 1.787253e+001	           0.0	           0.0
 9.438600e+002	 8.978357e+000	 1.518791e+004	 8.974506e-001	 1.795287e+001	           0.0	           0.0
 9.462600e+002	 9.017298e+000	 1.517906e+004	 9.026158e-001	 1.803074e+001	           0.0	           0.0
 9.486800e+002	 9.056566e+000	 1.517180e+004	 9.073117e-001	 1.810926e+001	           0.0	           0.0
 9.511000e+002	 9.097417e+000	 1.516204e+004	 9.093067e-001	 1.819094e+001	           0.0	           0.0
 9.540400e+002	 9.142984e+000	 1.514468e+004	 9.151122e-001	 1.828206e+001	           0.0	           0.0
 9.570400e+002	 9.191864e+000	 1.513133e+004	 9.236249e-001	 1.837979e+001	           0.0	           0.0
 9.595800e+002	 9.232563e+000	 1.511998e+004	 9.272512e-001	 1.846118e+001	           0.0	           0.0
 9.620200e+002	 9.273353e+000	 1.510655e+004	 9.327378e-001	 1.854274e+001	           0.0	           0.0
 9.644200e+002	 9.312872e+000	 1.509261e+004	 9.374316e-001	 1.862176e+001	           0.0	           0.0
 9.668400e+002	 9.353572e+000	 1.507626e+004	 9.409369e-001	 1.870314e+001	           0.0	           0.0
 9.692600e+002	 9.393961e+000	 1.505923e+004	 9.445521e-001	 1.878390e+001	           0.0	           0.0
 9.720400e+002	 9.441635e+000	 1.503762e+004	 9.477817e-001	 1.887923e+001	           0.0	           0.0
 9.750400e+002	 9.491434e+000	 1.501534e+004	 9.575732e-001	 1.897881e+001	           0.0	           0.0
 9.777400e+002	 9.536804e+000	 1.498772e+004	 9.607688e-001	 1.906953e+001	           0.0	           0.0
 9.801600e+002	 9.577089e+000	 1.496611e+004	 9.642372e-001	 1.915008e+001	           0.0	           0.0
 9.825800e+002	 9.618800e+000	 1.494182e+004	 9.675040e-001	 1.923348e+001	           0.0	           0.0
 9.850000e+002	 9.658262e+000	 1.491729e+004	 9.702898e-001	 1.931239e+001	           0.0	           0.0
 9.874200e+002	 9.702170e+000	 1.488850e+004	 9.706414e-001	 1.940019e+001	           0.0	           0.0
 9.900400e+002	 9.746724e+000	 1.485379e+004	 9.786674e-001	 1.948928e+001	           0.0	           0.0
 9.930400e+002	 9.799048e+000	 1.481248e+004	 9.827319e-001	 1.959390e+001	           0.0	           0.0
 9.958800e+002	 9.849257e+000	 1.476466e+004	 9.846649e-001	 1.969430e+001	           0.0	           0.0
 9.982800e+002	 9.892903e+000	 1.470066e+004	 9.856861e-001	 1.978157e+001	           0.0	           0.0
 9.994600e+002	 9.915309e+000	 1.464333e+004	 9.850453e-001	 1.982638e+001	           0.0	           0.0