File: DP800 Tensile Tests/Fehlemann_Test_WP_KL_2024_1017.TRA
$Fehlemann_Test_WP_KL_2024_101.ZSE
Material:                               St
Auftrags-Nr.:                           WP_KL_2024_101
Probe:                                  3_45°_A
Vorkraft:                               100 N
Probengeometrie:                        H12,5x50
Messlänge:                              50.8315 mm
Probendicke a0:                         1.49 mm
Probenbreite b0:                        12.6 mm
Prüfgeschwindigkeit:                    1 mm/min
Datum:                                  26.09.2024
Maschinendaten:                         4204 WN:800315
Traversenwegaufnehmer WN:800315
Videoextensometer
Videoextensometer - Querdehnung
Kraftsensor ID:0 WN:800316 50 kN

Bemerkung:                              Bruch außerh. der Messmarken
$
      Prüfzeit	   Standardweg	 Spannung    	Breitenänderung	       Dehnung	 wahre Dehnung	wahre Spannung
 1.984375e-002	 2.151484e-005	 1.991926e+002	-2.087572e-004	 4.232580e-005	 0.000000e+000	 1.061089e+001
 4.198438e-001	 2.641882e-004	 2.102912e+002	 7.852100e-005	 5.197332e-004	 0.000000e+000	 1.120216e+001
 6.598437e-001	 1.903805e-003	 2.801370e+002	 1.380084e-003	 3.745324e-003	 0.000000e+000	 1.492331e+001
 8.198438e-001	 3.128063e-003	 3.266174e+002	 1.216630e-003	 6.153787e-003	 0.000000e+000	 1.739981e+001
 1.179844e+000	 3.652188e-003	 4.208299e+002	-9.051665e-004	 7.184889e-003	 0.000000e+000	 2.241900e+001
 1.559844e+000	 2.983063e-003	 5.241382e+002	 1.098146e-003	 5.868531e-003	 0.000000e+000	 2.792221e+001
 2.059844e+000	 4.701563e-003	 6.554850e+002	 1.589114e-003	 9.249307e-003	 0.000000e+000	 3.492058e+001
 2.299844e+000	 5.505751e-003	 7.224936e+002	 8.644898e-004	 1.083137e-002	 0.000000e+000	 3.849103e+001
 2.499844e+000	 4.713902e-003	 7.765677e+002	 2.413017e-003	 9.273581e-003	 0.000000e+000	 4.137120e+001
 2.619844e+000	 6.923999e-003	 8.091124e+002	 2.169146e-003	 1.362147e-002	 0.000000e+000	 4.310687e+001
 2.759844e+000	 8.749451e-003	 8.474984e+002	 3.810170e-004	 1.721265e-002	 0.000000e+000	 4.515357e+001
 2.979844e+000	 9.530772e-003	 9.068297e+002	-8.094669e-004	 1.874973e-002	 0.000000e+000	 4.831541e+001
 3.099844e+000	 1.122784e-002	 9.417109e+002	 6.205654e-004	 2.208834e-002	 0.000000e+000	 5.017554e+001
 3.719844e+000	 1.015822e-002	 1.111610e+003	 1.528146e-003	 1.998411e-002	 0.000000e+000	 5.922675e+001
 3.839844e+000	 9.730902e-003	 1.145407e+003	 1.671460e-004	 1.914344e-002	 0.000000e+000	 6.102692e+001
 4.119844e+000	 1.173113e-002	 1.221928e+003	 5.671460e-004	 2.307845e-002	 0.000000e+000	 6.510653e+001
 4.359844e+000	 1.384248e-002	 1.288854e+003	 2.556662e-003	 2.723209e-002	 0.000000e+000	 6.867527e+001
 5.099844e+000	 1.561397e-002	 1.489045e+003	 1.635630e-003	 3.071710e-002	 0.000000e+000	 7.934502e+001
 5.219844e+000	 1.763168e-002	 1.520922e+003	 1.468694e-003	 3.468650e-002	 1.055597e-005	 8.104683e+001
 5.399844e+000	 1.946432e-002	 1.570740e+003	 3.235146e-003	 3.829184e-002	 3.292715e-005	 8.370456e+001
 5.899844e+000	 1.995839e-002	 1.702087e+003	 2.271146e-003	 3.926380e-002	 6.575360e-006	 9.070490e+001
 6.459844e+000	 2.052755e-002	 1.847787e+003	 2.681920e-003	 4.038350e-002	 0.000000e+000	 9.847040e+001
 6.699844e+000	 2.241906e-002	 1.908286e+003	 1.318694e-003	 4.410465e-002	 0.000000e+000	 1.016983e+002
 6.839844e+000	 2.386110e-002	 1.945421e+003	 9.801460e-004	 4.694154e-002	 1.652549e-005	 1.036802e+002
 7.099844e+000	 2.573777e-002	 2.012680e+003	 2.200533e-003	 5.063350e-002	 3.497318e-005	 1.072687e+002
 7.279844e+000	 2.782129e-002	 2.057574e+003	 4.990146e-003	 5.473236e-002	 6.363088e-005	 1.096659e+002
 7.519844e+000	 2.584706e-002	 2.118324e+003	 4.162436e-003	 5.084850e-002	 8.110367e-006	 1.128994e+002
 8.019844e+000	 2.521806e-002	 2.242495e+003	 3.801662e-003	 4.961108e-002	 0.000000e+000	 1.195158e+002
 8.239843e+000	 2.685197e-002	 2.296402e+003	 2.453565e-003	 5.282543e-002	 0.000000e+000	 1.223928e+002
 8.419844e+000	 2.857225e-002	 2.339878e+003	 1.620521e-003	 5.620971e-002	 8.769412e-007	 1.247142e+002
 8.819843e+000	 3.048431e-002	 2.441351e+003	 3.341630e-003	 5.997128e-002	 1.062506e-005	 1.301275e+002
 8.959844e+000	 3.252903e-002	 2.472226e+003	 3.809791e-003	 6.399382e-002	 4.237015e-005	 1.317785e+002
 9.139844e+000	 3.156655e-002	 2.515369e+003	 3.533630e-003	 6.210034e-002	 1.158787e-005	 1.340756e+002
 9.239843e+000	 2.917390e-002	 2.539235e+003	 5.073695e-003	 5.739333e-002	 0.000000e+000	 1.353414e+002
 9.459844e+000	 2.874864e-002	 2.589053e+003	 3.593146e-003	 5.655673e-002	 0.000000e+000	 1.379955e+002
 9.579844e+000	 3.106687e-002	 2.616675e+003	 2.505339e-003	 6.111734e-002	 0.000000e+000	 1.394741e+002
 9.699843e+000	 3.316416e-002	 2.644713e+003	 3.051985e-003	 6.524330e-002	 7.495555e-006	 1.409744e+002
 9.939844e+000	 3.179450e-002	 2.697535e+003	 3.514952e-003	 6.254879e-002	 0.000000e+000	 1.437862e+002
 1.019984e+001	 3.401919e-002	 2.756533e+003	 3.424953e-003	 6.692538e-002	 0.000000e+000	 1.469374e+002
 1.037984e+001	 3.615748e-002	 2.796755e+003	 4.424363e-004	 7.113201e-002	 2.462697e-005	 1.490877e+002
 1.093984e+001	 3.687116e-002	 2.912580e+003	 3.818404e-003	 7.253602e-002	 6.857909e-006	 1.552642e+002
 1.143984e+001	 3.766866e-002	 3.009880e+003	 2.473146e-003	 7.410492e-002	 0.000000e+000	 1.604536e+002
 1.179984e+001	 3.824000e-002	 3.079059e+003	 4.929865e-003	 7.522892e-002	 0.000000e+000	 1.641433e+002
 1.201984e+001	 3.990290e-002	 3.118196e+003	 4.209533e-003	 7.850032e-002	 1.003249e-005	 1.662351e+002
 1.227984e+001	 4.055396e-002	 3.164175e+003	 5.452333e-003	 7.978114e-002	 1.021323e-005	 1.686885e+002
 1.277984e+001	 4.072968e-002	 3.249208e+003	 3.405146e-003	 8.012682e-002	 0.000000e+000	 1.732224e+002
 1.321984e+001	 4.257964e-002	 3.321474e+003	 5.669146e-003	 8.376623e-002	 6.864828e-006	 1.770814e+002
 1.381984e+001	 4.329763e-002	 3.419525e+003	 5.114888e-003	 8.517870e-002	 0.000000e+000	 1.823115e+002
 1.417984e+001	 4.399388e-002	 3.476520e+003	 5.070333e-003	 8.654842e-002	 0.000000e+000	 1.853527e+002
 1.457984e+001	 4.578958e-002	 3.540191e+003	 4.924824e-003	 9.008108e-002	 9.946917e-006	 1.887540e+002
 1.503984e+001	 4.508894e-002	 3.614292e+003	 5.612740e-003	 8.870272e-002	 0.000000e+000	 1.927023e+002
 1.535984e+001	 4.681858e-002	 3.664445e+003	 5.551307e-003	 9.210542e-002	 0.000000e+000	 1.953829e+002
 1.585984e+001	 4.817048e-002	 3.743470e+003	 6.939565e-003	 9.476499e-002	 9.592587e-007	 1.996017e+002
 1.611984e+001	 4.921577e-002	 3.782857e+003	 7.881307e-003	 9.682137e-002	 1.070606e-005	 2.017059e+002
 1.985984e+001	 5.855593e-002	 4.354057e+003	 7.241985e-003	 1.151961e-001	 3.758334e-005	 2.322056e+002
 2.473984e+001	 6.615481e-002	 5.038663e+003	 9.793211e-003	 1.301453e-001	 0.000000e+000	 2.687563e+002
 3.073984e+001	 8.288126e-002	 5.791445e+003	 8.542824e-003	 1.630509e-001	 1.213728e-004	 3.090103e+002
 3.673985e+001	 9.546203e-002	 6.458610e+003	 9.260920e-003	 1.878009e-001	 1.856379e-004	 3.446929e+002
 4.225984e+001	 1.094051e-001	 6.988252e+003	 1.232857e-002	 2.152308e-001	 3.144487e-004	 3.730618e+002
 4.573985e+001	 1.192855e-001	 7.293838e+003	 1.561299e-002	 2.346683e-001	 4.248596e-004	 3.894507e+002
 5.153984e+001	 1.395721e-001	 7.749797e+003	 1.920249e-002	 2.745779e-001	 6.985811e-004	 4.139612e+002
 5.473985e+001	 1.507039e-001	 7.978778e+003	 2.255905e-002	 2.964773e-001	 8.545682e-004	 4.262854e+002
 6.001984e+001	 1.698662e-001	 8.330176e+003	 2.491257e-002	 3.341749e-001	 1.134761e-003	 4.452270e+002
 6.373985e+001	 1.836973e-001	 8.553565e+003	 2.454228e-002	 3.613847e-001	 1.345248e-003	 4.572906e+002
 6.745985e+001	 2.001710e-001	 8.768527e+003	 2.637728e-002	 3.937931e-001	 1.609905e-003	 4.689342e+002
 7.215984e+001	 2.205731e-001	 9.024211e+003	 2.657602e-002	 4.339298e-001	 1.940466e-003	 4.828009e+002
 7.573985e+001	 2.352641e-001	 9.205627e+003	 2.875986e-002	 4.628312e-001	 2.179164e-003	 4.926485e+002
 7.889984e+001	 2.507925e-001	 9.361257e+003	 2.781615e-002	 4.933799e-001	 2.441305e-003	 5.011295e+002
 8.247984e+001	 2.710725e-001	 9.525315e+003	 3.009957e-002	 5.332765e-001	 2.794289e-003	 5.101144e+002
 8.671984e+001	 2.913396e-001	 9.710903e+003	 3.031115e-002	 5.731476e-001	 3.141003e-003	 5.202595e+002
 9.057984e+001	 3.114216e-001	 9.874210e+003	 3.297127e-002	 6.126546e-001	 3.490064e-003	 5.292164e+002
 9.373985e+001	 3.288216e-001	 1.000314e+004	 3.387418e-002	 6.468852e-001	 3.795847e-003	 5.363087e+002
 9.673985e+001	 3.443494e-001	 1.012172e+004	 3.547702e-002	 6.774328e-001	 4.067685e-003	 5.428310e+002
 9.973985e+001	 3.631673e-001	 1.023804e+004	 3.594628e-002	 7.144529e-001	 4.404510e-003	 5.492714e+002
 1.029598e+002	 3.823177e-001	 1.035362e+004	 3.872421e-002	 7.521273e-001	 4.747939e-003	 5.556798e+002
 1.063198e+002	 4.024282e-001	 1.047253e+004	 4.077376e-002	 7.916903e-001	 5.109127e-003	 5.622825e+002
 1.098398e+002	 4.227625e-001	 1.059812e+004	 4.230314e-002	 8.316938e-001	 5.472741e-003	 5.692514e+002
 1.129598e+002	 4.430625e-001	 1.069884e+004	 4.491302e-002	 8.716294e-001	 5.842340e-003	 5.748890e+002
 1.162798e+002	 4.632876e-001	 1.080933e+004	 4.772215e-002	 9.114180e-001	 6.207675e-003	 5.810549e+002
 1.194798e+002	 4.833216e-001	 1.091063e+004	 4.933315e-002	 9.508307e-001	 6.571647e-003	 5.867296e+002
 1.224798e+002	 5.035136e-001	 1.099733e+004	 5.158163e-002	 9.905540e-001	 6.942555e-003	 5.916248e+002
 1.256598e+002	 5.237744e-001	 1.109263e+004	 5.513415e-002	 1.030413e+000	 7.312325e-003	 5.969870e+002
 1.288398e+002	 5.440399e-001	 1.118434e+004	 5.687115e-002	 1.070281e+000	 7.683029e-003	 6.021601e+002
 1.317398e+002	 5.641959e-001	 1.126745e+004	 5.767392e-002	 1.109933e+000	 8.053799e-003	 6.068729e+002
 1.347198e+002	 5.844929e-001	 1.134723e+004	 6.020414e-002	 1.149863e+000	 8.428092e-003	 6.114111e+002
 1.377198e+002	 6.048270e-001	 1.142617e+004	 6.331815e-002	 1.189866e+000	 8.803197e-003	 6.159081e+002
 1.409198e+002	 6.253106e-001	 1.150511e+004	 6.582414e-002	 1.230163e+000	 9.181074e-003	 6.204102e+002
 1.437398e+002	 6.453522e-001	 1.157554e+004	 6.732418e-002	 1.269591e+000	 9.552512e-003	 6.244512e+002
 1.467398e+002	 6.654600e-001	 1.164556e+004	 7.045431e-002	 1.309148e+000	 9.925214e-003	 6.284735e+002
 1.497398e+002	 6.855065e-001	 1.171774e+004	 7.243931e-002	 1.348586e+000	 1.029599e-002	 6.326151e+002
 1.527598e+002	 7.057403e-001	 1.178750e+004	 7.496847e-002	 1.388391e+000	 1.067094e-002	 6.366313e+002
 1.554198e+002	 7.260382e-001	 1.184525e+004	 7.666089e-002	 1.428323e+000	 1.105026e-002	 6.400020e+002
 1.584198e+002	 7.464518e-001	 1.191059e+004	 8.008914e-002	 1.468482e+000	 1.142962e-002	 6.437872e+002
 1.614198e+002	 7.667192e-001	 1.197501e+004	 8.279627e-002	 1.508354e+000	 1.180624e-002	 6.475236e+002
 1.641398e+002	 7.868227e-001	 1.202917e+004	 8.616640e-002	 1.547903e+000	 1.218232e-002	 6.507054e+002
 1.668398e+002	 8.069624e-001	 1.208483e+004	 8.455615e-002	 1.587524e+000	 1.255856e-002	 6.539714e+002
 1.694998e+002	 8.270059e-001	 1.213715e+004	 8.805615e-002	 1.626955e+000	 1.293369e-002	 6.570576e+002
 1.723598e+002	 8.472577e-001	 1.219080e+004	 9.049617e-002	 1.666796e+000	 1.331236e-002	 6.602211e+002
 1.750998e+002	 8.672847e-001	 1.224605e+004	 9.266715e-002	 1.706195e+000	 1.368610e-002	 6.634699e+002
 1.780198e+002	 8.874262e-001	 1.229795e+004	 9.653434e-002	 1.745819e+000	 1.406282e-002	 6.665415e+002
 1.807398e+002	 9.076561e-001	 1.234535e+004	 9.861983e-002	 1.785617e+000	 1.444234e-002	 6.693722e+002
 1.837398e+002	 9.312005e-001	 1.240067e+004	 9.957986e-002	 1.831935e+000	 1.488381e-002	 6.726780e+002
 1.867398e+002	 9.525017e-001	 1.245183e+004	 1.042586e-001	 1.873841e+000	 1.528275e-002	 6.757307e+002
 1.897398e+002	 9.757590e-001	 1.249964e+004	 1.065734e-001	 1.919594e+000	 1.572032e-002	 6.786302e+002
 1.926398e+002	 9.987457e-001	 1.255021e+004	 1.058745e-001	 1.964816e+000	 1.615171e-002	 6.816780e+002
 1.952598e+002	 1.017745e+000	 1.259302e+004	 1.099952e-001	 2.002192e+000	 1.650786e-002	 6.842539e+002
 1.964998e+002	 1.026958e+000	 1.261255e+004	 1.123331e-001	 2.020318e+000	 1.668086e-002	 6.854367e+002
 1.989198e+002	 1.044580e+000	 1.265244e+004	 1.136148e-001	 2.054985e+000	 1.701097e-002	 6.878381e+002
 2.017398e+002	 1.067297e+000	 1.269625e+004	 1.164769e-001	 2.099675e+000	 1.743841e-002	 6.905220e+002
 2.047398e+002	 1.092038e+000	 1.274114e+004	 1.186436e-001	 2.148348e+000	 1.790450e-002	 6.932941e+002
 2.073998e+002	 1.111769e+000	 1.278287e+004	 1.231631e-001	 2.187165e+000	 1.827445e-002	 6.958287e+002
 2.098198e+002	 1.129535e+000	 1.281499e+004	 1.231531e-001	 2.222115e+000	 1.860891e-002	 6.978161e+002
 2.122398e+002	 1.148505e+000	 1.285104e+004	 1.268500e-001	 2.259435e+000	 1.896544e-002	 7.000346e+002
 2.146599e+002	 1.167856e+000	 1.288534e+004	 1.281751e-001	 2.297504e+000	 1.932968e-002	 7.021642e+002
 2.170798e+002	 1.186688e+000	 1.291813e+004	 1.304654e-001	 2.334552e+000	 1.968416e-002	 7.042062e+002
 2.197398e+002	 1.208421e+000	 1.295594e+004	 1.341794e-001	 2.377306e+000	 2.009311e-002	 7.065619e+002
 2.227398e+002	 1.231791e+000	 1.299624e+004	 1.358757e-001	 2.423283e+000	 2.053279e-002	 7.090782e+002
 2.255598e+002	 1.256144e+000	 1.303354e+004	 1.372992e-001	 2.471190e+000	 2.099199e-002	 7.114460e+002
 2.279798e+002	 1.272827e+000	 1.306442e+004	 1.387985e-001	 2.504011e+000	 2.130502e-002	 7.133597e+002
 2.303998e+002	 1.290830e+000	 1.309630e+004	 1.410151e-001	 2.539429e+000	 2.164311e-002	 7.153474e+002
 2.328198e+002	 1.309271e+000	 1.312675e+004	 1.443432e-001	 2.575707e+000	 2.198987e-002	 7.172648e+002
 2.352398e+002	 1.328440e+000	 1.315671e+004	 1.471557e-001	 2.613419e+000	 2.235068e-002	 7.191660e+002
 2.377398e+002	 1.351941e+000	 1.318467e+004	 1.496088e-001	 2.659651e+000	 2.279518e-002	 7.210188e+002
 2.407398e+002	 1.375915e+000	 1.322280e+004	 1.513987e-001	 2.706815e+000	 2.324585e-002	 7.234364e+002
 2.436998e+002	 1.402953e+000	 1.325626e+004	 1.520027e-001	 2.760006e+000	 2.375642e-002	 7.256428e+002
 2.461198e+002	 1.426590e+000	 1.328297e+004	 1.548471e-001	 2.806506e+000	 2.420325e-002	 7.274335e+002
 2.485398e+002	 1.438341e+000	 1.331167e+004	 1.585890e-001	 2.829624e+000	 2.442118e-002	 7.291695e+002
 2.521599e+002	 1.469781e+000	 1.335114e+004	 1.594781e-001	 2.891476e+000	 2.501402e-002	 7.317714e+002
 2.545798e+002	 1.489746e+000	 1.337793e+004	 1.646413e-001	 2.930752e+000	 2.538984e-002	 7.335195e+002
 2.569998e+002	 1.510538e+000	 1.340505e+004	 1.656691e-001	 2.971657e+000	 2.578129e-002	 7.352985e+002
 2.594198e+002	 1.530066e+000	 1.343092e+004	 1.689485e-001	 3.010073e+000	 2.614868e-002	 7.369924e+002
 2.618398e+002	 1.550896e+000	 1.345804e+004	 1.722731e-001	 3.051052e+000	 2.654056e-002	 7.387743e+002
 2.647398e+002	 1.575381e+000	 1.348558e+004	 1.714596e-001	 3.099220e+000	 2.700216e-002	 7.406320e+002
 2.677398e+002	 1.601700e+000	 1.352038e+004	 1.750046e-001	 3.150998e+000	 2.749672e-002	 7.429160e+002
 2.702998e+002	 1.621062e+000	 1.354433e+004	 1.769017e-001	 3.189089e+000	 2.786083e-002	 7.445067e+002
 2.727198e+002	 1.642803e+000	 1.356527e+004	 1.779851e-001	 3.231859e+000	 2.827110e-002	 7.459671e+002
 2.751198e+002	 1.662290e+000	 1.359031e+004	 1.815201e-001	 3.270196e+000	 2.863704e-002	 7.476213e+002
 2.775598e+002	 1.682993e+000	 1.361234e+004	 1.807331e-001	 3.310924e+000	 2.902687e-002	 7.491285e+002
 2.799799e+002	 1.703732e+000	 1.363478e+004	 1.846496e-001	 3.351725e+000	 2.941713e-002	 7.506602e+002
 2.827398e+002	 1.727577e+000	 1.366466e+004	 1.884809e-001	 3.398634e+000	 2.986456e-002	 7.526463e+002
 2.857398e+002	 1.752226e+000	 1.368827e+004	 1.902376e-001	 3.447126e+000	 3.032881e-002	 7.543006e+002
 2.884398e+002	 1.774243e+000	 1.371506e+004	 1.933629e-001	 3.490438e+000	 3.074177e-002	 7.560931e+002
 2.908598e+002	 1.796357e+000	 1.373926e+004	 1.942794e-001	 3.533944e+000	 3.115713e-002	 7.577456e+002
 2.932798e+002	 1.817866e+000	 1.375779e+004	 1.960381e-001	 3.576258e+000	 3.156227e-002	 7.590774e+002
 2.956998e+002	 1.839714e+000	 1.377865e+004	 1.991893e-001	 3.619238e+000	 3.197308e-002	 7.605439e+002
 2.981198e+002	 1.860880e+000	 1.380034e+004	 1.995001e-001	 3.660879e+000	 3.237054e-002	 7.620476e+002
 3.007398e+002	 1.883164e+000	 1.382254e+004	 2.024950e-001	 3.704718e+000	 3.278897e-002	 7.635960e+002
 3.037398e+002	 1.909442e+000	 1.384457e+004	 2.042906e-001	 3.756414e+000	 3.328328e-002	 7.651943e+002
 3.065798e+002	 1.934369e+000	 1.387203e+004	 2.093118e-001	 3.805453e+000	 3.375022e-002	 7.670741e+002
 3.089998e+002	 1.956536e+000	 1.389289e+004	 2.100991e-001	 3.849061e+000	 3.416620e-002	 7.685503e+002
 3.114198e+002	 1.977463e+000	 1.391066e+004	 2.117600e-001	 3.890229e+000	 3.455926e-002	 7.698387e+002
 3.138398e+002	 1.999122e+000	 1.392752e+004	 2.133461e-001	 3.932840e+000	 3.496634e-002	 7.710876e+002
 3.162798e+002	 2.021350e+000	 1.394521e+004	 2.139701e-001	 3.976569e+000	 3.538382e-002	 7.723919e+002
 3.187398e+002	 2.043428e+000	 1.396390e+004	 2.186772e-001	 4.020002e+000	 3.579801e-002	 7.737503e+002
 3.217398e+002	 2.068959e+000	 1.399002e+004	 2.191505e-001	 4.070230e+000	 3.627559e-002	 7.755719e+002
 3.247398e+002	 2.096867e+000	 1.401255e+004	 2.226362e-001	 4.125131e+000	 3.679894e-002	 7.772307e+002
 3.271798e+002	 2.119186e+000	 1.403149e+004	 2.253419e-001	 4.169040e+000	 3.721707e-002	 7.786095e+002
 3.295999e+002	 2.141824e+000	 1.404927e+004	 2.280362e-001	 4.213574e+000	 3.764134e-002	 7.799291e+002
 3.320198e+002	 2.162777e+000	 1.406813e+004	 2.280228e-001	 4.254796e+000	 3.803327e-002	 7.812849e+002
 3.344398e+002	 2.185162e+000	 1.408448e+004	 2.320042e-001	 4.298833e+000	 3.845279e-002	 7.825237e+002
 3.368799e+002	 2.206599e+000	 1.409917e+004	 2.347142e-001	 4.341007e+000	 3.885466e-002	 7.836563e+002
 3.397398e+002	 2.232939e+000	 1.412195e+004	 2.348932e-001	 4.392823e+000	 3.934694e-002	 7.853123e+002
 3.427398e+002	 2.260417e+000	 1.413939e+004	 2.382885e-001	 4.446881e+000	 3.986193e-002	 7.866893e+002
 3.453398e+002	 2.284600e+000	 1.415875e+004	 2.400211e-001	 4.494455e+000	 4.031386e-002	 7.881252e+002
 3.477599e+002	 2.306912e+000	 1.417561e+004	 2.440275e-001	 4.538349e+000	 4.073093e-002	 7.893949e+002
 3.501798e+002	 2.329869e+000	 1.419138e+004	 2.464670e-001	 4.583513e+000	 4.116029e-002	 7.906147e+002
 3.525999e+002	 2.351103e+000	 1.420690e+004	 2.479030e-001	 4.625287e+000	 4.155701e-002	 7.917954e+002
 3.550198e+002	 2.373941e+000	 1.422392e+004	 2.483037e-001	 4.670215e+000	 4.198343e-002	 7.930846e+002
 3.577398e+002	 2.397933e+000	 1.423736e+004	 2.524779e-001	 4.717413e+000	 4.243237e-002	 7.941917e+002
 3.607398e+002	 2.426983e+000	 1.425872e+004	 2.540362e-001	 4.774564e+000	 4.297436e-002	 7.958174e+002
 3.634799e+002	 2.450437e+000	 1.427750e+004	 2.565480e-001	 4.820704e+000	 4.341132e-002	 7.972162e+002
 3.658799e+002	 2.474418e+000	 1.429244e+004	 2.582422e-001	 4.867881e+000	 4.385902e-002	 7.984094e+002
 3.682798e+002	 2.495960e+000	 1.430796e+004	 2.586972e-001	 4.910260e+000	 4.426047e-002	 7.995994e+002
 3.706998e+002	 2.518256e+000	 1.432089e+004	 2.629068e-001	 4.954124e+000	 4.467662e-002	 8.006569e+002
 3.731198e+002	 2.542684e+000	 1.433783e+004	 2.640001e-001	 5.002180e+000	 4.513163e-002	 8.019709e+002
 3.757398e+002	 2.566915e+000	 1.434768e+004	 2.666294e-001	 5.049849e+000	 4.558461e-002	 8.028860e+002
 3.787398e+002	 2.595571e+000	 1.436537e+004	 2.707245e-001	 5.106224e+000	 4.611845e-002	 8.043074e+002
 3.815999e+002	 2.622282e+000	 1.438122e+004	 2.711332e-001	 5.158772e+000	 4.661596e-002	 8.055976e+002
 3.840198e+002	 2.643953e+000	 1.439491e+004	 2.749780e-001	 5.201405e+000	 4.701921e-002	 8.066911e+002
 3.864198e+002	 2.667920e+000	 1.440876e+004	 2.767030e-001	 5.248556e+000	 4.746532e-002	 8.078292e+002
 3.888199e+002	 2.690868e+000	 1.442170e+004	 2.804691e-001	 5.293701e+000	 4.789237e-002	 8.089012e+002
 3.912398e+002	 2.713851e+000	 1.443588e+004	 2.816452e-001	 5.338915e+000	 4.831956e-002	 8.100446e+002
 3.937398e+002	 2.738803e+000	 1.444990e+004	 2.842135e-001	 5.388003e+000	 4.878351e-002	 8.112090e+002
 3.967398e+002	 2.768575e+000	 1.446751e+004	 2.854397e-001	 5.446572e+000	 4.933656e-002	 8.126488e+002
 3.997198e+002	 2.794697e+000	 1.447827e+004	 2.892402e-001	 5.497962e+000	 4.982278e-002	 8.136498e+002
 4.021398e+002	 2.817745e+000	 1.449071e+004	 2.909108e-001	 5.543303e+000	 5.025082e-002	 8.146986e+002
 4.045598e+002	 2.844822e+000	 1.450331e+004	 2.939931e-001	 5.596572e+000	 5.075398e-002	 8.158185e+002
 4.069799e+002	 2.867507e+000	 1.451666e+004	 2.952160e-001	 5.641199e+000	 5.117460e-002	 8.169146e+002
 4.093998e+002	 2.890857e+000	 1.452784e+004	 2.979032e-001	 5.687134e+000	 5.160802e-002	 8.178993e+002
 4.117998e+002	 2.913069e+000	 1.453969e+004	 3.004469e-001	 5.730832e+000	 5.201984e-002	 8.189049e+002
 4.147398e+002	 2.940342e+000	 1.454954e+004	 3.025542e-001	 5.784486e+000	 5.252649e-002	 8.198753e+002
 4.177398e+002	 2.971502e+000	 1.456631e+004	 3.058389e-001	 5.845787e+000	 5.310360e-002	 8.212961e+002
 4.202998e+002	 2.995839e+000	 1.457499e+004	 3.071534e-001	 5.893665e+000	 5.355525e-002	 8.221571e+002
 4.227198e+002	 3.021172e+000	 1.458634e+004	 3.091241e-001	 5.943502e+000	 5.402457e-002	 8.231845e+002
 4.251398e+002	 3.044943e+000	 1.459836e+004	 3.137779e-001	 5.990265e+000	 5.446439e-002	 8.242263e+002
 4.275598e+002	 3.068720e+000	 1.460812e+004	 3.148831e-001	 6.037041e+000	 5.490472e-002	 8.251414e+002
 4.299799e+002	 3.092615e+000	 1.461938e+004	 3.166912e-001	 6.084051e+000	 5.534667e-002	 8.261438e+002
 4.327398e+002	 3.114462e+000	 1.463040e+004	 3.205858e-001	 6.127029e+000	 5.575037e-002	 8.271013e+002
 4.357398e+002	 3.149259e+000	 1.464442e+004	 3.241642e-001	 6.195485e+000	 5.639396e-002	 8.284277e+002
 4.384398e+002	 3.175848e+000	 1.465685e+004	 3.260002e-001	 6.247792e+000	 5.688500e-002	 8.295395e+002
 4.408598e+002	 3.198331e+000	 1.466528e+004	 3.287639e-001	 6.292024e+000	 5.730059e-002	 8.303620e+002
 4.432798e+002	 3.222770e+000	 1.467479e+004	 3.294851e-001	 6.340102e+000	 5.775203e-002	 8.312765e+002
 4.456998e+002	 3.246149e+000	 1.468439e+004	 3.335522e-001	 6.386096e+000	 5.818357e-002	 8.321798e+002
 4.481198e+002	 3.269919e+000	 1.469574e+004	 3.366441e-001	 6.432857e+000	 5.862171e-002	 8.331890e+002
 4.507398e+002	 3.294564e+000	 1.470859e+004	 3.382206e-001	 6.481341e+000	 5.907552e-002	 8.342975e+002
 4.537398e+002	 3.324571e+000	 1.471769e+004	 3.404231e-001	 6.540373e+000	 5.962947e-002	 8.352762e+002
 4.565999e+002	 3.351325e+000	 1.472703e+004	 3.436581e-001	 6.593005e+000	 6.012278e-002	 8.362194e+002
 4.590198e+002	 3.376830e+000	 1.473746e+004	 3.464071e-001	 6.643182e+000	 6.059247e-002	 8.372056e+002
 4.614398e+002	 3.399875e+000	 1.474664e+004	 3.509372e-001	 6.688517e+000	 6.101670e-002	 8.380832e+002
 4.638598e+002	 3.425302e+000	 1.475507e+004	 3.481514e-001	 6.738540e+000	 6.148503e-002	 8.389553e+002
 4.662798e+002	 3.446734e+000	 1.476408e+004	 3.532872e-001	 6.780704e+000	 6.187912e-002	 8.397994e+002
 4.687398e+002	 3.472947e+000	 1.477393e+004	 3.557208e-001	 6.832272e+000	 6.236120e-002	 8.407653e+002
 4.717398e+002	 3.503020e+000	 1.478361e+004	 3.587270e-001	 6.891432e+000	 6.291439e-002	 8.417820e+002
 4.747398e+002	 3.531773e+000	 1.479471e+004	 3.609809e-001	 6.947998e+000	 6.344255e-002	 8.428597e+002
 4.777398e+002	 3.560323e+000	 1.480823e+004	 3.649990e-001	 7.004164e+000	 6.396606e-002	 8.440729e+002
 4.807398e+002	 3.590890e+000	 1.481674e+004	 3.685321e-001	 7.064299e+000	 6.452780e-002	 8.450326e+002
 4.832198e+002	 3.613942e+000	 1.482500e+004	 3.698237e-001	 7.109648e+000	 6.495073e-002	 8.458619e+002
 4.856599e+002	 3.639398e+000	 1.483076e+004	 3.730102e-001	 7.159728e+000	 6.541845e-002	 8.465860e+002
 4.880798e+002	 3.662264e+000	 1.483910e+004	 3.760376e-001	 7.204711e+000	 6.583756e-002	 8.474180e+002
 4.904998e+002	 3.686486e+000	 1.484862e+004	 3.776782e-001	 7.252364e+000	 6.628118e-002	 8.483381e+002
 4.929198e+002	 3.711129e+000	 1.485479e+004	 3.795518e-001	 7.300843e+000	 6.673320e-002	 8.490745e+002
 4.957398e+002	 3.739770e+000	 1.485996e+004	 3.842636e-001	 7.357188e+000	 6.725881e-002	 8.498162e+002
 4.987398e+002	 3.770574e+000	 1.487023e+004	 3.851003e-001	 7.417788e+000	 6.782259e-002	 8.508832e+002
 5.013998e+002	 3.798458e+000	 1.488358e+004	 3.882262e-001	 7.472644e+000	 6.833162e-002	 8.520820e+002
 5.038199e+002	 3.821538e+000	 1.488884e+004	 3.908792e-001	 7.518048e+000	 6.875424e-002	 8.527431e+002
 5.062398e+002	 3.845943e+000	 1.489626e+004	 3.924884e-001	 7.566059e+000	 6.920045e-002	 8.535494e+002
 5.086599e+002	 3.871780e+000	 1.490177e+004	 3.966270e-001	 7.616889e+000	 6.967323e-002	 8.542684e+002
 5.110798e+002	 3.896287e+000	 1.490803e+004	 3.968729e-001	 7.665102e+000	 7.012121e-002	 8.550101e+002
 5.137399e+002	 3.924793e+000	 1.491270e+004	 3.975619e-001	 7.721181e+000	 7.064270e-002	 8.557235e+002
 5.167399e+002	 3.953324e+000	 1.492280e+004	 4.003365e-001	 7.777309e+000	 7.116297e-002	 8.567490e+002
 5.195598e+002	 3.982729e+000	 1.492939e+004	 4.043432e-001	 7.835157e+000	 7.169988e-002	 8.575876e+002
 5.219799e+002	 4.008533e+000	 1.493665e+004	 4.057342e-001	 7.885921e+000	 7.217043e-002	 8.584085e+002
 5.243998e+002	 4.032213e+000	 1.494283e+004	 4.080271e-001	 7.932505e+000	 7.260217e-002	 8.591342e+002
 5.268198e+002	 4.057722e+000	 1.494867e+004	 4.105047e-001	 7.982689e+000	 7.306726e-002	 8.598696e+002
 5.292399e+002	 4.084998e+000	 1.495651e+004	 4.133024e-001	 8.036349e+000	 7.356393e-002	 8.607482e+002
 5.317399e+002	 4.109699e+000	 1.496260e+004	 4.145953e-001	 8.084943e+000	 7.401375e-002	 8.614861e+002
 5.347399e+002	 4.140718e+000	 1.496936e+004	 4.174008e-001	 8.145966e+000	 7.457856e-002	 8.623619e+002
 5.377399e+002	 4.168959e+000	 1.497462e+004	 4.215616e-001	 8.201523e+000	 7.509274e-002	 8.631079e+002
 5.407399e+002	 4.199612e+000	 1.498171e+004	 4.224811e-001	 8.261827e+000	 7.565018e-002	 8.639979e+002
 5.437399e+002	 4.230601e+000	 1.498964e+004	 4.245596e-001	 8.322792e+000	 7.621324e-002	 8.649418e+002
 5.461998e+002	 4.255778e+000	 1.499290e+004	 4.267972e-001	 8.372321e+000	 7.667125e-002	 8.655252e+002
 5.486199e+002	 4.280774e+000	 1.499665e+004	 4.292322e-001	 8.421496e+000	 7.712565e-002	 8.661348e+002
 5.510399e+002	 4.305014e+000	 1.500249e+004	 4.318296e-001	 8.469182e+000	 7.756553e-002	 8.668532e+002
 5.534598e+002	 4.330060e+000	 1.500959e+004	 4.355856e-001	 8.518456e+000	 7.801959e-002	 8.676570e+002
 5.558798e+002	 4.354922e+000	 1.501526e+004	 4.361151e-001	 8.567367e+000	 7.847044e-002	 8.683762e+002
 5.587399e+002	 4.384928e+000	 1.502202e+004	 4.375354e-001	 8.626396e+000	 7.901432e-002	 8.692394e+002
 5.617399e+002	 4.414441e+000	 1.502845e+004	 4.428091e-001	 8.684457e+000	 7.954905e-002	 8.700760e+002
 5.643398e+002	 4.440795e+000	 1.503596e+004	 4.450282e-001	 8.736302e+000	 8.002584e-002	 8.709260e+002
 5.667598e+002	 4.465923e+000	 1.504088e+004	 4.467781e-001	 8.785736e+000	 8.048081e-002	 8.716073e+002
 5.691799e+002	 4.489296e+000	 1.504513e+004	 4.490021e-001	 8.831719e+000	 8.090391e-002	 8.722224e+002
 5.715999e+002	 4.514451e+000	 1.504981e+004	 4.514995e-001	 8.881204e+000	 8.135901e-002	 8.728900e+002
 5.740198e+002	 4.541053e+000	 1.505415e+004	 4.536383e-001	 8.933538e+000	 8.184025e-002	 8.735613e+002
 5.767399e+002	 4.567277e+000	 1.506182e+004	 4.557599e-001	 8.985129e+000	 8.231357e-002	 8.744207e+002
 5.797399e+002	 4.597761e+000	 1.506408e+004	 4.595359e-001	 9.045099e+000	 8.286516e-002	 8.750327e+002
 5.824799e+002	 4.624604e+000	 1.506992e+004	 4.622436e-001	 9.097906e+000	 8.334964e-002	 8.757959e+002
 5.848998e+002	 4.649718e+000	 1.507251e+004	 4.611391e-001	 9.147313e+000	 8.380344e-002	 8.763429e+002
 5.873198e+002	 4.674129e+000	 1.507726e+004	 4.667966e-001	 9.195338e+000	 8.424378e-002	 8.770051e+002
 5.897399e+002	 4.700496e+000	 1.508018e+004	 4.659159e-001	 9.247207e+000	 8.471972e-002	 8.775917e+002
 5.921599e+002	 4.724529e+000	 1.508602e+004	 4.674422e-001	 9.294488e+000	 8.515256e-002	 8.783115e+002
 5.947399e+002	 4.747622e+000	 1.509020e+004	 4.700279e-001	 9.339917e+000	 8.556862e-002	 8.789196e+002
 5.977399e+002	 4.779755e+000	 1.509687e+004	 4.724721e-001	 9.403132e+000	 8.614708e-002	 8.798167e+002
 6.006199e+002	 4.810555e+000	 1.510205e+004	 4.744281e-001	 9.463724e+000	 8.670153e-002	 8.806057e+002
 6.030399e+002	 4.832982e+000	 1.510714e+004	 4.761556e-001	 9.507845e+000	 8.710473e-002	 8.812576e+002
 6.054598e+002	 4.858119e+000	 1.510956e+004	 4.788999e-001	 9.557298e+000	 8.755730e-002	 8.817967e+002
 6.078798e+002	 4.884333e+000	 1.511289e+004	 4.805112e-001	 9.608868e+000	 8.802881e-002	 8.824067e+002
 6.102999e+002	 4.909014e+000	 1.511540e+004	 4.830309e-001	 9.657421e+000	 8.847271e-002	 8.829437e+002
 6.139398e+002	 4.945070e+000	 1.511974e+004	 4.868371e-001	 9.728355e+000	 8.912068e-002	 8.837685e+002
 6.163599e+002	 4.969383e+000	 1.512174e+004	 4.898854e-001	 9.776185e+000	 8.955760e-002	 8.842708e+002
 6.187798e+002	 4.993251e+000	 1.512650e+004	 4.946592e-001	 9.823140e+000	 8.998564e-002	 8.849272e+002
 6.217399e+002	 5.024241e+000	 1.512900e+004	 4.958847e-001	 9.884106e+000	 9.054205e-002	 8.855650e+002
 6.247399e+002	 5.053404e+000	 1.513150e+004	 4.984498e-001	 9.941479e+000	 9.106535e-002	 8.861739e+002
 6.272798e+002	 5.080494e+000	 1.513709e+004	 5.016701e-001	 9.994772e+000	 9.155037e-002	 8.869311e+002
 6.296998e+002	 5.105230e+000	 1.514110e+004	 5.031900e-001	 1.004343e+001	 9.199332e-002	 8.875582e+002
 6.320999e+002	 5.129339e+000	 1.514519e+004	 5.044361e-001	 1.009086e+001	 9.242481e-002	 8.881805e+002
 6.345198e+002	 5.155148e+000	 1.514944e+004	 5.089007e-001	 1.014164e+001	 9.288656e-002	 8.888398e+002
 6.369398e+002	 5.181345e+000	 1.514903e+004	 5.111061e-001	 1.019317e+001	 9.335621e-002	 8.892312e+002
 6.397399e+002	 5.209999e+000	 1.515011e+004	 5.143417e-001	 1.024954e+001	 9.386926e-002	 8.897498e+002
 6.427399e+002	 5.241882e+000	 1.515545e+004	 5.140111e-001	 1.031227e+001	 9.443879e-002	 8.905697e+002
 6.454199e+002	 5.268430e+000	 1.515487e+004	 5.172975e-001	 1.036450e+001	 9.491404e-002	 8.909570e+002
 6.478398e+002	 5.292098e+000	 1.515829e+004	 5.197672e-001	 1.041106e+001	 9.533654e-002	 8.915341e+002
 6.502598e+002	 5.318871e+000	 1.516154e+004	 5.221052e-001	 1.046373e+001	 9.581442e-002	 8.921509e+002
 6.526799e+002	 5.341362e+000	 1.516246e+004	 5.256332e-001	 1.050797e+001	 9.621616e-002	 8.925622e+002
 6.551199e+002	 5.366185e+000	 1.516463e+004	 5.269002e-001	 1.055681e+001	 9.665906e-002	 8.930844e+002
 6.577399e+002	 5.392910e+000	 1.516981e+004	 5.278674e-001	 1.060938e+001	 9.713497e-002	 8.938139e+002
 6.607399e+002	 5.423522e+000	 1.517456e+004	 5.320659e-001	 1.066961e+001	 9.768012e-002	 8.945810e+002
 6.635798e+002	 5.454613e+000	 1.517323e+004	 5.322036e-001	 1.073077e+001	 9.823502e-002	 8.949966e+002
 6.659799e+002	 5.477331e+000	 1.517631e+004	 5.355774e-001	 1.077546e+001	 9.863928e-002	 8.955400e+002
 6.683998e+002	 5.499612e+000	 1.517782e+004	 5.380091e-001	 1.081930e+001	 9.903599e-002	 8.959830e+002
 6.707999e+002	 5.524745e+000	 1.518115e+004	 5.395704e-001	 1.086874e+001	 9.948287e-002	 8.965798e+002
 6.732198e+002	 5.545897e+000	 1.518383e+004	 5.424922e-001	 1.091035e+001	 9.985886e-002	 8.970741e+002
 6.757399e+002	 5.573491e+000	 1.518524e+004	 5.431324e-001	 1.096464e+001	 1.003496e-001	 8.975970e+002
 6.787399e+002	 5.602300e+000	 1.518650e+004	 5.483736e-001	 1.102131e+001	 1.008618e-001	 8.981294e+002
 6.817198e+002	 5.630505e+000	 1.518549e+004	 5.487552e-001	 1.107680e+001	 1.013636e-001	 8.985190e+002
 6.841199e+002	 5.653169e+000	 1.518725e+004	 5.512431e-001	 1.112139e+001	 1.017660e-001	 8.989834e+002
 6.865399e+002	 5.676959e+000	 1.518775e+004	 5.550432e-001	 1.116819e+001	 1.021885e-001	 8.993917e+002
 6.901599e+002	 5.713110e+000	 1.519451e+004	 5.554761e-001	 1.123931e+001	 1.028287e-001	 9.003675e+002
 6.925798e+002	 5.735662e+000	 1.519551e+004	 5.587046e-001	 1.128367e+001	 1.032287e-001	 9.007860e+002
 6.949998e+002	 5.758842e+000	 1.519567e+004	 5.614381e-001	 1.132927e+001	 1.036399e-001	 9.011650e+002
 6.974199e+002	 5.780908e+000	 1.519542e+004	 5.629655e-001	 1.137268e+001	 1.040312e-001	 9.015014e+002
 6.998398e+002	 5.804355e+000	 1.519901e+004	 5.658491e-001	 1.141881e+001	 1.044459e-001	 9.020878e+002
 7.027399e+002	 5.832992e+000	 1.519885e+004	 5.664212e-001	 1.147515e+001	 1.049533e-001	 9.025340e+002
 7.057399e+002	 5.861415e+000	 1.519776e+004	 5.690114e-001	 1.153107e+001	 1.054569e-001	 9.029222e+002
 7.082999e+002	 5.884967e+000	 1.520235e+004	 5.719872e-001	 1.157740e+001	 1.058727e-001	 9.035701e+002
 7.107198e+002	 5.908508e+000	 1.520252e+004	 5.760462e-001	 1.162371e+001	 1.062891e-001	 9.039550e+002
 7.131199e+002	 5.930097e+000	 1.520202e+004	 5.757502e-001	 1.166618e+001	 1.066711e-001	 9.042691e+002
 7.155399e+002	 5.954442e+000	 1.520235e+004	 5.766152e-001	 1.171407e+001	 1.071014e-001	 9.046768e+002
 7.179598e+002	 5.976610e+000	 1.520085e+004	 5.773379e-001	 1.175769e+001	 1.074935e-001	 9.049405e+002
 7.207399e+002	 6.003994e+000	 1.520152e+004	 5.821155e-001	 1.181156e+001	 1.079770e-001	 9.054165e+002
 7.237399e+002	 6.030568e+000	 1.520218e+004	 5.851981e-001	 1.186384e+001	 1.084460e-001	 9.058796e+002
 7.264398e+002	 6.055387e+000	 1.519968e+004	 5.862231e-001	 1.191266e+001	 1.088846e-001	 9.061257e+002
 7.288599e+002	 6.076884e+000	 1.520310e+004	 5.865574e-001	 1.195495e+001	 1.092630e-001	 9.066721e+002
 7.312798e+002	 6.098374e+000	 1.520101e+004	 5.878341e-001	 1.199723e+001	           0.0	           0.0
 7.336998e+002	 6.120118e+000	 1.520001e+004	 5.917691e-001	 1.204001e+001	           0.0	           0.0
 7.361199e+002	 6.141751e+000	 1.519843e+004	 5.897002e-001	 1.208257e+001	           0.0	           0.0
 7.387399e+002	 6.165375e+000	 1.519484e+004	 5.931518e-001	 1.212904e+001	           0.0	           0.0
 7.417399e+002	 6.191764e+000	 1.519617e+004	 5.956442e-001	 1.218095e+001	           0.0	           0.0
 7.445999e+002	 6.213546e+000	 1.519417e+004	 5.962321e-001	 1.222381e+001	           0.0	           0.0
 7.470399e+002	 6.237327e+000	 1.519050e+004	 5.955842e-001	 1.227059e+001	           0.0	           0.0
 7.494598e+002	 6.257765e+000	 1.518758e+004	 6.007727e-001	 1.231080e+001	           0.0	           0.0
 7.518798e+002	 6.278022e+000	 1.518533e+004	 5.995321e-001	 1.235065e+001	           0.0	           0.0
 7.542798e+002	 6.299574e+000	 1.518316e+004	 6.014311e-001	 1.239305e+001	           0.0	           0.0
 7.567399e+002	 6.319317e+000	 1.517898e+004	 6.019748e-001	 1.243189e+001	           0.0	           0.0
 7.597399e+002	 6.343988e+000	 1.517298e+004	 6.023646e-001	 1.248042e+001	           0.0	           0.0
 7.627399e+002	 6.367719e+000	 1.516730e+004	 6.045551e-001	 1.252711e+001	           0.0	           0.0
 7.651799e+002	 6.388131e+000	 1.516355e+004	 6.029331e-001	 1.256726e+001	           0.0	           0.0
 7.675999e+002	 6.406615e+000	 1.516054e+004	 6.059542e-001	 1.260363e+001	           0.0	           0.0
 7.700198e+002	 6.425204e+000	 1.515387e+004	 6.050610e-001	 1.264020e+001	           0.0	           0.0
 7.724398e+002	 6.442441e+000	 1.514794e+004	 6.057141e-001	 1.267411e+001	           0.0	           0.0
 7.748599e+002	 6.460311e+000	 1.514152e+004	 6.066485e-001	 1.270926e+001	           0.0	           0.0
 7.777399e+002	 6.481970e+000	 1.512783e+004	 6.094565e-001	 1.275187e+001	           0.0	           0.0
 7.807399e+002	 6.501895e+000	 1.511815e+004	 6.090002e-001	 1.279107e+001	           0.0	           0.0
 7.833398e+002	 6.519774e+000	 1.510822e+004	 6.090552e-001	 1.282624e+001	           0.0	           0.0
 7.857598e+002	 6.541072e+000	 1.509804e+004	 6.083291e-001	 1.286814e+001	           0.0	           0.0
 7.881799e+002	 6.554371e+000	 1.508636e+004	 6.100395e-001	 1.289431e+001	           0.0	           0.0
 7.905999e+002	 6.568214e+000	 1.507467e+004	 6.090878e-001	 1.292154e+001	           0.0	           0.0
 7.930198e+002	 6.583689e+000	 1.506141e+004	 6.097215e-001	 1.295198e+001	           0.0	           0.0
 7.957399e+002	 6.600619e+000	 1.504497e+004	 6.092327e-001	 1.298529e+001	           0.0	           0.0
 7.987399e+002	 6.620660e+000	 1.502903e+004	 6.110393e-001	 1.302472e+001	           0.0	           0.0
 8.014998e+002	 6.639477e+000	 1.500900e+004	 6.092471e-001	 1.306173e+001	           0.0	           0.0
 8.039199e+002	 6.655457e+000	 1.498731e+004	 6.115337e-001	 1.309317e+001	           0.0	           0.0
 8.063398e+002	 6.668795e+000	 1.497028e+004	 6.109774e-001	 1.311941e+001	           0.0	           0.0
 8.087598e+002	 6.682191e+000	 1.494867e+004	 6.129587e-001	 1.314576e+001	           0.0	           0.0
 8.111799e+002	 6.697599e+000	 1.492722e+004	 6.116009e-001	 1.317608e+001	           0.0	           0.0
 8.137399e+002	 6.712896e+000	 1.490119e+004	 6.105228e-001	 1.320617e+001	           0.0	           0.0
 8.167399e+002	 6.731373e+000	 1.486514e+004	 6.126351e-001	 1.324252e+001	           0.0	           0.0
 8.196599e+002	 6.750583e+000	 1.482967e+004	 6.115279e-001	 1.328031e+001	           0.0	           0.0
 8.220798e+002	 6.765010e+000	 1.479646e+004	 6.107870e-001	 1.330869e+001	           0.0	           0.0
 8.244998e+002	 6.779142e+000	 1.476225e+004	 6.117452e-001	 1.333649e+001	           0.0	           0.0
 8.269199e+002	 6.793411e+000	 1.472353e+004	 6.128747e-001	 1.336457e+001	           0.0	           0.0
 8.293398e+002	 6.807639e+000	 1.468464e+004	 6.114001e-001	 1.339255e+001	           0.0	           0.0
 8.317598e+002	 6.821783e+000	 1.463365e+004	 6.106069e-001	 1.342038e+001	           0.0	           0.0
 8.347399e+002	 6.841316e+000	 1.453994e+004	 6.118705e-001	 1.345881e+001	           0.0	           0.0
 8.365999e+002	 6.859009e+000	 1.443104e+004	 6.072378e-001	 1.349362e+001	           0.0	           0.0