File: DP800 Tensile Tests/Fehlemann_Test_WP_KL_2024_1015.TRA
$Fehlemann_Test_WP_KL_2024_101.ZSE
Material:                               St
Auftrags-Nr.:                           WP_KL_2024_101
Probe:                                  2_90°_B
Vorkraft:                               100 N
Probengeometrie:                        H12,5x50
Messlänge:                              50.5077 mm
Probendicke a0:                         1.49 mm
Probenbreite b0:                        12.6 mm
Prüfgeschwindigkeit:                    1 mm/min
Datum:                                  26.09.2024
Maschinendaten:                         4204 WN:800315
Traversenwegaufnehmer WN:800315
Videoextensometer
Videoextensometer - Querdehnung
Kraftsensor ID:0 WN:800316 50 kN

Bemerkung:
$
      Prüfzeit	   Standardweg	 Spannung 	Breitenänderung	       Dehnung	 wahre Dehnung	wahre Spannung
 1.992187e-002	-2.915845e-004	 1.919320e+002	-4.345956e-005	-5.773065e-004	 0.000000e+000	 1.022434e+001
 2.399219e-001	-2.018007e-003	 1.927665e+002	-2.546959e-003	-3.995441e-003	 0.000000e+000	 1.026844e+001
 6.399219e-001	-1.539423e-003	 2.702895e+002	-1.199008e-003	-3.047895e-003	 0.000000e+000	 1.439813e+001
 9.799219e-001	 3.094307e-004	 3.650861e+002	-2.608356e-005	 6.126401e-004	 0.000000e+000	 1.944859e+001
 1.139922e+000	 1.685480e-003	 4.117334e+002	-1.888524e-003	 3.337073e-003	 0.000000e+000	 2.193415e+001
 2.079922e+000	 3.280738e-003	 6.862766e+002	 2.279153e-003	 6.495516e-003	 0.000000e+000	 3.656096e+001
 2.219922e+000	 4.979286e-003	 7.275833e+002	-1.758427e-003	 9.858462e-003	 0.000000e+000	 3.876285e+001
 2.639922e+000	 5.759706e-003	 8.506687e+002	-2.022524e-003	 1.140361e-002	 0.000000e+000	 4.532107e+001
 3.039922e+000	 6.063803e-003	 9.687473e+002	 3.641211e-004	 1.200569e-002	 0.000000e+000	 5.161225e+001
 3.219922e+000	 7.913318e-003	 1.024741e+003	-2.133615e-003	 1.566754e-002	 0.000000e+000	 5.459743e+001
 3.599922e+000	 9.997900e-003	 1.134308e+003	 1.364198e-003	 1.979479e-002	 0.000000e+000	 6.043757e+001
 3.919922e+000	 9.750061e-003	 1.229271e+003	 1.069282e-003	 1.930409e-002	 0.000000e+000	 6.549705e+001
 4.119922e+000	 1.061890e-002	 1.287685e+003	-3.384273e-004	 2.102430e-002	 0.000000e+000	 6.861057e+001
 4.199922e+000	 1.246845e-002	 1.310716e+003	-7.519434e-004	 2.468621e-002	 0.000000e+000	 6.984029e+001
 4.679922e+000	 1.417477e-002	 1.454246e+003	-3.492660e-004	 2.806455e-002	 0.000000e+000	 7.749078e+001
 5.279922e+000	 1.489509e-002	 1.630738e+003	-5.984273e-004	 2.949071e-002	 0.000000e+000	 8.689655e+001
 5.419922e+000	 1.661638e-002	 1.673130e+003	 1.952637e-003	 3.289869e-002	 4.297753e-006	 8.915849e+001
 5.919922e+000	 1.835790e-002	 1.815241e+003	 6.030243e-004	 3.634670e-002	 2.001837e-006	 9.673473e+001
 6.499922e+000	 2.005527e-002	 1.973876e+003	 6.255727e-004	 3.970733e-002	 0.000000e+000	 1.051919e+002
 6.719922e+000	 2.173651e-002	 2.034709e+003	 3.311073e-003	 4.303600e-002	 1.210019e-005	 1.084375e+002
 7.139922e+000	 2.320419e-002	 2.144693e+003	 1.695766e-003	 4.594185e-002	 1.269665e-005	 1.143023e+002
 7.879922e+000	 2.483665e-002	 2.334036e+003	 4.604637e-003	 4.917395e-002	 0.000000e+000	 1.243974e+002
 8.099922e+000	 2.671390e-002	 2.386859e+003	 1.093073e-003	 5.289071e-002	 1.951671e-005	 1.272174e+002
 8.779922e+000	 2.855654e-002	 2.548914e+003	 3.016573e-003	 5.653895e-002	 1.406192e-005	 1.358598e+002
 9.539922e+000	 3.030364e-002	 2.721568e+003	 2.106347e-003	 5.999802e-002	 3.972924e-006	 1.450674e+002
 1.023992e+001	 3.149309e-002	 2.868770e+003	 3.181604e-003	 6.235299e-002	 0.000000e+000	 1.529173e+002
 1.043992e+001	 3.348054e-002	 2.906989e+003	 3.106927e-003	 6.628795e-002	 1.888823e-005	 1.549606e+002
 1.107992e+001	 3.394667e-002	 3.031659e+003	 2.907282e-003	 6.721084e-002	 0.000000e+000	 1.616078e+002
 1.177992e+001	 3.565270e-002	 3.161671e+003	 3.184573e-003	 7.058860e-002	 0.000000e+000	 1.685440e+002
 1.235992e+001	 3.753234e-002	 3.260473e+003	 3.884760e-003	 7.431007e-002	 7.633658e-006	 1.738175e+002
 1.283992e+001	 3.801622e-002	 3.343754e+003	 3.095573e-003	 7.526811e-002	 0.000000e+000	 1.782589e+002
 1.331992e+001	 3.914100e-002	 3.426701e+003	 5.789411e-003	 7.749504e-002	 0.000000e+000	 1.826850e+002
 1.385992e+001	 4.085515e-002	 3.517242e+003	 3.764010e-003	 8.088889e-002	 6.974408e-006	 1.875183e+002
 1.475992e+001	 4.137661e-002	 3.663192e+003	 6.846476e-003	 8.192132e-002	 0.000000e+000	 1.953015e+002
 1.503992e+001	 4.298984e-002	 3.710257e+003	 5.437766e-003	 8.511534e-002	 0.000000e+000	 1.978170e+002
 1.613992e+001	 4.558945e-002	 3.884996e+003	 6.954024e-003	 9.026230e-002	 5.539881e-006	 2.071441e+002
 2.213992e+001	 5.736725e-002	 4.744258e+003	 8.009669e-003	 1.135811e-001	 1.636533e-005	 2.530180e+002
 2.813992e+001	 6.653693e-002	 5.491533e+003	 1.192419e-002	 1.317361e-001	 4.533333e-006	 2.929243e+002
 3.413992e+001	 7.816248e-002	 6.152439e+003	 9.227218e-003	 1.547535e-001	 6.367335e-005	 3.282532e+002
 4.013992e+001	 8.971303e-002	 6.738743e+003	 1.095686e-002	 1.776223e-001	 1.406286e-004	 3.596166e+002
 4.613992e+001	 1.044790e-001	 7.241600e+003	 1.137193e-002	 2.068574e-001	 3.028123e-004	 3.865646e+002
 5.099992e+001	 1.147076e-001	 7.606266e+003	 1.311857e-002	 2.271089e-001	 4.109189e-004	 4.061129e+002
 5.513992e+001	 1.262421e-001	 7.891574e+003	 1.198848e-002	 2.499461e-001	 5.653829e-004	 4.214421e+002
 6.099992e+001	 1.449592e-001	 8.261415e+003	 1.767757e-002	 2.870040e-001	 8.400603e-004	 4.413561e+002
 6.419992e+001	 1.549762e-001	 8.451258e+003	 1.648306e-002	 3.068365e-001	 9.891208e-004	 4.515875e+002
 6.995992e+001	 1.753040e-001	 8.772365e+003	 2.094090e-002	 3.470835e-001	 1.308127e-003	 4.689338e+002
 7.313992e+001	 1.887664e-001	 8.941765e+003	 2.174648e-002	 3.737376e-001	 1.530514e-003	 4.781161e+002
 7.699992e+001	 2.056418e-001	 9.135780e+003	 2.306057e-002	 4.071490e-001	 1.813946e-003	 4.886527e+002
 8.213992e+001	 2.247813e-001	 9.381117e+003	 2.755254e-002	 4.450432e-001	 2.128777e-003	 5.019646e+002
 8.513992e+001	 2.373361e-001	 9.520558e+003	 3.012486e-002	 4.699005e-001	 2.340791e-003	 5.095518e+002
 8.887992e+001	 2.559120e-001	 9.680527e+003	 3.078148e-002	 5.066787e-001	 2.666360e-003	 5.183032e+002
 9.295992e+001	 2.762497e-001	 9.856603e+003	 3.410741e-002	 5.469452e-001	 3.022445e-003	 5.279418e+002
 9.713992e+001	 2.960435e-001	 1.002667e+004	 3.744667e-002	 5.861349e-001	 3.369222e-003	 5.372603e+002
 1.001399e+002	 3.138101e-001	 1.013999e+004	 3.725951e-002	 6.213108e-001	 3.690519e-003	 5.435224e+002
 1.031399e+002	 3.304577e-001	 1.025265e+004	 4.145067e-002	 6.542715e-001	 3.989821e-003	 5.497409e+002
 1.063399e+002	 3.474092e-001	 1.036989e+004	 4.386757e-002	 6.878335e-001	 4.293839e-003	 5.562129e+002
 1.100599e+002	 3.675795e-001	 1.050090e+004	 4.614957e-002	 7.277686e-001	 4.657654e-003	 5.634634e+002
 1.135599e+002	 3.878748e-001	 1.062173e+004	 5.142757e-002	 7.679512e-001	 5.026421e-003	 5.701744e+002
 1.169199e+002	 4.080285e-001	 1.073239e+004	 5.194502e-002	 8.078534e-001	 5.394883e-003	 5.763423e+002
 1.203599e+002	 4.281269e-001	 1.084112e+004	 5.356282e-002	 8.476461e-001	 5.762614e-003	 5.824112e+002
 1.235999e+002	 4.483869e-001	 1.094067e+004	 5.786495e-002	 8.877588e-001	 6.135752e-003	 5.879932e+002
 1.269599e+002	 4.686400e-001	 1.104189e+004	 6.088399e-002	 9.278577e-001	 6.508185e-003	 5.936691e+002
 1.299999e+002	 4.887826e-001	 1.112543e+004	 6.210057e-002	 9.677380e-001	 6.882854e-003	 5.983965e+002
 1.331399e+002	 5.088034e-001	 1.121980e+004	 6.642731e-002	 1.007377e+000	 7.252202e-003	 6.037097e+002
 1.361399e+002	 5.283742e-001	 1.130100e+004	 6.886993e-002	 1.046125e+000	 7.615957e-003	 6.083118e+002
 1.391399e+002	 5.485925e-001	 1.138512e+004	 6.947986e-002	 1.086155e+000	 7.991547e-003	 6.130824e+002
 1.421399e+002	 5.672445e-001	 1.146230e+004	 7.270054e-002	 1.123084e+000	 8.338021e-003	 6.174644e+002
 1.451399e+002	 5.873995e-001	 1.153899e+004	 7.390989e-002	 1.162989e+000	 8.714004e-003	 6.218408e+002
 1.481399e+002	 6.090227e-001	 1.161276e+004	 7.657489e-002	 1.205801e+000	 9.119399e-003	 6.260810e+002
 1.511399e+002	 6.301158e-001	 1.168928e+004	 7.815309e-002	 1.247563e+000	 9.513530e-003	 6.304666e+002
 1.541399e+002	 6.485182e-001	 1.176080e+004	 8.000296e-002	 1.283998e+000	 9.856038e-003	 6.345520e+002
 1.571399e+002	 6.684665e-001	 1.182764e+004	 8.409528e-002	 1.323493e+000	 1.022992e-002	 6.384072e+002
 1.601399e+002	 6.896150e-001	 1.189548e+004	 8.689180e-002	 1.365365e+000	 1.062692e-002	 6.423344e+002
 1.631399e+002	 7.093931e-001	 1.196116e+004	 8.941038e-002	 1.404524e+000	 1.099748e-002	 6.461302e+002
 1.661399e+002	 7.300165e-001	 1.202833e+004	 9.058367e-002	 1.445356e+000	 1.138407e-002	 6.500205e+002
 1.691399e+002	 7.510431e-001	 1.209175e+004	 9.252103e-002	 1.486986e+000	 1.177936e-002	 6.537159e+002
 1.719199e+002	 7.726547e-001	 1.214825e+004	 9.601215e-002	 1.529775e+000	 1.218770e-002	 6.570471e+002
 1.748399e+002	 7.928698e-001	 1.220799e+004	 9.723357e-002	 1.569799e+000	 1.256775e-002	 6.605388e+002
 1.777799e+002	 8.131912e-001	 1.226591e+004	 9.944057e-002	 1.610033e+000	 1.295019e-002	 6.639352e+002
 1.805399e+002	 8.335111e-001	 1.231723e+004	 1.006097e-001	 1.650264e+000	 1.333414e-002	 6.669771e+002
 1.833199e+002	 8.539448e-001	 1.237063e+004	 1.025646e-001	 1.690721e+000	 1.371964e-002	 6.701356e+002
 1.858199e+002	 8.740197e-001	 1.241786e+004	 1.038358e-001	 1.730467e+000	 1.409956e-002	 6.729571e+002
 1.886799e+002	 8.944182e-001	 1.246944e+004	 1.084791e-001	 1.770854e+000	 1.448454e-002	 6.760201e+002
 1.914999e+002	 9.148631e-001	 1.252151e+004	 1.091946e-001	 1.811332e+000	 1.487015e-002	 6.791131e+002
 1.942599e+002	 9.352936e-001	 1.256582e+004	 1.120399e-001	 1.851783e+000	 1.525731e-002	 6.817870e+002
 1.969599e+002	 9.554253e-001	 1.261831e+004	 1.147270e-001	 1.891641e+000	 1.563641e-002	 6.849028e+002
 1.997399e+002	 9.757380e-001	 1.266070e+004	 1.163997e-001	 1.931858e+000	 1.602146e-002	 6.874750e+002
 2.021599e+002	 9.957966e-001	 1.269975e+004	 1.169936e-001	 1.971572e+000	 1.640227e-002	 6.898642e+002
 2.042999e+002	 1.011394e+000	 1.273547e+004	 1.205917e-001	 2.002454e+000	 1.669693e-002	 6.920138e+002
 2.067199e+002	 1.029151e+000	 1.277510e+004	 1.216956e-001	 2.037610e+000	 1.703253e-002	 6.944069e+002
 2.091399e+002	 1.048215e+000	 1.281332e+004	 1.231641e-001	 2.075355e+000	 1.739381e-002	 6.967419e+002
 2.115599e+002	 1.066520e+000	 1.284987e+004	 1.265476e-001	 2.111597e+000	 1.774063e-002	 6.989774e+002
 2.141399e+002	 1.085559e+000	 1.288934e+004	 1.274612e-001	 2.149293e+000	 1.810086e-002	 7.013833e+002
 2.171399e+002	 1.108206e+000	 1.293608e+004	 1.309953e-001	 2.194130e+000	 1.852922e-002	 7.042351e+002
 2.200199e+002	 1.130890e+000	 1.297888e+004	 1.328205e-001	 2.239042e+000	 1.895913e-002	 7.068761e+002
 2.224399e+002	 1.150815e+000	 1.301276e+004	 1.346886e-001	 2.278492e+000	 1.933754e-002	 7.089948e+002
 2.248599e+002	 1.169299e+000	 1.304831e+004	 1.366649e-001	 2.315089e+000	 1.968742e-002	 7.111860e+002
 2.272799e+002	 1.188091e+000	 1.308203e+004	 1.375626e-001	 2.352295e+000	 2.004361e-002	 7.132827e+002
 2.297199e+002	 1.208102e+000	 1.311340e+004	 1.394816e-001	 2.391915e+000	 2.042391e-002	 7.152702e+002
 2.333599e+002	 1.236565e+000	 1.316472e+004	 1.439084e-001	 2.448268e+000	 2.096289e-002	 7.184646e+002
 2.357799e+002	 1.254424e+000	 1.319735e+004	 1.452936e-001	 2.483628e+000	 2.130083e-002	 7.204939e+002
 2.381999e+002	 1.274250e+000	 1.322823e+004	 1.455214e-001	 2.522881e+000	 2.167720e-002	 7.224561e+002
 2.411399e+002	 1.299203e+000	 1.326319e+004	 1.487997e-001	 2.572286e+000	 2.215168e-002	 7.247147e+002
 2.441399e+002	 1.319942e+000	 1.329966e+004	 1.512281e-001	 2.613346e+000	 2.254398e-002	 7.269982e+002
 2.466799e+002	 1.342731e+000	 1.333579e+004	 1.527406e-001	 2.658467e+000	 2.297590e-002	 7.292938e+002
 2.490999e+002	 1.362766e+000	 1.336683e+004	 1.552535e-001	 2.698133e+000	 2.335563e-002	 7.312738e+002
 2.514999e+002	 1.382922e+000	 1.339562e+004	 1.569876e-001	 2.738040e+000	 2.373814e-002	 7.331336e+002
 2.539199e+002	 1.403391e+000	 1.342441e+004	 1.597786e-001	 2.778567e+000	 2.412655e-002	 7.349990e+002
 2.563199e+002	 1.423975e+000	 1.345337e+004	 1.614661e-001	 2.819321e+000	 2.451698e-002	 7.368765e+002
 2.591399e+002	 1.448136e+000	 1.348199e+004	 1.633931e-001	 2.867156e+000	 2.497641e-002	 7.387877e+002
 2.621399e+002	 1.473609e+000	 1.351929e+004	 1.660693e-001	 2.917590e+000	 2.545878e-002	 7.411949e+002
 2.647799e+002	 1.495987e+000	 1.354825e+004	 1.676166e-001	 2.961897e+000	 2.588331e-002	 7.431022e+002
 2.671999e+002	 1.517215e+000	 1.357287e+004	 1.714305e-001	 3.003926e+000	 2.628658e-002	 7.447563e+002
 2.696199e+002	 1.537731e+000	 1.359915e+004	 1.727146e-001	 3.044546e+000	 2.667554e-002	 7.464928e+002
 2.720399e+002	 1.560251e+000	 1.362636e+004	 1.740880e-001	 3.089132e+000	 2.710272e-002	 7.483097e+002
 2.744399e+002	 1.580071e+000	 1.365181e+004	 1.756959e-001	 3.128374e+000	 2.747816e-002	 7.499928e+002
 2.771399e+002	 1.603245e+000	 1.367943e+004	 1.770449e-001	 3.174256e+000	 2.791750e-002	 7.518445e+002
 2.801399e+002	 1.627699e+000	 1.371080e+004	 1.808970e-001	 3.222672e+000	 2.838033e-002	 7.539226e+002
 2.829399e+002	 1.653522e+000	 1.373726e+004	 1.823646e-001	 3.273800e+000	 2.887052e-002	 7.557513e+002
 2.853599e+002	 1.674851e+000	 1.376129e+004	 1.836859e-001	 3.316029e+000	 2.927467e-002	 7.573830e+002
 2.877799e+002	 1.695224e+000	 1.378315e+004	 1.877746e-001	 3.356366e+000	 2.966083e-002	 7.588824e+002
 2.901999e+002	 1.715957e+000	 1.380702e+004	 1.886404e-001	 3.397415e+000	 3.005325e-002	 7.604984e+002
 2.926199e+002	 1.736689e+000	 1.383005e+004	 1.902626e-001	 3.438460e+000	 3.044570e-002	 7.620693e+002
 2.951399e+002	 1.759040e+000	 1.385458e+004	 1.933123e-001	 3.482713e+000	 3.086870e-002	 7.637478e+002
 2.981399e+002	 1.784630e+000	 1.387920e+004	 1.957550e-001	 3.533379e+000	 3.135367e-002	 7.654794e+002
 3.010799e+002	 1.811518e+000	 1.390816e+004	 1.987754e-001	 3.586615e+000	 3.186220e-002	 7.674708e+002
 3.035199e+002	 1.832266e+000	 1.392885e+004	 2.010264e-001	 3.627693e+000	 3.225484e-002	 7.689175e+002
 3.059399e+002	 1.855437e+000	 1.394955e+004	 1.989206e-001	 3.673570e+000	 3.269377e-002	 7.704008e+002
 3.095599e+002	 1.885729e+000	 1.398184e+004	 2.042946e-001	 3.733545e+000	 3.326598e-002	 7.726310e+002
 3.119799e+002	 1.905192e+000	 1.400321e+004	 2.083861e-001	 3.772079e+000	 3.363329e-002	 7.740989e+002
 3.143999e+002	 1.928784e+000	 1.402257e+004	 2.114278e-001	 3.818788e+000	 3.407999e-002	 7.755181e+002
 3.168199e+002	 1.951952e+000	 1.404368e+004	 2.116192e-001	 3.864660e+000	 3.451796e-002	 7.770288e+002
 3.192599e+002	 1.973396e+000	 1.405995e+004	 2.139502e-001	 3.907116e+000	 3.492397e-002	 7.782471e+002
 3.221399e+002	 1.999097e+000	 1.408674e+004	 2.177162e-001	 3.958000e+000	 3.540853e-002	 7.801116e+002
 3.251399e+002	 2.026892e+000	 1.410868e+004	 2.200470e-001	 4.013033e+000	 3.593410e-002	 7.817405e+002
 3.277199e+002	 2.048856e+000	 1.413130e+004	 2.228196e-001	 4.056520e+000	 3.634788e-002	 7.833209e+002
 3.301399e+002	 2.072448e+000	 1.414765e+004	 2.241730e-001	 4.103228e+000	 3.679411e-002	 7.845795e+002
 3.325599e+002	 2.092257e+000	 1.416651e+004	 2.272416e-001	 4.142447e+000	 3.716736e-002	 7.859213e+002
 3.349799e+002	 2.114115e+000	 1.418462e+004	 2.296333e-001	 4.185726e+000	 3.757976e-002	 7.872529e+002
 3.373999e+002	 2.134441e+000	 1.419864e+004	 2.323353e-001	 4.225968e+000	 3.796377e-002	 7.883353e+002
 3.401399e+002	 2.159961e+000	 1.421992e+004	 2.360218e-001	 4.276494e+000	 3.844479e-002	 7.898995e+002
 3.431399e+002	 2.186777e+000	 1.424078e+004	 2.393839e-001	 4.329588e+000	 3.895038e-002	 7.914611e+002
 3.458799e+002	 2.211864e+000	 1.426056e+004	 2.410426e-001	 4.379258e+000	 3.942308e-002	 7.929375e+002
 3.482999e+002	 2.231859e+000	 1.427800e+004	 2.435632e-001	 4.418846e+000	 3.979924e-002	 7.942084e+002
 3.506999e+002	 2.255371e+000	 1.429577e+004	 2.442514e-001	 4.465397e+000	 4.024207e-002	 7.955515e+002
 3.531199e+002	 2.278773e+000	 1.431305e+004	 2.489416e-001	 4.511729e+000	 4.068273e-002	 7.968660e+002
 3.555399e+002	 2.301681e+000	 1.432957e+004	 2.497302e-001	 4.557085e+000	 4.111401e-002	 7.981321e+002
 3.581399e+002	 2.326055e+000	 1.434376e+004	 2.540917e-001	 4.605344e+000	 4.157353e-002	 7.992910e+002
 3.611399e+002	 2.353439e+000	 1.436353e+004	 2.541711e-001	 4.659561e+000	 4.208857e-002	 8.008078e+002
 3.639999e+002	 2.379086e+000	 1.438231e+004	 2.579116e-001	 4.710339e+000	 4.257065e-002	 8.022436e+002
 3.664199e+002	 2.401832e+000	 1.439800e+004	 2.600014e-001	 4.755374e+000	 4.299825e-002	 8.034640e+002
 3.688399e+002	 2.423903e+000	 1.441277e+004	 2.620946e-001	 4.799073e+000	 4.341310e-002	 8.046238e+002
 3.712599e+002	 2.448075e+000	 1.442795e+004	 2.646620e-001	 4.846931e+000	 4.386748e-002	 8.058394e+002
 3.736799e+002	 2.469123e+000	 1.444114e+004	 2.668268e-001	 4.888604e+000	 4.426298e-002	 8.068964e+002
 3.761399e+002	 2.493716e+000	 1.445699e+004	 2.683134e-001	 4.937294e+000	 4.472477e-002	 8.081572e+002
 3.791399e+002	 2.521799e+000	 1.447226e+004	 2.707745e-001	 4.992896e+000	 4.525255e-002	 8.094395e+002
 3.821399e+002	 2.549305e+000	 1.448695e+004	 2.740588e-001	 5.047356e+000	 4.576929e-002	 8.106812e+002
 3.845799e+002	 2.574548e+000	 1.450181e+004	 2.773846e-001	 5.097334e+000	 4.624292e-002	 8.118984e+002
 3.869999e+002	 2.597131e+000	 1.451825e+004	 2.791086e-001	 5.142045e+000	 4.666568e-002	 8.131646e+002
 3.893999e+002	 2.619865e+000	 1.453185e+004	 2.809068e-001	 5.187057e+000	 4.709183e-002	 8.142748e+002
 3.918199e+002	 2.643062e+000	 1.454470e+004	 2.858519e-001	 5.232983e+000	 4.752670e-002	 8.153507e+002
 3.942399e+002	 2.664676e+000	 1.455646e+004	 2.878966e-001	 5.275777e+000	 4.793179e-002	 8.163421e+002
 3.971399e+002	 2.693812e+000	 1.457015e+004	 2.896145e-001	 5.333463e+000	 4.847812e-002	 8.175573e+002
 4.001399e+002	 2.721177e+000	 1.458751e+004	 2.924516e-001	 5.387644e+000	 4.898988e-002	 8.189522e+002
 4.026999e+002	 2.746811e+000	 1.459835e+004	 2.947204e-001	 5.438396e+000	 4.947035e-002	 8.199559e+002
 4.050999e+002	 2.769196e+000	 1.461087e+004	 2.969356e-001	 5.482716e+000	 4.988899e-002	 8.210039e+002
 4.075199e+002	 2.792134e+000	 1.462222e+004	 2.976024e-001	 5.528131e+000	 5.031815e-002	 8.219953e+002
 4.099399e+002	 2.815911e+000	 1.463357e+004	 2.969246e-001	 5.575206e+000	 5.076291e-002	 8.230002e+002
 4.123599e+002	 2.839639e+000	 1.464584e+004	 3.017766e-001	 5.622186e+000	 5.120634e-002	 8.240566e+002
 4.151399e+002	 2.865931e+000	 1.466152e+004	 3.055899e-001	 5.674240e+000	 5.169692e-002	 8.253458e+002
 4.181399e+002	 2.894732e+000	 1.467471e+004	 3.084629e-001	 5.731265e+000	 5.223505e-002	 8.265337e+002
 4.208199e+002	 2.922196e+000	 1.468389e+004	 3.102661e-001	 5.785641e+000	 5.274875e-002	 8.274761e+002
 4.232399e+002	 2.945192e+000	 1.469415e+004	 3.135870e-001	 5.831170e+000	 5.317803e-002	 8.284108e+002
 4.256599e+002	 2.968997e+000	 1.470533e+004	 3.143966e-001	 5.878301e+000	 5.362210e-002	 8.294104e+002
 4.280799e+002	 2.992759e+000	 1.471718e+004	 3.156669e-001	 5.925347e+000	 5.406499e-002	 8.304476e+002
 4.304999e+002	 3.016263e+000	 1.472887e+004	 3.193616e-001	 5.971883e+000	 5.450289e-002	 8.314719e+002
 4.331399e+002	 3.040767e+000	 1.473971e+004	 3.211788e-001	 6.020397e+000	 5.495954e-002	 8.324651e+002
 4.361399e+002	 3.071089e+000	 1.475081e+004	 3.236460e-001	 6.080432e+000	 5.552491e-002	 8.335637e+002
 4.389799e+002	 3.098615e+000	 1.476250e+004	 3.265856e-001	 6.134931e+000	 5.603747e-002	 8.346524e+002
 4.413799e+002	 3.122643e+000	 1.477359e+004	 3.288026e-001	 6.182504e+000	 5.648446e-002	 8.356542e+002
 4.438199e+002	 3.145011e+000	 1.478219e+004	 3.300179e-001	 6.226791e+000	 5.690081e-002	 8.364891e+002
 4.462399e+002	 3.168615e+000	 1.479254e+004	 3.328499e-001	 6.273524e+000	 5.733967e-002	 8.374429e+002
 4.486599e+002	 3.193208e+000	 1.480138e+004	 3.349976e-001	 6.322216e+000	 5.779719e-002	 8.383275e+002
 4.511399e+002	 3.215812e+000	 1.481390e+004	 3.370434e-001	 6.366969e+000	 5.821644e-002	 8.393896e+002
 4.541399e+002	 3.244577e+000	 1.482592e+004	 3.398211e-001	 6.423920e+000	 5.875067e-002	 8.405203e+002
 4.571199e+002	 3.273031e+000	 1.483944e+004	 3.428226e-001	 6.480255e+000	 5.927844e-002	 8.417320e+002
 4.595399e+002	 3.296326e+000	 1.484711e+004	 3.445206e-001	 6.526378e+000	 5.971116e-002	 8.425322e+002
 4.619599e+002	 3.319325e+000	 1.485412e+004	 3.454052e-001	 6.571913e+000	 6.013831e-002	 8.432902e+002
 4.643599e+002	 3.343260e+000	 1.486664e+004	 3.491993e-001	 6.619302e+000	 6.058140e-002	 8.443761e+002
 4.667799e+002	 3.365622e+000	 1.487064e+004	 3.516166e-001	 6.663577e+000	 6.099706e-002	 8.449543e+002
 4.691999e+002	 3.388026e+000	 1.488216e+004	 3.540703e-001	 6.707934e+000	 6.141149e-002	 8.459602e+002
 4.721399e+002	 3.416983e+000	 1.489418e+004	 3.555166e-001	 6.765266e+000	 6.194759e-002	 8.470981e+002
 4.751399e+002	 3.448841e+000	 1.490503e+004	 3.576495e-001	 6.828341e+000	 6.253764e-002	 8.482159e+002
 4.776599e+002	 3.472637e+000	 1.491204e+004	 3.611022e-001	 6.875456e+000	 6.297843e-002	 8.489890e+002
 4.800799e+002	 3.494324e+000	 1.491888e+004	 3.631154e-001	 6.918393e+000	 6.337984e-002	 8.497198e+002
 4.824999e+002	 3.518575e+000	 1.492614e+004	 3.660226e-001	 6.966407e+000	 6.382864e-002	 8.505151e+002
 4.849199e+002	 3.542843e+000	 1.493390e+004	 3.699871e-001	 7.014456e+000	 6.427743e-002	 8.513395e+002
 4.873399e+002	 3.567773e+000	 1.493932e+004	 3.720356e-001	 7.063814e+000	 6.473886e-002	 8.520414e+002
 4.901399e+002	 3.595390e+000	 1.495092e+004	 3.744480e-001	 7.118494e+000	 6.524844e-002	 8.531385e+002
 4.931399e+002	 3.625368e+000	 1.495910e+004	 3.761805e-001	 7.177846e+000	 6.580233e-002	 8.540780e+002
 4.957799e+002	 3.651806e+000	 1.496953e+004	 3.796286e-001	 7.230191e+000	 6.628980e-002	 8.550909e+002
 4.981999e+002	 3.674321e+000	 1.497445e+004	 3.804746e-001	 7.274769e+000	 6.670571e-002	 8.557277e+002
 5.006199e+002	 3.700624e+000	 1.498372e+004	 3.832426e-001	 7.326845e+000	 6.719050e-002	 8.566727e+002
 5.030399e+002	 3.722688e+000	 1.499206e+004	 3.855611e-001	 7.370531e+000	 6.759687e-002	 8.574986e+002
 5.054799e+002	 3.747947e+000	 1.499431e+004	 3.855902e-001	 7.420539e+000	 6.806361e-002	 8.580269e+002
 5.081399e+002	 3.773376e+000	 1.500199e+004	 3.888267e-001	 7.470886e+000	 6.853199e-002	 8.588685e+002
 5.111399e+002	 3.803669e+000	 1.501125e+004	 3.913844e-001	 7.530864e+000	 6.908965e-002	 8.598784e+002
 5.139399e+002	 3.831174e+000	 1.502068e+004	 3.937479e-001	 7.585321e+000	 6.959546e-002	 8.608542e+002
 5.163599e+002	 3.857227e+000	 1.502744e+004	 3.977543e-001	 7.636902e+000	 7.007485e-002	 8.616545e+002
 5.187799e+002	 3.879800e+000	 1.503370e+004	 3.995696e-001	 7.681595e+000	 7.048993e-002	 8.623712e+002
 5.212000e+002	 3.904445e+000	 1.503879e+004	 4.023834e-001	 7.730389e+000	 7.094334e-002	 8.630541e+002
 5.236199e+002	 3.929366e+000	 1.504639e+004	 4.036016e-001	 7.779731e+000	 7.140102e-002	 8.638853e+002
 5.261399e+002	 3.953359e+000	 1.505206e+004	 4.057615e-001	 7.827235e+000	 7.184186e-002	 8.645920e+002
 5.291399e+002	 3.983656e+000	 1.506007e+004	 4.101546e-001	 7.887219e+000	 7.239804e-002	 8.655333e+002
 5.320799e+002	 4.015449e+000	 1.506691e+004	 4.102216e-001	 7.950165e+000	 7.298172e-002	 8.664318e+002
 5.344799e+002	 4.039967e+000	 1.507401e+004	 4.139705e-001	 7.998709e+000	 7.343119e-002	 8.672294e+002
 5.368999e+002	 4.063172e+000	 1.507951e+004	 4.164579e-001	 8.044653e+000	 7.385668e-002	 8.679153e+002
 5.393199e+002	 4.088207e+000	 1.508486e+004	 4.188091e-001	 8.094218e+000	 7.431566e-002	 8.686210e+002
 5.417399e+002	 4.112906e+000	 1.509053e+004	 4.201989e-001	 8.143121e+000	 7.476820e-002	 8.693408e+002
 5.441599e+002	 4.137219e+000	 1.509545e+004	 4.212656e-001	 8.191257e+000	 7.521360e-002	 8.700115e+002
 5.471399e+002	 4.167089e+000	 1.510146e+004	 4.231685e-001	 8.250398e+000	 7.576056e-002	 8.708334e+002
 5.501399e+002	 4.197851e+000	 1.510605e+004	 4.261411e-001	 8.311302e+000	 7.632391e-002	 8.715882e+002
 5.526399e+002	 4.220853e+000	 1.511356e+004	 4.287356e-001	 8.356845e+000	 7.674398e-002	 8.723881e+002
 5.550599e+002	 4.247072e+000	 1.511790e+004	 4.303156e-001	 8.408755e+000	 7.722358e-002	 8.730566e+002
 5.574799e+002	 4.272554e+000	 1.512416e+004	 4.315329e-001	 8.459206e+000	 7.768899e-002	 8.738245e+002
 5.598999e+002	 4.294990e+000	 1.512950e+004	 4.338745e-001	 8.503627e+000	 7.809863e-002	 8.744910e+002
 5.623199e+002	 4.318952e+000	 1.513559e+004	 4.360055e-001	 8.551070e+000	 7.853586e-002	 8.752256e+002
 5.651399e+002	 4.348990e+000	 1.513651e+004	 4.384212e-001	 8.610542e+000	 7.908529e-002	 8.757581e+002
 5.681399e+002	 4.378844e+000	 1.514402e+004	 4.427147e-001	 8.669649e+000	 7.962948e-002	 8.766695e+002
 5.708199e+002	 4.405968e+000	 1.515036e+004	 4.447486e-001	 8.723352e+000	 8.012376e-002	 8.774700e+002
 5.732399e+002	 4.427981e+000	 1.515487e+004	 4.479745e-001	 8.766935e+000	 8.052488e-002	 8.780828e+002
 5.756599e+002	 4.453692e+000	 1.515904e+004	 4.487596e-001	 8.817841e+000	 8.099345e-002	 8.787356e+002
 5.780599e+002	 4.478231e+000	 1.516438e+004	 4.500366e-001	 8.866425e+000	 8.144012e-002	 8.794376e+002
 5.804599e+002	 4.500421e+000	 1.516864e+004	 4.539256e-001	 8.910359e+000	 8.184400e-002	 8.800394e+002
 5.831399e+002	 4.528561e+000	 1.517239e+004	 4.562080e-001	 8.966073e+000	 8.235633e-002	 8.807075e+002
 5.861399e+002	 4.558622e+000	 1.517932e+004	 4.563431e-001	 9.025592e+000	 8.290266e-002	 8.815908e+002
 5.889199e+002	 4.586187e+000	 1.518132e+004	 4.609955e-001	 9.080166e+000	 8.340439e-002	 8.821484e+002
 5.913399e+002	 4.610821e+000	 1.518508e+004	 4.622406e-001	 9.128940e+000	 8.385210e-002	 8.827611e+002
 5.937599e+002	 4.636405e+000	 1.518950e+004	 4.651712e-001	 9.179592e+000	 8.431672e-002	 8.834280e+002
 5.961799e+002	 4.661286e+000	 1.519442e+004	 4.683407e-001	 9.228855e+000	 8.476824e-002	 8.841130e+002
 5.985799e+002	 4.684156e+000	 1.520001e+004	 4.702300e-001	 9.274135e+000	 8.518282e-002	 8.848050e+002
 6.011399e+002	 4.709547e+000	 1.520452e+004	 4.715753e-001	 9.324407e+000	 8.564331e-002	 8.854744e+002
 6.041399e+002	 4.739866e+000	 1.520744e+004	 4.759010e-001	 9.384435e+000	 8.619349e-002	 8.861307e+002
 6.070599e+002	 4.769262e+000	 1.521061e+004	 4.761926e-001	 9.442637e+000	 8.672654e-002	 8.867871e+002
 6.094799e+002	 4.793178e+000	 1.521353e+004	 4.791827e-001	 9.489987e+000	 8.715992e-002	 8.873411e+002
 6.118999e+002	 4.819578e+000	 1.521762e+004	 4.803905e-001	 9.542257e+000	 8.763790e-002	 8.880032e+002
 6.143199e+002	 4.843792e+000	 1.521954e+004	 4.835246e-001	 9.590197e+000	 8.807654e-002	 8.885039e+002
 6.167399e+002	 4.868843e+000	 1.522396e+004	 4.856190e-001	 9.639796e+000	 8.852955e-002	 8.891643e+002
 6.191599e+002	 4.891401e+000	 1.522838e+004	 4.863966e-001	 9.684459e+000	 8.893721e-002	 8.897848e+002
 6.221399e+002	 4.921095e+000	 1.523089e+004	 4.902627e-001	 9.743250e+000	 8.947436e-002	 8.904081e+002
 6.251399e+002	 4.950238e+000	 1.523623e+004	 4.933927e-001	 9.800950e+000	 9.000057e-002	 8.911886e+002
 6.276399e+002	 4.977506e+000	 1.523832e+004	 4.941825e-001	 9.854937e+000	 9.049336e-002	 8.917488e+002
 6.300599e+002	 5.001561e+000	 1.524074e+004	 4.973336e-001	 9.902563e+000	 9.092775e-002	 8.922770e+002
 6.324799e+002	 5.026511e+000	 1.524499e+004	 4.988637e-001	 9.951961e+000	 9.137769e-002	 8.929273e+002
 6.348999e+002	 5.051195e+000	 1.524624e+004	 5.005836e-001	 1.000083e+001	 9.182333e-002	 8.933975e+002
 6.373199e+002	 5.076271e+000	 1.525092e+004	 5.032406e-001	 1.005048e+001	 9.227505e-002	 8.940747e+002
 6.401399e+002	 5.105205e+000	 1.525292e+004	 5.065187e-001	 1.010777e+001	 9.279681e-002	 8.946575e+002
 6.431399e+002	 5.135187e+000	 1.525742e+004	 5.080318e-001	 1.016713e+001	 9.333660e-002	 8.954042e+002
 6.457599e+002	 5.162829e+000	 1.526160e+004	 5.097752e-001	 1.022186e+001	 9.383402e-002	 8.960940e+002
 6.482000e+002	 5.187313e+000	 1.526051e+004	 5.117511e-001	 1.027033e+001	 9.427551e-002	 8.964243e+002
 6.506199e+002	 5.212584e+000	 1.526310e+004	 5.144186e-001	 1.032037e+001	 9.473013e-002	 8.969831e+002
 6.530399e+002	 5.235062e+000	 1.526502e+004	 5.189506e-001	 1.036487e+001	 9.513441e-002	 8.974577e+002
 6.554599e+002	 5.260769e+000	 1.526836e+004	 5.190368e-001	 1.041577e+001	 9.559629e-002	 8.980679e+002
 6.581399e+002	 5.287126e+000	 1.527520e+004	 5.202346e-001	 1.046795e+001	 9.606884e-002	 8.988950e+002
 6.611399e+002	 5.319371e+000	 1.527445e+004	 5.220974e-001	 1.053179e+001	 9.664878e-002	 8.993702e+002
 6.639199e+002	 5.348994e+000	 1.528021e+004	 5.270441e-001	 1.059044e+001	 9.717976e-002	 9.001866e+002
 6.663399e+002	 5.374273e+000	 1.528254e+004	 5.283425e-001	 1.064049e+001	 9.763327e-002	 9.007317e+002
 6.687599e+002	 5.399292e+000	 1.528196e+004	 5.292553e-001	 1.069003e+001	 9.808256e-002	 9.011004e+002
 6.711799e+002	 5.423724e+000	 1.528354e+004	 5.311922e-001	 1.073840e+001	 9.852063e-002	 9.015877e+002
 6.735799e+002	 5.449688e+000	 1.528755e+004	 5.333350e-001	 1.078981e+001	 9.898542e-002	 9.022426e+002
 6.761399e+002	 5.474339e+000	 1.528805e+004	 5.367005e-001	 1.083861e+001	 9.942727e-002	 9.026696e+002
 6.791399e+002	 5.506067e+000	 1.528947e+004	 5.371515e-001	 1.090143e+001	 9.999551e-002	 9.032649e+002
 6.820399e+002	 5.533539e+000	 1.529756e+004	 5.397337e-001	 1.095582e+001	 1.004856e-001	 9.041863e+002
 6.844599e+002	 5.560296e+000	 1.529856e+004	 5.419344e-001	 1.100880e+001	 1.009644e-001	 9.046772e+002
 6.868799e+002	 5.585942e+000	 1.529806e+004	 5.435920e-001	 1.105958e+001	 1.014234e-001	 9.050614e+002
 6.892999e+002	 5.611037e+000	 1.529614e+004	 5.436130e-001	 1.110926e+001	 1.018727e-001	 9.053526e+002
 6.917199e+002	 5.635271e+000	 1.529890e+004	 5.453224e-001	 1.115724e+001	 1.023053e-001	 9.059066e+002
 6.953399e+002	 5.671723e+000	 1.530340e+004	 5.482901e-001	 1.122941e+001	 1.029556e-001	 9.067617e+002
 6.977599e+002	 5.698171e+000	 1.530432e+004	 5.510710e-001	 1.128178e+001	 1.034277e-001	 9.072430e+002
 7.001799e+002	 5.721652e+000	 1.530516e+004	 5.529377e-001	 1.132827e+001	 1.038466e-001	 9.076714e+002
 7.031399e+002	 5.752109e+000	 1.530741e+004	 5.549647e-001	 1.138857e+001	 1.043895e-001	 9.082967e+002
 7.061399e+002	 5.783118e+000	 1.530691e+004	 5.558601e-001	 1.144996e+001	 1.049425e-001	 9.087676e+002
 7.086599e+002	 5.809935e+000	 1.530791e+004	 5.576110e-001	 1.150306e+001	 1.054202e-001	 9.092600e+002
 7.110799e+002	 5.832843e+000	 1.531050e+004	 5.589709e-001	 1.154841e+001	 1.058277e-001	 9.097835e+002
 7.134999e+002	 5.856799e+000	 1.531175e+004	 5.610576e-001	 1.159584e+001	 1.062540e-001	 9.102447e+002
 7.159199e+002	 5.882171e+000	 1.531283e+004	 5.644259e-001	 1.164608e+001	 1.067053e-001	 9.107189e+002
 7.183399e+002	 5.906700e+000	 1.531417e+004	 5.657212e-001	 1.169464e+001	 1.071414e-001	 9.111945e+002
 7.211399e+002	 5.937103e+000	 1.531409e+004	 5.684782e-001	 1.175484e+001	 1.076821e-001	 9.116805e+002
 7.241399e+002	 5.968888e+000	 1.531601e+004	 5.684649e-001	 1.181777e+001	 1.082466e-001	 9.123082e+002
 7.267999e+002	 5.996784e+000	 1.531500e+004	 5.692933e-001	 1.187300e+001	 1.087423e-001	 9.126991e+002
 7.292199e+002	 6.020420e+000	 1.531492e+004	 5.715549e-001	 1.191980e+001	 1.091620e-001	 9.130759e+002
 7.316399e+002	 6.043943e+000	 1.531726e+004	 5.738502e-001	 1.196637e+001	 1.095789e-001	 9.135951e+002
 7.340599e+002	 6.069251e+000	 1.531726e+004	 5.745808e-001	 1.201648e+001	 1.100279e-001	 9.140040e+002
 7.364799e+002	 6.093152e+000	 1.532018e+004	 5.762569e-001	 1.206380e+001	 1.104510e-001	 9.145644e+002
 7.391399e+002	 6.121378e+000	 1.532018e+004	 5.775427e-001	 1.211968e+001	 1.109513e-001	 9.150204e+002
 7.421399e+002	 6.152471e+000	 1.532143e+004	 5.783283e-001	 1.218124e+001	 1.115018e-001	 9.155976e+002
 7.449599e+002	 6.180702e+000	 1.532235e+004	 5.807803e-001	 1.223714e+001	 1.120015e-001	 9.161086e+002
 7.473799e+002	 6.207105e+000	 1.532235e+004	 5.835159e-001	 1.228941e+001	 1.124687e-001	 9.165353e+002
 7.497999e+002	 6.231737e+000	 1.532151e+004	 5.853493e-001	 1.233818e+001	 1.129046e-001	 9.168833e+002
 7.522199e+002	 6.256438e+000	 1.532018e+004	 5.853332e-001	 1.238709e+001	 1.133417e-001	 9.172025e+002
 7.546399e+002	 6.280107e+000	 1.532043e+004	 5.865334e-001	 1.243395e+001	 1.137599e-001	 9.175999e+002
 7.571399e+002	 6.307234e+000	 1.532327e+004	 5.873464e-001	 1.248766e+001	 1.142385e-001	 9.182083e+002
 7.601399e+002	 6.338775e+000	 1.532143e+004	 5.898308e-001	 1.255011e+001	 1.147958e-001	 9.186079e+002
 7.630999e+002	 6.366913e+000	 1.531984e+004	 5.910832e-001	 1.260582e+001	 1.152928e-001	 9.189674e+002
 7.654999e+002	 6.393368e+000	 1.532076e+004	 5.921596e-001	 1.265820e+001	 1.157592e-001	 9.194499e+002
 7.679199e+002	 6.417774e+000	 1.532151e+004	 5.938514e-001	 1.270652e+001	 1.161893e-001	 9.198893e+002
 7.703399e+002	 6.443630e+000	 1.532176e+004	 5.940335e-001	 1.275771e+001	 1.166449e-001	 9.203222e+002
 7.727599e+002	 6.467048e+000	 1.532068e+004	 5.951174e-001	 1.280407e+001	           0.0	           0.0
 7.751799e+002	 6.491922e+000	 1.532193e+004	 5.963010e-001	 1.285332e+001	           0.0	           0.0
 7.781399e+002	 6.522675e+000	 1.532251e+004	 5.989821e-001	 1.291421e+001	           0.0	           0.0
 7.811399e+002	 6.552346e+000	 1.532126e+004	 5.992346e-001	 1.297295e+001	           0.0	           0.0
 7.836399e+002	 6.580191e+000	 1.532160e+004	 6.001358e-001	 1.302808e+001	           0.0	           0.0
 7.860799e+002	 6.604074e+000	 1.531817e+004	 6.028364e-001	 1.307537e+001	           0.0	           0.0
 7.884999e+002	 6.629708e+000	 1.531843e+004	 6.024325e-001	 1.312612e+001	           0.0	           0.0
 7.909399e+002	 6.654187e+000	 1.531542e+004	 6.047046e-001	 1.317459e+001	           0.0	           0.0
 7.933599e+002	 6.681110e+000	 1.531409e+004	 6.058095e-001	 1.322789e+001	           0.0	           0.0
 7.961399e+002	 6.710359e+000	 1.531884e+004	 6.062707e-001	 1.328580e+001	           0.0	           0.0
 7.991399e+002	 6.741881e+000	 1.531517e+004	 6.068408e-001	 1.334821e+001	           0.0	           0.0
 8.018199e+002	 6.770374e+000	 1.531350e+004	 6.090446e-001	 1.340463e+001	           0.0	           0.0
 8.042399e+002	 6.795270e+000	 1.530966e+004	 6.096832e-001	 1.345392e+001	           0.0	           0.0
 8.066599e+002	 6.821875e+000	 1.530908e+004	 6.116406e-001	 1.350659e+001	           0.0	           0.0
 8.090799e+002	 6.845862e+000	 1.530624e+004	 6.095796e-001	 1.355409e+001	           0.0	           0.0
 8.114999e+002	 6.872599e+000	 1.530441e+004	 6.125256e-001	 1.360702e+001	           0.0	           0.0
 8.141399e+002	 6.901943e+000	 1.530032e+004	 6.146511e-001	 1.366512e+001	           0.0	           0.0
 8.171399e+002	 6.934226e+000	 1.529573e+004	 6.135442e-001	 1.372904e+001	           0.0	           0.0
 8.199599e+002	 6.966418e+000	 1.529648e+004	 6.145044e-001	 1.379277e+001	           0.0	           0.0
 8.223799e+002	 6.992913e+000	 1.529189e+004	 6.151516e-001	 1.384523e+001	           0.0	           0.0
 8.247999e+002	 7.020524e+000	 1.528897e+004	 6.161729e-001	 1.389990e+001	           0.0	           0.0
 8.272199e+002	 7.048109e+000	 1.528363e+004	 6.172346e-001	 1.395451e+001	           0.0	           0.0
 8.296399e+002	 7.072530e+000	 1.528029e+004	 6.173339e-001	 1.400286e+001	           0.0	           0.0
 8.321399e+002	 7.102792e+000	 1.527695e+004	 6.182287e-001	 1.406278e+001	           0.0	           0.0
 8.351399e+002	 7.138589e+000	 1.527211e+004	 6.193968e-001	 1.413365e+001	           0.0	           0.0
 8.380999e+002	 7.171730e+000	 1.526869e+004	 6.191106e-001	 1.419927e+001	           0.0	           0.0
 8.405199e+002	 7.199313e+000	 1.526176e+004	 6.201832e-001	 1.425388e+001	           0.0	           0.0
 8.429399e+002	 7.227263e+000	 1.525717e+004	 6.208899e-001	 1.430922e+001	           0.0	           0.0
 8.453599e+002	 7.256029e+000	 1.525075e+004	 6.209097e-001	 1.436617e+001	           0.0	           0.0
 8.477799e+002	 7.285513e+000	 1.524065e+004	 6.205299e-001	 1.442455e+001	           0.0	           0.0
 8.501799e+002	 7.312652e+000	 1.523489e+004	 6.203886e-001	 1.447828e+001	           0.0	           0.0
 8.531399e+002	 7.347428e+000	 1.522772e+004	 6.219639e-001	 1.454713e+001	           0.0	           0.0
 8.561399e+002	 7.382904e+000	 1.521336e+004	 6.210616e-001	 1.461737e+001	           0.0	           0.0
 8.586599e+002	 7.412237e+000	 1.520268e+004	 6.231446e-001	 1.467545e+001	           0.0	           0.0
 8.610799e+002	 7.442605e+000	 1.519200e+004	 6.225709e-001	 1.473557e+001	           0.0	           0.0
 8.634999e+002	 7.473000e+000	 1.518124e+004	 6.214949e-001	 1.479575e+001	           0.0	           0.0
 8.659199e+002	 7.503369e+000	 1.516847e+004	 6.234541e-001	 1.485588e+001	           0.0	           0.0
 8.683399e+002	 7.534111e+000	 1.515270e+004	 6.231536e-001	 1.491675e+001	           0.0	           0.0
 8.711399e+002	 7.569211e+000	 1.513492e+004	 6.226770e-001	 1.498624e+001	           0.0	           0.0
 8.741399e+002	 7.609553e+000	 1.511515e+004	 6.229935e-001	 1.506611e+001	           0.0	           0.0
 8.768199e+002	 7.644695e+000	 1.509921e+004	 6.233796e-001	 1.513569e+001	           0.0	           0.0
 8.792399e+002	 7.676171e+000	 1.507901e+004	 6.239219e-001	 1.519801e+001	           0.0	           0.0
 8.816599e+002	 7.710808e+000	 1.506057e+004	 6.235177e-001	 1.526659e+001	           0.0	           0.0
 8.840799e+002	 7.744099e+000	 1.503871e+004	 6.223344e-001	 1.533250e+001	           0.0	           0.0
 8.864999e+002	 7.776955e+000	 1.501576e+004	 6.239793e-001	 1.539755e+001	           0.0	           0.0
 8.891399e+002	 7.812949e+000	 1.498305e+004	 6.231747e-001	 1.546882e+001	           0.0	           0.0
 8.921399e+002	 7.856318e+000	 1.495459e+004	 6.222953e-001	 1.555468e+001	           0.0	           0.0
 8.949799e+002	 7.896908e+000	 1.491829e+004	 6.223496e-001	 1.563504e+001	           0.0	           0.0
 8.974199e+002	 7.931527e+000	 1.488600e+004	 6.216015e-001	 1.570359e+001	           0.0	           0.0
 8.998199e+002	 7.968128e+000	 1.485421e+004	 6.224605e-001	 1.577605e+001	           0.0	           0.0
 9.022399e+002	 8.005076e+000	 1.481857e+004	 6.229498e-001	 1.584921e+001	           0.0	           0.0
 9.046599e+002	 8.041939e+000	 1.478111e+004	 6.223586e-001	 1.592219e+001	           0.0	           0.0
 9.071399e+002	 8.082595e+000	 1.473613e+004	 6.222541e-001	 1.600269e+001	           0.0	           0.0
 9.101399e+002	 8.131455e+000	 1.467771e+004	 6.223044e-001	 1.609942e+001	           0.0	           0.0
 9.131399e+002	 8.179494e+000	 1.460670e+004	 6.231319e-001	 1.619454e+001	           0.0	           0.0
 9.161399e+002	 8.231585e+000	 1.452392e+004	 6.216506e-001	 1.629767e+001	           0.0	           0.0
 9.191399e+002	 8.287286e+000	 1.439508e+004	 6.205391e-001	 1.640795e+001	           0.0	           0.0
 9.203999e+002	 8.313386e+000	 1.430420e+004	 6.204528e-001	 1.645963e+001	           0.0	           0.0