File: DP800 Tensile Tests/Fehlemann_Test_WP_KL_2024_1014.TRA
$Fehlemann_Test_WP_KL_2024_101.ZSE
Material:                               St
Auftrags-Nr.:                           WP_KL_2024_101
Probe:                                  2_90°_A
Vorkraft:                               100 N
Probengeometrie:                        H12,5x50
Messlänge:                              50.7839 mm
Probendicke a0:                         1.49 mm
Probenbreite b0:                        12.63 mm
Prüfgeschwindigkeit:                    1 mm/min
Datum:                                  26.09.2024
Maschinendaten:                         4204 WN:800315
Traversenwegaufnehmer WN:800315
Videoextensometer
Videoextensometer - Querdehnung
Kraftsensor ID:0 WN:800316 50 kN

Bemerkung:
$
      Prüfzeit	   Standardweg	 Spannung    	Breitenänderung	       Dehnung	 wahre Dehnung	wahre Spannung
 2.023437e-002	 3.267773e-004	 2.057009e+002	-5.174072e-005	 6.434666e-004	 0.000000e+000	 1.093138e+001
 1.402344e-001	 2.643197e-003	 2.062016e+002	-4.159455e-005	 5.204795e-003	 0.000000e+000	 1.095849e+001
 5.002344e-001	 1.981100e-003	 2.371607e+002	 1.458180e-003	 3.901041e-003	 0.000000e+000	 1.260363e+001
 8.402344e-001	 3.618584e-003	 3.403856e+002	 1.427083e-003	 7.125458e-003	 0.000000e+000	 1.808998e+001
 1.340234e+000	 5.418326e-003	 4.812454e+002	 1.991083e-003	 1.066938e-002	 0.000000e+000	 2.557696e+001
 1.960234e+000	 7.184777e-003	 6.574037e+002	 1.918986e-003	 1.414775e-002	 0.000000e+000	 3.494053e+001
 2.120234e+000	 9.139229e-003	 7.026323e+002	 2.716599e-003	 1.799632e-002	 0.000000e+000	 3.734584e+001
 2.600234e+000	 1.021291e-002	 8.407384e+002	 2.620147e-003	 2.011053e-002	 0.000000e+000	 4.468731e+001
 3.060234e+000	 1.204262e-002	 9.713342e+002	 3.982309e-003	 2.371346e-002	 0.000000e+000	 5.163065e+001
 3.520234e+000	 1.364352e-002	 1.104934e+003	 4.117728e-003	 2.686585e-002	 0.000000e+000	 5.873392e+001
 3.740234e+000	 1.533578e-002	 1.170107e+003	 3.954567e-003	 3.019812e-002	 0.000000e+000	 6.220031e+001
 4.240234e+000	 1.706887e-002	 1.312302e+003	 5.513373e-003	 3.361082e-002	 0.000000e+000	 6.976147e+001
 4.780234e+000	 1.879587e-002	 1.459086e+003	 6.179259e-003	 3.701149e-002	 0.000000e+000	 7.756712e+001
 5.020235e+000	 1.955445e-002	 1.524676e+003	 6.685728e-003	 3.850524e-002	 0.000000e+000	 8.105518e+001
 5.340234e+000	 1.993329e-002	 1.612547e+003	 6.341018e-003	 3.925123e-002	 0.000000e+000	 8.572721e+001
 5.640234e+000	 2.193578e-002	 1.694493e+003	 6.352696e-003	 4.319438e-002	 0.000000e+000	 9.008722e+001
 6.060235e+000	 2.389162e-002	 1.803893e+003	 7.876179e-003	 4.704568e-002	 6.895906e-007	 9.590713e+001
 6.380234e+000	 2.445155e-002	 1.886005e+003	 7.497857e-003	 4.814826e-002	 0.000000e+000	 1.002739e+002
 6.640234e+000	 2.612784e-002	 1.954265e+003	 7.874115e-003	 5.144909e-002	 6.526455e-007	 1.039065e+002
 6.960234e+000	 2.663549e-002	 2.034125e+003	 6.577373e-003	 5.244871e-002	 0.000000e+000	 1.081537e+002
 7.160234e+000	 2.837908e-002	 2.087698e+003	 7.270728e-003	 5.588208e-002	 5.876085e-006	 1.110060e+002
 7.580235e+000	 2.954329e-002	 2.190089e+003	 7.762986e-003	 5.817456e-002	 0.000000e+000	 1.164529e+002
 7.920234e+000	 3.175605e-002	 2.275206e+003	 6.528915e-003	 6.253177e-002	 1.741848e-005	 1.209840e+002
 8.440234e+000	 3.351600e-002	 2.398375e+003	 7.811212e-003	 6.599734e-002	 1.597597e-005	 1.275380e+002
 8.800235e+000	 3.455480e-002	 2.483408e+003	 9.774259e-003	 6.804286e-002	 1.150985e-005	 1.320625e+002
 8.940234e+000	 3.677474e-002	 2.515368e+003	 8.735147e-003	 7.241421e-002	 4.585545e-005	 1.337679e+002
 9.140234e+000	 3.447181e-002	 2.558511e+003	 8.443018e-003	 6.787944e-002	 0.000000e+000	 1.360561e+002
 9.540235e+000	 3.653187e-002	 2.643794e+003	 8.878634e-003	 7.193596e-002	 3.434888e-006	 1.405970e+002
 1.016023e+001	 3.844190e-002	 2.768966e+003	 8.314228e-003	 7.569705e-002	 4.360693e-006	 1.472591e+002
 1.060023e+001	 3.794710e-002	 2.851329e+003	 9.272244e-003	 7.472274e-002	 0.000000e+000	 1.516379e+002
 1.100023e+001	 3.989394e-002	 2.923678e+003	 1.131870e-002	 7.855632e-002	 0.000000e+000	 1.554915e+002
 1.144023e+001	 4.152323e-002	 2.996862e+003	 8.676631e-003	 8.176460e-002	 0.000000e+000	 1.593887e+002
 1.200023e+001	 4.304084e-002	 3.087403e+003	 1.095853e-002	 8.475297e-002	 1.592845e-006	 1.642091e+002
 1.218023e+001	 4.475705e-002	 3.116359e+003	 9.507309e-003	 8.813241e-002	 2.690035e-005	 1.657548e+002
 1.248023e+001	 4.300968e-002	 3.160503e+003	 9.815050e-003	 8.469161e-002	 0.000000e+000	 1.680969e+002
 1.308023e+001	 4.514142e-002	 3.248290e+003	 9.473051e-003	 8.888928e-002	 0.000000e+000	 1.727733e+002
 1.366023e+001	 4.708265e-002	 3.330236e+003	 1.131423e-002	 9.271181e-002	 1.001194e-005	 1.771387e+002
 1.422023e+001	 4.788552e-002	 3.408176e+003	 9.900277e-003	 9.429276e-002	 2.978923e-006	 1.812872e+002
 1.456023e+001	 4.845462e-002	 3.454323e+003	 1.050289e-002	 9.541339e-002	 6.605632e-007	 1.837439e+002
 1.464023e+001	 5.037781e-002	 3.464837e+003	 1.006876e-002	 9.920041e-002	 3.544852e-005	 1.843102e+002
 1.482023e+001	 5.013726e-002	 3.488536e+003	 9.998470e-003	 9.872674e-002	 2.376647e-005	 1.855700e+002
 1.498023e+001	 4.972468e-002	 3.512235e+003	 9.606760e-003	 9.791431e-002	 8.696677e-006	 1.868291e+002
 1.532023e+001	 4.772358e-002	 3.554710e+003	 1.045802e-002	 9.397389e-002	 0.000000e+000	 1.890811e+002
 1.608023e+001	 4.965717e-002	 3.655682e+003	 1.042837e-002	 9.778137e-002	 0.000000e+000	 1.944593e+002
 1.622023e+001	 5.155013e-002	 3.671620e+003	 1.011892e-002	 1.015089e-001	 0.000000e+000	 1.953144e+002
 1.678024e+001	 5.102018e-002	 3.743636e+003	 1.118298e-002	 1.004653e-001	 0.000000e+000	 1.991433e+002
 1.716023e+001	 5.285230e-002	 3.789616e+003	 1.217573e-002	 1.040730e-001	 0.000000e+000	 2.015964e+002
 2.050023e+001	 6.118591e-002	 4.186994e+003	 1.067518e-002	 1.204829e-001	 3.662500e-005	 2.227723e+002
 2.650023e+001	 7.142384e-002	 4.867344e+003	 5.991696e-003	 1.406428e-001	 3.882683e-005	 2.590230e+002
 3.144024e+001	 8.245065e-002	 5.375374e+003	 4.953663e-003	 1.623560e-001	 1.070611e-004	 2.861206e+002
 3.700023e+001	 9.249087e-002	 5.894252e+003	 1.008370e-002	 1.821265e-001	 1.526878e-004	 3.138014e+002
 4.246024e+001	 1.030684e-001	 6.333020e+003	 1.196992e-002	 2.029550e-001	 2.323643e-004	 3.372309e+002
 4.812024e+001	 1.131852e-001	 6.732568e+003	 1.359270e-002	 2.228763e-001	 3.144552e-004	 3.585779e+002
 5.388023e+001	 1.232678e-001	 7.095733e+003	 1.727431e-002	 2.427302e-001	 4.065251e-004	 3.779950e+002
 5.950023e+001	 1.352899e-001	 7.412083e+003	 1.486353e-002	 2.664032e-001	 5.504713e-004	 3.949404e+002
 6.550024e+001	 1.477433e-001	 7.714331e+003	 1.557447e-002	 2.909256e-001	 7.070143e-004	 4.111457e+002
 7.150024e+001	 1.593315e-001	 7.992880e+003	 1.522870e-002	 3.137442e-001	 8.534489e-004	 4.260883e+002
 7.590024e+001	 1.743225e-001	 8.184726e+003	 1.667917e-002	 3.432635e-001	 1.092183e-003	 4.364437e+002
 8.090024e+001	 1.843768e-001	 8.398353e+003	 1.629310e-002	 3.630618e-001	 1.227400e-003	 4.479235e+002
 8.650024e+001	 1.976794e-001	 8.618988e+003	 1.798299e-002	 3.892562e-001	 1.424419e-003	 4.598110e+002
 9.246024e+001	 2.145312e-001	 8.846717e+003	 2.242515e-002	 4.224397e-001	 1.689099e-003	 4.721160e+002
 9.626023e+001	 2.246544e-001	 8.981318e+003	 2.296815e-002	 4.423734e-001	 1.848705e-003	 4.793944e+002
 1.015002e+002	 2.399953e-001	 9.162567e+003	 2.779750e-002	 4.725816e-001	 2.097176e-003	 4.892159e+002
 1.065002e+002	 2.550070e-001	 9.327293e+003	 2.732563e-002	 5.021417e-001	 2.343951e-003	 4.981576e+002
 1.105002e+002	 2.673565e-001	 9.452965e+003	 2.766773e-002	 5.264594e-001	 2.549791e-003	 5.049917e+002
 1.158202e+002	 2.853450e-001	 9.616105e+003	 3.149411e-002	 5.618812e-001	 2.855370e-003	 5.138879e+002
 1.195002e+002	 2.991495e-001	 9.730930e+003	 3.337128e-002	 5.890640e-001	 3.092838e-003	 5.201648e+002
 1.239402e+002	 3.154829e-001	 9.854349e+003	 3.563108e-002	 6.212265e-001	 3.377369e-003	 5.269305e+002
 1.285002e+002	 3.296080e-001	 9.977018e+003	 3.811198e-002	 6.490407e-001	 3.618714e-003	 5.336373e+002
 1.330602e+002	 3.456876e-001	 1.009910e+004	 4.066102e-002	 6.807035e-001	 3.898509e-003	 5.403371e+002
 1.375002e+002	 3.633139e-001	 1.021868e+004	 4.141650e-002	 7.154120e-001	 4.209285e-003	 5.469235e+002
 1.405002e+002	 3.760336e-001	 1.029737e+004	 4.404808e-002	 7.404586e-001	 4.435707e-003	 5.512723e+002
 1.451202e+002	 3.962564e-001	 1.041837e+004	 4.604666e-002	 7.802799e-001	 4.796787e-003	 5.579704e+002
 1.489602e+002	 4.166135e-001	 1.051651e+004	 4.978028e-002	 8.203657e-001	 5.167034e-003	 5.634502e+002
 1.525002e+002	 4.314351e-001	 1.060671e+004	 4.902331e-002	 8.495513e-001	 5.431050e-003	 5.684478e+002
 1.558602e+002	 4.472432e-001	 1.069700e+004	 5.209660e-002	 8.806795e-001	 5.714287e-003	 5.734637e+002
 1.596202e+002	 4.674493e-001	 1.078754e+004	 5.466344e-002	 9.204680e-001	 6.083452e-003	 5.785456e+002
 1.635602e+002	 4.876636e-001	 1.089060e+004	 5.769102e-002	 9.602726e-001	 6.448996e-003	 5.843031e+002
 1.672002e+002	 5.079018e-001	 1.098281e+004	 5.674457e-002	 1.000124e+000	 6.818031e-003	 5.894829e+002
 1.705002e+002	 5.267696e-001	 1.106526e+004	 6.051518e-002	 1.037277e+000	 7.162980e-003	 5.941265e+002
 1.735002e+002	 5.438986e-001	 1.114303e+004	 6.160334e-002	 1.071007e+000	 7.475185e-003	 5.985021e+002
 1.765002e+002	 5.618957e-001	 1.121897e+004	 6.255334e-002	 1.106445e+000	 7.804786e-003	 6.027921e+002
 1.795002e+002	 5.810130e-001	 1.129374e+004	 6.549483e-002	 1.144089e+000	 8.156499e-003	 6.070353e+002
 1.825002e+002	 5.988029e-001	 1.136918e+004	 6.890886e-002	 1.179120e+000	 8.481978e-003	 6.113017e+002
 1.855002e+002	 6.181124e-001	 1.144511e+004	 7.206521e-002	 1.217143e+000	 8.836865e-003	 6.156160e+002
 1.882602e+002	 6.288495e-001	 1.151045e+004	 7.298137e-002	 1.238286e+000	 9.027433e-003	 6.192598e+002
 1.904802e+002	 6.492876e-001	 1.156778e+004	 7.371841e-002	 1.278531e+000	 9.409544e-003	 6.225914e+002
 1.933802e+002	 6.696258e-001	 1.163746e+004	 7.726341e-002	 1.318580e+000	 9.785977e-003	 6.265893e+002
 1.965202e+002	 6.900360e-001	 1.171298e+004	 8.070476e-002	 1.358770e+000	 1.016198e-002	 6.309056e+002
 1.998402e+002	 7.103215e-001	 1.178959e+004	 8.288599e-002	 1.398715e+000	 1.053510e-002	 6.352821e+002
 2.020202e+002	 7.307733e-001	 1.183966e+004	 8.486232e-002	 1.438987e+000	 1.091900e-002	 6.382335e+002
 2.048802e+002	 7.513529e-001	 1.190383e+004	 8.671325e-002	 1.479511e+000	 1.130116e-002	 6.419490e+002
 2.079402e+002	 7.713770e-001	 1.197067e+004	 8.804154e-002	 1.518941e+000	 1.167159e-002	 6.458045e+002
 2.108002e+002	 7.915253e-001	 1.203667e+004	 9.223785e-002	 1.558615e+000	 1.204455e-002	 6.496192e+002
 2.137002e+002	 8.119418e-001	 1.210135e+004	 9.573063e-002	 1.598818e+000	 1.242296e-002	 6.533681e+002
 2.162202e+002	 8.319522e-001	 1.215342e+004	 9.666028e-002	 1.638221e+000	 1.279699e-002	 6.564340e+002
 2.191402e+002	 8.523396e-001	 1.221233e+004	 9.907360e-002	 1.678367e+000	 1.317622e-002	 6.598766e+002
 2.218602e+002	 8.723695e-001	 1.227175e+004	 1.016273e-001	 1.717808e+000	 1.354821e-002	 6.633442e+002
 2.245002e+002	 8.941329e-001	 1.232182e+004	 1.063875e-001	 1.760663e+000	 1.395644e-002	 6.663313e+002
 2.275002e+002	 9.171242e-001	 1.238173e+004	 1.050151e-001	 1.805936e+000	 1.438548e-002	 6.698692e+002
 2.305002e+002	 9.397399e-001	 1.243814e+004	 1.089126e-001	 1.850469e+000	 1.480807e-002	 6.732154e+002
 2.335002e+002	 9.616819e-001	 1.249614e+004	 1.092724e-001	 1.893676e+000	 1.521695e-002	 6.766414e+002
 2.362202e+002	 9.838848e-001	 1.254813e+004	 1.120944e-001	 1.937396e+000	 1.563246e-002	 6.797479e+002
 2.388002e+002	 1.004139e+000	 1.259160e+004	 1.158378e-001	 1.977278e+000	 1.601248e-002	 6.823700e+002
 2.401002e+002	 1.016269e+000	 1.261881e+004	 1.162821e-001	 2.001166e+000	 1.623969e-002	 6.840044e+002
 2.425002e+002	 1.032812e+000	 1.266095e+004	 1.191098e-001	 2.033741e+000	 1.654799e-002	 6.865078e+002
 2.449802e+002	 1.052611e+000	 1.270651e+004	 1.214330e-001	 2.072728e+000	 1.691826e-002	 6.892415e+002
 2.474202e+002	 1.074010e+000	 1.274606e+004	 1.227591e-001	 2.114865e+000	 1.732108e-002	 6.916725e+002
 2.498602e+002	 1.094137e+000	 1.278737e+004	 1.257514e-001	 2.154497e+000	 1.769863e-002	 6.941833e+002
 2.522802e+002	 1.113892e+000	 1.282626e+004	 1.261677e-001	 2.193397e+000	 1.806953e-002	 6.965595e+002
 2.547002e+002	 1.134777e+000	 1.286456e+004	 1.290022e-001	 2.234522e+000	 1.846232e-002	 6.989207e+002
 2.575002e+002	 1.157272e+000	 1.291188e+004	 1.312783e-001	 2.278818e+000	 1.888347e-002	 7.017952e+002
 2.605002e+002	 1.182597e+000	 1.295969e+004	 1.321096e-001	 2.328685e+000	 1.935896e-002	 7.047375e+002
 2.631602e+002	 1.206406e+000	 1.299716e+004	 1.363962e-001	 2.375570e+000	 1.980794e-002	 7.070989e+002
 2.655802e+002	 1.227458e+000	 1.303346e+004	 1.385046e-001	 2.417024e+000	 2.020385e-002	 7.093608e+002
 2.680202e+002	 1.248374e+000	 1.306967e+004	 1.392684e-001	 2.458210e+000	 2.059699e-002	 7.116180e+002
 2.704402e+002	 1.269202e+000	 1.310531e+004	 1.409641e-001	 2.499223e+000	 2.098845e-002	 7.138437e+002
 2.728602e+002	 1.289810e+000	 1.314161e+004	 1.435969e-001	 2.539803e+000	 2.137533e-002	 7.161043e+002
 2.755002e+002	 1.313321e+000	 1.317924e+004	 1.455390e-001	 2.586098e+000	 2.181759e-002	 7.184793e+002
 2.785002e+002	 1.340678e+000	 1.321930e+004	 1.493913e-001	 2.639968e+000	 2.233305e-002	 7.210414e+002
 2.813202e+002	 1.366012e+000	 1.325927e+004	 1.517728e-001	 2.689854e+000	 2.280932e-002	 7.235731e+002
 2.837402e+002	 1.385895e+000	 1.329048e+004	 1.503497e-001	 2.729005e+000	 2.318299e-002	 7.255527e+002
 2.861602e+002	 1.408912e+000	 1.332369e+004	 1.559427e-001	 2.774330e+000	 2.361625e-002	 7.276867e+002
 2.885802e+002	 1.427189e+000	 1.335190e+004	 1.561730e-001	 2.810320e+000	 2.395962e-002	 7.294825e+002
 2.910002e+002	 1.448675e+000	 1.338319e+004	 1.595071e-001	 2.852628e+000	 2.436364e-002	 7.314931e+002
 2.935002e+002	 1.471844e+000	 1.341340e+004	 1.619186e-001	 2.898250e+000	 2.480015e-002	 7.334694e+002
 2.965002e+002	 1.498875e+000	 1.345078e+004	 1.637914e-001	 2.951477e+000	 2.530857e-002	 7.358941e+002
 2.994602e+002	 1.523740e+000	 1.348917e+004	 1.667383e-001	 3.000441e+000	 2.577490e-002	 7.383452e+002
 3.018802e+002	 1.546701e+000	 1.351629e+004	 1.683129e-001	 3.045654e+000	 2.620767e-002	 7.401544e+002
 3.043002e+002	 1.566791e+000	 1.354549e+004	 1.710524e-001	 3.085213e+000	 2.658462e-002	 7.420385e+002
 3.067202e+002	 1.589086e+000	 1.357253e+004	 1.712594e-001	 3.129115e+000	 2.700433e-002	 7.438362e+002
 3.091402e+002	 1.606337e+000	 1.360124e+004	 1.742773e-001	 3.163085e+000	 2.732673e-002	 7.456550e+002
 3.115602e+002	 1.630570e+000	 1.362936e+004	 1.764317e-001	 3.210802e+000	 2.778291e-002	 7.475423e+002
 3.145002e+002	 1.657638e+000	 1.365873e+004	 1.784462e-001	 3.264104e+000	 2.829282e-002	 7.495402e+002
 3.175002e+002	 1.682849e+000	 1.369261e+004	 1.817832e-001	 3.313746e+000	 2.876564e-002	 7.517606e+002
 3.200402e+002	 1.705083e+000	 1.372007e+004	 1.830238e-001	 3.357529e+000	 2.918314e-002	 7.535871e+002
 3.224602e+002	 1.725999e+000	 1.374710e+004	 1.853097e-001	 3.398716e+000	 2.957539e-002	 7.553730e+002
 3.248802e+002	 1.747035e+000	 1.376838e+004	 1.865945e-001	 3.440138e+000	 2.997141e-002	 7.568453e+002
 3.273002e+002	 1.767794e+000	 1.379367e+004	 1.884617e-001	 3.481014e+000	 3.036083e-002	 7.585349e+002
 3.297402e+002	 1.789492e+000	 1.381678e+004	 1.897297e-001	 3.523740e+000	 3.076866e-002	 7.601197e+002
 3.325002e+002	 1.813543e+000	 1.384682e+004	 1.938697e-001	 3.571100e+000	 3.121927e-002	 7.621209e+002
 3.355002e+002	 1.841136e+000	 1.387461e+004	 1.963382e-001	 3.625434e+000	 3.173788e-002	 7.640509e+002
 3.382002e+002	 1.864350e+000	 1.390073e+004	 1.980156e-001	 3.671146e+000	 3.217321e-002	 7.658269e+002
 3.406202e+002	 1.886927e+000	 1.392401e+004	 2.013413e-001	 3.715602e+000	 3.259700e-002	 7.674384e+002
 3.430402e+002	 1.907780e+000	 1.394446e+004	 2.038261e-001	 3.756665e+000	 3.298858e-002	 7.688696e+002
 3.454602e+002	 1.930654e+000	 1.396757e+004	 2.054269e-001	 3.801707e+000	 3.341774e-002	 7.704784e+002
 3.478802e+002	 1.952110e+000	 1.398935e+004	 2.058583e-001	 3.843956e+000	 3.382009e-002	 7.719939e+002
 3.505002e+002	 1.974176e+000	 1.400880e+004	 2.093430e-001	 3.887407e+000	 3.423456e-002	 7.733903e+002
 3.535002e+002	 2.000808e+000	 1.403442e+004	 2.127304e-001	 3.939850e+000	 3.473396e-002	 7.751958e+002
 3.563602e+002	 2.029472e+000	 1.406053e+004	 2.144749e-001	 3.996293e+000	 3.527158e-002	 7.770602e+002
 3.587802e+002	 2.050441e+000	 1.408231e+004	 2.184922e-001	 4.037582e+000	 3.566392e-002	 7.785728e+002
 3.612002e+002	 2.070210e+000	 1.410117e+004	 2.212301e-001	 4.076510e+000	 3.603416e-002	 7.799072e+002
 3.636202e+002	 2.092199e+000	 1.412137e+004	 2.226950e-001	 4.119810e+000	 3.644604e-002	 7.813490e+002
 3.660402e+002	 2.114537e+000	 1.413914e+004	 2.250810e-001	 4.163795e+000	 3.686504e-002	 7.826630e+002
 3.685002e+002	 2.136940e+000	 1.416025e+004	 2.260083e-001	 4.207910e+000	 3.728417e-002	 7.841636e+002
 3.715002e+002	 2.163460e+000	 1.418387e+004	 2.298513e-001	 4.260132e+000	 3.778049e-002	 7.858649e+002
 3.745002e+002	 2.193310e+000	 1.420765e+004	 2.320383e-001	 4.318910e+000	 3.833961e-002	 7.876264e+002
 3.769402e+002	 2.215964e+000	 1.422634e+004	 2.349312e-001	 4.363518e+000	 3.876355e-002	 7.889999e+002
 3.793602e+002	 2.239199e+000	 1.424420e+004	 2.362761e-001	 4.409272e+000	 3.919856e-002	 7.903366e+002
 3.817802e+002	 2.260358e+000	 1.426189e+004	 2.396440e-001	 4.450936e+000	 3.959412e-002	 7.916339e+002
 3.842002e+002	 2.285044e+000	 1.427933e+004	 2.398245e-001	 4.499547e+000	 4.005634e-002	 7.929709e+002
 3.866202e+002	 2.307388e+000	 1.429552e+004	 2.429509e-001	 4.543545e+000	 4.047440e-002	 7.942041e+002
 3.895002e+002	 2.334650e+000	 1.431163e+004	 2.450522e-001	 4.597227e+000	 4.098526e-002	 7.955071e+002
 3.925002e+002	 2.365095e+000	 1.433383e+004	 2.504093e-001	 4.657177e+000	 4.155428e-002	 7.971975e+002
 3.951002e+002	 2.387258e+000	 1.434885e+004	 2.502688e-001	 4.700819e+000	 4.196863e-002	 7.983657e+002
 3.975202e+002	 2.411261e+000	 1.436720e+004	 2.530851e-001	 4.748084e+000	 4.241659e-002	 7.997480e+002
 3.999402e+002	 2.431199e+000	 1.438097e+004	 2.540235e-001	 4.787345e+000	 4.278896e-002	 8.008145e+002
 4.023402e+002	 2.454823e+000	 1.439942e+004	 2.568622e-001	 4.833864e+000	 4.322939e-002	 8.021974e+002
 4.047602e+002	 2.480537e+000	 1.441452e+004	 2.610627e-001	 4.884498e+000	 4.370995e-002	 8.034267e+002
 4.075002e+002	 2.507666e+000	 1.442962e+004	 2.619325e-001	 4.937918e+000	 4.421694e-002	 8.046781e+002
 4.105002e+002	 2.534652e+000	 1.444965e+004	 2.640332e-001	 4.991056e+000	 4.471960e-002	 8.062030e+002
 4.132402e+002	 2.560291e+000	 1.446726e+004	 2.667402e-001	 5.041543e+000	 4.519733e-002	 8.075735e+002
 4.156602e+002	 2.582715e+000	 1.448053e+004	 2.688027e-001	 5.085699e+000	 4.561557e-002	 8.086539e+002
 4.180802e+002	 2.607745e+000	 1.449730e+004	 2.717150e-001	 5.134987e+000	 4.608168e-002	 8.099703e+002
 4.205002e+002	 2.629825e+000	 1.450957e+004	 2.747106e-001	 5.178465e+000	 4.649335e-002	 8.109909e+002
 4.229202e+002	 2.653663e+000	 1.452484e+004	 2.763121e-001	 5.225405e+000	 4.693706e-002	 8.122067e+002
 4.255002e+002	 2.678495e+000	 1.453861e+004	 2.788755e-001	 5.274302e+000	 4.739965e-002	 8.133544e+002
 4.285002e+002	 2.707203e+000	 1.455521e+004	 2.808011e-001	 5.330833e+000	 4.793401e-002	 8.147206e+002
 4.314002e+002	 2.734481e+000	 1.456848e+004	 2.846794e-001	 5.384547e+000	 4.844217e-002	 8.158792e+002
 4.338202e+002	 2.757760e+000	 1.458308e+004	 2.868432e-001	 5.430385e+000	 4.887470e-002	 8.170522e+002
 4.362402e+002	 2.780246e+000	 1.459635e+004	 2.898297e-001	 5.474662e+000	 4.929257e-002	 8.181390e+002
 4.386602e+002	 2.800082e+000	 1.461012e+004	 2.907547e-001	 5.513723e+000	 4.966048e-002	 8.192141e+002
 4.410802e+002	 2.828118e+000	 1.462356e+004	 2.946078e-001	 5.568929e+000	 5.018191e-002	 8.203963e+002
 4.447002e+002	 2.863319e+000	 1.464283e+004	 2.970948e-001	 5.638244e+000	 5.083555e-002	 8.220171e+002
 4.471402e+002	 2.887865e+000	 1.465376e+004	 2.997867e-001	 5.686579e+000	 5.129180e-002	 8.230072e+002
 4.495602e+002	 2.909829e+000	 1.466520e+004	 3.005607e-001	 5.729828e+000	 5.169939e-002	 8.239863e+002
 4.525002e+002	 2.940406e+000	 1.467913e+004	 3.036738e-001	 5.790038e+000	 5.226711e-002	 8.252389e+002
 4.555002e+002	 2.968752e+000	 1.469741e+004	 3.079853e-001	 5.845855e+000	 5.279164e-002	 8.267023e+002
 4.580202e+002	 2.992473e+000	 1.470675e+004	 3.109384e-001	 5.892565e+000	 5.323203e-002	 8.275930e+002
 4.604402e+002	 3.016178e+000	 1.471785e+004	 3.131105e-001	 5.939243e+000	 5.367143e-002	 8.285826e+002
 4.628802e+002	 3.039192e+000	 1.472578e+004	 3.154545e-001	 5.984561e+000	 5.409863e-002	 8.293835e+002
 4.652802e+002	 3.063009e+000	 1.473696e+004	 3.173559e-001	 6.031459e+000	 5.453971e-002	 8.303806e+002
 4.677202e+002	 3.085885e+000	 1.474789e+004	 3.203655e-001	 6.076506e+000	 5.496315e-002	 8.313496e+002
 4.705002e+002	 3.113465e+000	 1.476400e+004	 3.232201e-001	 6.130815e+000	 5.547260e-002	 8.326835e+002
 4.735002e+002	 3.141789e+000	 1.477159e+004	 3.265298e-001	 6.186589e+000	 5.599799e-002	 8.335496e+002
 4.761802e+002	 3.167430e+000	 1.478620e+004	 3.275906e-001	 6.237079e+000	 5.647124e-002	 8.347704e+002
 4.786002e+002	 3.192344e+000	 1.479830e+004	 3.284839e-001	 6.286138e+000	 5.693143e-002	 8.358393e+002
 4.810202e+002	 3.215903e+000	 1.481023e+004	 3.314209e-001	 6.332528e+000	 5.736627e-002	 8.368784e+002
 4.834402e+002	 3.239116e+000	 1.481907e+004	 3.341904e-001	 6.378237e+000	 5.779533e-002	 8.377382e+002
 4.858602e+002	 3.262977e+000	 1.482658e+004	 3.362586e-001	 6.425223e+000	 5.823663e-002	 8.385329e+002
 4.885002e+002	 3.287701e+000	 1.483568e+004	 3.370678e-001	 6.473908e+000	 5.869332e-002	 8.394311e+002
 4.915002e+002	 3.318186e+000	 1.484811e+004	 3.413752e-001	 6.533937e+000	 5.925580e-002	 8.406082e+002
 4.943202e+002	 3.345611e+000	 1.485746e+004	 3.430015e-001	 6.587940e+000	 5.976204e-002	 8.415638e+002
 4.967402e+002	 3.370432e+000	 1.486681e+004	 3.457631e-001	 6.636815e+000	 6.021976e-002	 8.424792e+002
 4.991602e+002	 3.394423e+000	 1.487740e+004	 3.470897e-001	 6.684056e+000	 6.066154e-002	 8.434533e+002
 5.015602e+002	 3.417817e+000	 1.488892e+004	 3.508240e-001	 6.730122e+000	 6.109181e-002	 8.444706e+002
 5.040002e+002	 3.442314e+000	 1.489493e+004	 3.535038e-001	 6.778360e+000	 6.154385e-002	 8.451932e+002
 5.065002e+002	 3.465554e+000	 1.490419e+004	 3.559944e-001	 6.824124e+000	 6.197153e-002	 8.460812e+002
 5.095002e+002	 3.495316e+000	 1.491713e+004	 3.597424e-001	 6.882729e+000	 6.251865e-002	 8.472801e+002
 5.124802e+002	 3.525558e+000	 1.492998e+004	 3.612952e-001	 6.942278e+000	 6.307436e-002	 8.484824e+002
 5.149002e+002	 3.549683e+000	 1.493540e+004	 3.636967e-001	 6.989784e+000	 6.351879e-002	 8.491677e+002
 5.173203e+002	 3.572234e+000	 1.494333e+004	 3.661725e-001	 7.034190e+000	 6.393325e-002	 8.499711e+002
 5.197402e+002	 3.595422e+000	 1.495276e+004	 3.694097e-001	 7.079849e+000	 6.435888e-002	 8.508702e+002
 5.221602e+002	 3.620534e+000	 1.496035e+004	 3.712612e-001	 7.129299e+000	 6.482036e-002	 8.516954e+002
 5.245803e+002	 3.644521e+000	 1.496678e+004	 3.736290e-001	 7.176532e+000	 6.526119e-002	 8.524369e+002
 5.275002e+002	 3.675489e+000	 1.497521e+004	 3.737220e-001	 7.237513e+000	 6.582999e-002	 8.534022e+002
 5.305002e+002	 3.705546e+000	 1.498288e+004	 3.795473e-001	 7.296698e+000	 6.638188e-002	 8.543109e+002
 5.330602e+002	 3.731579e+000	 1.499089e+004	 3.815195e-001	 7.347960e+000	 6.685926e-002	 8.551760e+002
 5.354602e+002	 3.753403e+000	 1.499957e+004	 3.815023e-001	 7.390936e+000	 6.725877e-002	 8.560136e+002
 5.378802e+002	 3.777058e+000	 1.500858e+004	 3.857205e-001	 7.437515e+000	 6.769170e-002	 8.568995e+002
 5.403002e+002	 3.802073e+000	 1.501693e+004	 3.862646e-001	 7.486772e+000	 6.814964e-002	 8.577690e+002
 5.427202e+002	 3.825293e+000	 1.502436e+004	 3.882203e-001	 7.532496e+000	 6.857464e-002	 8.585582e+002
 5.455002e+002	 3.853079e+000	 1.502769e+004	 3.914265e-001	 7.587209e+000	 6.908446e-002	 8.591859e+002
 5.485002e+002	 3.884054e+000	 1.503704e+004	 3.952719e-001	 7.648204e+000	 6.965098e-002	 8.602076e+002
 5.511802e+002	 3.908905e+000	 1.504639e+004	 3.956357e-001	 7.697137e+000	 7.010473e-002	 8.611335e+002
 5.536002e+002	 3.932035e+000	 1.505248e+004	 3.982021e-001	 7.742685e+000	 7.052761e-002	 8.618465e+002
 5.560203e+002	 3.955744e+000	 1.505899e+004	 4.005302e-001	 7.789370e+000	 7.096081e-002	 8.625927e+002
 5.584202e+002	 3.979862e+000	 1.506700e+004	 4.018412e-001	 7.836862e+000	 7.140090e-002	 8.634318e+002
 5.608402e+002	 4.005201e+000	 1.507309e+004	 4.051667e-001	 7.886757e+000	 7.186371e-002	 8.641806e+002
 5.635002e+002	 4.030335e+000	 1.507901e+004	 4.049690e-001	 7.936251e+000	 7.232260e-002	 8.649168e+002
 5.665002e+002	 4.060980e+000	 1.508878e+004	 4.090090e-001	 7.996593e+000	 7.288111e-002	 8.659607e+002
 5.693203e+002	 4.088047e+000	 1.509053e+004	 4.120730e-001	 8.049892e+000	 7.337603e-002	 8.664886e+002
 5.717402e+002	 4.111883e+000	 1.509854e+004	 4.139142e-001	 8.096829e+000	 7.380991e-002	 8.673252e+002
 5.741602e+002	 4.136406e+000	 1.510446e+004	 4.146622e-001	 8.145117e+000	 7.425673e-002	 8.680531e+002
 5.765803e+002	 4.158819e+000	 1.511198e+004	 4.198380e-001	 8.189252e+000	 7.466436e-002	 8.688392e+002
 5.790002e+002	 4.184963e+000	 1.511740e+004	 4.222952e-001	 8.240733e+000	 7.514054e-002	 8.695646e+002
 5.815002e+002	 4.209417e+000	 1.512449e+004	 4.219982e-001	 8.288886e+000	 7.558519e-002	 8.703596e+002
 5.845002e+002	 4.239082e+000	 1.513000e+004	 4.252418e-001	 8.347300e+000	 7.612517e-002	 8.711461e+002
 5.874602e+002	 4.267884e+000	 1.513401e+004	 4.280884e-001	 8.404015e+000	 7.664952e-002	 8.718329e+002
 5.898602e+002	 4.291824e+000	 1.514193e+004	 4.287319e-001	 8.451155e+000	 7.708389e-002	 8.726689e+002
 5.923002e+002	 4.316185e+000	 1.514602e+004	 4.315589e-001	 8.499125e+000	 7.752680e-002	 8.732906e+002
 5.959202e+002	 4.352271e+000	 1.515437e+004	 4.358604e-001	 8.570183e+000	 7.818189e-002	 8.743440e+002
 5.983402e+002	 4.376508e+000	 1.516054e+004	 4.373758e-001	 8.617909e+000	 7.862148e-002	 8.750847e+002
 6.007603e+002	 4.400340e+000	 1.516279e+004	 4.400210e-001	 8.664836e+000	 7.905458e-002	 8.755929e+002
 6.031802e+002	 4.425822e+000	 1.516738e+004	 4.407981e-001	 8.715014e+000	 7.951686e-002	 8.762623e+002
 6.056202e+002	 4.449186e+000	 1.517056e+004	 4.442731e-001	 8.761021e+000	 7.994082e-002	 8.768164e+002
 6.085002e+002	 4.479520e+000	 1.517948e+004	 4.460707e-001	 8.820754e+000	 8.048968e-002	 8.778143e+002
 6.115002e+002	 4.510175e+000	 1.518374e+004	 4.474477e-001	 8.881116e+000	 8.104532e-002	 8.785474e+002
 6.140803e+002	 4.533578e+000	 1.519092e+004	 4.500183e-001	 8.927201e+000	 8.146826e-002	 8.793347e+002
 6.165002e+002	 4.559112e+000	 1.519492e+004	 4.509003e-001	 8.977480e+000	 8.193053e-002	 8.799725e+002
 6.189202e+002	 4.580858e+000	 1.519901e+004	 4.575526e-001	 9.020300e+000	 8.232386e-002	 8.805552e+002
 6.213402e+002	 4.610116e+000	 1.520402e+004	 4.568139e-001	 9.077913e+000	 8.285298e-002	 8.813107e+002
 6.237603e+002	 4.631592e+000	 1.520752e+004	 4.579339e-001	 9.120203e+000	 8.324122e-002	 8.818556e+002
 6.265002e+002	 4.659297e+000	 1.521261e+004	 4.614295e-001	 9.174757e+000	 8.374169e-002	 8.825918e+002
 6.295002e+002	 4.690075e+000	 1.521637e+004	 4.641916e-001	 9.235364e+000	 8.429791e-002	 8.832997e+002
 6.322402e+002	 4.717171e+000	 1.522196e+004	 4.654479e-001	 9.288719e+000	 8.478670e-002	 8.840559e+002
 6.346602e+002	 4.740916e+000	 1.522555e+004	 4.686822e-001	 9.335475e+000	 8.521519e-002	 8.846425e+002
 6.370803e+002	 4.766178e+000	 1.522955e+004	 4.694862e-001	 9.385220e+000	 8.567083e-002	 8.852778e+002
 6.395002e+002	 4.790916e+000	 1.523489e+004	 4.721695e-001	 9.433933e+000	 8.611642e-002	 8.859827e+002
 6.419202e+002	 4.815114e+000	 1.523690e+004	 4.737227e-001	 9.481580e+000	 8.655295e-002	 8.864849e+002
 6.445002e+002	 4.842418e+000	 1.524199e+004	 4.757885e-001	 9.535346e+000	 8.704454e-002	 8.872165e+002
 6.475002e+002	 4.871247e+000	 1.524983e+004	 4.777809e-001	 9.592114e+000	 8.756265e-002	 8.881331e+002
 6.504002e+002	 4.900744e+000	 1.525425e+004	 4.820759e-001	 9.650197e+000	 8.809346e-002	 8.888615e+002
 6.528402e+002	 4.926381e+000	 1.525709e+004	 4.829185e-001	 9.700679e+000	 8.855485e-002	 8.894361e+002
 6.552603e+002	 4.951144e+000	 1.526060e+004	 4.842719e-001	 9.749441e+000	 8.900010e-002	 8.900358e+002
 6.576802e+002	 4.974374e+000	 1.526452e+004	 4.853212e-001	 9.795184e+000	 8.941744e-002	 8.906357e+002
 6.601002e+002	 5.000104e+000	 1.526669e+004	 4.899539e-001	 9.845851e+000	 8.988008e-002	 8.911733e+002
 6.625203e+002	 5.025885e+000	 1.526986e+004	 4.915079e-001	 9.896615e+000	 9.034313e-002	 8.917703e+002
 6.655002e+002	 5.053909e+000	 1.527195e+004	 4.931825e-001	 9.951800e+000	 9.084662e-002	 8.923400e+002
 6.685002e+002	 5.084819e+000	 1.527653e+004	 4.971397e-001	 1.001266e+001	 9.140103e-002	 8.931022e+002
 6.709802e+002	 5.111898e+000	 1.527870e+004	 5.001462e-001	 1.006599e+001	 9.188699e-002	 8.936620e+002
 6.734002e+002	 5.133972e+000	 1.528246e+004	 5.008848e-001	 1.010945e+001	 9.228240e-002	 8.942346e+002
 6.758203e+002	 5.158288e+000	 1.528538e+004	 5.033528e-001	 1.015734e+001	 9.271814e-002	 8.947944e+002
 6.782402e+002	 5.183251e+000	 1.528930e+004	 5.046010e-001	 1.020649e+001	 9.316501e-002	 8.954234e+002
 6.806602e+002	 5.207532e+000	 1.529414e+004	 5.076827e-001	 1.025430e+001	 9.359922e-002	 8.960954e+002
 6.835002e+002	 5.236318e+000	 1.529281e+004	 5.088691e-001	 1.031099e+001	 9.411563e-002	 8.964778e+002
 6.865002e+002	 5.266540e+000	 1.529514e+004	 5.131485e-001	 1.037050e+001	 9.465651e-002	 8.970985e+002
 6.891403e+002	 5.292830e+000	 1.530157e+004	 5.148717e-001	 1.042227e+001	 9.512563e-002	 8.978963e+002
 6.915602e+002	 5.317749e+000	 1.530416e+004	 5.146157e-001	 1.047133e+001	 9.557098e-002	 8.984471e+002
 6.939802e+002	 5.342218e+000	 1.530499e+004	 5.192529e-001	 1.051952e+001	 9.600858e-002	 8.988880e+002
 6.964002e+002	 5.366884e+000	 1.530641e+004	 5.203295e-001	 1.056809e+001	 9.644935e-002	 8.993664e+002
 6.988203e+002	 5.392626e+000	 1.531033e+004	 5.217610e-001	 1.061878e+001	 9.690849e-002	 9.000092e+002
 7.015002e+002	 5.418952e+000	 1.531233e+004	 5.227116e-001	 1.067061e+001	 9.737835e-002	 9.005487e+002
 7.045002e+002	 5.452898e+000	 1.531651e+004	 5.251289e-001	 1.073746e+001	 9.798348e-002	 9.013381e+002
 7.073002e+002	 5.479259e+000	 1.531667e+004	 5.290608e-001	 1.078937e+001	 9.845395e-002	 9.017704e+002
 7.097202e+002	 5.505164e+000	 1.531918e+004	 5.306646e-001	 1.084038e+001	 9.891547e-002	 9.023331e+002
 7.121403e+002	 5.528190e+000	 1.532176e+004	 5.306906e-001	 1.088572e+001	 9.932540e-002	 9.028546e+002
 7.145402e+002	 5.554470e+000	 1.532268e+004	 5.333921e-001	 1.093747e+001	 9.979360e-002	 9.033301e+002
 7.169802e+002	 5.580554e+000	 1.532594e+004	 5.347883e-001	 1.098883e+001	 1.002575e-001	 9.039402e+002
 7.195002e+002	 5.603346e+000	 1.532652e+004	 5.361579e-001	 1.103371e+001	 1.006632e-001	 9.043402e+002
 7.225002e+002	 5.634563e+000	 1.532886e+004	 5.384139e-001	 1.109518e+001	 1.012183e-001	 9.049788e+002
 7.254602e+002	 5.666239e+000	 1.533028e+004	 5.426402e-001	 1.115756e+001	 1.017815e-001	 9.055707e+002
 7.278802e+002	 5.689508e+000	 1.533078e+004	 5.431315e-001	 1.120338e+001	 1.021951e-001	 9.059735e+002
 7.303002e+002	 5.713735e+000	 1.533328e+004	 5.459017e-001	 1.125108e+001	 1.026251e-001	 9.065101e+002
 7.339202e+002	 5.751441e+000	 1.533503e+004	 5.499891e-001	 1.132533e+001	 1.032944e-001	 9.072187e+002
 7.363402e+002	 5.776070e+000	 1.533562e+004	 5.502197e-001	 1.137383e+001	 1.037316e-001	 9.076485e+002
 7.387603e+002	 5.800850e+000	 1.533879e+004	 5.510504e-001	 1.142262e+001	 1.041705e-001	 9.082340e+002
 7.411802e+002	 5.826858e+000	 1.533904e+004	 5.524256e-001	 1.147383e+001	 1.046318e-001	 9.086662e+002
 7.436002e+002	 5.851422e+000	 1.534071e+004	 5.555446e-001	 1.152221e+001	 1.050669e-001	 9.091594e+002
 7.465002e+002	 5.881859e+000	 1.534321e+004	 5.563758e-001	 1.158214e+001	 1.056057e-001	 9.097964e+002
 7.495002e+002	 5.912939e+000	 1.534705e+004	 5.580429e-001	 1.164334e+001	 1.061552e-001	 9.105231e+002
 7.520402e+002	 5.938703e+000	 1.534788e+004	 5.602800e-001	 1.169407e+001	 1.066111e-001	 9.109864e+002
 7.544602e+002	 5.963785e+000	 1.534955e+004	 5.617257e-001	 1.174346e+001	 1.070545e-001	 9.114883e+002
 7.568802e+002	 5.988651e+000	 1.534947e+004	 5.631192e-001	 1.179243e+001	 1.074944e-001	 9.118827e+002
 7.593203e+002	 6.011462e+000	 1.534755e+004	 5.657536e-001	 1.183734e+001	 1.078982e-001	 9.121350e+002
 7.617402e+002	 6.036046e+000	 1.534938e+004	 5.676748e-001	 1.188575e+001	 1.083322e-001	 9.126390e+002
 7.645002e+002	 6.064795e+000	 1.535406e+004	 5.693978e-001	 1.194236e+001	 1.088388e-001	 9.133787e+002
 7.675002e+002	 6.093239e+000	 1.535172e+004	 5.715877e-001	 1.199837e+001	 1.093416e-001	 9.136966e+002
 7.702003e+002	 6.122961e+000	 1.535331e+004	 5.717363e-001	 1.205690e+001	 1.098657e-001	 9.142685e+002
 7.726202e+002	 6.147382e+000	 1.535481e+004	 5.744411e-001	 1.210499e+001	 1.102961e-001	 9.147503e+002
 7.750402e+002	 6.171381e+000	 1.535598e+004	 5.754147e-001	 1.215225e+001	 1.107189e-001	 9.152055e+002
 7.774602e+002	 6.195689e+000	 1.535631e+004	 5.762745e-001	 1.220011e+001	 1.111472e-001	 9.156160e+002
 7.798802e+002	 6.220417e+000	 1.535706e+004	 5.786881e-001	 1.224880e+001	 1.115826e-001	 9.160581e+002
 7.825002e+002	 6.249447e+000	 1.535648e+004	 5.800678e-001	 1.230597e+001	 1.120939e-001	 9.164897e+002
 7.855002e+002	 6.278800e+000	 1.535656e+004	 5.814561e-001	 1.236377e+001	 1.126105e-001	 9.169664e+002
 7.883402e+002	 6.308036e+000	 1.536224e+004	 5.832995e-001	 1.242134e+001	 1.131232e-001	 9.177752e+002
 7.907603e+002	 6.332133e+000	 1.536123e+004	 5.862606e-001	 1.246879e+001	           0.0	           0.0
 7.931802e+002	 6.355000e+000	 1.536040e+004	 5.865686e-001	 1.251382e+001	           0.0	           0.0
 7.956002e+002	 6.379742e+000	 1.535831e+004	 5.873666e-001	 1.256254e+001	           0.0	           0.0
 7.980203e+002	 6.404444e+000	 1.535957e+004	 5.892088e-001	 1.261118e+001	           0.0	           0.0
 8.005002e+002	 6.429770e+000	 1.535539e+004	 5.882064e-001	 1.266105e+001	           0.0	           0.0
 8.035002e+002	 6.459939e+000	 1.535915e+004	 5.909508e-001	 1.272045e+001	           0.0	           0.0
 8.065002e+002	 6.491096e+000	 1.535957e+004	 5.923694e-001	 1.278180e+001	           0.0	           0.0
 8.095002e+002	 6.520400e+000	 1.535781e+004	 5.948963e-001	 1.283951e+001	           0.0	           0.0
 8.125002e+002	 6.552029e+000	 1.535723e+004	 5.957267e-001	 1.290179e+001	           0.0	           0.0
 8.149802e+002	 6.577271e+000	 1.535790e+004	 5.980843e-001	 1.295150e+001	           0.0	           0.0
 8.174002e+002	 6.602440e+000	 1.535773e+004	 5.983438e-001	 1.300106e+001	           0.0	           0.0
 8.198203e+002	 6.626923e+000	 1.535631e+004	 5.996567e-001	 1.304927e+001	           0.0	           0.0
 8.222402e+002	 6.650348e+000	 1.535815e+004	 6.000087e-001	 1.309539e+001	           0.0	           0.0
 8.246602e+002	 6.675924e+000	 1.535765e+004	 6.014332e-001	 1.314576e+001	           0.0	           0.0
 8.275002e+002	 6.703925e+000	 1.535740e+004	 6.018727e-001	 1.320089e+001	           0.0	           0.0
 8.305002e+002	 6.736532e+000	 1.535873e+004	 6.039373e-001	 1.326510e+001	           0.0	           0.0
 8.331403e+002	 6.758754e+000	 1.535464e+004	 6.053594e-001	 1.330886e+001	           0.0	           0.0
 8.355602e+002	 6.784873e+000	 1.535314e+004	 6.054241e-001	 1.336029e+001	           0.0	           0.0
 8.379802e+002	 6.809197e+000	 1.535239e+004	 6.081263e-001	 1.340819e+001	           0.0	           0.0
 8.404002e+002	 6.832457e+000	 1.535306e+004	 6.068838e-001	 1.345399e+001	           0.0	           0.0
 8.428203e+002	 6.858465e+000	 1.535322e+004	 6.097325e-001	 1.350520e+001	           0.0	           0.0
 8.455002e+002	 6.886659e+000	 1.535264e+004	 6.117136e-001	 1.356072e+001	           0.0	           0.0
 8.485002e+002	 6.917681e+000	 1.535205e+004	 6.126514e-001	 1.362181e+001	           0.0	           0.0
 8.513002e+002	 6.945526e+000	 1.534955e+004	 6.128840e-001	 1.367664e+001	           0.0	           0.0
 8.537202e+002	 6.972600e+000	 1.534630e+004	 6.141562e-001	 1.372995e+001	           0.0	           0.0
 8.561403e+002	 6.997117e+000	 1.534563e+004	 6.146203e-001	 1.377823e+001	           0.0	           0.0
 8.585602e+002	 7.021175e+000	 1.534530e+004	 6.154144e-001	 1.382560e+001	           0.0	           0.0
 8.609802e+002	 7.049076e+000	 1.534438e+004	 6.180496e-001	 1.388054e+001	           0.0	           0.0
 8.635002e+002	 7.075423e+000	 1.534204e+004	 6.153470e-001	 1.393242e+001	           0.0	           0.0
 8.665002e+002	 7.104739e+000	 1.533703e+004	 6.178710e-001	 1.399015e+001	           0.0	           0.0
 8.694402e+002	 7.136271e+000	 1.534037e+004	 6.197060e-001	 1.405224e+001	           0.0	           0.0
 8.718802e+002	 7.161607e+000	 1.533712e+004	 6.187035e-001	 1.410213e+001	           0.0	           0.0
 8.743002e+002	 7.187522e+000	 1.533436e+004	 6.214215e-001	 1.415316e+001	           0.0	           0.0
 8.779202e+002	 7.223985e+000	 1.533211e+004	 6.211057e-001	 1.422496e+001	           0.0	           0.0
 8.803402e+002	 7.248726e+000	 1.533228e+004	 6.222830e-001	 1.427368e+001	           0.0	           0.0
 8.827603e+002	 7.274736e+000	 1.533069e+004	 6.228207e-001	 1.432489e+001	           0.0	           0.0
 8.851802e+002	 7.299754e+000	 1.532811e+004	 6.244068e-001	 1.437416e+001	           0.0	           0.0
 8.876002e+002	 7.323699e+000	 1.532418e+004	 6.245093e-001	 1.442131e+001	           0.0	           0.0
 8.905002e+002	 7.355714e+000	 1.532377e+004	 6.259825e-001	 1.448435e+001	           0.0	           0.0
 8.935002e+002	 7.387496e+000	 1.531709e+004	 6.263733e-001	 1.454693e+001	           0.0	           0.0
 8.960602e+002	 7.414193e+000	 1.531400e+004	 6.277012e-001	 1.459950e+001	           0.0	           0.0
 8.984802e+002	 7.439006e+000	 1.531258e+004	 6.268587e-001	 1.464836e+001	           0.0	           0.0
 9.009002e+002	 7.465144e+000	 1.530816e+004	 6.276176e-001	 1.469983e+001	           0.0	           0.0
 9.033203e+002	 7.488306e+000	 1.530624e+004	 6.279075e-001	 1.474544e+001	           0.0	           0.0
 9.057402e+002	 7.513783e+000	 1.530215e+004	 6.292499e-001	 1.479561e+001	           0.0	           0.0
 9.085002e+002	 7.544616e+000	 1.529765e+004	 6.297610e-001	 1.485632e+001	           0.0	           0.0
 9.115002e+002	 7.573861e+000	 1.529331e+004	 6.294328e-001	 1.491391e+001	           0.0	           0.0
 9.142202e+002	 7.605156e+000	 1.528972e+004	 6.287147e-001	 1.497553e+001	           0.0	           0.0
 9.166403e+002	 7.630187e+000	 1.528772e+004	 6.284598e-001	 1.502482e+001	           0.0	           0.0
 9.190402e+002	 7.655899e+000	 1.528371e+004	 6.299248e-001	 1.507545e+001	           0.0	           0.0
 9.214602e+002	 7.683388e+000	 1.528062e+004	 6.305426e-001	 1.512958e+001	           0.0	           0.0
 9.238802e+002	 7.707963e+000	 1.527512e+004	 6.329039e-001	 1.517797e+001	           0.0	           0.0
 9.265002e+002	 7.736646e+000	 1.526685e+004	 6.337984e-001	 1.523445e+001	           0.0	           0.0
 9.295002e+002	 7.769909e+000	 1.526051e+004	 6.330845e-001	 1.529995e+001	           0.0	           0.0
 9.323602e+002	 7.800369e+000	 1.525359e+004	 6.323975e-001	 1.535993e+001	           0.0	           0.0
 9.347802e+002	 7.826750e+000	 1.524633e+004	 6.317604e-001	 1.541188e+001	           0.0	           0.0
 9.372003e+002	 7.852608e+000	 1.524057e+004	 6.344894e-001	 1.546280e+001	           0.0	           0.0
 9.396202e+002	 7.880493e+000	 1.523448e+004	 6.321568e-001	 1.551771e+001	           0.0	           0.0
 9.420402e+002	 7.907207e+000	 1.522738e+004	 6.344934e-001	 1.557031e+001	           0.0	           0.0
 9.445002e+002	 7.935780e+000	 1.521929e+004	 6.329712e-001	 1.562657e+001	           0.0	           0.0
 9.475002e+002	 7.970345e+000	 1.520744e+004	 6.337171e-001	 1.569464e+001	           0.0	           0.0
 9.505002e+002	 8.006600e+000	 1.519167e+004	 6.347211e-001	 1.576603e+001	           0.0	           0.0
 9.529602e+002	 8.034880e+000	 1.518207e+004	 6.343336e-001	 1.582171e+001	           0.0	           0.0
 9.553802e+002	 8.065783e+000	 1.517122e+004	 6.338851e-001	 1.588257e+001	           0.0	           0.0
 9.578002e+002	 8.095754e+000	 1.515645e+004	 6.336579e-001	 1.594158e+001	           0.0	           0.0
 9.602003e+002	 8.126152e+000	 1.514444e+004	 6.358646e-001	 1.600144e+001	           0.0	           0.0
 9.626202e+002	 8.156986e+000	 1.512683e+004	 6.347333e-001	 1.606216e+001	           0.0	           0.0
 9.655002e+002	 8.195537e+000	 1.510705e+004	 6.364015e-001	 1.613807e+001	           0.0	           0.0
 9.685002e+002	 8.235878e+000	 1.508269e+004	 6.339586e-001	 1.621751e+001	           0.0	           0.0
 9.711002e+002	 8.271953e+000	 1.505832e+004	 6.337019e-001	 1.628854e+001	           0.0	           0.0
 9.735203e+002	 8.304461e+000	 1.503504e+004	 6.348520e-001	 1.635255e+001	           0.0	           0.0
 9.759402e+002	 8.340081e+000	 1.500858e+004	 6.343710e-001	 1.642270e+001	           0.0	           0.0
 9.783402e+002	 8.373801e+000	 1.497771e+004	 6.348841e-001	 1.648910e+001	           0.0	           0.0
 9.807603e+002	 8.412331e+000	 1.494166e+004	 6.342123e-001	 1.656496e+001	           0.0	           0.0
 9.835002e+002	 8.458385e+000	 1.487373e+004	 6.347676e-001	 1.665565e+001	           0.0	           0.0
 9.855602e+002	 8.500641e+000	 1.470016e+004	 6.345419e-001	 1.673886e+001	           0.0	           0.0