File: DP800 Tensile Tests/Fehlemann_Test_WP_KL_2024_1013.TRA
$Fehlemann_Test_WP_KL_2024_101.ZSE
Material:                               St
Auftrags-Nr.:                           WP_KL_2024_101
Probe:                                  1_0°_C
Vorkraft:                               100 N
Probengeometrie:                        H12,5x50
Messlänge:                              49.9451 mm
Probendicke a0:                         1.49 mm
Probenbreite b0:                        12.6 mm
Prüfgeschwindigkeit:                    1 mm/min
Datum:                                  26.09.2024
Maschinendaten:                         4204 WN:800315
Traversenwegaufnehmer WN:800315
Videoextensometer
Videoextensometer - Querdehnung
Kraftsensor ID:0 WN:800316 50 kN

Bemerkung:
$
      Prüfzeit	   Standardweg	 Spannung       Breitenänderung	       Dehnung	 wahre Dehnung	wahre Spannung
 2.005859e-002	 1.551644e-004	 1.973533e+002	-2.947827e-004	 3.106701e-004	 0.000000e+000	 1.051282e+001
 2.200586e-001	-9.437711e-004	 1.974368e+002	-8.110579e-004	-1.889619e-003	 0.000000e+000	 1.051704e+001
 9.000586e-001	 9.123902e-004	 3.478096e+002	-1.162001e-003	 1.826788e-003	 0.000000e+000	 1.852777e+001
 1.220059e+000	 2.745777e-003	 4.395187e+002	-9.379288e-004	 5.497596e-003	 0.000000e+000	 2.341396e+001
 1.580059e+000	 4.702906e-003	 5.401567e+002	 7.135550e-004	 9.416159e-003	 0.000000e+000	 2.877626e+001
 2.120059e+000	 6.116487e-003	 6.927827e+002	 5.255505e-005	 1.224643e-002	 0.000000e+000	 3.690829e+001
 2.620059e+000	 7.418229e-003	 8.333922e+002	-8.097675e-004	 1.485278e-002	 0.000000e+000	 4.440047e+001
 3.040059e+000	 9.175842e-003	 9.472984e+002	 1.082936e-003	 1.837187e-002	 0.000000e+000	 5.047080e+001
 3.200059e+000	 1.095529e-002	 9.941960e+002	 1.358730e-005	 2.193469e-002	 0.000000e+000	 5.297134e+001
 3.820059e+000	 1.170442e-002	 1.169937e+003	 7.085550e-004	 2.343460e-002	 0.000000e+000	 6.233585e+001
 4.360059e+000	 1.363104e-002	 1.320143e+003	 8.187486e-004	 2.729206e-002	 0.000000e+000	 7.034175e+001
 4.580059e+000	 1.550981e-002	 1.381227e+003	 1.357910e-003	 3.105374e-002	 0.000000e+000	 7.359926e+001
 5.120059e+000	 1.628810e-002	 1.532184e+003	 1.151781e-003	 3.261203e-002	 0.000000e+000	 8.164435e+001
 5.380059e+000	 1.727613e-002	 1.604032e+003	 2.138362e-003	 3.459027e-002	 0.000000e+000	 8.547458e+001
 5.740058e+000	 1.923807e-002	 1.701416e+003	 1.910716e-003	 3.851846e-002	 0.000000e+000	 9.066744e+001
 6.000059e+000	 2.089939e-002	 1.771429e+003	 2.024200e-003	 4.184476e-002	 7.247702e-006	 9.440152e+001
 6.440059e+000	 2.272784e-002	 1.888589e+003	 2.347200e-003	 4.550569e-002	 1.202199e-005	 1.006488e+002
 6.960059e+000	 2.445768e-002	 2.022106e+003	 1.978523e-003	 4.896917e-002	 1.037775e-005	 1.077681e+002
 7.420059e+000	 2.615634e-002	 2.139684e+003	 1.727749e-003	 5.237023e-002	 1.244002e-005	 1.140383e+002
 8.120059e+000	 2.776971e-002	 2.308415e+003	 2.829103e-003	 5.560052e-002	 0.000000e+000	 1.230351e+002
 8.580059e+000	 2.976010e-002	 2.422071e+003	 1.267523e-003	 5.958567e-002	 7.864221e-006	 1.290979e+002
 9.340058e+000	 3.131500e-002	 2.596226e+003	 1.637620e-003	 6.269890e-002	 0.000000e+000	 1.383848e+002
 9.660059e+000	 3.293234e-002	 2.667991e+003	 1.908124e-003	 6.593714e-002	 4.557258e-006	 1.422146e+002
 1.030006e+001	 3.463703e-002	 2.805930e+003	 2.914265e-003	 6.935026e-002	 1.207758e-006	 1.495724e+002
 1.076006e+001	 3.520784e-002	 2.897973e+003	 3.098458e-003	 7.049314e-002	 0.000000e+000	 1.544806e+002
 1.112006e+001	 3.657126e-002	 2.970490e+003	 4.062878e-003	 7.322298e-002	 0.000000e+000	 1.583505e+002
 1.134006e+001	 3.806010e-002	 3.012130e+003	 4.928458e-003	 7.620393e-002	 1.371580e-005	 1.605751e+002
 1.156006e+001	 3.756059e-002	 3.054605e+003	 3.698684e-003	 7.520382e-002	 0.000000e+000	 1.628378e+002
 1.184006e+001	 3.816465e-002	 3.105842e+003	 2.481749e-003	 7.641326e-002	 0.000000e+000	 1.655712e+002
 1.238006e+001	 4.004645e-002	 3.203392e+003	 3.465458e-003	 8.018101e-002	 1.516822e-006	 1.707780e+002
 1.326006e+001	 4.171716e-002	 3.353598e+003	 2.868200e-003	 8.352611e-002	 0.000000e+000	 1.787917e+002
 1.338006e+001	 4.351007e-002	 3.375211e+003	 2.845297e-003	 8.711586e-002	 2.417838e-005	 1.799504e+002
 1.412006e+001	 4.306197e-002	 3.494041e+003	 2.117039e-003	 8.621868e-002	 0.000000e+000	 1.862841e+002
 1.458006e+001	 4.466000e-002	 3.571647e+003	 5.186523e-003	 8.941826e-002	 0.000000e+000	 1.904278e+002
 1.566006e+001	 4.619415e-002	 3.737124e+003	 5.067874e-003	 9.248994e-002	 0.000000e+000	 1.992566e+002
 1.586006e+001	 4.792339e-002	 3.769085e+003	 5.615813e-003	 9.595221e-002	 5.518812e-006	 2.009676e+002
 2.012006e+001	 5.607362e-002	 4.364568e+003	 5.579200e-003	 1.122706e-001	 6.897888e-006	 2.327567e+002
 2.464006e+001	 6.825381e-002	 4.921332e+003	 6.877623e-003	 1.366578e-001	 9.948084e-005	 2.625121e+002
 3.094006e+001	 7.846084e-002	 5.600596e+003	 7.895393e-003	 1.570943e-001	 1.192740e-004	 2.988062e+002
 3.544006e+001	 8.847084e-002	 6.032689e+003	 1.052917e-002	 1.771363e-001	 2.022725e-004	 3.219238e+002
 4.112006e+001	 1.003873e-001	 6.528619e+003	 1.159868e-002	 2.009954e-001	 3.060832e-004	 3.484712e+002
 4.712006e+001	 1.169444e-001	 7.001684e+003	 1.270401e-002	 2.341461e-001	 5.089654e-004	 3.738452e+002
 5.168006e+001	 1.287738e-001	 7.328466e+003	 1.442126e-002	 2.578310e-001	 6.569352e-004	 3.913857e+002
 5.612006e+001	 1.415531e-001	 7.614608e+003	 1.701323e-002	 2.834177e-001	 8.349188e-004	 4.067712e+002
 6.212006e+001	 1.570596e-001	 7.961667e+003	 1.969343e-002	 3.144648e-001	 1.050883e-003	 4.254428e+002
 6.512006e+001	 1.690600e-001	 8.124808e+003	 1.823836e-002	 3.384919e-001	 1.246601e-003	 4.342644e+002
 7.112006e+001	 1.875193e-001	 8.420630e+003	 1.998494e-002	 3.754512e-001	 1.535410e-003	 4.502416e+002
 7.470006e+001	 1.996046e-001	 8.585022e+003	 2.453981e-002	 3.996484e-001	 1.732392e-003	 4.591421e+002
 8.012006e+001	 2.188431e-001	 8.815839e+003	 2.485172e-002	 4.381677e-001	 2.054258e-003	 4.716675e+002
 8.312006e+001	 2.295790e-001	 8.935920e+003	 2.534649e-002	 4.596630e-001	 2.236192e-003	 4.781944e+002
 8.828006e+001	 2.499145e-001	 9.126515e+003	 2.819672e-002	 5.003789e-001	 2.590705e-003	 4.885918e+002
 9.212006e+001	 2.655458e-001	 9.260198e+003	 2.876920e-002	 5.316758e-001	 2.866596e-003	 4.959029e+002
 9.574006e+001	 2.802670e-001	 9.385203e+003	 3.147094e-002	 5.611505e-001	 3.126597e-003	 5.027446e+002
 1.008001e+002	 3.005427e-001	 9.544004e+003	 3.234717e-002	 6.017466e-001	 3.488210e-003	 5.114575e+002
 1.041201e+002	 3.144942e-001	 9.644309e+003	 3.514046e-002	 6.296803e-001	 3.739383e-003	 5.169763e+002
 1.079601e+002	 3.309181e-001	 9.763305e+003	 3.578717e-002	 6.625642e-001	 4.034738e-003	 5.235260e+002
 1.126601e+002	 3.509611e-001	 9.897155e+003	 3.732575e-002	 7.026944e-001	 4.398135e-003	 5.309149e+002
 1.161201e+002	 3.662603e-001	 9.993537e+003	 3.928239e-002	 7.333263e-001	 4.676997e-003	 5.362482e+002
 1.191601e+002	 3.812685e-001	 1.007774e+004	 4.122769e-002	 7.633758e-001	 4.953279e-003	 5.409276e+002
 1.236401e+002	 4.014283e-001	 1.020307e+004	 4.341431e-002	 8.037398e-001	 5.320969e-003	 5.478745e+002
 1.277001e+002	 4.218317e-001	 1.030897e+004	 4.469536e-002	 8.445914e-001	 5.698624e-003	 5.537851e+002
 1.311201e+002	 4.380998e-001	 1.039634e+004	 4.515152e-002	 8.771635e-001	 5.998844e-003	 5.586589e+002
 1.341201e+002	 4.536353e-001	 1.047211e+004	 4.791130e-002	 9.082687e-001	 6.287529e-003	 5.629040e+002
 1.373201e+002	 4.721342e-001	 1.054938e+004	 4.846059e-002	 9.453072e-001	 6.634667e-003	 5.672657e+002
 1.413401e+002	 4.924387e-001	 1.064526e+004	 5.149842e-002	 9.859607e-001	 7.012562e-003	 5.726520e+002
 1.451601e+002	 5.129570e-001	 1.073789e+004	 5.502756e-002	 1.027042e+000	 7.395443e-003	 5.778698e+002
 1.486801e+002	 5.330508e-001	 1.081992e+004	 5.714588e-002	 1.067274e+000	 7.772601e-003	 5.825161e+002
 1.521201e+002	 5.522470e-001	 1.089844e+004	 5.960485e-002	 1.105709e+000	 8.132736e-003	 5.869668e+002
 1.551201e+002	 5.685850e-001	 1.096445e+004	 6.359123e-002	 1.138421e+000	 8.439369e-003	 5.907128e+002
 1.581201e+002	 5.872304e-001	 1.103096e+004	 6.390710e-002	 1.175753e+000	 8.791567e-003	 5.945153e+002
 1.611401e+002	 6.054251e-001	 1.109672e+004	 6.286488e-002	 1.212182e+000	 9.134902e-003	 5.982746e+002
 1.641401e+002	 6.234397e-001	 1.116247e+004	 6.689431e-002	 1.248251e+000	 9.474548e-003	 6.020343e+002
 1.672801e+002	 6.444899e-001	 1.123090e+004	 7.014022e-002	 1.290398e+000	 9.873544e-003	 6.059770e+002
 1.703801e+002	 6.647502e-001	 1.129415e+004	 7.134523e-002	 1.330963e+000	 1.025812e-002	 6.096339e+002
 1.737001e+002	 6.851369e-001	 1.136125e+004	 7.233543e-002	 1.371781e+000	 1.064402e-002	 6.135024e+002
 1.768401e+002	 7.055416e-001	 1.142392e+004	 7.863239e-002	 1.412635e+000	 1.103131e-002	 6.171351e+002
 1.799601e+002	 7.258164e-001	 1.148600e+004	 7.906626e-002	 1.453230e+000	 1.141604e-002	 6.207374e+002
 1.829001e+002	 7.460275e-001	 1.154341e+004	 8.141537e-002	 1.493696e+000	 1.180062e-002	 6.240889e+002
 1.858001e+002	 7.662908e-001	 1.159957e+004	 8.126478e-002	 1.534268e+000	 1.218641e-002	 6.273759e+002
 1.888001e+002	 7.864526e-001	 1.165607e+004	 8.847972e-002	 1.574635e+000	 1.256996e-002	 6.306821e+002
 1.915201e+002	 8.068241e-001	 1.170881e+004	 8.946147e-002	 1.615423e+000	 1.295852e-002	 6.337900e+002
 1.944001e+002	 8.270949e-001	 1.175988e+004	 9.215537e-002	 1.656009e+000	 1.334539e-002	 6.368086e+002
 1.972601e+002	 8.473015e-001	 1.181412e+004	 9.508420e-002	 1.696467e+000	 1.372998e-002	 6.400004e+002
 2.001401e+002	 8.700926e-001	 1.186293e+004	 9.953725e-002	 1.742100e+000	 1.416690e-002	 6.429333e+002
 2.031401e+002	 8.920183e-001	 1.191576e+004	 9.907400e-002	 1.785999e+000	 1.458549e-002	 6.460748e+002
 2.061401e+002	 9.152158e-001	 1.197042e+004	 1.006488e-001	 1.832445e+000	 1.502849e-002	 6.493345e+002
 2.091401e+002	 9.379027e-001	 1.202123e+004	 1.029184e-001	 1.877869e+000	 1.546225e-002	 6.523820e+002
 2.118201e+002	 9.586737e-001	 1.206605e+004	 1.069995e-001	 1.919456e+000	 1.585968e-002	 6.550812e+002
 2.144001e+002	 9.790547e-001	 1.210677e+004	 1.097858e-001	 1.960263e+000	 1.625036e-002	 6.575552e+002
 2.173601e+002	 9.995217e-001	 1.215433e+004	 1.129239e-001	 2.001242e+000	 1.664075e-002	 6.604040e+002
 2.181401e+002	 1.005790e+000	 1.216535e+004	 1.140049e-001	 2.013793e+000	 1.676123e-002	 6.610838e+002
 2.210601e+002	 1.030587e+000	 1.221425e+004	 1.164985e-001	 2.063442e+000	 1.723629e-002	 6.640641e+002
 2.234801e+002	 1.048217e+000	 1.225213e+004	 1.209690e-001	 2.098740e+000	 1.757306e-002	 6.663542e+002
 2.259001e+002	 1.066454e+000	 1.228852e+004	 1.212330e-001	 2.135255e+000	 1.792208e-002	 6.685720e+002
 2.283201e+002	 1.086691e+000	 1.232774e+004	 1.251647e-001	 2.175773e+000	 1.830952e-002	 6.709719e+002
 2.307401e+002	 1.105585e+000	 1.236153e+004	 1.267639e-001	 2.213603e+000	 1.867187e-002	 6.730604e+002
 2.331601e+002	 1.125255e+000	 1.239592e+004	 1.286933e-001	 2.252986e+000	 1.904918e-002	 6.751924e+002
 2.361401e+002	 1.147726e+000	 1.244039e+004	 1.324814e-001	 2.297977e+000	 1.947865e-002	 6.779132e+002
 2.391401e+002	 1.172342e+000	 1.248329e+004	 1.351516e-001	 2.347263e+000	 1.995046e-002	 6.805783e+002
 2.416001e+002	 1.193864e+000	 1.251600e+004	 1.366235e-001	 2.390355e+000	 2.036407e-002	 6.826489e+002
 2.440201e+002	 1.213268e+000	 1.254921e+004	 1.383095e-001	 2.429205e+000	 2.073583e-002	 6.847200e+002
 2.464401e+002	 1.231175e+000	 1.258167e+004	 1.425508e-001	 2.465058e+000	 2.107831e-002	 6.867315e+002
 2.488601e+002	 1.252388e+000	 1.261063e+004	 1.430982e-001	 2.507532e+000	 2.148640e-002	 6.885973e+002
 2.513001e+002	 1.272269e+000	 1.264125e+004	 1.458478e-001	 2.547338e+000	 2.186778e-002	 6.905376e+002
 2.541401e+002	 1.296663e+000	 1.268030e+004	 1.477321e-001	 2.596179e+000	 2.233513e-002	 6.930008e+002
 2.571400e+002	 1.321686e+000	 1.271485e+004	 1.507806e-001	 2.646279e+000	 2.281577e-002	 6.952282e+002
 2.597801e+002	 1.344804e+000	 1.274815e+004	 1.530761e-001	 2.692567e+000	 2.325926e-002	 6.973630e+002
 2.622001e+002	 1.365438e+000	 1.278044e+004	 1.547569e-001	 2.733881e+000	 2.365426e-002	 6.994109e+002
 2.646201e+002	 1.386721e+000	 1.280798e+004	 1.562735e-001	 2.776494e+000	 2.406303e-002	 7.012086e+002
 2.670401e+002	 1.406647e+000	 1.283543e+004	 1.604784e-001	 2.816388e+000	 2.444514e-002	 7.029845e+002
 2.694601e+002	 1.428249e+000	 1.286322e+004	 1.609927e-001	 2.859639e+000	 2.485975e-002	 7.048027e+002
 2.721400e+002	 1.449956e+000	 1.288834e+004	 1.648965e-001	 2.903101e+000	 2.527695e-002	 7.064773e+002
 2.751400e+002	 1.477106e+000	 1.292447e+004	 1.645589e-001	 2.957462e+000	 2.579729e-002	 7.088322e+002
 2.779401e+002	 1.502594e+000	 1.295693e+004	 1.683624e-001	 3.008494e+000	 2.628589e-002	 7.109647e+002
 2.803600e+002	 1.522195e+000	 1.298230e+004	 1.706778e-001	 3.047739e+000	 2.666138e-002	 7.126281e+002
 2.827601e+002	 1.541623e+000	 1.300859e+004	 1.743142e-001	 3.086638e+000	 2.703311e-002	 7.143405e+002
 2.851801e+002	 1.562528e+000	 1.303220e+004	 1.764497e-001	 3.128494e+000	 2.743418e-002	 7.159279e+002
 2.876001e+002	 1.584267e+000	 1.305657e+004	 1.789331e-001	 3.172019e+000	 2.785112e-002	 7.175692e+002
 2.901400e+002	 1.606642e+000	 1.308211e+004	 1.809373e-001	 3.216818e+000	 2.827996e-002	 7.192847e+002
 2.931400e+002	 1.634492e+000	 1.311615e+004	 1.811446e-001	 3.272579e+000	 2.881290e-002	 7.215462e+002
 2.960800e+002	 1.662109e+000	 1.314302e+004	 1.854344e-001	 3.327875e+000	 2.934291e-002	 7.234115e+002
 2.985001e+002	 1.681433e+000	 1.316372e+004	 1.874917e-001	 3.366565e+000	 2.971309e-002	 7.248219e+002
 3.009200e+002	 1.703095e+000	 1.318900e+004	 1.900298e-001	 3.409938e+000	 3.012737e-002	 7.265188e+002
 3.045601e+002	 1.734006e+000	 1.322221e+004	 1.932484e-001	 3.471828e+000	 3.071897e-002	 7.287842e+002
 3.069801e+002	 1.755163e+000	 1.324491e+004	 1.960374e-001	 3.514187e+000	 3.112369e-002	 7.303341e+002
 3.094001e+002	 1.777898e+000	 1.326828e+004	 1.971796e-001	 3.559707e+000	 3.155869e-002	 7.319442e+002
 3.118201e+002	 1.798686e+000	 1.328939e+004	 1.995219e-001	 3.601330e+000	 3.195635e-002	 7.334035e+002
 3.142401e+002	 1.818754e+000	 1.331025e+004	 2.045205e-001	 3.641510e+000	 3.233995e-002	 7.348397e+002
 3.171400e+002	 1.845359e+000	 1.333662e+004	 2.055994e-001	 3.694777e+000	 3.284861e-002	 7.366739e+002
 3.201400e+002	 1.874963e+000	 1.336458e+004	 2.097423e-001	 3.754051e+000	 3.341467e-002	 7.386400e+002
 3.227001e+002	 1.897786e+000	 1.338319e+004	 2.124688e-001	 3.799747e+000	 3.385164e-002	 7.399942e+002
 3.251001e+002	 1.917596e+000	 1.340346e+004	 2.143158e-001	 3.839412e+000	 3.422968e-002	 7.413986e+002
 3.275201e+002	 1.939259e+000	 1.342274e+004	 2.158064e-001	 3.882784e+000	 3.464367e-002	 7.427749e+002
 3.299401e+002	 1.961472e+000	 1.344227e+004	 2.195201e-001	 3.927259e+000	 3.506805e-002	 7.441740e+002
 3.323600e+002	 1.981842e+000	 1.346338e+004	 2.202439e-001	 3.968044e+000	 3.545623e-002	 7.456352e+002
 3.351400e+002	 2.008702e+000	 1.348683e+004	 2.224484e-001	 4.021824e+000	 3.596902e-002	 7.473202e+002
 3.381400e+002	 2.034603e+000	 1.350686e+004	 2.249548e-001	 4.073683e+000	 3.646391e-002	 7.488031e+002
 3.408201e+002	 2.057951e+000	 1.353072e+004	 2.282265e-001	 4.120431e+000	 3.690830e-002	 7.504631e+002
 3.432401e+002	 2.082602e+000	 1.354850e+004	 2.336675e-001	 4.169786e+000	 3.737921e-002	 7.518051e+002
 3.456601e+002	 2.104128e+000	 1.356936e+004	 2.328063e-001	 4.212885e+000	 3.778883e-002	 7.532742e+002
 3.481001e+002	 2.125977e+000	 1.358321e+004	 2.366840e-001	 4.256631e+000	 3.820637e-002	 7.543597e+002
 3.505201e+002	 2.149459e+000	 1.359848e+004	 2.373003e-001	 4.303647e+000	 3.865480e-002	 7.555484e+002
 3.531400e+002	 2.171800e+000	 1.362135e+004	 2.375533e-001	 4.348377e+000	 3.907908e-002	 7.571433e+002
 3.561400e+002	 2.200971e+000	 1.364079e+004	 2.414998e-001	 4.406784e+000	 3.963552e-002	 7.586484e+002
 3.589801e+002	 2.224953e+000	 1.366282e+004	 2.455416e-001	 4.454801e+000	 4.009118e-002	 7.602231e+002
 3.614001e+002	 2.247876e+000	 1.367826e+004	 2.480820e-001	 4.500698e+000	 4.052799e-002	 7.614165e+002
 3.638201e+002	 2.270619e+000	 1.369278e+004	 2.504462e-001	 4.546234e+000	 4.096138e-002	 7.625569e+002
 3.662401e+002	 2.293131e+000	 1.371122e+004	 2.544719e-001	 4.591307e+000	 4.138912e-002	 7.639131e+002
 3.686601e+002	 2.315346e+000	 1.372566e+004	 2.574066e-001	 4.635787e+000	 4.181203e-002	 7.650426e+002
 3.711400e+002	 2.337998e+000	 1.374234e+004	 2.583262e-001	 4.681139e+000	 4.224254e-002	 7.663048e+002
 3.741400e+002	 2.366148e+000	 1.376312e+004	 2.614618e-001	 4.737503e+000	 4.277731e-002	 7.678767e+002
 3.771001e+002	 2.394058e+000	 1.378357e+004	 2.645177e-001	 4.793382e+000	 4.330724e-002	 7.694276e+002
 3.795201e+002	 2.415822e+000	 1.379709e+004	 2.661946e-001	 4.836959e+000	 4.372093e-002	 7.705024e+002
 3.819401e+002	 2.438587e+000	 1.381060e+004	 2.687033e-001	 4.882539e+000	 4.415363e-002	 7.715927e+002
 3.843600e+002	 2.462180e+000	 1.382346e+004	 2.713233e-001	 4.929776e+000	 4.460215e-002	 7.726585e+002
 3.867801e+002	 2.483750e+000	 1.383764e+004	 2.744700e-001	 4.972965e+000	 4.501143e-002	 7.737697e+002
 3.892001e+002	 2.505531e+000	 1.385141e+004	 2.783595e-001	 5.016575e+000	 4.542467e-002	 7.748615e+002
 3.921400e+002	 2.533250e+000	 1.386785e+004	 2.819132e-001	 5.072073e+000	 4.595060e-002	 7.761910e+002
 3.951400e+002	 2.562066e+000	 1.388471e+004	 2.841794e-001	 5.129768e+000	 4.649712e-002	 7.775611e+002
 3.976601e+002	 2.585769e+000	 1.390023e+004	 2.864054e-001	 5.177227e+000	 4.694602e-002	 7.787818e+002
 4.000601e+002	 2.609322e+000	 1.391525e+004	 2.895798e-001	 5.224385e+000	 4.739198e-002	 7.799728e+002
 4.024801e+002	 2.632203e+000	 1.392735e+004	 2.914299e-001	 5.270197e+000	 4.782567e-002	 7.809910e+002
 4.049001e+002	 2.655835e+000	 1.394153e+004	 2.937306e-001	 5.317513e+000	 4.827295e-002	 7.821378e+002
 4.073201e+002	 2.674864e+000	 1.395522e+004	 2.989810e-001	 5.355612e+000	 4.863238e-002	 7.831888e+002
 4.101400e+002	 2.706471e+000	 1.396632e+004	 3.008612e-001	 5.418897e+000	 4.923213e-002	 7.842824e+002
 4.131400e+002	 2.733872e+000	 1.398184e+004	 3.009844e-001	 5.473760e+000	 4.975026e-002	 7.855626e+002
 4.158000e+002	 2.758916e+000	 1.399778e+004	 3.048972e-001	 5.523902e+000	 5.022311e-002	 7.868320e+002
 4.182201e+002	 2.780244e+000	 1.401046e+004	 3.081014e-001	 5.566605e+000	 5.062587e-002	 7.878636e+002
 4.206400e+002	 2.805012e+000	 1.402081e+004	 3.106151e-001	 5.616196e+000	 5.109451e-002	 7.888159e+002
 4.230401e+002	 2.826465e+000	 1.403316e+004	 3.148344e-001	 5.659149e+000	 5.149938e-002	 7.898318e+002
 4.254601e+002	 2.849206e+000	 1.404593e+004	 3.172302e-001	 5.704681e+000	 5.192846e-002	 7.908910e+002
 4.281400e+002	 2.875278e+000	 1.405669e+004	 3.193305e-001	 5.756882e+000	 5.242115e-002	 7.918880e+002
 4.311400e+002	 2.903743e+000	 1.407296e+004	 3.208262e-001	 5.813874e+000	 5.295762e-002	 7.932319e+002
 4.339401e+002	 2.930443e+000	 1.408381e+004	 3.236631e-001	 5.867333e+000	 5.346172e-002	 7.942444e+002
 4.363401e+002	 2.953678e+000	 1.409625e+004	 3.277873e-001	 5.913854e+000	 5.389941e-002	 7.952949e+002
 4.387601e+002	 2.977170e+000	 1.410726e+004	 3.316478e-001	 5.960891e+000	 5.434217e-002	 7.962698e+002
 4.411801e+002	 3.000286e+000	 1.411903e+004	 3.327569e-001	 6.007173e+000	 5.477738e-002	 7.972820e+002
 4.436001e+002	 3.022034e+000	 1.413138e+004	 3.352263e-001	 6.050717e+000	 5.518635e-002	 7.983072e+002
 4.461400e+002	 3.048015e+000	 1.414089e+004	 3.369229e-001	 6.102736e+000	 5.567605e-002	 7.992364e+002
 4.491400e+002	 3.075837e+000	 1.415441e+004	 3.402823e-001	 6.158442e+000	 5.619933e-002	 8.004204e+002
 4.520601e+002	 3.106981e+000	 1.416576e+004	 3.425432e-001	 6.220798e+000	 5.678573e-002	 8.015327e+002
 4.544801e+002	 3.127723e+000	 1.417460e+004	 3.464773e-001	 6.262327e+000	 5.717574e-002	 8.023468e+002
 4.569001e+002	 3.149641e+000	 1.418320e+004	 3.500891e-001	 6.306212e+000	 5.758791e-002	 8.031648e+002
 4.593201e+002	 3.175242e+000	 1.419313e+004	 3.517670e-001	 6.357470e+000	 5.806915e-002	 8.041147e+002
 4.617401e+002	 3.199239e+000	 1.420481e+004	 3.538595e-001	 6.405517e+000	 5.851941e-002	 8.051401e+002
 4.641601e+002	 3.222789e+000	 1.421391e+004	 3.563111e-001	 6.452668e+000	 5.896169e-002	 8.060126e+002
 4.671400e+002	 3.250926e+000	 1.422400e+004	 3.593734e-001	 6.509005e+000	 5.949008e-002	 8.070120e+002
 4.701400e+002	 3.279985e+000	 1.423560e+004	 3.634051e-001	 6.567186e+000	 6.003517e-002	 8.081113e+002
 4.726400e+002	 3.304830e+000	 1.424770e+004	 3.645189e-001	 6.616931e+000	 6.050043e-002	 8.091757e+002
 4.750601e+002	 3.328125e+000	 1.425546e+004	 3.659743e-001	 6.663571e+000	 6.093737e-002	 8.099706e+002
 4.774801e+002	 3.351587e+000	 1.426389e+004	 3.690739e-001	 6.710547e+000	 6.137711e-002	 8.108064e+002
 4.799001e+002	 3.375889e+000	 1.427332e+004	 3.718225e-001	 6.759205e+000	 6.183221e-002	 8.117123e+002
 4.823201e+002	 3.397472e+000	 1.428317e+004	 3.717871e-001	 6.802419e+000	 6.223584e-002	 8.126011e+002
 4.851400e+002	 3.427207e+000	 1.429460e+004	 3.759109e-001	 6.861954e+000	 6.279219e-002	 8.137048e+002
 4.881400e+002	 3.456063e+000	 1.430211e+004	 3.794649e-001	 6.919730e+000	 6.333273e-002	 8.145724e+002
 4.908000e+002	 3.481814e+000	 1.430912e+004	 3.820969e-001	 6.971289e+000	 6.381477e-002	 8.153646e+002
 4.932201e+002	 3.506790e+000	 1.431797e+004	 3.846807e-001	 7.021296e+000	 6.428156e-002	 8.162501e+002
 4.956601e+002	 3.530786e+000	 1.432665e+004	 3.857534e-001	 7.069341e+000	 6.472978e-002	 8.171114e+002
 4.980800e+002	 3.556862e+000	 1.433315e+004	 3.895010e-001	 7.121549e+000	 6.521736e-002	 8.178812e+002
 5.005001e+002	 3.580154e+000	 1.434258e+004	 3.928038e-001	 7.168184e+000	 6.565178e-002	 8.187756e+002
 5.031400e+002	 3.609627e+000	 1.435393e+004	 3.926195e-001	 7.227195e+000	 6.620135e-002	 8.198747e+002
 5.061400e+002	 3.637214e+000	 1.436345e+004	 3.960836e-001	 7.282430e+000	 6.671577e-002	 8.208406e+002
 5.089801e+002	 3.665805e+000	 1.437037e+004	 3.984324e-001	 7.339675e+000	 6.724937e-002	 8.216746e+002
 5.114200e+002	 3.689731e+000	 1.437730e+004	 4.019068e-001	 7.387579e+000	 6.769540e-002	 8.224375e+002
 5.138401e+002	 3.709824e+000	 1.438523e+004	 4.058069e-001	 7.427809e+000	 6.806928e-002	 8.231992e+002
 5.162601e+002	 3.738674e+000	 1.439324e+004	 4.050155e-001	 7.485573e+000	 6.860673e-002	 8.241005e+002
 5.186801e+002	 3.761840e+000	 1.439991e+004	 4.086224e-001	 7.531956e+000	 6.903802e-002	 8.248385e+002
 5.211401e+002	 3.789590e+000	 1.440609e+004	 4.103454e-001	 7.587518e+000	 6.955487e-002	 8.256186e+002
 5.241401e+002	 3.821781e+000	 1.441360e+004	 4.139494e-001	 7.651970e+000	 7.015401e-002	 8.265438e+002
 5.271401e+002	 3.848865e+000	 1.442420e+004	 4.158528e-001	 7.706198e+000	 7.065674e-002	 8.275682e+002
 5.301401e+002	 3.879148e+000	 1.443187e+004	 4.214616e-001	 7.766829e+000	 7.121959e-002	 8.284747e+002
 5.331401e+002	 3.909259e+000	 1.443988e+004	 4.211208e-001	 7.827118e+000	 7.177884e-002	 8.293983e+002
 5.356201e+002	 3.933639e+000	 1.444798e+004	 4.245542e-001	 7.875931e+000	 7.223102e-002	 8.302389e+002
 5.380400e+002	 3.959769e+000	 1.445541e+004	 4.274049e-001	 7.928249e+000	 7.271574e-002	 8.310685e+002
 5.404601e+002	 3.983982e+000	 1.445866e+004	 4.306771e-001	 7.976728e+000	 7.316561e-002	 8.316290e+002
 5.429001e+002	 4.008255e+000	 1.446417e+004	 4.305896e-001	 8.025328e+000	 7.361582e-002	 8.323202e+002
 5.453000e+002	 4.033021e+000	 1.447493e+004	 4.355704e-001	 8.074916e+000	 7.407369e-002	 8.333220e+002
 5.481401e+002	 4.061693e+000	 1.447969e+004	 4.366078e-001	 8.132322e+000	 7.460543e-002	 8.340386e+002
 5.511401e+002	 4.091689e+000	 1.448561e+004	 4.396732e-001	 8.192380e+000	 7.516118e-002	 8.348432e+002
 5.537601e+002	 4.117549e+000	 1.449371e+004	 4.427406e-001	 8.244157e+000	 7.563931e-002	 8.357094e+002
 5.561801e+002	 4.141931e+000	 1.449988e+004	 4.454769e-001	 8.292975e+000	 7.609026e-002	 8.364425e+002
 5.586000e+002	 4.166264e+000	 1.450556e+004	 4.485335e-001	 8.341694e+000	 7.654023e-002	 8.371463e+002
 5.610201e+002	 4.192145e+000	 1.451098e+004	 4.502712e-001	 8.393514e+000	 7.701877e-002	 8.378599e+002
 5.634401e+002	 4.214981e+000	 1.451616e+004	 4.534937e-001	 8.439235e+000	 7.744070e-002	 8.385121e+002
 5.661401e+002	 4.242413e+000	 1.452292e+004	 4.532072e-001	 8.494159e+000	 7.794718e-002	 8.393274e+002
 5.691401e+002	 4.273609e+000	 1.453068e+004	 4.571269e-001	 8.556621e+000	 7.852284e-002	 8.402594e+002
 5.719200e+002	 4.301169e+000	 1.453585e+004	 4.607377e-001	 8.611801e+000	 7.903154e-002	 8.409858e+002
 5.743401e+002	 4.325613e+000	 1.454044e+004	 4.638565e-001	 8.660744e+000	 7.948253e-002	 8.416304e+002
 5.767800e+002	 4.351301e+000	 1.454770e+004	 4.634973e-001	 8.712175e+000	 7.995560e-002	 8.424492e+002
 5.791801e+002	 4.377021e+000	 1.455346e+004	 4.682674e-001	 8.763672e+000	 8.042945e-002	 8.431818e+002
 5.816000e+002	 4.401826e+000	 1.455855e+004	 4.705848e-001	 8.813336e+000	 8.088633e-002	 8.438618e+002
 5.841401e+002	 4.428051e+000	 1.456030e+004	 4.743853e-001	 8.865845e+000	 8.137006e-002	 8.443706e+002
 5.871401e+002	 4.459378e+000	 1.456622e+004	 4.769521e-001	 8.928567e+000	 8.194662e-002	 8.452009e+002
 5.900801e+002	 4.489953e+000	 1.457273e+004	 4.809020e-001	 8.989784e+000	 8.250884e-002	 8.460537e+002
 5.925001e+002	 4.514257e+000	 1.457674e+004	 4.820317e-001	 9.038447e+000	 8.295582e-002	 8.466641e+002
 5.949200e+002	 4.540266e+000	 1.458041e+004	 4.838938e-001	 9.090521e+000	 8.343408e-002	 8.472818e+002
 5.973201e+002	 4.563988e+000	 1.458692e+004	 4.853862e-001	 9.138017e+000	 8.386929e-002	 8.480291e+002
 5.997401e+002	 4.587920e+000	 1.459410e+004	 4.891578e-001	 9.185934e+000	 8.430803e-002	 8.488188e+002
 6.021600e+002	 4.613816e+000	 1.459468e+004	 4.923466e-001	 9.237782e+000	 8.478433e-002	 8.492558e+002
 6.051401e+002	 4.644760e+000	 1.459944e+004	 4.945401e-001	 9.299739e+000	 8.535218e-002	 8.500144e+002
 6.081401e+002	 4.676406e+000	 1.460444e+004	 4.998402e-001	 9.363101e+000	 8.593255e-002	 8.507988e+002
 6.106201e+002	 4.702687e+000	 1.460945e+004	 5.011823e-001	 9.415721e+000	 8.641405e-002	 8.514999e+002
 6.130400e+002	 4.728567e+000	 1.461437e+004	 5.062618e-001	 9.467536e+000	 8.688797e-002	 8.521903e+002
 6.154601e+002	 4.754842e+000	 1.461788e+004	 5.082347e-001	 9.520146e+000	 8.736929e-002	 8.528043e+002
 6.178801e+002	 4.780863e+000	 1.462080e+004	 5.106561e-001	 9.572244e+000	 8.784585e-002	 8.533804e+002
 6.203000e+002	 4.806012e+000	 1.462581e+004	 5.114937e-001	 9.622598e+000	 8.830569e-002	 8.540649e+002
 6.231401e+002	 4.836308e+000	 1.462990e+004	 5.139688e-001	 9.683257e+000	 8.885985e-002	 8.547764e+002
 6.261401e+002	 4.869058e+000	 1.463574e+004	 5.190067e-001	 9.748828e+000	 8.945817e-002	 8.556288e+002
 6.287800e+002	 4.896587e+000	 1.463507e+004	 5.203826e-001	 9.803947e+000	 8.996223e-002	 8.560194e+002
 6.312001e+002	 4.921891e+000	 1.464016e+004	 5.217276e-001	 9.854611e+000	 9.042391e-002	 8.567123e+002
 6.336201e+002	 4.949019e+000	 1.464375e+004	 5.284268e-001	 9.908926e+000	 9.091909e-002	 8.573459e+002
 6.360400e+002	 4.973062e+000	 1.464825e+004	 5.293451e-001	 9.957064e+000	 9.135742e-002	 8.579854e+002
 6.384601e+002	 5.000113e+000	 1.465309e+004	 5.344768e-001	 1.001123e+001	 9.185043e-002	 8.586916e+002
 6.411401e+002	 5.027094e+000	 1.465718e+004	 5.347068e-001	 1.006525e+001	 9.234211e-002	 8.593530e+002
 6.441401e+002	 5.060119e+000	 1.466161e+004	 5.418547e-001	 1.013137e+001	 9.294373e-002	 8.601286e+002
 6.469401e+002	 5.090447e+000	 1.466202e+004	 5.418260e-001	 1.019209e+001	 9.349681e-002	 8.606273e+002
 6.493600e+002	 5.115176e+000	 1.466678e+004	 5.457547e-001	 1.024161e+001	 9.394646e-002	 8.612934e+002
 6.517800e+002	 5.140286e+000	 1.467120e+004	 5.494058e-001	 1.029188e+001	 9.440293e-002	 8.619460e+002
 6.542001e+002	 5.165572e+000	 1.467279e+004	 5.481836e-001	 1.034251e+001	 9.486310e-002	 8.624348e+002
 6.566201e+002	 5.192412e+000	 1.467479e+004	 5.546027e-001	 1.039625e+001	 9.535125e-002	 8.629726e+002
 6.591401e+002	 5.218337e+000	 1.468055e+004	 5.561187e-001	 1.044815e+001	 9.582157e-002	 8.637170e+002
 6.621401e+002	 5.250526e+000	 1.468372e+004	 5.620828e-001	 1.051260e+001	 9.640622e-002	 8.644077e+002
 6.651000e+002	 5.282430e+000	 1.468672e+004	 5.642213e-001	 1.057648e+001	 9.698539e-002	 8.650842e+002
 6.675201e+002	 5.308309e+000	 1.468956e+004	 5.650887e-001	 1.062830e+001	 9.745483e-002	 8.656568e+002
 6.699401e+002	 5.334095e+000	 1.469307e+004	 5.693547e-001	 1.067993e+001	 9.792221e-002	 8.662674e+002
 6.723801e+002	 5.359467e+000	 1.469724e+004	 5.721914e-001	 1.073073e+001	 9.838169e-002	 8.669111e+002
 6.748000e+002	 5.387573e+000	 1.470049e+004	 5.771503e-001	 1.078700e+001	 9.889077e-002	 8.675437e+002
 6.772200e+002	 5.413252e+000	 1.470183e+004	 5.806596e-001	 1.083841e+001	 9.935606e-002	 8.680251e+002
 6.801401e+002	 5.445443e+000	 1.470441e+004	 5.850980e-001	 1.090287e+001	 9.993883e-002	 8.686826e+002
 6.831401e+002	 5.476987e+000	 1.471067e+004	 5.849416e-001	 1.096602e+001	 1.005086e-001	 8.695473e+002
 6.857001e+002	 5.506287e+000	 1.470975e+004	 5.888426e-001	 1.102469e+001	 1.010393e-001	 8.699527e+002
 6.881201e+002	 5.533251e+000	 1.471192e+004	 5.896108e-001	 1.107868e+001	 1.015266e-001	 8.705040e+002
 6.905400e+002	 5.558187e+000	 1.471309e+004	 5.937017e-001	 1.112860e+001	 1.019773e-001	 8.709644e+002
 6.929601e+002	 5.587512e+000	 1.471610e+004	 5.954781e-001	 1.118732e+001	 1.025066e-001	 8.716025e+002
 6.953801e+002	 5.612187e+000	 1.471827e+004	 5.997611e-001	 1.123672e+001	 1.029519e-001	 8.721183e+002
 6.981401e+002	 5.641163e+000	 1.472503e+004	 6.031862e-001	 1.129474e+001	 1.034735e-001	 8.729739e+002
 7.011401e+002	 5.674858e+000	 1.472536e+004	 6.040988e-001	 1.136220e+001	 1.040816e-001	 8.735228e+002
 7.038401e+002	 5.704945e+000	 1.473187e+004	 6.081541e-001	 1.142244e+001	 1.046227e-001	 8.743816e+002
 7.062601e+002	 5.731659e+000	 1.473020e+004	 6.109426e-001	 1.147593e+001	 1.051047e-001	 8.747022e+002
 7.086801e+002	 5.757037e+000	 1.473128e+004	 6.110029e-001	 1.152674e+001	 1.055618e-001	 8.751653e+002
 7.111000e+002	 5.784111e+000	 1.473337e+004	 6.158372e-001	 1.158095e+001	 1.060489e-001	 8.757147e+002
 7.135201e+002	 5.809839e+000	 1.473537e+004	 6.207227e-001	 1.163246e+001	 1.065116e-001	 8.762380e+002
 7.161401e+002	 5.839342e+000	 1.473754e+004	 6.207123e-001	 1.169153e+001	 1.070420e-001	 8.768308e+002
 7.191401e+002	 5.872499e+000	 1.473738e+004	 6.247141e-001	 1.175792e+001	 1.076383e-001	 8.773420e+002
 7.219800e+002	 5.905568e+000	 1.474464e+004	 6.292269e-001	 1.182413e+001	 1.082309e-001	 8.782942e+002
 7.244001e+002	 5.931261e+000	 1.474380e+004	 6.307782e-001	 1.187557e+001	 1.086927e-001	 8.786484e+002
 7.268201e+002	 5.959908e+000	 1.474497e+004	 6.334372e-001	 1.193293e+001	 1.092067e-001	 8.791685e+002
 7.292401e+002	 5.986814e+000	 1.474539e+004	 6.342823e-001	 1.198680e+001	 1.096895e-001	 8.796165e+002
 7.316600e+002	 6.013221e+000	 1.474756e+004	 6.358054e-001	 1.203967e+001	 1.101626e-001	 8.801613e+002
 7.341401e+002	 6.042443e+000	 1.475056e+004	 6.386130e-001	 1.209818e+001	 1.106858e-001	 8.808003e+002
 7.371401e+002	 6.075634e+000	 1.475265e+004	 6.453904e-001	 1.216463e+001	 1.112801e-001	 8.814470e+002
 7.401201e+002	 6.109941e+000	 1.475573e+004	 6.443407e-001	 1.223333e+001	 1.118937e-001	 8.821714e+002
 7.425400e+002	 6.137831e+000	 1.475907e+004	 6.504838e-001	 1.228917e+001	 1.123920e-001	 8.828100e+002
 7.449601e+002	 6.164952e+000	 1.475982e+004	 6.515000e-001	 1.234347e+001	 1.128770e-001	 8.832818e+002
 7.473801e+002	 6.191130e+000	 1.476082e+004	 6.545138e-001	 1.239588e+001	 1.133449e-001	 8.837538e+002
 7.498000e+002	 6.217980e+000	 1.476208e+004	 6.580307e-001	 1.244964e+001	 1.138244e-001	 8.842515e+002
 7.522401e+002	 6.247609e+000	 1.475924e+004	 6.587670e-001	 1.250896e+001	 1.143544e-001	 8.845479e+002
 7.551401e+002	 6.280625e+000	 1.476483e+004	 6.636481e-001	 1.257507e+001	 1.149425e-001	 8.854028e+002
 7.581401e+002	 6.315354e+000	 1.476391e+004	 6.650549e-001	 1.264460e+001	 1.155623e-001	 8.858946e+002
 7.606801e+002	 6.343032e+000	 1.476541e+004	 6.695732e-001	 1.270002e+001	 1.160556e-001	 8.864206e+002
 7.631000e+002	 6.370456e+000	 1.476625e+004	 6.707696e-001	 1.275493e+001	 1.165442e-001	 8.869026e+002
 7.655201e+002	 6.397614e+000	 1.476750e+004	 6.734216e-001	 1.280930e+001	 1.170277e-001	 8.874054e+002
 7.679401e+002	 6.423927e+000	 1.477034e+004	 6.761245e-001	 1.286199e+001	 1.174955e-001	 8.879904e+002
 7.703600e+002	 6.454412e+000	 1.477059e+004	 6.797768e-001	 1.292302e+001	 1.180380e-001	 8.884857e+002
 7.731401e+002	 6.486349e+000	 1.476984e+004	 6.824927e-001	 1.298697e+001	 1.186063e-001	 8.889436e+002
 7.761401e+002	 6.521407e+000	 1.477050e+004	 6.859564e-001	 1.305716e+001	 1.192294e-001	 8.895360e+002
 7.788401e+002	 6.550176e+000	 1.477543e+004	 6.882766e-001	 1.311476e+001	 1.197393e-001	 8.902858e+002
 7.812601e+002	 6.577811e+000	 1.477651e+004	 6.902664e-001	 1.317009e+001	 1.202298e-001	 8.907867e+002
 7.836801e+002	 6.607175e+000	 1.477726e+004	 6.935672e-001	 1.322889e+001	 1.207508e-001	 8.912947e+002
 7.861000e+002	 6.634432e+000	 1.477810e+004	 6.944249e-001	 1.328346e+001	 1.212342e-001	 8.917747e+002
 7.885201e+002	 6.662460e+000	 1.477726e+004	 6.968210e-001	 1.333958e+001	 1.217313e-001	 8.921660e+002
 7.911401e+002	 6.693403e+000	 1.477701e+004	 7.017748e-001	 1.340153e+001	 1.222798e-001	 8.926386e+002
 7.941401e+002	 6.727530e+000	 1.477852e+004	 7.040437e-001	 1.346986e+001	 1.228839e-001	 8.932672e+002
 7.970001e+002	 6.761807e+000	 1.477868e+004	 7.067887e-001	 1.353849e+001	 1.234906e-001	 8.938175e+002
 7.994200e+002	 6.790579e+000	 1.478060e+004	 7.096597e-001	 1.359610e+001	 1.239992e-001	 8.943871e+002
 8.018401e+002	 6.818191e+000	 1.477868e+004	 7.140383e-001	 1.365138e+001	 1.244879e-001	 8.947062e+002
 8.042401e+002	 6.845442e+000	 1.478127e+004	 7.159657e-001	 1.370594e+001	 1.249689e-001	 8.952924e+002
 8.066600e+002	 6.875316e+000	 1.478244e+004	 7.174572e-001	 1.376576e+001	 1.254964e-001	 8.958341e+002
 8.091401e+002	 6.904308e+000	 1.478294e+004	 7.193028e-001	 1.382381e+001	 1.260081e-001	 8.963215e+002
 8.121401e+002	 6.939617e+000	 1.478169e+004	 7.236137e-001	 1.389450e+001	 1.266315e-001	 8.968022e+002
 8.151401e+002	 6.975494e+000	 1.478035e+004	 7.269098e-001	 1.396633e+001	 1.272645e-001	 8.972868e+002
 8.181401e+002	 7.011140e+000	 1.478119e+004	 7.278438e-001	 1.403771e+001	 1.278925e-001	 8.978993e+002
 8.211401e+002	 7.046496e+000	 1.478586e+004	 7.315487e-001	 1.410850e+001	 1.285141e-001	 8.987407e+002
 8.236000e+002	 7.074286e+000	 1.478377e+004	 7.373485e-001	 1.416414e+001	 1.290038e-001	 8.990520e+002
 8.260201e+002	 7.105771e+000	 1.478102e+004	 7.400628e-001	 1.422717e+001	           0.0	           0.0
 8.284401e+002	 7.134464e+000	 1.478160e+004	 7.412658e-001	 1.428462e+001	           0.0	           0.0
 8.308600e+002	 7.162600e+000	 1.478219e+004	 7.456318e-001	 1.434096e+001	           0.0	           0.0
 8.332800e+002	 7.190295e+000	 1.478311e+004	 7.477487e-001	 1.439641e+001	           0.0	           0.0
 8.361401e+002	 7.225924e+000	 1.478452e+004	 7.503487e-001	 1.446775e+001	           0.0	           0.0
 8.391401e+002	 7.261605e+000	 1.478427e+004	 7.555327e-001	 1.453919e+001	           0.0	           0.0
 8.417401e+002	 7.294742e+000	 1.478477e+004	 7.588037e-001	 1.460553e+001	           0.0	           0.0
 8.441600e+002	 7.321531e+000	 1.478569e+004	 7.620928e-001	 1.465917e+001	           0.0	           0.0
 8.465801e+002	 7.354347e+000	 1.478386e+004	 7.633213e-001	 1.472487e+001	           0.0	           0.0
 8.490001e+002	 7.385476e+000	 1.478361e+004	 7.681018e-001	 1.478720e+001	           0.0	           0.0
 8.514200e+002	 7.413248e+000	 1.478386e+004	 7.710361e-001	 1.484281e+001	           0.0	           0.0
 8.541401e+002	 7.448263e+000	 1.478302e+004	 7.732468e-001	 1.491291e+001	           0.0	           0.0
 8.571401e+002	 7.484875e+000	 1.478194e+004	 7.779378e-001	 1.498622e+001	           0.0	           0.0
 8.598801e+002	 7.520479e+000	 1.478302e+004	 7.806718e-001	 1.505750e+001	           0.0	           0.0
 8.623000e+002	 7.549256e+000	 1.478194e+004	 7.844887e-001	 1.511512e+001	           0.0	           0.0
 8.647200e+002	 7.579400e+000	 1.478177e+004	 7.870787e-001	 1.517548e+001	           0.0	           0.0
 8.671401e+002	 7.610151e+000	 1.478160e+004	 7.913368e-001	 1.523704e+001	           0.0	           0.0
 8.695601e+002	 7.637230e+000	 1.478060e+004	 7.981948e-001	 1.529126e+001	           0.0	           0.0
 8.721401e+002	 7.670726e+000	 1.478327e+004	 7.980947e-001	 1.535833e+001	           0.0	           0.0
 8.751401e+002	 7.709359e+000	 1.478202e+004	 7.989017e-001	 1.543568e+001	           0.0	           0.0
 8.780001e+002	 7.744362e+000	 1.478219e+004	 8.060418e-001	 1.550576e+001	           0.0	           0.0
 8.804200e+002	 7.774741e+000	 1.478185e+004	 8.102277e-001	 1.556659e+001	           0.0	           0.0
 8.828401e+002	 7.806972e+000	 1.478344e+004	 8.144957e-001	 1.563112e+001	           0.0	           0.0
 8.852601e+002	 7.839205e+000	 1.478027e+004	 8.180274e-001	 1.569566e+001	           0.0	           0.0
 8.876801e+002	 7.868927e+000	 1.478160e+004	 8.225188e-001	 1.575517e+001	           0.0	           0.0
 8.901401e+002	 7.901033e+000	 1.477518e+004	 8.224084e-001	 1.581945e+001	           0.0	           0.0
 8.931401e+002	 7.937131e+000	 1.477768e+004	 8.282765e-001	 1.589173e+001	           0.0	           0.0
 8.961401e+002	 7.976707e+000	 1.477660e+004	 8.310694e-001	 1.597096e+001	           0.0	           0.0
 8.985801e+002	 8.009699e+000	 1.477468e+004	 8.367137e-001	 1.603702e+001	           0.0	           0.0
 9.010001e+002	 8.041700e+000	 1.477418e+004	 8.385847e-001	 1.610109e+001	           0.0	           0.0
 9.034200e+002	 8.072871e+000	 1.477284e+004	 8.412139e-001	 1.616350e+001	           0.0	           0.0
 9.058401e+002	 8.104280e+000	 1.477176e+004	 8.471578e-001	 1.622639e+001	           0.0	           0.0
 9.082601e+002	 8.138238e+000	 1.477059e+004	 8.476365e-001	 1.629438e+001	           0.0	           0.0
 9.111401e+002	 8.174086e+000	 1.476858e+004	 8.534986e-001	 1.636615e+001	           0.0	           0.0
 9.141401e+002	 8.214618e+000	 1.476541e+004	 8.576274e-001	 1.644731e+001	           0.0	           0.0
 9.167200e+002	 8.249753e+000	 1.476775e+004	 8.614737e-001	 1.651766e+001	           0.0	           0.0
 9.191401e+002	 8.280042e+000	 1.476817e+004	 8.649791e-001	 1.657830e+001	           0.0	           0.0
 9.215601e+002	 8.312113e+000	 1.476692e+004	 8.705789e-001	 1.664251e+001	           0.0	           0.0
 9.239800e+002	 8.347340e+000	 1.476466e+004	 8.728208e-001	 1.671304e+001	           0.0	           0.0
 9.264001e+002	 8.377748e+000	 1.476433e+004	 8.757908e-001	 1.677393e+001	           0.0	           0.0
 9.291401e+002	 8.415262e+000	 1.475991e+004	 8.807046e-001	 1.684904e+001	           0.0	           0.0
 9.321401e+002	 8.457107e+000	 1.475916e+004	 8.862435e-001	 1.693282e+001	           0.0	           0.0
 9.348801e+002	 8.495451e+000	 1.475523e+004	 8.889052e-001	 1.700959e+001	           0.0	           0.0
 9.373000e+002	 8.527155e+000	 1.475532e+004	 8.923925e-001	 1.707307e+001	           0.0	           0.0
 9.397200e+002	 8.560521e+000	 1.475382e+004	 8.956788e-001	 1.713988e+001	           0.0	           0.0
 9.421201e+002	 8.594493e+000	 1.475206e+004	 8.989899e-001	 1.720789e+001	           0.0	           0.0
 9.445400e+002	 8.628402e+000	 1.475048e+004	 9.045128e-001	 1.727579e+001	           0.0	           0.0
 9.471401e+002	 8.663749e+000	 1.474781e+004	 9.088661e-001	 1.734656e+001	           0.0	           0.0
 9.501401e+002	 8.706767e+000	 1.474764e+004	 9.116806e-001	 1.743269e+001	           0.0	           0.0
 9.530201e+002	 8.746853e+000	 1.474205e+004	 9.165490e-001	 1.751295e+001	           0.0	           0.0
 9.554401e+002	 8.780745e+000	 1.474080e+004	 9.209696e-001	 1.758081e+001	           0.0	           0.0
 9.578600e+002	 8.815984e+000	 1.473988e+004	 9.249913e-001	 1.765136e+001	           0.0	           0.0
 9.602800e+002	 8.848733e+000	 1.473879e+004	 9.280029e-001	 1.771693e+001	           0.0	           0.0
 9.627001e+002	 8.884892e+000	 1.473479e+004	 9.324221e-001	 1.778933e+001	           0.0	           0.0
 9.651401e+002	 8.918766e+000	 1.473362e+004	 9.354585e-001	 1.785715e+001	           0.0	           0.0
 9.681401e+002	 8.958378e+000	 1.472811e+004	 9.401425e-001	 1.793646e+001	           0.0	           0.0
 9.711401e+002	 9.005075e+000	 1.472452e+004	 9.442127e-001	 1.802996e+001	           0.0	           0.0
 9.736000e+002	 9.039582e+000	 1.472302e+004	 9.507508e-001	 1.809905e+001	           0.0	           0.0
 9.760201e+002	 9.075575e+000	 1.472135e+004	 9.524229e-001	 1.817112e+001	           0.0	           0.0
 9.784401e+002	 9.110351e+000	 1.472135e+004	 9.576867e-001	 1.824074e+001	           0.0	           0.0
 9.808600e+002	 9.148880e+000	 1.471902e+004	 9.624171e-001	 1.831789e+001	           0.0	           0.0
 9.833000e+002	 9.183128e+000	 1.471401e+004	 9.665162e-001	 1.838646e+001	           0.0	           0.0
 9.861401e+002	 9.225859e+000	 1.470884e+004	 9.741559e-001	 1.847201e+001	           0.0	           0.0
 9.891401e+002	 9.269629e+000	 1.470733e+004	 9.761263e-001	 1.855965e+001	           0.0	           0.0
 9.917800e+002	 9.309265e+000	 1.469974e+004	 9.838974e-001	 1.863901e+001	           0.0	           0.0
 9.942001e+002	 9.344910e+000	 1.469657e+004	 9.871374e-001	 1.871038e+001	           0.0	           0.0
 9.966201e+002	 9.382992e+000	 1.469198e+004	 9.906254e-001	 1.878663e+001	           0.0	           0.0
 9.990400e+002	 9.419465e+000	 1.468597e+004	 9.947594e-001	 1.885965e+001	           0.0	           0.0
 1.001460e+003	 9.456143e+000	 1.468205e+004	 1.001122e+000	 1.893309e+001	           0.0	           0.0
 1.004140e+003	 9.498707e+000	 1.467963e+004	 1.005367e+000	 1.901831e+001	           0.0	           0.0
 1.007140e+003	 9.544310e+000	 1.467362e+004	 1.014199e+000	 1.910962e+001	           0.0	           0.0
 1.009940e+003	 9.588313e+000	 1.466311e+004	 1.017988e+000	 1.919772e+001	           0.0	           0.0
 1.012360e+003	 9.627728e+000	 1.465860e+004	 1.022839e+000	 1.927664e+001	           0.0	           0.0
 1.014780e+003	 9.664736e+000	 1.465176e+004	 1.024999e+000	 1.935073e+001	           0.0	           0.0
 1.017180e+003	 9.702657e+000	 1.464617e+004	 1.030869e+000	 1.942666e+001	           0.0	           0.0
 1.019600e+003	 9.738646e+000	 1.463974e+004	 1.038978e+000	 1.949872e+001	           0.0	           0.0
 1.022140e+003	 9.781927e+000	 1.463106e+004	 1.044067e+000	 1.958538e+001	           0.0	           0.0
 1.025140e+003	 9.829911e+000	 1.462072e+004	 1.049392e+000	 1.968145e+001	           0.0	           0.0
 1.028100e+003	 9.877209e+000	 1.460561e+004	 1.056872e+000	 1.977615e+001	           0.0	           0.0
 1.030520e+003	 9.916644e+000	 1.459652e+004	 1.059188e+000	 1.985511e+001	           0.0	           0.0
 1.032940e+003	 9.954997e+000	 1.458684e+004	 1.062442e+000	 1.993190e+001	           0.0	           0.0
 1.035340e+003	 9.994605e+000	 1.457582e+004	 1.067877e+000	 2.001120e+001	           0.0	           0.0
 1.037760e+003	 1.003373e+001	 1.456422e+004	 1.074112e+000	 2.008953e+001	           0.0	           0.0
 1.040180e+003	 1.007392e+001	 1.455204e+004	 1.078220e+000	 2.017000e+001	           0.0	           0.0
 1.043140e+003	 1.012101e+001	 1.453760e+004	 1.084620e+000	 2.026430e+001	           0.0	           0.0
 1.046140e+003	 1.017425e+001	 1.452016e+004	 1.090676e+000	 2.037089e+001	           0.0	           0.0
 1.048660e+003	 1.021601e+001	 1.450255e+004	 1.091160e+000	 2.045449e+001	           0.0	           0.0
 1.051080e+003	 1.025544e+001	 1.448745e+004	 1.096705e+000	 2.053345e+001	           0.0	           0.0
 1.053500e+003	 1.029584e+001	 1.446993e+004	 1.097964e+000	 2.061433e+001	           0.0	           0.0
 1.055920e+003	 1.033769e+001	 1.444840e+004	 1.103614e+000	 2.069812e+001	           0.0	           0.0
 1.058340e+003	 1.037730e+001	 1.442770e+004	 1.107975e+000	 2.077743e+001	           0.0	           0.0
 1.061140e+003	 1.042593e+001	 1.440575e+004	 1.113759e+000	 2.087479e+001	           0.0	           0.0
 1.064140e+003	 1.047679e+001	 1.437605e+004	 1.111831e+000	 2.097662e+001	           0.0	           0.0
 1.066800e+003	 1.052332e+001	 1.434500e+004	 1.116544e+000	 2.106980e+001	           0.0	           0.0
 1.069240e+003	 1.056622e+001	 1.431404e+004	 1.120839e+000	 2.115568e+001	           0.0	           0.0
 1.071660e+003	 1.060303e+001	 1.428609e+004	 1.125151e+000	 2.122938e+001	           0.0	           0.0
 1.074080e+003	 1.064411e+001	 1.425380e+004	 1.128964e+000	 2.131164e+001	           0.0	           0.0
 1.076500e+003	 1.068800e+001	 1.421533e+004	 1.133000e+000	 2.139951e+001	           0.0	           0.0
 1.079140e+003	 1.073335e+001	 1.416134e+004	 1.135000e+000	 2.149031e+001	           0.0	           0.0
 1.082140e+003	 1.078906e+001	 1.400137e+004	 1.141819e+000	 2.160185e+001	           0.0	           0.0
 1.083760e+003	 1.082455e+001	 1.367751e+004	 1.142877e+000	 2.167292e+001	           0.0	           0.0