File: DP800 Tensile Tests/Fehlemann_Test_WP_KL_2024_1016.TRA
$Fehlemann_Test_WP_KL_2024_101.ZSE
Material:                               St
Auftrags-Nr.:                           WP_KL_2024_101
Probe:                                  2_90°_C
Vorkraft:                               100 N
Probengeometrie:                        H12,5x50
Messlänge:                              50.2183 mm
Probendicke a0:                         1.49 mm
Probenbreite b0:                        12.61 mm
Prüfgeschwindigkeit:                    1 mm/min
Datum:                                  26.09.2024
Maschinendaten:                         4204 WN:800315
Traversenwegaufnehmer WN:800315
Videoextensometer
Videoextensometer - Querdehnung
Kraftsensor ID:0 WN:800316 50 kN

Bemerkung:
$
      Prüfzeit	   Standardweg	 Spannung       Breitenänderung	       Dehnung	 wahre Dehnung	wahre Spannung
 2.070313e-002	-6.489771e-005	 2.002768e+002	-7.435626e-005	-1.292311e-004	 0.000000e+000	 1.065956e+001
 1.607031e-001	-1.885679e-003	 2.004437e+002	-5.123563e-004	-3.754962e-003	 0.000000e+000	 1.066805e+001
 4.607031e-001	-1.139027e-003	 2.232249e+002	-1.289542e-003	-2.268150e-003	 0.000000e+000	 1.188070e+001
 8.607031e-001	-7.589770e-005	 3.433897e+002	-7.426062e-004	-1.511355e-004	 0.000000e+000	 1.827661e+001
 1.220703e+000	-5.691880e-004	 4.456132e+002	 7.548776e-004	-1.133427e-003	 0.000000e+000	 2.371714e+001
 1.620703e+000	 4.563926e-004	 5.574332e+002	 2.506841e-004	 9.088169e-004	 0.000000e+000	 2.966920e+001
 2.380703e+000	 2.015618e-003	 7.771512e+002	 7.104905e-004	 4.013711e-003	 0.000000e+000	 4.136491e+001
 3.240703e+000	 3.769199e-003	 1.025826e+003	 6.151034e-004	 7.505625e-003	 0.000000e+000	 5.460284e+001
 3.840703e+000	 5.632457e-003	 1.200231e+003	 2.320523e-003	 1.121594e-002	 0.000000e+000	 6.388852e+001
 4.260703e+000	 6.795457e-003	 1.328240e+003	 2.411394e-003	 1.353183e-002	 0.000000e+000	 7.070408e+001
 4.840703e+000	 7.415134e-003	 1.498307e+003	 1.534974e-003	 1.476579e-002	 0.000000e+000	 7.975795e+001
 5.220703e+000	 9.079264e-003	 1.605454e+003	 3.588329e-003	 1.807958e-002	 0.000000e+000	 8.546443e+001
 6.000703e+000	 1.099594e-002	 1.827592e+003	 4.617490e-003	 2.189627e-002	 0.000000e+000	 9.729340e+001
 6.260703e+000	 1.153149e-002	 1.897938e+003	 4.013394e-003	 2.296271e-002	 0.000000e+000	 1.010394e+002
 7.080703e+000	 1.321810e-002	 2.108811e+003	 5.723394e-003	 2.632127e-002	 0.000000e+000	 1.122693e+002
 7.540703e+000	 1.453760e-002	 2.223885e+003	 4.470706e-003	 2.894880e-002	 6.680639e-006	 1.183988e+002
 8.480703e+000	 1.485842e-002	 2.448443e+003	 4.783394e-003	 2.958766e-002	 0.000000e+000	 1.303550e+002
 8.760703e+000	 1.676820e-002	 2.511947e+003	 4.740394e-003	 3.339060e-002	 1.134617e-005	 1.337410e+002
 9.260703e+000	 1.746281e-002	 2.618510e+003	 4.426394e-003	 3.477379e-002	 1.047244e-005	 1.394165e+002
 9.540703e+000	 1.824935e-002	 2.680094e+003	 4.113394e-003	 3.634003e-002	 1.763610e-005	 1.426977e+002
 1.038070e+001	 1.828310e-002	 2.847991e+003	 2.449813e-003	 3.640723e-002	 0.000000e+000	 1.516372e+002
 1.066070e+001	 1.893860e-002	 2.899145e+003	 1.886019e-003	 3.771254e-002	 1.132448e-006	 1.543628e+002
 1.150070e+001	 2.083304e-002	 3.049517e+003	 3.185394e-003	 4.148493e-002	 1.810487e-005	 1.623754e+002
 1.202070e+001	 2.265560e-002	 3.136470e+003	 2.804175e-003	 4.511422e-002	 4.239752e-005	 1.670114e+002
 1.240070e+001	 2.303207e-002	 3.198305e+003	 3.567894e-003	 4.586388e-002	 4.136103e-005	 1.703053e+002
 1.274070e+001	 2.097984e-002	 3.252796e+003	 3.206942e-003	 4.177727e-002	 0.000000e+000	 1.731998e+002
 1.298070e+001	 2.156839e-002	 3.290348e+003	 6.255394e-003	 4.294925e-002	 0.000000e+000	 1.752013e+002
 1.322070e+001	 2.294304e-002	 3.327983e+003	 4.015910e-003	 4.568659e-002	 2.169322e-005	 1.772101e+002
 1.360070e+001	 2.188581e-002	 3.388315e+003	 3.940233e-003	 4.358133e-002	 0.000000e+000	 1.804189e+002
 1.372070e+001	 2.422781e-002	 3.406257e+003	 3.295942e-003	 4.824497e-002	 3.647480e-005	 1.813827e+002
 1.408070e+001	 2.237310e-002	 3.462417e+003	 4.737394e-003	 4.455167e-002	 0.000000e+000	 1.843665e+002
 1.482070e+001	 2.292336e-002	 3.575906e+003	 4.433458e-003	 4.564740e-002	 0.000000e+000	 1.904116e+002
 1.530070e+001	 2.463562e-002	 3.647921e+003	 4.230490e-003	 4.905703e-002	 1.124639e-005	 1.942529e+002
 1.582070e+001	 2.515397e-002	 3.724860e+003	 3.728749e-003	 5.008924e-002	 1.095092e-005	 1.983520e+002
 1.608070e+001	 2.345310e-002	 3.764081e+003	 4.890394e-003	 4.670228e-002	 0.000000e+000	 2.004337e+002
 1.922070e+001	 2.646849e-002	 4.214532e+003	 3.701232e-003	 5.270684e-002	 0.000000e+000	 2.244333e+002
 2.700070e+001	 3.376617e-002	 5.130037e+003	 5.561265e-003	 6.723874e-002	 0.000000e+000	 2.732257e+002
 3.422070e+001	 3.932965e-002	 5.838091e+003	 7.217297e-003	 7.831733e-002	 1.606771e-006	 3.109711e+002
 4.022070e+001	 4.508662e-002	 6.356135e+003	 5.971458e-003	 8.978121e-002	 4.475465e-005	 3.386039e+002
 4.658070e+001	 5.411510e-002	 6.845139e+003	 9.286393e-003	 1.077597e-001	 1.570456e-004	 3.647196e+002
 5.288070e+001	 6.416701e-002	 7.281571e+003	 9.608394e-003	 1.277761e-001	 2.969505e-004	 3.880509e+002
 5.842070e+001	 7.419141e-002	 7.628547e+003	 1.028839e-002	 1.477377e-001	 4.486279e-004	 4.066231e+002
 6.422070e+001	 8.624662e-002	 7.974771e+003	 1.437572e-002	 1.717433e-001	 6.408002e-004	 4.251797e+002
 7.022070e+001	 1.016403e-001	 8.309814e+003	 1.733365e-002	 2.023969e-001	 9.008995e-004	 4.431783e+002
 7.434071e+001	 1.150139e-001	 8.529866e+003	 1.608410e-002	 2.290278e-001	 1.136601e-003	 4.550350e+002
 7.922070e+001	 1.327441e-001	 8.781461e+003	 1.728110e-002	 2.643339e-001	 1.454531e-003	 4.686216e+002
 8.346070e+001	 1.455707e-001	 8.990581e+003	 2.000868e-002	 2.898756e-001	 1.680733e-003	 4.799035e+002
 8.780070e+001	 1.657371e-001	 9.197364e+003	 2.366939e-002	 3.300331e-001	 2.053077e-003	 4.911379e+002
 9.122070e+001	 1.768684e-001	 9.360505e+003	 2.713933e-002	 3.521990e-001	 2.251794e-003	 4.999600e+002
 9.532070e+001	 1.960080e-001	 9.549264e+003	 3.329185e-002	 3.903117e-001	 2.606012e-003	 5.102356e+002
 9.948071e+001	 2.163230e-001	 9.728260e+003	 3.168739e-002	 4.307651e-001	 2.984783e-003	 5.200092e+002
 1.032207e+002	 2.346615e-001	 9.886310e+003	 3.272752e-002	 4.672825e-001	 3.327065e-003	 5.286496e+002
 1.062207e+002	 2.506872e-001	 1.000789e+004	 3.728230e-002	 4.991948e-001	 3.628359e-003	 5.353210e+002
 1.092207e+002	 2.663080e-001	 1.012338e+004	 3.918333e-002	 5.303004e-001	 3.922366e-003	 5.416662e+002
 1.128007e+002	 2.869191e-001	 1.025623e+004	 4.166539e-002	 5.713435e-001	 4.312852e-003	 5.489985e+002
 1.164607e+002	 3.072635e-001	 1.039058e+004	 4.369343e-002	 6.118553e-001	 4.697693e-003	 5.564141e+002
 1.199607e+002	 3.274152e-001	 1.051142e+004	 4.610765e-002	 6.519835e-001	 5.080424e-003	 5.631092e+002
 1.237607e+002	 3.478002e-001	 1.064185e+004	 4.910239e-002	 6.925762e-001	 5.466312e-003	 5.703264e+002
 1.272207e+002	 3.669457e-001	 1.075033e+004	 5.115975e-002	 7.307007e-001	 5.830523e-003	 5.763584e+002
 1.302207e+002	 3.860602e-001	 1.084563e+004	 5.346394e-002	 7.687636e-001	 6.195798e-003	 5.816872e+002
 1.332207e+002	 4.044210e-001	 1.094084e+004	 5.528414e-002	 8.053255e-001	 6.546039e-003	 5.870068e+002
 1.362207e+002	 4.230123e-001	 1.102729e+004	 5.680530e-002	 8.423465e-001	 6.901918e-003	 5.918625e+002
 1.392207e+002	 4.401435e-001	 1.111032e+004	 5.683956e-002	 8.764600e-001	 7.229273e-003	 5.965206e+002
 1.422207e+002	 4.594674e-001	 1.119786e+004	 5.943781e-002	 9.149397e-001	 7.599236e-003	 6.014499e+002
 1.454607e+002	 4.792184e-001	 1.128122e+004	 6.184104e-002	 9.542701e-001	 7.978074e-003	 6.061636e+002
 1.485607e+002	 4.993027e-001	 1.136534e+004	 6.334465e-002	 9.942641e-001	 8.363246e-003	 6.109252e+002
 1.518207e+002	 5.196038e-001	 1.145304e+004	 6.723304e-002	 1.034690e+000	 8.752059e-003	 6.158860e+002
 1.550407e+002	 5.398501e-001	 1.153298e+004	 6.977208e-002	 1.075006e+000	 9.140699e-003	 6.204324e+002
 1.581807e+002	 5.600353e-001	 1.161193e+004	 7.223475e-002	 1.115201e+000	 9.528121e-003	 6.249276e+002
 1.610207e+002	 5.803082e-001	 1.167893e+004	 7.419477e-002	 1.155571e+000	 9.918752e-003	 6.287848e+002
 1.641607e+002	 6.004004e-001	 1.175521e+004	 7.409514e-002	 1.195580e+000	 1.030440e-002	 6.331415e+002
 1.672207e+002	 6.204431e-001	 1.182672e+004	 7.663491e-002	 1.235491e+000	 1.068958e-002	 6.372445e+002
 1.703607e+002	 6.406131e-001	 1.189314e+004	 8.126085e-002	 1.275656e+000	 1.107781e-002	 6.410778e+002
 1.733007e+002	 6.608365e-001	 1.195498e+004	 8.148075e-002	 1.315927e+000	 1.146757e-002	 6.446671e+002
 1.760607e+002	 6.811231e-001	 1.201523e+004	 8.260604e-002	 1.356324e+000	 1.185864e-002	 6.481744e+002
 1.790607e+002	 7.013607e-001	 1.207923e+004	 8.761430e-002	 1.396623e+000	 1.224807e-002	 6.518863e+002
 1.819807e+002	 7.216278e-001	 1.213815e+004	 8.991239e-002	 1.436981e+000	 1.263863e-002	 6.553264e+002
 1.849407e+002	 7.419593e-001	 1.219998e+004	 9.054530e-002	 1.477467e+000	 1.302991e-002	 6.589277e+002
 1.875407e+002	 7.623906e-001	 1.224821e+004	 9.311383e-002	 1.518152e+000	 1.342484e-002	 6.617980e+002
 1.908607e+002	 7.827261e-001	 1.231456e+004	 9.569339e-002	 1.558646e+000	 1.381528e-002	 6.656479e+002
 1.933407e+002	 8.027955e-001	 1.236246e+004	 9.798678e-002	 1.598611e+000	 1.420284e-002	 6.685000e+002
 1.963207e+002	 8.230852e-001	 1.241578e+004	 9.956484e-002	 1.639014e+000	 1.459384e-002	 6.716505e+002
 1.992207e+002	 8.446355e-001	 1.246818e+004	 1.023253e-001	 1.681927e+000	 1.500954e-002	 6.747702e+002
 2.022207e+002	 8.667317e-001	 1.252151e+004	 1.024148e-001	 1.725927e+000	 1.543565e-002	 6.779492e+002
 2.052207e+002	 8.868443e-001	 1.257658e+004	 1.053469e-001	 1.765978e+000	 1.582246e-002	 6.811993e+002
 2.082207e+002	 9.078372e-001	 1.262415e+004	 1.093066e-001	 1.807781e+000	 1.622739e-002	 6.840565e+002
 2.112207e+002	 9.318765e-001	 1.267547e+004	 1.114419e-001	 1.855650e+000	 1.669130e-002	 6.871603e+002
 2.142207e+002	 9.544150e-001	 1.272212e+004	 1.131638e-001	 1.900531e+000	 1.712626e-002	 6.899930e+002
 2.170807e+002	 9.752468e-001	 1.277177e+004	 1.152374e-001	 1.942014e+000	 1.752722e-002	 6.929679e+002
 2.200207e+002	 9.956525e-001	 1.281541e+004	 1.179561e-001	 1.982648e+000	 1.792051e-002	 6.956130e+002
 2.213607e+002	 1.006409e+000	 1.283569e+004	 1.181863e-001	 2.004067e+000	 1.812813e-002	 6.968600e+002
 2.238007e+002	 1.024508e+000	 1.287107e+004	 1.202648e-001	 2.040107e+000	 1.847720e-002	 6.990278e+002
 2.262207e+002	 1.041537e+000	 1.290745e+004	 1.219131e-001	 2.074019e+000	 1.880512e-002	 7.012367e+002
 2.292207e+002	 1.067240e+000	 1.295251e+004	 1.241716e-001	 2.125201e+000	 1.930118e-002	 7.040377e+002
 2.322207e+002	 1.088418e+000	 1.299674e+004	 1.262703e-001	 2.167373e+000	 1.970877e-002	 7.067333e+002
 2.346807e+002	 1.107981e+000	 1.303196e+004	 1.272116e-001	 2.206327e+000	 2.008588e-002	 7.089185e+002
 2.371007e+002	 1.125591e+000	 1.306684e+004	 1.313959e-001	 2.241395e+000	 2.042480e-002	 7.110598e+002
 2.395207e+002	 1.145951e+000	 1.310022e+004	 1.334963e-001	 2.281938e+000	 2.081744e-002	 7.131589e+002
 2.419407e+002	 1.162839e+000	 1.313435e+004	 1.355371e-001	 2.315568e+000	 2.114215e-002	 7.152520e+002
 2.443607e+002	 1.181885e+000	 1.316397e+004	 1.383284e-001	 2.353494e+000	 2.150941e-002	 7.171309e+002
 2.472207e+002	 1.203102e+000	 1.320294e+004	 1.411043e-001	 2.395742e+000	 2.191755e-002	 7.195508e+002
 2.502207e+002	 1.226027e+000	 1.324174e+004	 1.449110e-001	 2.441394e+000	 2.235884e-002	 7.219872e+002
 2.528207e+002	 1.246133e+000	 1.327604e+004	 1.451453e-001	 2.481431e+000	 2.274566e-002	 7.241401e+002
 2.552207e+002	 1.266305e+000	 1.330650e+004	 1.467688e-001	 2.521599e+000	 2.313411e-002	 7.260860e+002
 2.576407e+002	 1.282750e+000	 1.333454e+004	 1.489704e-001	 2.554346e+000	 2.345027e-002	 7.278483e+002
 2.600607e+002	 1.302066e+000	 1.336441e+004	 1.517632e-001	 2.592811e+000	 2.382191e-002	 7.297526e+002
 2.624807e+002	 1.321057e+000	 1.339120e+004	 1.550944e-001	 2.630628e+000	 2.418749e-002	 7.314848e+002
 2.652207e+002	 1.343191e+000	 1.342533e+004	 1.561265e-001	 2.674703e+000	 2.461302e-002	 7.336640e+002
 2.682207e+002	 1.366668e+000	 1.346004e+004	 1.595636e-001	 2.721454e+000	 2.506439e-002	 7.358960e+002
 2.709607e+002	 1.389119e+000	 1.349301e+004	 1.629817e-001	 2.766160e+000	 2.549586e-002	 7.380192e+002
 2.733807e+002	 1.403474e+000	 1.351754e+004	 1.634066e-001	 2.794746e+000	 2.577118e-002	 7.395667e+002
 2.758007e+002	 1.425671e+000	 1.354449e+004	 1.668924e-001	 2.838946e+000	 2.619822e-002	 7.413601e+002
 2.782207e+002	 1.442661e+000	 1.357161e+004	 1.699916e-001	 2.872777e+000	 2.652409e-002	 7.430889e+002
 2.806407e+002	 1.463579e+000	 1.359807e+004	 1.707874e-001	 2.914432e+000	 2.692610e-002	 7.448387e+002
 2.832207e+002	 1.483680e+000	 1.362335e+004	 1.734382e-001	 2.954460e+000	 2.731227e-002	 7.465139e+002
 2.862207e+002	 1.506066e+000	 1.365548e+004	 1.768629e-001	 2.999037e+000	 2.774163e-002	 7.485984e+002
 2.891207e+002	 1.532656e+000	 1.368569e+004	 1.786831e-001	 3.051986e+000	 2.825244e-002	 7.506401e+002
 2.915207e+002	 1.550793e+000	 1.370955e+004	 1.813304e-001	 3.088102e+000	 2.860028e-002	 7.522126e+002
 2.939407e+002	 1.571063e+000	 1.373459e+004	 1.845838e-001	 3.128465e+000	 2.898910e-002	 7.538813e+002
 2.963607e+002	 1.591377e+000	 1.375712e+004	 1.857054e-001	 3.168917e+000	 2.937896e-002	 7.554141e+002
 2.987807e+002	 1.611445e+000	 1.377965e+004	 1.876254e-001	 3.208878e+000	 2.976391e-002	 7.569444e+002
 3.012207e+002	 1.631422e+000	 1.380260e+004	 1.884539e-001	 3.248659e+000	 3.014690e-002	 7.584972e+002
 3.042207e+002	 1.655834e+000	 1.383222e+004	 1.931674e-001	 3.297271e+000	 3.061452e-002	 7.604830e+002
 3.072207e+002	 1.682180e+000	 1.385984e+004	 1.968412e-001	 3.349733e+000	 3.111949e-002	 7.623886e+002
 3.096807e+002	 1.699269e+000	 1.388279e+004	 1.981323e-001	 3.383764e+000	 3.144625e-002	 7.639024e+002
 3.120807e+002	 1.722130e+000	 1.390399e+004	 2.007814e-001	 3.429286e+000	 3.188445e-002	 7.654055e+002
 3.145007e+002	 1.743706e+000	 1.392819e+004	 1.996833e-001	 3.472251e+000	 3.229730e-002	 7.670562e+002
 3.169207e+002	 1.761027e+000	 1.394896e+004	 2.050654e-001	 3.506742e+000	 3.262841e-002	 7.684566e+002
 3.193407e+002	 1.782032e+000	 1.397091e+004	 2.063339e-001	 3.548569e+000	 3.303024e-002	 7.699767e+002
 3.222207e+002	 1.814290e+000	 1.399161e+004	 2.049775e-001	 3.612806e+000	 3.364878e-002	 7.715956e+002
 3.252207e+002	 1.835743e+000	 1.401781e+004	 2.102916e-001	 3.655524e+000	 3.405825e-002	 7.733593e+002
 3.278207e+002	 1.856824e+000	 1.403817e+004	 2.130613e-001	 3.697504e+000	 3.446120e-002	 7.747963e+002
 3.302407e+002	 1.879451e+000	 1.405728e+004	 2.164847e-001	 3.742559e+000	 3.489385e-002	 7.761881e+002
 3.326607e+002	 1.894860e+000	 1.407631e+004	 2.172538e-001	 3.773244e+000	 3.518759e-002	 7.774685e+002
 3.350807e+002	 1.917881e+000	 1.409466e+004	 2.193584e-001	 3.819086e+000	 3.562762e-002	 7.788264e+002
 3.374807e+002	 1.939905e+000	 1.411636e+004	 2.211814e-001	 3.862943e+000	 3.604786e-002	 7.803547e+002
 3.402207e+002	 1.962052e+000	 1.413722e+004	 2.227372e-001	 3.907044e+000	 3.647039e-002	 7.818398e+002
 3.432207e+002	 1.988814e+000	 1.416184e+004	 2.252480e-001	 3.960335e+000	 3.698081e-002	 7.836029e+002
 3.459607e+002	 2.010442e+000	 1.417769e+004	 2.283602e-001	 4.003403e+000	 3.739366e-002	 7.848052e+002
 3.483807e+002	 2.030498e+000	 1.419630e+004	 2.325002e-001	 4.043340e+000	 3.777583e-002	 7.861371e+002
 3.508007e+002	 2.048878e+000	 1.421374e+004	 2.336934e-001	 4.079941e+000	 3.812589e-002	 7.873797e+002
 3.532207e+002	 2.069979e+000	 1.423327e+004	 2.356423e-001	 4.121960e+000	 3.852769e-002	 7.887797e+002
 3.556407e+002	 2.090387e+000	 1.425021e+004	 2.362474e-001	 4.162598e+000	 3.891639e-002	 7.900267e+002
 3.582207e+002	 2.111281e+000	 1.426648e+004	 2.396916e-001	 4.204205e+000	 3.931433e-002	 7.912447e+002
 3.612207e+002	 2.138784e+000	 1.428484e+004	 2.419680e-001	 4.258972e+000	 3.983832e-002	 7.926794e+002
 3.641407e+002	 2.161875e+000	 1.430270e+004	 2.441394e-001	 4.304952e+000	 4.027769e-002	 7.940203e+002
 3.665607e+002	 2.182777e+000	 1.431830e+004	 2.444024e-001	 4.346575e+000	 4.067535e-002	 7.952038e+002
 3.689807e+002	 2.202771e+000	 1.433391e+004	 2.484584e-001	 4.386389e+000	 4.105548e-002	 7.963742e+002
 3.714007e+002	 2.221647e+000	 1.434993e+004	 2.517934e-001	 4.423977e+000	 4.141405e-002	 7.975514e+002
 3.738207e+002	 2.243317e+000	 1.436779e+004	 2.527238e-001	 4.467128e+000	 4.182560e-002	 7.988739e+002
 3.762407e+002	 2.264198e+000	 1.438373e+004	 2.545634e-001	 4.508709e+000	 4.222219e-002	 8.000784e+002
 3.792207e+002	 2.290900e+000	 1.439950e+004	 2.575723e-001	 4.561882e+000	 4.272972e-002	 8.013633e+002
 3.822207e+002	 2.315723e+000	 1.441669e+004	 2.600847e-001	 4.611311e+000	 4.320096e-002	 8.026992e+002
 3.846807e+002	 2.336180e+000	 1.443229e+004	 2.607566e-001	 4.652048e+000	 4.358896e-002	 8.038810e+002
 3.871007e+002	 2.356337e+000	 1.444756e+004	 2.657650e-001	 4.692186e+000	 4.397114e-002	 8.050402e+002
 3.895207e+002	 2.378654e+000	 1.446317e+004	 2.667234e-001	 4.736626e+000	 4.439426e-002	 8.062518e+002
 3.919407e+002	 2.398546e+000	 1.447602e+004	 2.688629e-001	 4.776238e+000	 4.477141e-002	 8.072734e+002
 3.943607e+002	 2.418941e+000	 1.448820e+004	 2.721784e-001	 4.816849e+000	 4.515807e-002	 8.082659e+002
 3.972207e+002	 2.443477e+000	 1.450848e+004	 2.738681e-001	 4.865708e+000	 4.562230e-002	 8.097745e+002
 4.002207e+002	 2.466412e+000	 1.452534e+004	 2.784221e-001	 4.911378e+000	 4.605631e-002	 8.110683e+002
 4.028207e+002	 2.490775e+000	 1.453485e+004	 2.786504e-001	 4.959894e+000	 4.651827e-002	 8.119748e+002
 4.052607e+002	 2.508631e+000	 1.454670e+004	 2.807474e-001	 4.995449e+000	 4.685604e-002	 8.129121e+002
 4.076807e+002	 2.530408e+000	 1.456039e+004	 2.817597e-001	 5.038814e+000	 4.726796e-002	 8.140129e+002
 4.101007e+002	 2.552085e+000	 1.457274e+004	 2.854007e-001	 5.081980e+000	 4.767798e-002	 8.150382e+002
 4.125207e+002	 2.571133e+000	 1.458650e+004	 2.879094e-001	 5.119910e+000	 4.803775e-002	 8.161027e+002
 4.152207e+002	 2.596934e+000	 1.460111e+004	 2.883978e-001	 5.171287e+000	 4.852538e-002	 8.173190e+002
 4.182207e+002	 2.621253e+000	 1.461471e+004	 2.914874e-001	 5.219713e+000	 4.898481e-002	 8.184571e+002
 4.209807e+002	 2.645694e+000	 1.463040e+004	 2.955014e-001	 5.268385e+000	 4.944609e-002	 8.197146e+002
 4.234007e+002	 2.666737e+000	 1.464183e+004	 2.970929e-001	 5.310287e+000	 4.984331e-002	 8.206817e+002
 4.258207e+002	 2.688215e+000	 1.465343e+004	 2.999148e-001	 5.353055e+000	 5.024860e-002	 8.216654e+002
 4.282407e+002	 2.706445e+000	 1.466236e+004	 3.007714e-001	 5.389358e+000	 5.059260e-002	 8.224494e+002
 4.306607e+002	 2.728594e+000	 1.467379e+004	 3.030986e-001	 5.433462e+000	 5.101030e-002	 8.234351e+002
 4.332207e+002	 2.750409e+000	 1.468639e+004	 3.071326e-001	 5.476904e+000	 5.142137e-002	 8.244817e+002
 4.362207e+002	 2.777894e+000	 1.469666e+004	 3.095050e-001	 5.531634e+000	 5.193976e-002	 8.254861e+002
 4.391207e+002	 2.803078e+000	 1.471393e+004	 3.108789e-001	 5.581783e+000	 5.241350e-002	 8.268490e+002
 4.415407e+002	 2.824427e+000	 1.472344e+004	 3.141973e-001	 5.624295e+000	 5.281558e-002	 8.277167e+002
 4.439607e+002	 2.847671e+000	 1.473554e+004	 3.161379e-001	 5.670582e+000	 5.325296e-002	 8.287600e+002
 4.463807e+002	 2.868305e+000	 1.474347e+004	 3.193772e-001	 5.711671e+000	 5.364143e-002	 8.295283e+002
 4.488007e+002	 2.888393e+000	 1.475515e+004	 3.201444e-001	 5.751672e+000	 5.401895e-002	 8.304997e+002
 4.524207e+002	 2.921150e+000	 1.477410e+004	 3.253344e-001	 5.816902e+000	 5.463428e-002	 8.320788e+002
 4.548407e+002	 2.944630e+000	 1.478236e+004	 3.262098e-001	 5.863657e+000	 5.507580e-002	 8.329119e+002
 4.572607e+002	 2.964815e+000	 1.479162e+004	 3.293004e-001	 5.903850e+000	 5.545491e-002	 8.337503e+002
 4.602207e+002	 2.990015e+000	 1.480255e+004	 3.325196e-001	 5.954032e+000	 5.592812e-002	 8.347619e+002
 4.632207e+002	 3.015811e+000	 1.481415e+004	 3.359169e-001	 6.005401e+000	 5.641223e-002	 8.358210e+002
 4.657407e+002	 3.038154e+000	 1.482024e+004	 3.387612e-001	 6.049892e+000	 5.683185e-002	 8.365156e+002
 4.681607e+002	 3.057769e+000	 1.482959e+004	 3.395586e-001	 6.088951e+000	 5.719959e-002	 8.373514e+002
 4.705807e+002	 3.080124e+000	 1.484002e+004	 3.423734e-001	 6.133467e+000	 5.761854e-002	 8.382920e+002
 4.730007e+002	 3.101637e+000	 1.484803e+004	 3.462341e-001	 6.176305e+000	 5.802182e-002	 8.390831e+002
 4.754207e+002	 3.124331e+000	 1.485863e+004	 3.478364e-001	 6.221496e+000	 5.844678e-002	 8.400393e+002
 4.782207e+002	 3.150120e+000	 1.486781e+004	 3.501968e-001	 6.272849e+000	 5.892985e-002	 8.409647e+002
 4.812207e+002	 3.176392e+000	 1.488074e+004	 3.528377e-001	 6.325165e+000	 5.942126e-002	 8.421106e+002
 4.839007e+002	 3.198483e+000	 1.488633e+004	 3.529969e-001	 6.369156e+000	 5.983498e-002	 8.427755e+002
 4.863207e+002	 3.218388e+000	 1.489751e+004	 3.557843e-001	 6.408792e+000	 6.020680e-002	 8.437229e+002
 4.887407e+002	 3.240070e+000	 1.490528e+004	 3.589084e-001	 6.451968e+000	 6.061224e-002	 8.445049e+002
 4.911607e+002	 3.265970e+000	 1.491379e+004	 3.608631e-001	 6.503543e+000	 6.109644e-002	 8.453965e+002
 4.935807e+002	 3.285627e+000	 1.492188e+004	 3.643329e-001	 6.542686e+000	 6.146355e-002	 8.461663e+002
 4.962207e+002	 3.309310e+000	 1.492914e+004	 3.665162e-001	 6.589847e+000	 6.190600e-002	 8.469527e+002
 4.992207e+002	 3.335434e+000	 1.494183e+004	 3.682063e-001	 6.641866e+000	 6.239321e-002	 8.480859e+002
 5.020607e+002	 3.362237e+000	 1.494466e+004	 3.721765e-001	 6.695240e+000	 6.289417e-002	 8.486715e+002
 5.044807e+002	 3.383339e+000	 1.495359e+004	 3.741374e-001	 6.737260e+000	 6.328752e-002	 8.495130e+002
 5.069007e+002	 3.408058e+000	 1.496077e+004	 3.730489e-001	 6.786483e+000	 6.374852e-002	 8.503126e+002
 5.093207e+002	 3.429854e+000	 1.496953e+004	 3.784232e-001	 6.829886e+000	 6.415454e-002	 8.511564e+002
 5.117407e+002	 3.451164e+000	 1.497646e+004	 3.789495e-001	 6.872320e+000	 6.455153e-002	 8.518884e+002
 5.142207e+002	 3.475113e+000	 1.498739e+004	 3.815305e-001	 6.920011e+000	 6.499711e-002	 8.528907e+002
 5.172207e+002	 3.502444e+000	 1.499131e+004	 3.852589e-001	 6.974434e+000	 6.550646e-002	 8.535481e+002
 5.202007e+002	 3.531465e+000	 1.500116e+004	 3.876684e-001	 7.032223e+000	 6.604629e-002	 8.545702e+002
 5.226007e+002	 3.553473e+000	 1.500892e+004	 3.903369e-001	 7.076049e+000	 6.645545e-002	 8.553624e+002
 5.250207e+002	 3.576439e+000	 1.501451e+004	 3.918464e-001	 7.121781e+000	 6.688256e-002	 8.560464e+002
 5.286407e+002	 3.609317e+000	 1.502636e+004	 3.956344e-001	 7.187251e+000	 6.749318e-002	 8.572456e+002
 5.310607e+002	 3.632040e+000	 1.503103e+004	 3.969380e-001	 7.232500e+000	 6.791545e-002	 8.578742e+002
 5.335007e+002	 3.654981e+000	 1.503487e+004	 3.992544e-001	 7.278181e+000	 6.834168e-002	 8.584588e+002
 5.359207e+002	 3.677641e+000	 1.504321e+004	 4.010814e-001	 7.323304e+000	 6.876194e-002	 8.592966e+002
 5.383407e+002	 3.699286e+000	 1.504722e+004	 4.043022e-001	 7.366406e+000	 6.916372e-002	 8.598705e+002
 5.412207e+002	 3.730624e+000	 1.505690e+004	 4.079176e-001	 7.428810e+000	 6.974464e-002	 8.609238e+002
 5.442207e+002	 3.753215e+000	 1.506316e+004	 4.083957e-001	 7.473797e+000	 7.016331e-002	 8.616423e+002
 5.468007e+002	 3.777656e+000	 1.507259e+004	 4.103724e-001	 7.522466e+000	 7.061570e-002	 8.625721e+002
 5.492207e+002	 3.799103e+000	 1.507885e+004	 4.149867e-001	 7.565173e+000	 7.101278e-002	 8.632730e+002
 5.516407e+002	 3.822153e+000	 1.508494e+004	 4.145614e-001	 7.611073e+000	 7.143944e-002	 8.639903e+002
 5.540607e+002	 3.844173e+000	 1.508869e+004	 4.168992e-001	 7.654922e+000	 7.184713e-002	 8.645575e+002
 5.564807e+002	 3.868293e+000	 1.509454e+004	 4.194514e-001	 7.702951e+000	 7.229327e-002	 8.652781e+002
 5.592207e+002	 3.894071e+000	 1.509963e+004	 4.210971e-001	 7.754282e+000	 7.277002e-002	 8.659824e+002
 5.622207e+002	 3.921541e+000	 1.510613e+004	 4.236615e-001	 7.808985e+000	 7.327769e-002	 8.667955e+002
 5.649807e+002	 3.949831e+000	 1.511006e+004	 4.253564e-001	 7.865319e+000	 7.380059e-002	 8.674736e+002
 5.673807e+002	 3.971933e+000	 1.511707e+004	 4.277144e-001	 7.909330e+000	 7.420840e-002	 8.682301e+002
 5.698007e+002	 3.992493e+000	 1.512257e+004	 4.323554e-001	 7.950272e+000	 7.458776e-002	 8.688759e+002
 5.722207e+002	 4.015802e+000	 1.512725e+004	 4.320486e-001	 7.996687e+000	 7.501786e-002	 8.695181e+002
 5.746407e+002	 4.037916e+000	 1.513125e+004	 4.326404e-001	 8.040723e+000	 7.542580e-002	 8.701030e+002
 5.772207e+002	 4.060722e+000	 1.513601e+004	 4.356477e-001	 8.086137e+000	 7.584625e-002	 8.707424e+002
 5.802207e+002	 4.090082e+000	 1.514460e+004	 4.380739e-001	 8.144601e+000	 7.638694e-002	 8.717081e+002
 5.831007e+002	 4.117593e+000	 1.515103e+004	 4.416789e-001	 8.199383e+000	 7.689352e-002	 8.725197e+002
 5.855207e+002	 4.140724e+000	 1.515512e+004	 4.435134e-001	 8.245445e+000	 7.731944e-002	 8.731267e+002
 5.879407e+002	 4.166946e+000	 1.515904e+004	 4.458629e-001	 8.297660e+000	 7.780212e-002	 8.737739e+002
 5.903607e+002	 4.186413e+000	 1.516463e+004	 4.464764e-001	 8.336426e+000	 7.815998e-002	 8.744091e+002
 5.927807e+002	 4.207695e+000	 1.516789e+004	 4.481664e-001	 8.378803e+000	 7.855140e-002	 8.749388e+002
 5.952207e+002	 4.228899e+000	 1.517239e+004	 4.519185e-001	 8.421027e+000	 7.894109e-002	 8.755397e+002
 5.982207e+002	 4.258637e+000	 1.517631e+004	 4.526742e-001	 8.480246e+000	 7.948768e-002	 8.762444e+002
 6.012207e+002	 4.285816e+000	 1.518015e+004	 4.550902e-001	 8.534366e+000	 7.998692e-002	 8.769033e+002
 6.036807e+002	 4.308052e+000	 1.518174e+004	 4.589467e-001	 8.578645e+000	 8.039538e-002	 8.773527e+002
 6.061007e+002	 4.330204e+000	 1.518683e+004	 4.596539e-001	 8.622757e+000	 8.080170e-002	 8.780034e+002
 6.085207e+002	 4.351932e+000	 1.519342e+004	 4.616854e-001	 8.666024e+000	 8.119986e-002	 8.787344e+002
 6.109407e+002	 4.371650e+000	 1.519684e+004	 4.645706e-001	 8.705288e+000	 8.156138e-002	 8.792498e+002
 6.133407e+002	 4.401091e+000	 1.520218e+004	 4.658972e-001	 8.763914e+000	 8.210089e-002	 8.800332e+002
 6.162207e+002	 4.426992e+000	 1.520252e+004	 4.674161e-001	 8.815491e+000	 8.257586e-002	 8.804698e+002
 6.192207e+002	 4.455204e+000	 1.520719e+004	 4.702817e-001	 8.871669e+000	 8.309239e-002	 8.811951e+002
 6.218407e+002	 4.480440e+000	 1.521445e+004	 4.714520e-001	 8.921923e+000	 8.355383e-002	 8.820227e+002
 6.242607e+002	 4.502904e+000	 1.521687e+004	 4.734814e-001	 8.966656e+000	 8.396491e-002	 8.825253e+002
 6.266807e+002	 4.525528e+000	 1.521862e+004	 4.776834e-001	 9.011707e+000	 8.437882e-002	 8.829919e+002
 6.291007e+002	 4.548891e+000	 1.522371e+004	 4.784962e-001	 9.058229e+000	 8.480566e-002	 8.836641e+002
 6.315207e+002	 4.571628e+000	 1.522830e+004	 4.799924e-001	 9.103506e+000	 8.522095e-002	 8.842975e+002
 6.342207e+002	 4.597497e+000	 1.522855e+004	 4.829896e-001	 9.155019e+000	 8.569386e-002	 8.847296e+002
 6.372207e+002	 4.625515e+000	 1.523489e+004	 4.847727e-001	 9.210811e+000	 8.620503e-002	 8.855505e+002
 6.400007e+002	 4.652431e+000	 1.523414e+004	 4.880774e-001	 9.264410e+000	 8.669672e-002	 8.859414e+002
 6.424207e+002	 4.675153e+000	 1.523832e+004	 4.885424e-001	 9.309656e+000	 8.711099e-002	 8.865510e+002
 6.448407e+002	 4.696855e+000	 1.524115e+004	 4.917015e-001	 9.352870e+000	 8.750664e-002	 8.870665e+002
 6.472607e+002	 4.719368e+000	 1.524432e+004	 4.931804e-001	 9.397701e+000	 8.791691e-002	 8.876149e+002
 6.496607e+002	 4.744080e+000	 1.524875e+004	 4.940523e-001	 9.446910e+000	 8.836692e-002	 8.882717e+002
 6.522207e+002	 4.767799e+000	 1.525258e+004	 4.954277e-001	 9.494143e+000	 8.879872e-002	 8.888788e+002
 6.552207e+002	 4.797082e+000	 1.525300e+004	 4.994713e-001	 9.552453e+000	 8.933209e-002	 8.893765e+002
 6.581207e+002	 4.823539e+000	 1.525751e+004	 5.028408e-001	 9.605137e+000	 8.981322e-002	 8.900671e+002
 6.605407e+002	 4.846596e+000	 1.525776e+004	 5.038640e-001	 9.651051e+000	 9.023279e-002	 8.904545e+002
 6.629607e+002	 4.870506e+000	 1.526210e+004	 5.065894e-001	 9.698664e+000	 9.066720e-002	 8.910945e+002
 6.653807e+002	 4.893175e+000	 1.526385e+004	 5.068854e-001	 9.743803e+000	 9.107916e-002	 8.915635e+002
 6.678007e+002	 4.915806e+000	 1.526577e+004	 5.102414e-001	 9.788870e+000	 9.149027e-002	 8.920418e+002
 6.714207e+002	 4.951265e+000	 1.526953e+004	 5.112364e-001	 9.859479e+000	 9.213395e-002	 8.928351e+002
 6.738407e+002	 4.974911e+000	 1.527036e+004	 5.138061e-001	 9.906565e+000	 9.256317e-002	 8.932665e+002
 6.762607e+002	 4.997534e+000	 1.527211e+004	 5.157284e-001	 9.951614e+000	 9.297353e-002	 8.937352e+002
 6.792207e+002	 5.025856e+000	 1.527553e+004	 5.186135e-001	 1.000801e+001	 9.348687e-002	 8.943939e+002
 6.822207e+002	 5.053078e+000	 1.527820e+004	 5.211857e-001	 1.006222e+001	 9.398011e-002	 8.949911e+002
 6.847207e+002	 5.080829e+000	 1.528196e+004	 5.219309e-001	 1.011748e+001	 9.448255e-002	 8.956605e+002
 6.871407e+002	 5.100779e+000	 1.528480e+004	 5.256274e-001	 1.015721e+001	 9.484357e-002	 8.961500e+002
 6.895607e+002	 5.123226e+000	 1.528588e+004	 5.281179e-001	 1.020191e+001	 9.524991e-002	 8.965772e+002
 6.919807e+002	 5.144058e+000	 1.528663e+004	 5.283904e-001	 1.024339e+001	 9.562687e-002	 8.969588e+002
 6.944007e+002	 5.168886e+000	 1.529014e+004	 5.338364e-001	 1.029283e+001	 9.607565e-002	 8.975668e+002
 6.972207e+002	 5.196721e+000	 1.529264e+004	 5.340954e-001	 1.034826e+001	 9.657872e-002	 8.981649e+002
 7.002207e+002	 5.225764e+000	 1.529139e+004	 5.347816e-001	 1.040609e+001	 9.710383e-002	 8.985621e+002
 7.028807e+002	 5.250210e+000	 1.529389e+004	 5.356971e-001	 1.045477e+001	 9.754517e-002	 8.991054e+002
 7.053007e+002	 5.274673e+000	 1.529514e+004	 5.391822e-001	 1.050348e+001	 9.798677e-002	 8.995755e+002
 7.077207e+002	 5.297345e+000	 1.529681e+004	 5.400097e-001	 1.054863e+001	 9.839580e-002	 9.000412e+002
 7.101407e+002	 5.319901e+000	 1.529665e+004	 5.434324e-001	 1.059355e+001	 9.880281e-002	 9.003971e+002
 7.125607e+002	 5.343259e+000	 1.529932e+004	 5.424506e-001	 1.064006e+001	 9.922376e-002	 9.009330e+002
 7.152207e+002	 5.369801e+000	 1.530299e+004	 5.457898e-001	 1.069291e+001	 9.970179e-002	 9.015797e+002
 7.182207e+002	 5.397588e+000	 1.530340e+004	 5.479134e-001	 1.074824e+001	 1.002024e-001	 9.020550e+002
 7.210407e+002	 5.425196e+000	 1.530457e+004	 5.495632e-001	 1.080322e+001	 1.006995e-001	 9.025717e+002
 7.234607e+002	 5.447506e+000	 1.530816e+004	 5.521293e-001	 1.084765e+001	 1.011007e-001	 9.031452e+002
 7.258807e+002	 5.471650e+000	 1.530733e+004	 5.535827e-001	 1.089572e+001	 1.015352e-001	 9.034877e+002
 7.282807e+002	 5.493312e+000	 1.531067e+004	 5.568188e-001	 1.093886e+001	 1.019245e-001	 9.040362e+002
 7.306807e+002	 5.518253e+000	 1.531125e+004	 5.571896e-001	 1.098852e+001	 1.023728e-001	 9.044754e+002
 7.332207e+002	 5.540611e+000	 1.530891e+004	 5.598201e-001	 1.103305e+001	 1.027749e-001	 9.047001e+002
 7.362207e+002	 5.571146e+000	 1.531067e+004	 5.603939e-001	 1.109385e+001	 1.033232e-001	 9.052992e+002
 7.391607e+002	 5.598144e+000	 1.530958e+004	 5.635365e-001	 1.114761e+001	 1.038080e-001	 9.056731e+002
 7.415807e+002	 5.620348e+000	 1.531092e+004	 5.651073e-001	 1.119183e+001	 1.042064e-001	 9.061124e+002
 7.440007e+002	 5.643502e+000	 1.531183e+004	 5.677941e-001	 1.123793e+001	 1.046216e-001	 9.065425e+002
 7.476407e+002	 5.678487e+000	 1.531192e+004	 5.701905e-001	 1.130760e+001	 1.052489e-001	 9.071151e+002
 7.500607e+002	 5.700796e+000	 1.531258e+004	 5.695089e-001	 1.135202e+001	 1.056486e-001	 9.075167e+002
 7.524807e+002	 5.725229e+000	 1.531392e+004	 5.733204e-001	 1.140068e+001	 1.060860e-001	 9.079924e+002
 7.549007e+002	 5.749627e+000	 1.531333e+004	 5.749594e-001	 1.144926e+001	 1.065230e-001	 9.083537e+002
 7.573207e+002	 5.773015e+000	 1.531517e+004	 5.770226e-001	 1.149583e+001	 1.069413e-001	 9.088423e+002
 7.602207e+002	 5.801134e+000	 1.531626e+004	 5.768048e-001	 1.155183e+001	 1.074442e-001	 9.093631e+002
 7.632207e+002	 5.829418e+000	 1.531834e+004	 5.813529e-001	 1.160815e+001	 1.079496e-001	 9.099461e+002
 7.657807e+002	 5.855133e+000	 1.531525e+004	 5.808438e-001	 1.165936e+001	 1.084096e-001	 9.101801e+002
 7.681807e+002	 5.876620e+000	 1.531868e+004	 5.830500e-001	 1.170214e+001	 1.087930e-001	 9.107323e+002
 7.706207e+002	 5.900747e+000	 1.531601e+004	 5.847993e-001	 1.175019e+001	 1.092242e-001	 9.109652e+002
 7.730407e+002	 5.924192e+000	 1.531467e+004	 5.874346e-001	 1.179687e+001	 1.096428e-001	 9.112663e+002
 7.754607e+002	 5.947910e+000	 1.531425e+004	 5.887247e-001	 1.184410e+001	 1.100660e-001	 9.116264e+002
 7.782207e+002	 5.973431e+000	 1.532126e+004	 5.870543e-001	 1.189492e+001	 1.105203e-001	 9.124581e+002
 7.812207e+002	 6.002975e+000	 1.531776e+004	 5.932964e-001	 1.195376e+001	           0.0	           0.0
 7.839207e+002	 6.029641e+000	 1.531676e+004	 5.942212e-001	 1.200685e+001	           0.0	           0.0
 7.863407e+002	 6.051132e+000	 1.531525e+004	 5.955582e-001	 1.204965e+001	           0.0	           0.0
 7.887807e+002	 6.076016e+000	 1.531392e+004	 5.949529e-001	 1.209920e+001	           0.0	           0.0
 7.911807e+002	 6.097839e+000	 1.531459e+004	 5.958166e-001	 1.214266e+001	           0.0	           0.0
 7.935807e+002	 6.119995e+000	 1.531434e+004	 5.991557e-001	 1.218678e+001	           0.0	           0.0
 7.962207e+002	 6.146800e+000	 1.531175e+004	 6.008217e-001	 1.224015e+001	           0.0	           0.0
 7.992207e+002	 6.173211e+000	 1.530900e+004	 6.017416e-001	 1.229275e+001	           0.0	           0.0
 8.020407e+002	 6.200253e+000	 1.531400e+004	 6.030927e-001	 1.234660e+001	           0.0	           0.0
 8.044607e+002	 6.224950e+000	 1.531142e+004	 6.015007e-001	 1.239577e+001	           0.0	           0.0
 8.068807e+002	 6.248671e+000	 1.530983e+004	 6.055530e-001	 1.244301e+001	           0.0	           0.0
 8.093007e+002	 6.270576e+000	 1.530900e+004	 6.060946e-001	 1.248663e+001	           0.0	           0.0
 8.117207e+002	 6.294239e+000	 1.530816e+004	 6.080995e-001	 1.253375e+001	           0.0	           0.0
 8.142207e+002	 6.318872e+000	 1.530449e+004	 6.077686e-001	 1.258280e+001	           0.0	           0.0
 8.172207e+002	 6.347707e+000	 1.530532e+004	 6.087132e-001	 1.264022e+001	           0.0	           0.0
 8.201807e+002	 6.377497e+000	 1.530416e+004	 6.111121e-001	 1.269954e+001	           0.0	           0.0
 8.226007e+002	 6.401989e+000	 1.530432e+004	 6.123129e-001	 1.274831e+001	           0.0	           0.0
 8.250207e+002	 6.424924e+000	 1.530090e+004	 6.151937e-001	 1.279398e+001	           0.0	           0.0
 8.274407e+002	 6.447715e+000	 1.529940e+004	 6.163388e-001	 1.283937e+001	           0.0	           0.0
 8.298607e+002	 6.472301e+000	 1.529781e+004	 6.131736e-001	 1.288833e+001	           0.0	           0.0
 8.322807e+002	 6.498394e+000	 1.529706e+004	 6.156238e-001	 1.294028e+001	           0.0	           0.0
 8.352207e+002	 6.526530e+000	 1.529272e+004	 6.170809e-001	 1.299631e+001	           0.0	           0.0
 8.382207e+002	 6.554818e+000	 1.528730e+004	 6.149003e-001	 1.305264e+001	           0.0	           0.0
 8.407607e+002	 6.581780e+000	 1.528688e+004	 6.190254e-001	 1.310633e+001	           0.0	           0.0
 8.431807e+002	 6.605464e+000	 1.528338e+004	 6.196004e-001	 1.315349e+001	           0.0	           0.0
 8.456007e+002	 6.631421e+000	 1.528046e+004	 6.193814e-001	 1.320518e+001	           0.0	           0.0
 8.480207e+002	 6.655879e+000	 1.527620e+004	 6.183965e-001	 1.325389e+001	           0.0	           0.0
 8.504407e+002	 6.682039e+000	 1.527378e+004	 6.212863e-001	 1.330598e+001	           0.0	           0.0
 8.532207e+002	 6.710840e+000	 1.526953e+004	 6.212943e-001	 1.336333e+001	           0.0	           0.0
 8.562207e+002	 6.743627e+000	 1.526360e+004	 6.232936e-001	 1.342862e+001	           0.0	           0.0
 8.589007e+002	 6.771992e+000	 1.526385e+004	 6.233913e-001	 1.348510e+001	           0.0	           0.0
 8.613207e+002	 6.799174e+000	 1.525893e+004	 6.248255e-001	 1.353923e+001	           0.0	           0.0
 8.637407e+002	 6.828163e+000	 1.525434e+004	 6.244115e-001	 1.359696e+001	           0.0	           0.0
 8.661607e+002	 6.855971e+000	 1.525158e+004	 6.259246e-001	 1.365233e+001	           0.0	           0.0
 8.685807e+002	 6.881593e+000	 1.524332e+004	 6.264720e-001	 1.370335e+001	           0.0	           0.0
 8.712207e+002	 6.915025e+000	 1.523573e+004	 6.251060e-001	 1.376992e+001	           0.0	           0.0
 8.742207e+002	 6.949293e+000	 1.522939e+004	 6.264625e-001	 1.383816e+001	           0.0	           0.0
 8.770607e+002	 6.985697e+000	 1.522029e+004	 6.257433e-001	 1.391065e+001	           0.0	           0.0
 8.794807e+002	 7.017670e+000	 1.521161e+004	 6.284194e-001	 1.397432e+001	           0.0	           0.0
 8.819007e+002	 7.046755e+000	 1.520343e+004	 6.279114e-001	 1.403224e+001	           0.0	           0.0
 8.843007e+002	 7.078507e+000	 1.519642e+004	 6.290045e-001	 1.409547e+001	           0.0	           0.0
 8.867407e+002	 7.112834e+000	 1.518591e+004	 6.276230e-001	 1.416382e+001	           0.0	           0.0
 8.892207e+002	 7.148821e+000	 1.517506e+004	 6.277362e-001	 1.423548e+001	           0.0	           0.0
 8.922207e+002	 7.190328e+000	 1.516013e+004	 6.277236e-001	 1.431814e+001	           0.0	           0.0
 8.952007e+002	 7.233069e+000	 1.514160e+004	 6.281831e-001	 1.440325e+001	           0.0	           0.0
 8.976207e+002	 7.271159e+000	 1.512775e+004	 6.281468e-001	 1.447910e+001	           0.0	           0.0
 9.000407e+002	 7.306882e+000	 1.511122e+004	 6.292408e-001	 1.455023e+001	           0.0	           0.0
 9.036407e+002	 7.362849e+000	 1.508644e+004	 6.298725e-001	 1.466168e+001	           0.0	           0.0
 9.060607e+002	 7.399820e+000	 1.506741e+004	 6.290337e-001	 1.473530e+001	           0.0	           0.0
 9.085007e+002	 7.439162e+000	 1.504355e+004	 6.288855e-001	 1.481364e+001	           0.0	           0.0
 9.109207e+002	 7.479142e+000	 1.501993e+004	 6.291628e-001	 1.489325e+001	           0.0	           0.0
 9.133407e+002	 7.519413e+000	 1.499507e+004	 6.297563e-001	 1.497344e+001	           0.0	           0.0
 9.162207e+002	 7.567113e+000	 1.496694e+004	 6.296490e-001	 1.506843e+001	           0.0	           0.0
 9.192207e+002	 7.617433e+000	 1.493407e+004	 6.295450e-001	 1.516863e+001	           0.0	           0.0
 9.218007e+002	 7.661142e+000	 1.490085e+004	 6.295861e-001	 1.525567e+001	           0.0	           0.0
 9.242207e+002	 7.702176e+000	 1.486806e+004	 6.295133e-001	 1.533738e+001	           0.0	           0.0
 9.266407e+002	 7.742709e+000	 1.483184e+004	 6.303182e-001	 1.541810e+001	           0.0	           0.0
 9.290607e+002	 7.785207e+000	 1.479237e+004	 6.274298e-001	 1.550272e+001	           0.0	           0.0
 9.315007e+002	 7.828871e+000	 1.474789e+004	 6.307179e-001	 1.558967e+001	           0.0	           0.0
 9.342207e+002	 7.875318e+000	 1.468723e+004	 6.295184e-001	 1.568216e+001	           0.0	           0.0
 9.372207e+002	 7.931222e+000	 1.452534e+004	 6.285696e-001	 1.579348e+001	           0.0	           0.0
 9.375407e+002	 7.934233e+000	 1.445332e+004	 6.290820e-001	 1.579948e+001	           0.0	           0.0