File: DP800 Tensile Tests/Fehlemann_Test_WP_KL_2024_1018.TRA
$Fehlemann_Test_WP_KL_2024_101.ZSE
Material:                               St
Auftrags-Nr.:                           WP_KL_2024_101
Probe:                                  3_45°_B
Vorkraft:                               100 N
Probengeometrie:                        H12,5x50
Messlänge:                              50.6149 mm
Probendicke a0:                         1.49 mm
Probenbreite b0:                        12.62 mm
Prüfgeschwindigkeit:                    1 mm/min
Datum:                                  26.09.2024
Maschinendaten:                         4204 WN:800315
Traversenwegaufnehmer WN:800315
Videoextensometer
Videoextensometer - Querdehnung
Kraftsensor ID:0 WN:800316 50 kN

Bemerkung:
$
      Prüfzeit	   Standardweg	 Spannung	Breitenänderung	       Dehnung	 wahre Dehnung	wahre Spannung
 2.054688e-002	-7.484711e-005	 1.991064e+002	 6.723773e-005	-1.478757e-004	 0.000000e+000	 1.059047e+001
 1.205469e-001	-8.495891e-004	 1.992733e+002	 1.633668e-004	-1.678536e-003	 0.000000e+000	 1.059918e+001
 2.205469e-001	-1.938815e-003	 1.992733e+002	 7.662700e-004	-3.830524e-003	 0.000000e+000	 1.059895e+001
 4.405469e-001	-7.739741e-004	 2.026947e+002	-1.880069e-003	-1.529143e-003	 0.000000e+000	 1.078118e+001
 5.805469e-001	 2.691206e-004	 2.414145e+002	-2.005762e-003	 5.317026e-004	 0.000000e+000	 1.284092e+001
 9.005468e-001	 1.000217e-003	 3.290346e+002	-1.782311e-003	 1.976133e-003	 0.000000e+000	 1.750171e+001
 1.140547e+000	 2.145475e-003	 3.949583e+002	-1.139375e-003	 4.238824e-003	 0.000000e+000	 2.100875e+001
 1.280547e+000	 3.513766e-003	 4.333443e+002	-9.811494e-004	 6.942160e-003	 0.000000e+000	 2.305121e+001
 1.660547e+000	 4.701218e-003	 5.341492e+002	-1.976117e-003	 9.288213e-003	 0.000000e+000	 2.841406e+001
 1.940547e+000	 5.747713e-003	 6.133412e+002	-1.473944e-003	 1.135578e-002	 0.000000e+000	 3.262735e+001
 2.460547e+000	 7.057733e-003	 7.538672e+002	 7.912700e-004	 1.394399e-002	 0.000000e+000	 4.010383e+001
 2.760547e+000	 8.331088e-003	 8.380660e+002	 7.431274e-006	 1.645976e-002	 0.000000e+000	 4.458411e+001
 3.060547e+000	 9.694776e-003	 9.185931e+002	-2.185850e-003	 1.915400e-002	 0.000000e+000	 4.886937e+001
 3.340547e+000	 1.097138e-002	 9.991202e+002	 1.605980e-003	 2.167619e-002	 0.000000e+000	 5.315477e+001
 3.500547e+000	 1.236948e-002	 1.042179e+003	-3.173429e-004	 2.443842e-002	 0.000000e+000	 5.544711e+001
 3.600547e+000	 1.376986e-002	 1.069717e+003	-1.015569e-003	 2.720517e-002	 0.000000e+000	 5.691378e+001
 3.900547e+000	 1.273554e-002	 1.153415e+003	 6.879151e-004	 2.516165e-002	 0.000000e+000	 6.136565e+001
 4.140547e+000	 1.302431e-002	 1.219923e+003	-4.223752e-004	 2.573218e-002	 0.000000e+000	 6.490446e+001
 4.480547e+000	 1.418309e-002	 1.317307e+003	 1.743431e-003	 2.802158e-002	 0.000000e+000	 7.008724e+001
 4.600547e+000	 1.521080e-002	 1.349517e+003	 7.943127e-005	 3.005203e-002	 0.000000e+000	 7.180247e+001
 4.920547e+000	 1.643237e-002	 1.441727e+003	-1.433319e-003	 3.246549e-002	 0.000000e+000	 7.671044e+001
 5.380547e+000	 1.652048e-002	 1.570153e+003	 5.751915e-003	 3.263956e-002	 0.000000e+000	 8.354379e+001
 5.500547e+000	 1.798799e-002	 1.603950e+003	 2.099818e-003	 3.553894e-002	 1.207600e-005	 8.534448e+001
 5.620547e+000	 1.919873e-002	 1.637662e+003	-1.504536e-003	 3.793101e-002	 2.509943e-005	 8.714039e+001
 5.780547e+000	 2.049231e-002	 1.683976e+003	-2.831440e-003	 4.048674e-002	 3.568645e-005	 8.960704e+001
 5.940547e+000	 2.026225e-002	 1.726034e+003	 8.163063e-004	 4.003219e-002	 1.754717e-005	 9.184457e+001
 6.140547e+000	 2.153044e-002	 1.780191e+003	 1.130141e-003	 4.253778e-002	 2.509749e-005	 9.472874e+001
 6.340547e+000	 2.266567e-002	 1.836268e+003	 1.147947e-003	 4.478064e-002	 2.940029e-005	 9.771493e+001
 6.520547e+000	 2.370002e-002	 1.885002e+003	-2.064569e-003	 4.682422e-002	 3.408378e-005	 1.003103e+002
 6.600547e+000	 2.492338e-002	 1.907032e+003	-3.086569e-003	 4.924121e-002	 5.113212e-005	 1.014851e+002
 6.780547e+000	 2.471325e-002	 1.954597e+003	-1.095117e-003	 4.882606e-002	 3.160687e-005	 1.040159e+002
 6.860547e+000	 2.338622e-002	 1.976460e+003	-9.964397e-004	 4.620423e-002	 0.000000e+000	 1.051766e+002
 6.920547e+000	 2.282215e-002	 1.992149e+003	-9.493188e-004	 4.508981e-002	 0.000000e+000	 1.060103e+002
 7.120547e+000	 2.424531e-002	 2.044053e+003	-5.004397e-004	 4.790155e-002	 0.000000e+000	 1.087754e+002
 7.160547e+000	 2.528364e-002	 2.054901e+003	-6.418163e-005	 4.995297e-002	 1.045512e-005	 1.093549e+002
 7.620547e+000	 2.674377e-002	 2.175817e+003	-7.811171e-004	 5.283775e-002	 2.193696e-007	 1.157930e+002
 7.740547e+000	 2.786683e-002	 2.206025e+003	-1.575246e-003	 5.505660e-002	 1.264359e-005	 1.174032e+002
 8.000546e+000	 2.910377e-002	 2.274953e+003	-3.523429e-004	 5.750041e-002	 1.480211e-005	 1.210744e+002
 8.240547e+000	 2.907580e-002	 2.334368e+003	-3.312784e-004	 5.744516e-002	 0.000000e+000	 1.242365e+002
 8.440547e+000	 3.040384e-002	 2.383853e+003	 6.430563e-004	 6.006897e-002	 5.288198e-006	 1.268734e+002
 8.720547e+000	 3.155399e-002	 2.453448e+003	 1.565463e-003	 6.234133e-002	 5.516468e-006	 1.305804e+002
 9.040546e+000	 3.266909e-002	 2.530637e+003	 6.834313e-004	 6.454444e-002	 2.597718e-006	 1.346916e+002
 9.180547e+000	 3.154187e-002	 2.564267e+003	 1.402438e-004	 6.231738e-002	 0.000000e+000	 1.364785e+002
 9.440547e+000	 3.268909e-002	 2.624432e+003	 8.454313e-004	 6.458395e-002	 0.000000e+000	 1.396838e+002
 9.640547e+000	 3.391806e-002	 2.670162e+003	-4.121171e-004	 6.701203e-002	 0.000000e+000	 1.421212e+002
 9.800547e+000	 3.532922e-002	 2.709466e+003	-6.379437e-004	 6.980006e-002	 0.000000e+000	 1.442172e+002
 9.960546e+000	 3.583338e-002	 2.743846e+003	 3.598184e-004	 7.079613e-002	 0.000000e+000	 1.460486e+002
 1.050055e+001	 3.716625e-002	 2.863427e+003	 1.325754e-003	 7.342949e-002	 0.000000e+000	 1.524176e+002
 1.100055e+001	 3.838577e-002	 2.962980e+003	 9.022700e-004	 7.583890e-002	 0.000000e+000	 1.577206e+002
 1.124055e+001	 3.947438e-002	 3.011630e+003	 6.196571e-004	 7.798967e-002	 0.000000e+000	 1.603137e+002
 1.162055e+001	 3.949919e-002	 3.084814e+003	 2.884313e-004	 7.803868e-002	 0.000000e+000	 1.642094e+002
 1.176055e+001	 4.070709e-002	 3.109347e+003	 3.614313e-004	 8.042514e-002	 0.000000e+000	 1.655193e+002
 1.194055e+001	 4.201331e-002	 3.140974e+003	 1.565681e-003	 8.300584e-002	 0.000000e+000	 1.672072e+002
 1.272055e+001	 4.326990e-002	 3.278162e+003	 8.672700e-004	 8.548849e-002	 0.000000e+000	 1.745147e+002
 1.290055e+001	 4.409883e-002	 3.307452e+003	 1.620238e-003	 8.712622e-002	 0.000000e+000	 1.760768e+002
 1.300055e+001	 4.485231e-002	 3.323141e+003	 2.577851e-003	 8.861488e-002	 0.000000e+000	 1.769146e+002
 1.338055e+001	 4.611535e-002	 3.384475e+003	 6.997861e-004	 9.111026e-002	 0.000000e+000	 1.801844e+002
 1.408055e+001	 4.611125e-002	 3.493291e+003	 1.643173e-003	 9.110216e-002	 0.000000e+000	 1.859776e+002
 1.434055e+001	 4.733309e-002	 3.530592e+003	 2.140335e-003	 9.351615e-002	 0.000000e+000	 1.879679e+002
 1.460055e+001	 4.853261e-002	 3.571731e+003	 1.986431e-003	 9.588604e-002	 0.000000e+000	 1.901627e+002
 1.500055e+001	 4.983367e-002	 3.632732e+003	 1.348464e-003	 9.845656e-002	 0.000000e+000	 1.934154e+002
 1.554055e+001	 5.128509e-002	 3.711506e+003	 2.897431e-003	 1.013241e-001	 0.000000e+000	 1.976152e+002
 1.590055e+001	 5.189944e-002	 3.764746e+003	 6.639474e-004	 1.025379e-001	 0.000000e+000	 2.004523e+002
 1.890055e+001	 5.960489e-002	 4.181484e+003	 6.115431e-003	 1.177616e-001	 1.165637e-006	 2.226753e+002
 2.190055e+001	 6.587899e-002	 4.557083e+003	 3.070883e-003	 1.301574e-001	 3.718593e-006	 2.427069e+002
 2.490055e+001	 7.404786e-002	 4.908398e+003	 2.910980e-003	 1.462966e-001	 5.155415e-005	 2.614598e+002
 2.870055e+001	 8.154777e-002	 5.324719e+003	 4.114496e-003	 1.611142e-001	 6.516176e-005	 2.836783e+002
 3.390055e+001	 9.128045e-002	 5.857282e+003	 4.051399e-003	 1.803431e-001	 8.530852e-005	 3.121109e+002
 3.690055e+001	 9.691761e-002	 6.139085e+003	 8.384335e-003	 1.914805e-001	 1.055929e-004	 3.271634e+002
 3.990055e+001	 1.029417e-001	 6.400778e+003	 8.021141e-003	 2.033823e-001	 1.400200e-004	 3.411500e+002
 4.468055e+001	 1.117822e-001	 6.792732e+003	 7.799869e-003	 2.208486e-001	 1.879837e-004	 3.621036e+002
 4.868055e+001	 1.217919e-001	 7.084382e+003	 7.066181e-003	 2.406247e-001	 2.914499e-004	 3.777252e+002
 5.190055e+001	 1.299915e-001	 7.306854e+003	 8.233560e-003	 2.568246e-001	 3.815093e-004	 3.896499e+002
 5.490055e+001	 1.363507e-001	 7.500786e+003	 7.910786e-003	 2.693886e-001	 4.444380e-004	 4.000418e+002
 5.790055e+001	 1.437947e-001	 7.682452e+003	 9.184850e-003	 2.840957e-001	 5.327464e-004	 4.097907e+002
 6.106055e+001	 1.519513e-001	 7.864785e+003	 9.181400e-003	 3.002107e-001	 6.349009e-004	 4.195840e+002
 6.522055e+001	 1.620050e-001	 8.097438e+003	 1.373511e-002	 3.200739e-001	 7.582468e-004	 4.320815e+002
 6.866055e+001	 1.721451e-001	 8.277351e+003	 1.599898e-002	 3.401077e-001	 9.003131e-004	 4.417699e+002
 7.258054e+001	 1.822561e-001	 8.470449e+003	 1.818066e-002	 3.600841e-001	 1.037529e-003	 4.521657e+002
 7.590054e+001	 1.918086e-001	 8.630585e+003	 1.664253e-002	 3.789570e-001	 1.174346e-003	 4.608006e+002
 7.890054e+001	 2.004555e-001	 8.766521e+003	 1.853669e-002	 3.960406e-001	 1.301086e-003	 4.681381e+002
 8.190054e+001	 2.113109e-001	 8.896450e+003	 1.744459e-002	 4.174877e-001	 1.473322e-003	 4.751779e+002
 8.490054e+001	 2.197175e-001	 9.024709e+003	 1.847975e-002	 4.340967e-001	 1.597763e-003	 4.821082e+002
 8.790054e+001	 2.292466e-001	 9.146793e+003	 1.763917e-002	 4.529233e-001	 1.746319e-003	 4.887216e+002
 9.090054e+001	 2.389125e-001	 9.262535e+003	 1.891101e-002	 4.720204e-001	 1.899599e-003	 4.949999e+002
 9.390054e+001	 2.509223e-001	 9.380697e+003	 2.059563e-002	 4.957481e-001	 2.098285e-003	 5.014329e+002
 9.690054e+001	 2.619476e-001	 9.494604e+003	 2.302340e-002	 5.175308e-001	 2.278899e-003	 5.076316e+002
 9.962054e+001	 2.728638e-001	 9.592905e+003	 2.436359e-002	 5.390980e-001	 2.462361e-003	 5.129974e+002
 1.024605e+002	 2.830359e-001	 9.694211e+003	 2.471985e-002	 5.591950e-001	 2.630158e-003	 5.185185e+002
 1.050805e+002	 2.930696e-001	 9.783333e+003	 2.529566e-002	 5.790186e-001	 2.799128e-003	 5.233886e+002
 1.071805e+002	 3.032682e-001	 9.856350e+003	 2.531506e-002	 5.991681e-001	 2.976509e-003	 5.274004e+002
 1.099805e+002	 3.133541e-001	 9.948810e+003	 2.614443e-002	 6.190948e-001	 3.145372e-003	 5.324533e+002
 1.123205e+002	 3.233991e-001	 1.002325e+004	 2.959914e-002	 6.389408e-001	 3.319209e-003	 5.365428e+002
 1.149005e+002	 3.346904e-001	 1.010911e+004	 2.969256e-002	 6.612490e-001	 3.513870e-003	 5.412592e+002
 1.179005e+002	 3.463623e-001	 1.020316e+004	 3.093562e-002	 6.843092e-001	 3.713351e-003	 5.464197e+002
 1.209005e+002	 3.594848e-001	 1.029495e+004	 3.214969e-002	 7.102353e-001	 3.942066e-003	 5.514775e+002
 1.239005e+002	 3.717152e-001	 1.038149e+004	 3.366782e-002	 7.343990e-001	 4.154868e-003	 5.562464e+002
 1.264205e+002	 3.836539e-001	 1.045242e+004	 3.634643e-002	 7.579865e-001	 4.366911e-003	 5.601780e+002
 1.285605e+002	 3.936595e-001	 1.051242e+004	 3.566140e-002	 7.777545e-001	 4.544405e-003	 5.635041e+002
 1.310005e+002	 4.036764e-001	 1.057784e+004	 3.756169e-002	 7.975450e-001	 4.720346e-003	 5.671223e+002
 1.330206e+002	 4.138946e-001	 1.062774e+004	 3.883743e-002	 8.177330e-001	 4.905204e-003	 5.699119e+002
 1.359005e+002	 4.251252e-001	 1.070451e+004	 4.066527e-002	 8.399213e-001	 5.101290e-003	 5.741551e+002
 1.389005e+002	 4.390742e-001	 1.078287e+004	 4.145711e-002	 8.674805e-001	 5.350249e-003	 5.785159e+002
 1.419005e+002	 4.524240e-001	 1.085564e+004	 4.345050e-002	 8.938558e-001	 5.589172e-003	 5.825722e+002
 1.444406e+002	 4.643425e-001	 1.091781e+004	 4.488943e-002	 9.174032e-001	 5.803327e-003	 5.860453e+002
 1.467405e+002	 4.743505e-001	 1.097413e+004	 4.641672e-002	 9.371759e-001	 5.981793e-003	 5.891842e+002
 1.485005e+002	 4.844020e-001	 1.101494e+004	 4.795627e-002	 9.570348e-001	 6.166069e-003	 5.914913e+002
 1.509005e+002	 4.952459e-001	 1.107427e+004	 4.935820e-002	 9.784592e-001	 6.359918e-003	 5.948035e+002
 1.539005e+002	 5.092542e-001	 1.114303e+004	 4.987130e-002	 1.006135e+000	 6.612808e-003	 5.986607e+002
 1.568806e+002	 5.251745e-001	 1.121154e+004	 5.241792e-002	 1.037589e+000	 6.903232e-003	 6.025290e+002
 1.589005e+002	 5.354135e-001	 1.126078e+004	 5.372088e-002	 1.057818e+000	 7.088311e-003	 6.052961e+002
 1.609005e+002	 5.454243e-001	 1.130500e+004	 5.389998e-002	 1.077597e+000	 7.270486e-003	 6.077923e+002
 1.629005e+002	 5.558307e-001	 1.134748e+004	 5.601540e-002	 1.098157e+000	 7.460949e-003	 6.102000e+002
 1.659005e+002	 5.725633e-001	 1.141532e+004	 5.817482e-002	 1.131215e+000	 7.767265e-003	 6.140489e+002
 1.683006e+002	 5.858979e-001	 1.147098e+004	 5.983071e-002	 1.157561e+000	 8.010797e-003	 6.172036e+002
 1.702805e+002	 5.961097e-001	 1.151437e+004	 6.112366e-002	 1.177736e+000	 8.197012e-003	 6.196619e+002
 1.721205e+002	 6.062487e-001	 1.155476e+004	 6.214901e-002	 1.197768e+000	 8.382728e-003	 6.219586e+002
 1.749005e+002	 6.224257e-001	 1.161359e+004	 6.370701e-002	 1.229729e+000	 8.680768e-003	 6.253227e+002
 1.772206e+002	 6.364086e-001	 1.166416e+004	 6.568836e-002	 1.257355e+000	 8.938402e-003	 6.282169e+002
 1.789605e+002	 6.464413e-001	 1.170188e+004	 6.704175e-002	 1.277176e+000	 9.122755e-003	 6.303717e+002
 1.809005e+002	 6.587369e-001	 1.174452e+004	 6.737331e-002	 1.301469e+000	 9.349791e-003	 6.328205e+002
 1.837605e+002	 6.770150e-001	 1.180410e+004	 6.907195e-002	 1.337581e+000	 9.688414e-003	 6.362576e+002
 1.855005e+002	 6.870387e-001	 1.184015e+004	 7.048192e-002	 1.357385e+000	 9.872986e-003	 6.383254e+002
 1.870605e+002	 6.971890e-001	 1.187462e+004	 7.175918e-002	 1.377439e+000	 1.006051e-002	 6.403101e+002
 1.898806e+002	 7.173247e-001	 1.193320e+004	 7.421260e-002	 1.417221e+000	 1.043553e-002	 6.437213e+002
 1.915605e+002	 7.273960e-001	 1.196541e+004	 7.513471e-002	 1.437119e+000	 1.062212e-002	 6.455855e+002
 1.929005e+002	 7.377610e-001	 1.199512e+004	 7.587175e-002	 1.457597e+000	 1.081522e-002	 6.473190e+002
 1.959005e+002	 7.567561e-001	 1.205637e+004	 7.917020e-002	 1.495126e+000	 1.116683e-002	 6.508650e+002
 1.976405e+002	 7.678736e-001	 1.208925e+004	 8.080711e-002	 1.517091e+000	 1.137351e-002	 6.527812e+002
 1.991005e+002	 7.779397e-001	 1.212096e+004	 8.070643e-002	 1.536978e+000	 1.155998e-002	 6.546216e+002
 2.019005e+002	 7.974423e-001	 1.217545e+004	 8.141024e-002	 1.575510e+000	 1.192339e-002	 6.578141e+002
 2.033405e+002	 8.079993e-001	 1.220065e+004	 8.544120e-002	 1.596367e+000	 1.212142e-002	 6.593110e+002
 2.049005e+002	 8.184538e-001	 1.223252e+004	 8.506488e-002	 1.617022e+000	 1.231529e-002	 6.611679e+002
 2.077005e+002	 8.383720e-001	 1.228810e+004	 9.017717e-002	 1.656375e+000	 1.268618e-002	 6.644290e+002
 2.090605e+002	 8.483912e-001	 1.230971e+004	 8.961672e-002	 1.676170e+000	 1.287472e-002	 6.657272e+002
 2.109005e+002	 8.622422e-001	 1.234551e+004	 9.074375e-002	 1.703535e+000	 1.313342e-002	 6.678429e+002
 2.132405e+002	 8.788283e-001	 1.239049e+004	 9.347114e-002	 1.736304e+000	 1.344244e-002	 6.704920e+002
 2.144805e+002	 8.888431e-001	 1.240793e+004	 9.306643e-002	 1.756090e+000	 1.363208e-002	 6.715663e+002
 2.169005e+002	 9.052263e-001	 1.245208e+004	 9.690963e-002	 1.788459e+000	 1.393726e-002	 6.741700e+002
 2.187206e+002	 9.193302e-001	 1.248395e+004	 9.920069e-002	 1.816324e+000	 1.420186e-002	 6.760808e+002
 2.201405e+002	 9.296790e-001	 1.250790e+004	 9.939437e-002	 1.836770e+000	 1.439578e-002	 6.775138e+002
 2.229005e+002	 9.497406e-001	 1.255864e+004	 1.010209e-001	 1.876406e+000	 1.477024e-002	 6.805268e+002
 2.255206e+002	 9.698823e-001	 1.260370e+004	 1.036191e-001	 1.916200e+000	 1.514792e-002	 6.832353e+002
 2.269406e+002	 9.801365e-001	 1.262665e+004	 1.067838e-001	 1.936459e+000	 1.534014e-002	 6.846153e+002
 2.289005e+002	 9.955065e-001	 1.265803e+004	 1.086048e-001	 1.966826e+000	 1.562916e-002	 6.865210e+002
 2.308006e+002	 1.010258e+000	 1.269065e+004	 1.081146e-001	 1.995970e+000	 1.590566e-002	 6.884873e+002
 2.313605e+002	 1.013679e+000	 1.269875e+004	 1.093821e-001	 2.002729e+000	 1.596960e-002	 6.889720e+002
 2.325605e+002	 1.022844e+000	 1.271986e+004	 1.105641e-001	 2.020837e+000	 1.614109e-002	 6.902400e+002
 2.349005e+002	 1.040613e+000	 1.275941e+004	 1.146730e-001	 2.055943e+000	 1.647389e-002	 6.926246e+002
 2.362005e+002	 1.051508e+000	 1.277936e+004	 1.142262e-001	 2.077469e+000	 1.667927e-002	 6.938536e+002
 2.379005e+002	 1.064591e+000	 1.280506e+004	 1.151092e-001	 2.103316e+000	 1.692527e-002	 6.954250e+002
 2.398006e+002	 1.079069e+000	 1.283527e+004	 1.177030e-001	 2.131920e+000	 1.719687e-002	 6.972609e+002
 2.410206e+002	 1.089272e+000	 1.285513e+004	 1.185538e-001	 2.152079e+000	 1.738870e-002	 6.984776e+002
 2.434406e+002	 1.107988e+000	 1.289101e+004	 1.223781e-001	 2.189057e+000	 1.774064e-002	 7.006807e+002
 2.446606e+002	 1.118489e+000	 1.290737e+004	 1.236072e-001	 2.209803e+000	 1.793923e-002	 7.017122e+002
 2.469005e+002	 1.133454e+000	 1.294075e+004	 1.246440e-001	 2.239368e+000	 1.821900e-002	 7.037303e+002
 2.482805e+002	 1.143862e+000	 1.296369e+004	 1.258486e-001	 2.259932e+000	 1.841361e-002	 7.051200e+002
 2.499005e+002	 1.157735e+000	 1.298531e+004	 1.271753e-001	 2.287341e+000	 1.867582e-002	 7.064849e+002
 2.519205e+002	 1.174230e+000	 1.301343e+004	 1.293729e-001	 2.319931e+000	 1.898671e-002	 7.082404e+002
 2.531205e+002	 1.183733e+000	 1.303154e+004	 1.288658e-001	 2.338706e+000	 1.916517e-002	 7.093560e+002
 2.555405e+002	 1.203421e+000	 1.306525e+004	 1.322356e-001	 2.377603e+000	 1.953600e-002	 7.114614e+002
 2.567606e+002	 1.213508e+000	 1.308152e+004	 1.340134e-001	 2.397533e+000	 1.972627e-002	 7.124862e+002
 2.589005e+002	 1.229713e+000	 1.311206e+004	 1.348678e-001	 2.429549e+000	 2.003045e-002	 7.143729e+002
 2.603806e+002	 1.244400e+000	 1.312967e+004	 1.364243e-001	 2.458566e+000	 2.030925e-002	 7.155348e+002
 2.619005e+002	 1.257151e+000	 1.315170e+004	 1.395667e-001	 2.483758e+000	 2.054909e-002	 7.169116e+002
 2.640005e+002	 1.273551e+000	 1.318341e+004	 1.420706e-001	 2.516159e+000	 2.085642e-002	 7.188673e+002
 2.652206e+002	 1.284642e+000	 1.319534e+004	 1.414574e-001	 2.538073e+000	 2.106724e-002	 7.196717e+002
 2.676405e+002	 1.305080e+000	 1.322831e+004	 1.463348e-001	 2.578452e+000	 2.145211e-002	 7.217535e+002
 2.688405e+002	 1.315009e+000	 1.324425e+004	 1.466445e-001	 2.598067e+000	 2.163904e-002	 7.227613e+002
 2.709005e+002	 1.332709e+000	 1.326953e+004	 1.469813e-001	 2.633037e+000	 2.197320e-002	 7.243879e+002
 2.724806e+002	 1.346071e+000	 1.328856e+004	 1.491671e-001	 2.659436e+000	 2.222541e-002	 7.256132e+002
 2.739005e+002	 1.358926e+000	 1.330541e+004	 1.501646e-001	 2.684835e+000	 2.246845e-002	 7.267133e+002
 2.761006e+002	 1.377713e+000	 1.333529e+004	 1.524324e-001	 2.721952e+000	 2.282187e-002	 7.286082e+002
 2.773206e+002	 1.387783e+000	 1.334772e+004	 1.553046e-001	 2.741848e+000	 2.301240e-002	 7.294288e+002
 2.797405e+002	 1.408426e+000	 1.337801e+004	 1.579734e-001	 2.782632e+000	 2.340132e-002	 7.313743e+002
 2.809406e+002	 1.413926e+000	 1.339237e+004	 1.580919e-001	 2.793498e+000	 2.350292e-002	 7.322364e+002
 2.829005e+002	 1.435645e+000	 1.341181e+004	 1.593785e-001	 2.836409e+000	 2.391584e-002	 7.336055e+002
 2.845605e+002	 1.451011e+000	 1.343384e+004	 1.612751e-001	 2.866768e+000	 2.420526e-002	 7.350274e+002
 2.859005e+002	 1.462568e+000	 1.344736e+004	 1.616138e-001	 2.889601e+000	 2.442385e-002	 7.359304e+002
 2.882006e+002	 1.481872e+000	 1.347222e+004	 1.661739e-001	 2.927739e+000	 2.478811e-002	 7.375645e+002
 2.894005e+002	 1.491895e+000	 1.348933e+004	 1.665393e-001	 2.947542e+000	 2.497588e-002	 7.386432e+002
 2.918206e+002	 1.512810e+000	 1.351445e+004	 1.681707e-001	 2.988864e+000	 2.537092e-002	 7.403155e+002
 2.930406e+002	 1.524135e+000	 1.352555e+004	 1.687232e-001	 3.011238e+000	 2.558553e-002	 7.410844e+002
 2.949005e+002	 1.540223e+000	 1.354841e+004	 1.714372e-001	 3.043023e+000	 2.588810e-002	 7.425662e+002
 2.966606e+002	 1.556525e+000	 1.356761e+004	 1.732728e-001	 3.075233e+000	 2.619587e-002	 7.438506e+002
 2.979005e+002	 1.567462e+000	 1.357979e+004	 1.724274e-001	 3.096840e+000	 2.640250e-002	 7.446746e+002
 3.003005e+002	 1.588333e+000	 1.360649e+004	 1.737479e-001	 3.138075e+000	 2.679562e-002	 7.464373e+002
 3.015005e+002	 1.600149e+000	 1.361951e+004	 1.775571e-001	 3.161421e+000	 2.701879e-002	 7.473205e+002
 3.039005e+002	 1.621045e+000	 1.364196e+004	 1.792553e-001	 3.202704e+000	 2.741348e-002	 7.488518e+002
 3.051405e+002	 1.632074e+000	 1.365464e+004	 1.796419e-001	 3.224495e+000	 2.762148e-002	 7.497062e+002
 3.069005e+002	 1.646937e+000	 1.367609e+004	 1.812589e-001	 3.253859e+000	 2.790034e-002	 7.510973e+002
 3.087805e+002	 1.665088e+000	 1.369128e+004	 1.831374e-001	 3.289720e+000	 2.824424e-002	 7.521925e+002
 3.099806e+002	 1.674982e+000	 1.370521e+004	 1.835242e-001	 3.309268e+000	 2.842989e-002	 7.531006e+002
 3.124005e+002	 1.697204e+000	 1.372891e+004	 1.869827e-001	 3.353172e+000	 2.884908e-002	 7.547234e+002
 3.136205e+002	 1.708132e+000	 1.373909e+004	 1.878022e-001	 3.374763e+000	 2.905564e-002	 7.554409e+002
 3.159005e+002	 1.728110e+000	 1.376054e+004	 1.893677e-001	 3.414234e+000	 2.943224e-002	 7.569089e+002
 3.172405e+002	 1.740693e+000	 1.377614e+004	 1.918563e-001	 3.439094e+000	 2.966870e-002	 7.579494e+002
 3.189005e+002	 1.754912e+000	 1.379266e+004	 1.927497e-001	 3.467187e+000	 2.993620e-002	 7.590645e+002
 3.208806e+002	 1.771806e+000	 1.380618e+004	 1.955603e-001	 3.500563e+000	 3.025583e-002	 7.600535e+002
 3.220805e+002	 1.785728e+000	 1.381753e+004	 1.948686e-001	 3.528070e+000	 3.051911e-002	 7.608805e+002
 3.245005e+002	 1.805172e+000	 1.383781e+004	 1.978914e-001	 3.566485e+000	 3.088529e-002	 7.622798e+002
 3.257206e+002	 1.815813e+000	 1.384866e+004	 1.987683e-001	 3.587508e+000	 3.108570e-002	 7.630322e+002
 3.279005e+002	 1.836053e+000	 1.386960e+004	 2.009063e-001	 3.627497e+000	 3.146671e-002	 7.644812e+002
 3.293405e+002	 1.849924e+000	 1.388321e+004	 2.021052e-001	 3.654901e+000	 3.172797e-002	 7.654333e+002
 3.309005e+002	 1.863034e+000	 1.389447e+004	 2.036018e-001	 3.680803e+000	 3.197534e-002	 7.662458e+002
 3.329605e+002	 1.880610e+000	 1.391475e+004	 2.077999e-001	 3.715528e+000	 3.230527e-002	 7.676210e+002
 3.341805e+002	 1.892600e+000	 1.392301e+004	 2.053116e-001	 3.739216e+000	 3.253200e-002	 7.682521e+002
 3.366006e+002	 1.913144e+000	 1.394446e+004	 2.088694e-001	 3.779806e+000	 3.291812e-002	 7.697365e+002
 3.378005e+002	 1.924297e+000	 1.395731e+004	 2.110114e-001	 3.801841e+000	 3.312730e-002	 7.706094e+002
 3.399005e+002	 1.943094e+000	 1.397233e+004	 2.133577e-001	 3.838979e+000	 3.348182e-002	 7.717147e+002
 3.414406e+002	 1.957556e+000	 1.398601e+004	 2.147649e-001	 3.867550e+000	 3.375381e-002	 7.726831e+002
 3.429005e+002	 1.970541e+000	 1.399636e+004	 2.173378e-001	 3.893204e+000	 3.399857e-002	 7.734457e+002
 3.450605e+002	 1.990464e+000	 1.401672e+004	 2.192416e-001	 3.932567e+000	 3.437261e-002	 7.748643e+002
 3.462805e+002	 2.000319e+000	 1.402724e+004	 2.181945e-001	 3.952036e+000	 3.455742e-002	 7.755908e+002
 3.487006e+002	 2.021982e+000	 1.404743e+004	 2.215905e-001	 3.994837e+000	 3.496450e-002	 7.770271e+002
 3.499005e+002	 2.034641e+000	 1.405452e+004	 2.237974e-001	 4.019847e+000	 3.520376e-002	 7.776064e+002
 3.519005e+002	 2.052459e+000	 1.406946e+004	 2.246439e-001	 4.055050e+000	 3.553890e-002	 7.786963e+002
 3.535406e+002	 2.067769e+000	 1.408365e+004	 2.255068e-001	 4.085298e+000	 3.582636e-002	 7.797079e+002
 3.549005e+002	 2.079420e+000	 1.409216e+004	 2.261203e-001	 4.108317e+000	 3.604577e-002	 7.803517e+002
 3.571805e+002	 2.100196e+000	 1.410901e+004	 2.291760e-001	 4.149365e+000	 3.643638e-002	 7.815931e+002
 3.583806e+002	 2.110039e+000	 1.412137e+004	 2.317267e-001	 4.168812e+000	 3.662003e-002	 7.824233e+002
 3.608005e+002	 2.132254e+000	 1.413872e+004	 2.321769e-001	 4.212703e+000	 3.703765e-002	 7.837151e+002
 3.620205e+002	 2.143436e+000	 1.414431e+004	 2.347645e-001	 4.234794e+000	 3.724877e-002	 7.841911e+002
 3.639005e+002	 2.160575e+000	 1.416317e+004	 2.364679e-001	 4.268656e+000	 3.756908e-002	 7.854918e+002
 3.656405e+002	 2.176305e+000	 1.417310e+004	 2.381714e-001	 4.299733e+000	 3.786527e-002	 7.862767e+002
 3.669005e+002	 2.188515e+000	 1.418470e+004	 2.404066e-001	 4.323858e+000	 3.809391e-002	 7.871022e+002
 3.692805e+002	 2.211729e+000	 1.420173e+004	 2.427821e-001	 4.369720e+000	 3.853000e-002	 7.883932e+002
 3.704806e+002	 2.222211e+000	 1.420740e+004	 2.448113e-001	 4.390430e+000	 3.872748e-002	 7.888647e+002
 3.729005e+002	 2.244656e+000	 1.422434e+004	 2.464168e-001	 4.434776e+000	 3.914874e-002	 7.901407e+002
 3.753206e+002	 2.267349e+000	 1.424145e+004	 2.475659e-001	 4.479610e+000	 3.957446e-002	 7.914305e+002
 3.765406e+002	 2.278293e+000	 1.425229e+004	 2.480180e-001	 4.501231e+000	 3.977889e-002	 7.921973e+002
 3.789005e+002	 2.300288e+000	 1.426790e+004	 2.494525e-001	 4.544687e+000	 4.019158e-002	 7.933944e+002
 3.801805e+002	 2.312497e+000	 1.427449e+004	 2.520386e-001	 4.568808e+000	 4.042121e-002	 7.939441e+002
 3.819005e+002	 2.327725e+000	 1.428442e+004	 2.534345e-001	 4.598894e+000	 4.070703e-002	 7.947249e+002
 3.838005e+002	 2.346625e+000	 1.429969e+004	 2.557609e-001	 4.636236e+000	 4.106075e-002	 7.958586e+002
 3.850205e+002	 2.357872e+000	 1.430420e+004	 2.575527e-001	 4.658457e+000	 4.127260e-002	 7.962784e+002
 3.874406e+002	 2.381394e+000	 1.431813e+004	 2.599417e-001	 4.704928e+000	 4.171410e-002	 7.974080e+002
 3.886405e+002	 2.393214e+000	 1.432823e+004	 2.596239e-001	 4.728281e+000	 4.193493e-002	 7.981483e+002
 3.909005e+002	 2.413341e+000	 1.434300e+004	 2.629494e-001	 4.768046e+000	 4.231160e-002	 7.992743e+002
 3.922805e+002	 2.427083e+000	 1.435060e+004	 2.634351e-001	 4.795197e+000	 4.256948e-002	 7.999047e+002
 3.939005e+002	 2.442259e+000	 1.436195e+004	 2.631663e-001	 4.825180e+000	 4.285326e-002	 8.007663e+002
 3.959005e+002	 2.460778e+000	 1.437046e+004	 2.662907e-001	 4.861769e+000	 4.320110e-002	 8.015206e+002
 3.971006e+002	 2.472990e+000	 1.437897e+004	 2.664834e-001	 4.885895e+000	 4.342950e-002	 8.021798e+002
 3.995406e+002	 2.495492e+000	 1.439215e+004	 2.696190e-001	 4.930352e+000	 4.385101e-002	 8.032556e+002
 4.007606e+002	 2.508415e+000	 1.439783e+004	 2.711164e-001	 4.955884e+000	 4.409359e-002	 8.037678e+002
 4.029005e+002	 2.528132e+000	 1.441327e+004	 2.730922e-001	 4.994839e+000	 4.446149e-002	 8.049282e+002
 4.043806e+002	 2.542207e+000	 1.442253e+004	 2.735618e-001	 5.022648e+000	 4.472459e-002	 8.056588e+002
 4.059005e+002	 2.556651e+000	 1.443154e+004	 2.763572e-001	 5.051185e+000	 4.499466e-002	 8.063812e+002
 4.080205e+002	 2.577470e+000	 1.444022e+004	 2.789054e-001	 5.092316e+000	 4.538511e-002	 8.071820e+002
 4.092206e+002	 2.588834e+000	 1.444931e+004	 2.792431e-001	 5.114768e+000	 4.559684e-002	 8.078630e+002
 4.116405e+002	 2.610262e+000	 1.446217e+004	 2.821126e-001	 5.157103e+000	 4.599727e-002	 8.089071e+002
 4.128605e+002	 2.621321e+000	 1.446851e+004	 2.817856e-001	 5.178954e+000	 4.620398e-002	 8.094300e+002
 4.149005e+002	 2.643700e+000	 1.447777e+004	 2.835847e-001	 5.223167e+000	 4.662320e-002	 8.102886e+002
 4.164806e+002	 2.659437e+000	 1.448795e+004	 2.848644e-001	 5.254259e+000	 4.691677e-002	 8.110979e+002
 4.179005e+002	 2.670781e+000	 1.449329e+004	 2.874129e-001	 5.276671e+000	 4.712895e-002	 8.115697e+002
 4.201205e+002	 2.692855e+000	 1.450606e+004	 2.896996e-001	 5.320284e+000	 4.754098e-002	 8.126210e+002
 4.213405e+002	 2.704390e+000	 1.451048e+004	 2.911158e-001	 5.343073e+000	 4.775690e-002	 8.130447e+002
 4.237606e+002	 2.726871e+000	 1.452300e+004	 2.924224e-001	 5.387490e+000	 4.817641e-002	 8.140890e+002
 4.249605e+002	 2.740482e+000	 1.453134e+004	 2.954814e-001	 5.414380e+000	 4.843007e-002	 8.147646e+002
 4.269005e+002	 2.759086e+000	 1.453986e+004	 2.965440e-001	 5.451135e+000	 4.877756e-002	 8.155261e+002
 4.286006e+002	 2.773936e+000	 1.454570e+004	 2.977064e-001	 5.480475e+000	 4.905515e-002	 8.160807e+002
 4.299005e+002	 2.785679e+000	 1.455521e+004	 2.987714e-001	 5.503677e+000	 4.927311e-002	 8.167940e+002
 4.322206e+002	 2.808959e+000	 1.456748e+004	 3.022296e-001	 5.549670e+000	 4.970706e-002	 8.178387e+002
 4.334406e+002	 2.820044e+000	 1.457307e+004	 3.033962e-001	 5.571572e+000	 4.991372e-002	 8.183223e+002
 4.358605e+002	 2.844118e+000	 1.458600e+004	 3.061745e-001	 5.619133e+000	 5.036210e-002	 8.194175e+002
 4.370605e+002	 2.854878e+000	 1.459068e+004	 3.064627e-001	 5.640393e+000	 5.056279e-002	 8.198451e+002
 4.389005e+002	 2.872465e+000	 1.459568e+004	 3.095427e-001	 5.675139e+000	 5.089153e-002	 8.203961e+002
 4.407006e+002	 2.889169e+000	 1.460887e+004	 3.093520e-001	 5.708142e+000	 5.120109e-002	 8.213936e+002
 4.419205e+002	 2.901165e+000	 1.461287e+004	 3.124894e-001	 5.731842e+000	 5.142501e-002	 8.218029e+002
 4.443405e+002	 2.923172e+000	 1.462222e+004	 3.139632e-001	 5.775321e+000	 5.183505e-002	 8.226667e+002
 4.455406e+002	 2.935179e+000	 1.463257e+004	 3.160430e-001	 5.799043e+000	 5.205708e-002	 8.234334e+002
 4.479005e+002	 2.958500e+000	 1.464300e+004	 3.167497e-001	 5.845119e+000	 5.249118e-002	 8.243792e+002
 4.491805e+002	 2.969113e+000	 1.464558e+004	 3.181814e-001	 5.866086e+000	 5.268932e-002	 8.246882e+002
 4.509005e+002	 2.983936e+000	 1.465576e+004	 3.209143e-001	 5.895372e+000	 5.296398e-002	 8.254897e+002
 4.528005e+002	 3.004076e+000	 1.466353e+004	 3.220677e-001	 5.935163e+000	 5.333892e-002	 8.262371e+002
 4.540205e+002	 3.013864e+000	 1.466820e+004	 3.236535e-001	 5.954502e+000	 5.352081e-002	 8.266513e+002
 4.564406e+002	 3.037765e+000	 1.467788e+004	 3.256094e-001	 6.001722e+000	 5.396534e-002	 8.275654e+002
 4.576405e+002	 3.049305e+000	 1.468247e+004	 3.281244e-001	 6.024524e+000	 5.417995e-002	 8.280022e+002
 4.599005e+002	 3.071736e+000	 1.469540e+004	 3.295932e-001	 6.068839e+000	 5.459568e-002	 8.290780e+002
 4.612805e+002	 3.084894e+000	 1.469849e+004	 3.318397e-001	 6.094836e+000	 5.484086e-002	 8.294554e+002
 4.629005e+002	 3.097176e+000	 1.470683e+004	 3.346576e-001	 6.119102e+000	 5.506800e-002	 8.301161e+002
 4.649205e+002	 3.117163e+000	 1.471551e+004	 3.334177e-001	 6.158591e+000	 5.543900e-002	 8.309149e+002
 4.661405e+002	 3.128404e+000	 1.471893e+004	 3.369699e-001	 6.180799e+000	 5.564804e-002	 8.312820e+002
 4.685605e+002	 3.152134e+000	 1.473229e+004	 3.400024e-001	 6.227682e+000	 5.608731e-002	 8.324034e+002
 4.697805e+002	 3.163136e+000	 1.473471e+004	 3.404220e-001	 6.249418e+000	 5.629206e-002	 8.327104e+002
 4.719005e+002	 3.183729e+000	 1.474247e+004	 3.425688e-001	 6.290105e+000	 5.667422e-002	 8.334680e+002
 4.734005e+002	 3.197358e+000	 1.475231e+004	 3.433111e-001	 6.317032e+000	 5.692561e-002	 8.342359e+002
 4.749005e+002	 3.212643e+000	 1.475699e+004	 3.458753e-001	 6.347231e+000	 5.720942e-002	 8.347372e+002
 4.770605e+002	 3.232629e+000	 1.476433e+004	 3.462741e-001	 6.386716e+000	 5.758000e-002	 8.354626e+002
 4.782606e+002	 3.242991e+000	 1.477251e+004	 3.484085e-001	 6.407188e+000	 5.777076e-002	 8.360862e+002
 4.807006e+002	 3.266993e+000	 1.477902e+004	 3.503622e-001	 6.454610e+000	 5.821627e-002	 8.368273e+002
 4.819005e+002	 3.278742e+000	 1.478603e+004	 3.520367e-001	 6.477823e+000	 5.843311e-002	 8.374067e+002
 4.839005e+002	 3.297779e+000	 1.479062e+004	 3.534311e-001	 6.515433e+000	 5.878641e-002	 8.379625e+002
 4.855406e+002	 3.312814e+000	 1.479604e+004	 3.541817e-001	 6.545139e+000	 5.906482e-002	 8.385035e+002
 4.869005e+002	 3.326446e+000	 1.480480e+004	 3.562614e-001	 6.572071e+000	 5.931598e-002	 8.392122e+002
 4.891805e+002	 3.348464e+000	 1.481056e+004	 3.606185e-001	 6.615571e+000	 5.972410e-002	 8.398812e+002
 4.904005e+002	 3.359327e+000	 1.481373e+004	 3.596952e-001	 6.637035e+000	 5.992530e-002	 8.402301e+002
 4.928206e+002	 3.382812e+000	 1.482308e+004	 3.616790e-001	 6.683434e+000	 6.035937e-002	 8.411259e+002
 4.940205e+002	 3.394449e+000	 1.482808e+004	 3.625437e-001	 6.706425e+000	 6.057426e-002	 8.415913e+002
 4.959005e+002	 3.411510e+000	 1.483543e+004	 3.661322e-001	 6.740132e+000	 6.088924e-002	 8.422741e+002
 4.976606e+002	 3.429569e+000	 1.484102e+004	 3.668430e-001	 6.775811e+000	 6.122320e-002	 8.428731e+002
 4.989005e+002	 3.441417e+000	 1.484594e+004	 3.694003e-001	 6.799219e+000	 6.144186e-002	 8.433375e+002
 5.012805e+002	 3.463919e+000	 1.485362e+004	 3.711986e-001	 6.843677e+000	 6.185752e-002	 8.441248e+002
 5.025005e+002	 3.476413e+000	 1.485879e+004	 3.714870e-001	 6.868363e+000	 6.208797e-002	 8.446139e+002
 5.049005e+002	 3.500404e+000	 1.486647e+004	 3.741833e-001	 6.915761e+000	 6.253099e-002	 8.454250e+002
 5.061405e+002	 3.511975e+000	 1.487073e+004	 3.754711e-001	 6.938621e+000	 6.274442e-002	 8.458478e+002
 5.079005e+002	 3.530603e+000	 1.487573e+004	 3.778222e-001	 6.975425e+000	 6.308850e-002	 8.464238e+002
 5.097606e+002	 3.547796e+000	 1.488258e+004	 3.797539e-001	 7.009394e+000	 6.340529e-002	 8.470820e+002
 5.109806e+002	 3.560341e+000	 1.488383e+004	 3.796350e-001	 7.034179e+000	 6.363751e-002	 8.473494e+002
 5.134006e+002	 3.584832e+000	 1.489175e+004	 3.839577e-001	 7.082565e+000	 6.408903e-002	 8.481839e+002
 5.146005e+002	 3.596147e+000	 1.489801e+004	 3.840804e-001	 7.104920e+000	 6.429678e-002	 8.487175e+002
 5.169006e+002	 3.618750e+000	 1.490561e+004	 3.861827e-001	 7.149577e+000	 6.471316e-002	 8.495041e+002
 5.182405e+002	 3.631722e+000	 1.490494e+004	 3.881802e-001	 7.175207e+000	 6.495357e-002	 8.496692e+002
 5.199006e+002	 3.649280e+000	 1.491328e+004	 3.904393e-001	 7.209896e+000	 6.527606e-002	 8.504200e+002
 5.218605e+002	 3.664490e+000	 1.491779e+004	 3.919050e-001	 7.239946e+000	 6.555617e-002	 8.509154e+002
 5.230806e+002	 3.678739e+000	 1.491954e+004	 3.926140e-001	 7.268098e+000	 6.581926e-002	 8.512387e+002
 5.254805e+002	 3.703077e+000	 1.492830e+004	 3.968185e-001	 7.316182e+000	 6.626672e-002	 8.521204e+002
 5.267006e+002	 3.715189e+000	 1.492856e+004	 3.979634e-001	 7.340113e+000	 6.649059e-002	 8.523247e+002
 5.289006e+002	 3.738307e+000	 1.493799e+004	 3.989542e-001	 7.385787e+000	 6.691501e-002	 8.532259e+002
 5.303005e+002	 3.751688e+000	 1.494366e+004	 4.004700e-001	 7.412223e+000	 6.716051e-002	 8.537601e+002
 5.319006e+002	 3.768195e+000	 1.494741e+004	 4.027003e-001	 7.444837e+000	 6.746428e-002	 8.542338e+002
 5.339406e+002	 3.788507e+000	 1.494892e+004	 4.042833e-001	 7.484966e+000	 6.783887e-002	 8.546388e+002
 5.351406e+002	 3.799481e+000	 1.495684e+004	 4.055791e-001	 7.506649e+000	 6.803906e-002	 8.552644e+002
 5.375605e+002	 3.825028e+000	 1.496285e+004	 4.069694e-001	 7.557122e+000	 6.850867e-002	 8.560096e+002
 5.387805e+002	 3.835280e+000	 1.496444e+004	 4.095007e-001	 7.577376e+000	 6.869730e-002	 8.562615e+002
 5.409006e+002	 3.859009e+000	 1.496828e+004	 4.114627e-001	 7.624258e+000	 6.913374e-002	 8.568544e+002
 5.424006e+002	 3.874378e+000	 1.497771e+004	 4.138253e-001	 7.654622e+000	 6.941422e-002	 8.576360e+002
 5.439006e+002	 3.885334e+000	 1.497637e+004	 4.132530e-001	 7.676267e+000	 6.961653e-002	 8.577320e+002
 5.460405e+002	 3.908195e+000	 1.498355e+004	 4.171836e-001	 7.721434e+000	 7.003557e-002	 8.585029e+002
 5.472606e+002	 3.920780e+000	 1.498230e+004	 4.192933e-001	 7.746299e+000	 7.026776e-002	 8.586293e+002
 5.496805e+002	 3.945220e+000	 1.498880e+004	 4.203104e-001	 7.794586e+000	 7.071580e-002	 8.593872e+002
 5.508806e+002	 3.957154e+000	 1.499423e+004	 4.202566e-001	 7.818164e+000	 7.093382e-002	 8.598862e+002
 5.529006e+002	 3.975724e+000	 1.499798e+004	 4.239959e-001	 7.854852e+000	 7.127440e-002	 8.603941e+002
 5.545005e+002	 3.991844e+000	 1.500132e+004	 4.239454e-001	 7.886701e+000	 7.156992e-002	 8.608398e+002
 5.559006e+002	 4.007410e+000	 1.500833e+004	 4.253568e-001	 7.917454e+000	 7.185407e-002	 8.614874e+002
 5.581205e+002	 4.026636e+000	 1.501175e+004	 4.280018e-001	 7.955438e+000	 7.220648e-002	 8.619871e+002
 5.593406e+002	 4.038529e+000	 1.501376e+004	 4.310145e-001	 7.978937e+000	 7.242447e-002	 8.622897e+002
 5.617606e+002	 4.062463e+000	 1.502043e+004	 4.320429e-001	 8.026223e+000	 7.286220e-002	 8.630509e+002
 5.629606e+002	 4.074048e+000	 1.502519e+004	 4.336373e-001	 8.049110e+000	 7.307353e-002	 8.635070e+002
 5.649006e+002	 4.094504e+000	 1.502803e+004	 4.334052e-001	 8.089527e+000	 7.344829e-002	 8.639931e+002
 5.666005e+002	 4.111306e+000	 1.503403e+004	 4.370964e-001	 8.122721e+000	 7.375488e-002	 8.646039e+002
 5.679006e+002	 4.124482e+000	 1.503645e+004	 4.387326e-001	 8.148754e+000	 7.399594e-002	 8.649512e+002
 5.702405e+002	 4.147774e+000	 1.504029e+004	 4.415026e-001	 8.194771e+000	 7.442205e-002	 8.655401e+002
 5.714406e+002	 4.157019e+000	 1.504455e+004	 4.409938e-001	 8.213038e+000	 7.459032e-002	 8.659312e+002
 5.738605e+002	 4.183310e+000	 1.505181e+004	 4.442310e-001	 8.264981e+000	 7.507012e-002	 8.667648e+002
 5.750806e+002	 4.192103e+000	 1.505381e+004	 4.470234e-001	 8.282353e+000	 7.523067e-002	 8.670193e+002
 5.769006e+002	 4.211878e+000	 1.505623e+004	 4.492975e-001	 8.321423e+000	 7.559227e-002	 8.674715e+002
 5.787006e+002	 4.228709e+000	 1.506124e+004	 4.485096e-001	 8.354676e+000	 7.589904e-002	 8.680263e+002
 5.799205e+002	 4.240312e+000	 1.506207e+004	 4.510482e-001	 8.377600e+000	 7.611125e-002	 8.682580e+002
 5.823406e+002	 4.265732e+000	 1.506691e+004	 4.538411e-001	 8.427823e+000	 7.657511e-002	 8.689394e+002
 5.835405e+002	 4.277417e+000	 1.507058e+004	 4.539882e-001	 8.450908e+000	 7.678783e-002	 8.693362e+002
 5.859006e+002	 4.300659e+000	 1.507601e+004	 4.573402e-001	 8.496828e+000	 7.721137e-002	 8.700173e+002
 5.871605e+002	 4.313603e+000	 1.507559e+004	 4.584206e-001	 8.522401e+000	 7.744819e-002	 8.701982e+002
 5.889006e+002	 4.330248e+000	 1.508126e+004	 4.597135e-001	 8.555287e+000	 7.775081e-002	 8.707895e+002
 5.907805e+002	 4.350265e+000	 1.508285e+004	 4.619950e-001	 8.594834e+000	 7.811615e-002	 8.711983e+002
 5.920005e+002	 4.361447e+000	 1.508727e+004	 4.629257e-001	 8.616927e+000	 7.831914e-002	 8.716310e+002
 5.944205e+002	 4.385081e+000	 1.509270e+004	 4.636724e-001	 8.663621e+000	 7.874919e-002	 8.723191e+002
 5.956205e+002	 4.397360e+000	 1.509362e+004	 4.673482e-001	 8.687880e+000	 7.897310e-002	 8.725669e+002
 5.979006e+002	 4.419816e+000	 1.509829e+004	 4.690466e-001	 8.732247e+000	 7.938161e-002	 8.731933e+002
 5.992606e+002	 4.432841e+000	 1.509921e+004	 4.705968e-001	 8.757980e+000	 7.961899e-002	 8.734530e+002
 6.009006e+002	 4.450044e+000	 1.510380e+004	 4.747058e-001	 8.791967e+000	 7.993144e-002	 8.739915e+002
 6.028806e+002	 4.467774e+000	 1.510822e+004	 4.766621e-001	 8.826998e+000	 8.025347e-002	 8.745289e+002
 6.040806e+002	 4.481387e+000	 1.511297e+004	 4.747475e-001	 8.853892e+000	 8.050021e-002	 8.750204e+002
 6.065005e+002	 4.505407e+000	 1.511715e+004	 4.780286e-001	 8.901349e+000	 8.093675e-002	 8.756435e+002
 6.077405e+002	 4.516704e+000	 1.511489e+004	 4.803552e-001	 8.923668e+000	 8.114322e-002	 8.756924e+002
 6.099006e+002	 4.537782e+000	 1.511923e+004	 4.821523e-001	 8.965313e+000	 8.152585e-002	 8.762786e+002
 6.113605e+002	 4.552003e+000	 1.512474e+004	 4.848484e-001	 8.993409e+000	 8.178315e-002	 8.768238e+002
 6.129006e+002	 4.565810e+000	 1.512649e+004	 4.872850e-001	 9.020688e+000	 8.203396e-002	 8.771448e+002
 6.150005e+002	 4.587847e+000	 1.513125e+004	 4.876079e-001	 9.064226e+000	 8.243356e-002	 8.777710e+002
 6.162006e+002	 4.599077e+000	 1.513067e+004	 4.864448e-001	 9.086412e+000	 8.263801e-002	 8.779157e+002
 6.186005e+002	 4.625284e+000	 1.513459e+004	 4.907484e-001	 9.138191e+000	 8.311345e-002	 8.785600e+002
 6.198206e+002	 4.634903e+000	 1.513742e+004	 4.907649e-001	 9.157194e+000	 8.328747e-002	 8.788776e+002
 6.219006e+002	 4.658985e+000	 1.514018e+004	 4.924428e-001	 9.204774e+000	 8.372433e-002	 8.794206e+002
 6.234606e+002	 4.673578e+000	 1.514076e+004	 4.947656e-001	 9.233605e+000	 8.398928e-002	 8.796867e+002
 6.249006e+002	 4.690004e+000	 1.514819e+004	 4.954897e-001	 9.266057e+000	 8.428541e-002	 8.803796e+002
 6.270806e+002	 4.709252e+000	 1.514794e+004	 5.033044e-001	 9.304087e+000	 8.463497e-002	 8.806714e+002
 6.283005e+002	 4.720647e+000	 1.514727e+004	 4.997318e-001	 9.326599e+000	 8.484200e-002	 8.808140e+002
 6.307205e+002	 4.746515e+000	 1.515245e+004	 5.036231e-001	 9.377706e+000	 8.530986e-002	 8.815266e+002
 6.319205e+002	 4.758672e+000	 1.515687e+004	 5.042029e-001	 9.401726e+000	 8.552908e-002	 8.819776e+002
 6.339006e+002	 4.777321e+000	 1.515787e+004	 5.051876e-001	 9.438570e+000	 8.586696e-002	 8.823329e+002
 6.355605e+002	 4.793819e+000	 1.516254e+004	 5.062367e-001	 9.471166e+000	 8.616467e-002	 8.828677e+002
 6.369006e+002	 4.806087e+000	 1.516221e+004	 5.086229e-001	 9.495403e+000	 8.638711e-002	 8.830437e+002
 6.391805e+002	 4.830327e+000	 1.516480e+004	 5.103572e-001	 9.543294e+000	 8.682552e-002	 8.835806e+002
 6.403806e+002	 4.840987e+000	 1.516772e+004	 5.109304e-001	 9.564355e+000	 8.701772e-002	 8.839207e+002
 6.428005e+002	 4.866772e+000	 1.517022e+004	 5.126216e-001	 9.615298e+000	 8.748385e-002	 8.844775e+002
 6.440005e+002	 4.879888e+000	 1.517105e+004	 5.157569e-001	 9.641212e+000	 8.772101e-002	 8.847353e+002
 6.459006e+002	 4.898621e+000	 1.517406e+004	 5.171413e-001	 9.678223e+000	 8.805909e-002	 8.852091e+002
 6.476406e+002	 4.916532e+000	 1.517690e+004	 5.170168e-001	 9.713610e+000	 8.838224e-002	 8.856602e+002
 6.489006e+002	 4.927656e+000	 1.517623e+004	 5.215118e-001	 9.735587e+000	 8.858359e-002	 8.857987e+002
 6.512805e+002	 4.951226e+000	 1.517840e+004	 5.223295e-001	 9.782155e+000	 8.900907e-002	 8.863012e+002
 6.524805e+002	 4.961463e+000	 1.518299e+004	 5.218853e-001	 9.802380e+000	 8.919272e-002	 8.867325e+002
 6.549006e+002	 4.984632e+000	 1.518424e+004	 5.257043e-001	 9.848155e+000	 8.961095e-002	 8.871753e+002
 6.573206e+002	 5.007877e+000	 1.518691e+004	 5.265073e-001	 9.894080e+000	 9.002996e-002	 8.877022e+002
 6.585405e+002	 5.020566e+000	 1.518624e+004	 5.287168e-001	 9.919149e+000	 9.025924e-002	 8.878656e+002
 6.609006e+002	 5.043602e+000	 1.518883e+004	 5.297662e-001	 9.964663e+000	 9.067425e-002	 8.883845e+002
 6.621605e+002	 5.056670e+000	 1.518991e+004	 5.333745e-001	 9.990481e+000	 9.090970e-002	 8.886565e+002
 6.639006e+002	 5.073318e+000	 1.519083e+004	 5.319916e-001	 1.002337e+001	 9.120970e-002	 8.889760e+002
 6.657805e+002	 5.090191e+000	 1.519559e+004	 5.338784e-001	 1.005671e+001	 9.151257e-002	 8.895237e+002
 6.670005e+002	 5.103609e+000	 1.519417e+004	 5.366675e-001	 1.008322e+001	 9.175486e-002	 8.896549e+002
 6.694205e+002	 5.125305e+000	 1.519809e+004	 5.365617e-001	 1.012608e+001	 9.214471e-002	 8.902310e+002
 6.706205e+002	 5.135354e+000	 1.520051e+004	 5.403768e-001	 1.014594e+001	 9.232504e-002	 8.905332e+002
 6.729006e+002	 5.157321e+000	 1.520443e+004	 5.407895e-001	 1.018934e+001	 9.271954e-002	 8.911139e+002
 6.742606e+002	 5.170915e+000	 1.520301e+004	 5.433115e-001	 1.021619e+001	 9.296471e-002	 8.912479e+002
 6.759006e+002	 5.187296e+000	 1.520518e+004	 5.453900e-001	 1.024856e+001	 9.325895e-002	 8.916368e+002
 6.778806e+002	 5.206241e+000	 1.520852e+004	 5.453109e-001	 1.028599e+001	 9.359886e-002	 8.921352e+002
 6.791005e+002	 5.216045e+000	 1.520869e+004	 5.462304e-001	 1.030536e+001	 9.377520e-002	 8.923017e+002
 6.815206e+002	 5.238425e+000	 1.521019e+004	 5.492476e-001	 1.034957e+001	 9.417725e-002	 8.927475e+002
 6.827205e+002	 5.251616e+000	 1.521069e+004	 5.503020e-001	 1.037564e+001	 9.441427e-002	 8.929877e+002
 6.849006e+002	 5.271611e+000	 1.521361e+004	 5.526564e-001	 1.041514e+001	 9.477280e-002	 8.934788e+002
 6.863406e+002	 5.286029e+000	 1.521562e+004	 5.555547e-001	 1.044363e+001	 9.503128e-002	 8.938269e+002
 6.879006e+002	 5.299846e+000	 1.521645e+004	 5.534309e-001	 1.047093e+001	 9.527924e-002	 8.940968e+002
 6.899606e+002	 5.318039e+000	 1.521495e+004	 5.588841e-001	 1.050687e+001	 9.560641e-002	 8.942994e+002
 6.911605e+002	 5.328944e+000	 1.521879e+004	 5.585216e-001	 1.052841e+001	 9.580105e-002	 8.946994e+002
 6.935806e+002	 5.354044e+000	 1.521987e+004	 5.611283e-001	 1.057800e+001	 9.625124e-002	 8.951646e+002
 6.948005e+002	 5.366126e+000	 1.521845e+004	 5.622414e-001	 1.060187e+001	 9.646843e-002	 8.952743e+002
 6.969006e+002	 5.385787e+000	 1.522388e+004	 5.626383e-001	 1.064072e+001	 9.681949e-002	 8.959079e+002
 6.984205e+002	 5.399284e+000	 1.522371e+004	 5.650575e-001	 1.066738e+001	 9.706157e-002	 8.961140e+002
 6.999006e+002	 5.414214e+000	 1.522696e+004	 5.659050e-001	 1.069688e+001	 9.732826e-002	 8.965444e+002
 7.020605e+002	 5.433886e+000	 1.522446e+004	 5.705328e-001	 1.073575e+001	 9.768155e-002	 8.967117e+002
 7.032606e+002	 5.444885e+000	 1.522563e+004	 5.701614e-001	 1.075748e+001	 9.787828e-002	 8.969564e+002
 7.056805e+002	 5.469194e+000	 1.522713e+004	 5.691698e-001	 1.080551e+001	 9.831324e-002	 8.974339e+002
 7.069006e+002	 5.477502e+000	 1.522671e+004	 5.713319e-001	 1.082192e+001	 9.846212e-002	 8.975422e+002
 7.089006e+002	 5.496303e+000	 1.522963e+004	 5.767844e-001	 1.085907e+001	 9.879783e-002	 8.980152e+002
 7.105005e+002	 5.511499e+000	 1.523164e+004	 5.759647e-001	 1.088909e+001	 9.906919e-002	 8.983765e+002
 7.119006e+002	 5.522647e+000	 1.523164e+004	 5.771322e-001	 1.091111e+001	 9.926865e-002	 8.985549e+002
 7.141406e+002	 5.542137e+000	 1.523014e+004	 5.765184e-001	 1.094962e+001	 9.961770e-002	 8.987782e+002
 7.153406e+002	 5.554995e+000	 1.523180e+004	 5.804524e-001	 1.097502e+001	 9.984713e-002	 8.990824e+002
 7.177606e+002	 5.575092e+000	 1.523139e+004	 5.803325e-001	 1.101473e+001	 1.002065e-001	 8.993795e+002
 7.189606e+002	 5.586441e+000	 1.523322e+004	 5.783594e-001	 1.103715e+001	 1.004088e-001	 8.996694e+002
 7.209006e+002	 5.603939e+000	 1.523022e+004	 5.834630e-001	 1.107172e+001	 1.007223e-001	 8.997720e+002
 7.226005e+002	 5.618555e+000	 1.523172e+004	 5.837554e-001	 1.110060e+001	 1.009829e-001	 9.000947e+002
 7.239006e+002	 5.630639e+000	 1.522997e+004	 5.837508e-001	 1.112447e+001	           0.0	           0.0
 7.262006e+002	 5.650898e+000	 1.523356e+004	 5.875464e-001	 1.116450e+001	           0.0	           0.0
 7.274205e+002	 5.661858e+000	 1.523214e+004	 5.884364e-001	 1.118615e+001	           0.0	           0.0
 7.298406e+002	 5.683048e+000	 1.523264e+004	 5.909711e-001	 1.122802e+001	           0.0	           0.0
 7.310405e+002	 5.693291e+000	 1.523072e+004	 5.888594e-001	 1.124826e+001	           0.0	           0.0
 7.329006e+002	 5.709089e+000	 1.522905e+004	 5.915679e-001	 1.127947e+001	           0.0	           0.0
 7.346805e+002	 5.723056e+000	 1.523089e+004	 5.915399e-001	 1.130706e+001	           0.0	           0.0
 7.371005e+002	 5.744195e+000	 1.522988e+004	 5.958225e-001	 1.134883e+001	           0.0	           0.0
 7.389006e+002	 5.757859e+000	 1.522972e+004	 5.948850e-001	 1.137582e+001	           0.0	           0.0
 7.407405e+002	 5.772837e+000	 1.522797e+004	 5.972632e-001	 1.140542e+001	           0.0	           0.0
 7.419606e+002	 5.782195e+000	 1.522855e+004	 5.980012e-001	 1.142390e+001	           0.0	           0.0
 7.443806e+002	 5.801727e+000	 1.522688e+004	 6.018890e-001	 1.146249e+001	           0.0	           0.0
 7.456005e+002	 5.810647e+000	 1.522563e+004	 5.998554e-001	 1.148012e+001	           0.0	           0.0
 7.479006e+002	 5.828197e+000	 1.522162e+004	 6.011188e-001	 1.151479e+001	           0.0	           0.0
 7.492205e+002	 5.838085e+000	 1.522404e+004	 6.043043e-001	 1.153432e+001	           0.0	           0.0
 7.509006e+002	 5.850780e+000	 1.521912e+004	 6.033025e-001	 1.155941e+001	           0.0	           0.0
 7.528605e+002	 5.864784e+000	 1.521578e+004	 6.033474e-001	 1.158708e+001	           0.0	           0.0
 7.540605e+002	 5.873271e+000	 1.521687e+004	 6.055374e-001	 1.160384e+001	           0.0	           0.0
 7.564805e+002	 5.888317e+000	 1.521236e+004	 6.059254e-001	 1.163357e+001	           0.0	           0.0
 7.576805e+002	 5.900405e+000	 1.521069e+004	 6.079644e-001	 1.165745e+001	           0.0	           0.0
 7.599006e+002	 5.914294e+000	 1.520585e+004	 6.092430e-001	 1.168489e+001	           0.0	           0.0
 7.613206e+002	 5.925789e+000	 1.520301e+004	 6.097624e-001	 1.170760e+001	           0.0	           0.0
 7.629006e+002	 5.933978e+000	 1.520343e+004	 6.090906e-001	 1.172378e+001	           0.0	           0.0
 7.649406e+002	 5.950257e+000	 1.520001e+004	 6.119921e-001	 1.175594e+001	           0.0	           0.0
 7.661605e+002	 5.957478e+000	 1.519200e+004	 6.121216e-001	 1.177021e+001	           0.0	           0.0
 7.685806e+002	 5.972889e+000	 1.518608e+004	 6.117504e-001	 1.180066e+001	           0.0	           0.0
 7.697805e+002	 5.983231e+000	 1.518499e+004	 6.128924e-001	 1.182109e+001	           0.0	           0.0
 7.719006e+002	 5.994407e+000	 1.517898e+004	 6.120239e-001	 1.184317e+001	           0.0	           0.0
 7.734205e+002	 6.005089e+000	 1.517581e+004	 6.139014e-001	 1.186428e+001	           0.0	           0.0
 7.749006e+002	 6.013090e+000	 1.516947e+004	 6.153721e-001	 1.188008e+001	           0.0	           0.0
 7.770405e+002	 6.023945e+000	 1.516505e+004	 6.150584e-001	 1.190153e+001	           0.0	           0.0
 7.782606e+002	 6.031147e+000	 1.515862e+004	 6.135305e-001	 1.191576e+001	           0.0	           0.0
 7.806805e+002	 6.044323e+000	 1.514894e+004	 6.166911e-001	 1.194179e+001	           0.0	           0.0
 7.819006e+002	 6.051731e+000	 1.514218e+004	 6.169930e-001	 1.195643e+001	           0.0	           0.0
 7.839006e+002	 6.061370e+000	 1.513467e+004	 6.166357e-001	 1.197547e+001	           0.0	           0.0
 7.855206e+002	 6.068522e+000	 1.512775e+004	 6.174638e-001	 1.198960e+001	           0.0	           0.0
 7.869006e+002	 6.075787e+000	 1.511473e+004	 6.162577e-001	 1.200395e+001	           0.0	           0.0
 7.891605e+002	 6.085137e+000	 1.510288e+004	 6.165758e-001	 1.202243e+001	           0.0	           0.0
 7.903605e+002	 6.090095e+000	 1.509645e+004	 6.180404e-001	 1.203222e+001	           0.0	           0.0
 7.927805e+002	 6.098753e+000	 1.508110e+004	 6.182699e-001	 1.204933e+001	           0.0	           0.0
 7.940005e+002	 6.103239e+000	 1.506783e+004	 6.189918e-001	 1.205819e+001	           0.0	           0.0
 7.959006e+002	 6.110696e+000	 1.505131e+004	 6.190515e-001	 1.207292e+001	           0.0	           0.0
 7.976205e+002	 6.117280e+000	 1.502928e+004	 6.165870e-001	 1.208593e+001	           0.0	           0.0
 7.989006e+002	 6.121369e+000	 1.500516e+004	 6.180159e-001	 1.209401e+001	           0.0	           0.0
 8.000405e+002	 6.124290e+000	 1.491262e+004	 6.190814e-001	 1.209978e+001	           0.0	           0.0